Workbook
Name test_Data_Enrollment_Summarizes_Data: #REF!

Sheet Quarter 1
J1: Total Number of Abbott Children | M1: ='Provider Planning Budget'!E5 -> 45
E2: Provider Reported Expenditures | F2: Provider Balance Prior to Ependiture Review | G2: Budget Modification Approved by the District | H2: District Calculated Expenditures 1st Quarter | I2: Unapproved / Approved Funds Expended (July-Sept.) | J2: DOE Share of DOE/DHS Shared Costs | M2: 0.7673
A3: Report Due Tuesday, October 15, 2019 by 3:00PM | D3: September Under Enrollment | J3: Change DOE Share of DOE/DHS Shared Costs
C4: NPS Approved | J4: DOE Share of Center-Wide Costs
A5: EXPENDITURES (Cash Paid Out) | C5: 2018-19Budget | E5: (July-Sept.) | F5: (July-Sept.) | H5: (July-Sept.) | I5: (District Use) | J5: Fund Balance | K5: . | N5: Proration Changes
A6: EDUCATIONAL PROGRAM COSTS (Instructional) 10-MONTH COST ONLY EXCLUDING BENEFITS
A7: Teacher Salary | C7: ='Provider Planning Budget'!H18 -> 169561 | D7: =C7/(A$63-C$13-C$14)*D$5*D$65 -> 0 | E7: 3452 | F7: =C7+D7-E7 -> 166109 | I7: =H7-E7 -> -3452 | J7: =IF(H7>0,(C7+D7+G7-H7),F7+G7) -> 166109
A8: Teacher Assistant Salary | C8: ='Provider Planning Budget'!H20 -> 86836 | D8: =C8/(A$63-C$13-C$14)*D$5*D$65 -> 0 | E8: 4700 | F8: =C8+D8-E8 -> 82136 | I8: =H8-E8 -> -4700 | J8: =IF(H8>0,C8-H8,F8) -> 82136
A9: Floating Teacher Assistant Salary | C9: ='Provider Planning Budget'!H21 -> 19800 | D9: =C9/(A$63-C$13-C$14)*D$5*D$65 -> 0 | E9: 863 | F9: =C9+D9-E9 -> 18937 | I9: =H9-E9 -> -863 | J9: =IF(H9>0,C9-H9,F9) -> 18937
A10: Teacher, Assistant and Floater Benefits | C10: ='Provider Planning Budget'!H23 -> 38599.75 | D10: =C10/(A$63-C$13-C$14)*D$5*D$65 -> 0 | E10: 11173 | F10: =C10+D10-E10 -> 27426.75 | I10: =H10-E10 -> -11173 | J10: =IF(H10>0,C10-H10,F10) -> 27426.75
A11: Substitute Teacher Daily Rate (Stipend) | C11: ='Provider Planning Budget'!H25 -> 3000 | D11: =C11/(A$63-C$13-C$14)*D$5*D$65 -> 0 | E11: 3338 | F11: =C11+D11-E11 -> -338 | I11: =H11-E11 -> -3338 | J11: =IF(H11>0,C11-H11,F11) -> -338
A12: Substitute Assistant Daily Rate (Stipend) | C12: ='Provider Planning Budget'!H26 -> 4800 | D12: =C12/(A$63-C$13-C$14)*D$5*D$65 -> 0 | F12: =C12+D12-E12 -> 4800 | I12: =H12-E12 -> 0 | J12: =IF(H12>0,C12-H12,F12) -> 4800
A13: Classroom Materials and Supplies | C13: ='Provider Planning Budget'!H28 -> 6000 | D13: =C13/(A$63-C$13-C$14)*D$5*D$65 -> 0 | E13: 2031 | F13: =C13+D13-E13 -> 3969 | I13: =H13-E13 -> -2031 | J13: =IF(H13>0,C13-H13,F13) -> 3969
A14: Classroom Technology | C14: ='Provider Planning Budget'!H29 -> 3000 | D14: =C14/(A$63-C$13-C$14)*D$5*D$65 -> 0 | F14: =C14+D14-E14 -> 3000 | I14: =H14-E14 -> 0 | J14: =IF(H14>0,C14-H14,F14) -> 3000
A15: Field Trips w/ Transportation | C15: ='Provider Planning Budget'!H30 -> 4500 | D15: =C15/(A$63-C$13-C$14)*D$5*D$65 -> 0 | E15: 560 | F15: =C15+D15-E15 -> 3940 | I15: =H15-E15 -> -560 | J15: =IF(H15>0,C15-H15,F15) -> 3940
A16: Family Worker Salary | C16: ='Provider Planning Budget'!H32 -> 24551.798 | D16: =C16/(A$63-C$13-C$14)*D$5*D$65 -> 0 | E16: 4870 | F16: =C16+D16-E16 -> 19681.798 | I16: =H16-E16 -> -4870 | J16: =IF(H16>0,C16-H16,F16) -> 19681.798
A17: Family Worker Benefits | C17: ='Provider Planning Budget'!H33 -> 0 | D17: =C17/(A$63-C$13-C$14)*D$5*D$65 -> 0 | F17: =C17+D17-E17 -> 0 | I17: =H17-E17 -> 0 | J17: =IF(H17>0,C17-H17,F17) -> 0
A18: Food CACFP; September - June (for contracted preschool children only) | C18: ='Provider Planning Budget'!H37 -> 0 | D18: =C18/(A$63-C$13-C$14)*D$5*D$65 -> 0 | F18: =C18+D18-E18 -> 0 | I18: =H18-E18 -> 0 | J18: =IF(H18>0,C18-H18,F18) -> 0
A19: Food Worker Salary (cook) | C19: ='Provider Planning Budget'!H38 -> 7500.4588 | D19: =C19/(A$63-C$13-C$14)*D$5*D$65 -> 0 | E19: 424 | F19: =C19+D19-E19 -> 7076.4588 | I19: =H19-E19 -> -424 | J19: =IF(H19>0,C19-H19,F19) -> 7076.4588
A20: Food Worker Salary (cook asst.) | C20: ='Provider Planning Budget'!H40 -> 0 | D20: =C20/(A$63-C$13-C$14)*D$5*D$65 -> 0 | F20: =C20+D20-E20 -> 0 | I20: =H20-E20 -> 0 | J20: =IF(H20>0,C20-H20,F20) -> 0
A21: Food Worker Benefits (Cook & Assist. Cook) | C21: ='Provider Planning Budget'!H39+'Provider Planning Budget'!H41 -> 0 | D21: =C21/(A$63-C$13-C$14)*D$5*D$65 -> 0 | F21: =C21+D21-E21 -> 0 | I21: =H21-E21 -> 0 | J21: =IF(H21>0,C21-H21,F21) -> 0
A22: Social Security (6.20%) | C22: ='Provider Planning Budget'!H44 -> 19595.054 | D22: =C22/(A$63-C$13-C$14)*D$5*D$65 -> 0 | E22: =17649*N22 -> 1094.238 | F22: =C22+D22-E22 -> 18500.816 | I22: =H22-E22 -> -1094.238 | J22: =IF(H22>0,C22-H22,F22) -> 18500.816 | N22: 0.062
A23: Medicare (1.45%) | C23: ='Provider Planning Budget'!H45 -> 4582.7142 | D23: =C23/(A$63-C$13-C$14)*D$5*D$65 -> 0 | E23: =17647*N23 -> 255.8815 | F23: =C23+D23-E23 -> 4326.8327 | I23: =H23-E23 -> -255.8815 | J23: =IF(H23>0,C23-H23,F23) -> 4326.8327 | N23: 0.0145
A24: Unemployment (2.80%) | C24: ='Provider Planning Budget'!H46 -> 8849.3792 | D24: =C24/(A$63-C$13-C$14)*D$5*D$65 -> 0 | E24: =17647*N24 -> 494.116 | F24: =C24+D24-E24 -> 8355.2632 | I24: =H24-E24 -> -494.116 | J24: =IF(H24>0,C24-H24,F24) -> 8355.2632 | N24: 0.028
A25: Disability (0.50%) | C25: ='Provider Planning Budget'!H47 -> 1580.2463 | D25: =C25/(A$63-C$13-C$14)*D$5*D$65 -> 0 | E25: =17647*N25 -> 88.235 | F25: =C25+D25-E25 -> 1492.0113 | I25: =H25-E25 -> -88.235 | J25: =IF(H25>0,C25-H25,F25) -> 1492.0113 | N25: 0.005
A26: Sub-Total | C26: =SUM(C7:C25) -> 402756.4 | D26: =SUM(D7:D25) -> 0 | E26: =SUM(E7:E25) -> 33343.471 | F26: =SUM(F7:F25) -> 369412.93 | G26: =SUM(G7:G25) -> 0 | H26: =SUM(H7:H25) -> 0 | I26: =SUM(I7:I25) -> -33343.471 | J26: =SUM(J7:J25) -> 369412.93
A27: ADMINISTRATIVE SUPPORT COSTS (NON-Instructional) 12-MONTH COST ONLY EXCLUDING BENEFITS
A28: Director Salary | C28: ='Provider Planning Budget'!H54 -> 44183.837 | D28: =C28/(A$63-C$13-C$14)*D$5*D$65 -> 0 | E28: 13288 | F28: =C28+D28-E28 -> 30895.837 | I28: =H28-E28 -> -13288 | J28: =IF(H28>0,C28-H28,F28) -> 30895.837
A29: Director Benefits | C29: ='Provider Planning Budget'!H55 -> 8103.1837 | D29: =C29/(A$63-C$13-C$14)*D$5*D$65 -> 0 | E29: 4306 | F29: =C29+D29-E29 -> 3797.1837 | I29: =H29-E29 -> -4306 | J29: =IF(H29>0,C29-H29,F29) -> 3797.1837
A30: Clerical Salary | C30: ='Provider Planning Budget'!H56 -> 3836.7347 | D30: =C30/(A$63-C$13-C$14)*D$5*D$65 -> 0 | E30: 3329 | F30: =C30+D30-E30 -> 507.73469 | I30: =H30-E30 -> -3329 | J30: =IF(H30>0,C30-H30,F30) -> 507.73469
A31: Clerical Benefits | C31: ='Provider Planning Budget'!H57 -> 0 | D31: =C31/(A$63-C$13-C$14)*D$5*D$65 -> 0 | F31: =C31+D31-E31 -> 0 | I31: =H31-E31 -> 0 | J31: =IF(H31>0,C31-H31,F31) -> 0
A32: Janitor Salary | C32: ='Provider Planning Budget'!H58 -> 8440.8163 | D32: =C32/(A$63-C$13-C$14)*D$5*D$65 -> 0 | E32: 1496 | F32: =C32+D32-E32 -> 6944.8163 | I32: =H32-E32 -> -1496 | J32: =IF(H32>0,C32-H32,F32) -> 6944.8163
A33: Janitor Benefits | C33: ='Provider Planning Budget'!H59 -> 0 | D33: =C33/(A$63-C$13-C$14)*D$5*D$65 -> 0 | F33: =C33+D33-E33 -> 0 | I33: =H33-E33 -> 0 | J33: =IF(H33>0,C33-H33,F33) -> 0
A34: Security Guard Salary | C34: ='Provider Planning Budget'!H60 -> 15346.939 | D34: =C34/(A$63-C$13-C$14)*D$5*D$65 -> 0 | E34: 5157 | F34: =C34+D34-E34 -> 10189.939 | I34: =H34-E34 -> -5157 | J34: =IF(H34>0,C34-H34,F34) -> 10189.939
A35: Secufity Guard Benefits | C35: ='Provider Planning Budget'!H61 -> 0 | D35: =C35/(A$63-C$13-C$14)*D$5*D$65 -> 0 | F35: =C35+D35-E35 -> 0 | I35: =H35-E35 -> 0 | J35: =IF(H35>0,C35-H35,F35) -> 0
A36: Social Security (6.20%) | C36: ='Provider Planning Budget'!H62 -> 4452.1162 | D36: =C36/(A$63-C$13-C$14)*D$5*D$65 -> 0 | E36: =23270*N36 -> 1442.74 | F36: =C36+D36-E36 -> 3009.3762 | I36: =H36-E36 -> -1442.74 | J36: =IF(H36>0,C36-H36,F36) -> 3009.3762 | N36: 0.062
A37: Medicare (1.45%) | C37: ='Provider Planning Budget'!H63 -> 1041.2207 | D37: =C37/(A$63-C$13-C$14)*D$5*D$65 -> 0 | E37: =23270*N37 -> 337.415 | F37: =C37+D37-E37 -> 703.80573 | I37: =H37-E37 -> -337.415 | J37: =IF(H37>0,C37-H37,F37) -> 703.80573 | N37: 0.0145
A38: Unemployment (2.80%) | C38: ='Provider Planning Budget'!H64 -> 2010.6331 | D38: =C38/(A$63-C$13-C$14)*D$5*D$65 -> 0 | E38: =23270*N38 -> 651.56 | F38: =C38+D38-E38 -> 1359.0731 | I38: =H38-E38 -> -651.56 | J38: =IF(H38>0,C38-H38,F38) -> 1359.0731 | N38: 0.028
A39: Disability (0.50%) | C39: ='Provider Planning Budget'!H65 -> 359.04163 | D39: =C39/(A$63-C$13-C$14)*D$5*D$65 -> 0 | E39: =23270*N39 -> 116.35 | F39: =C39+D39-E39 -> 242.69163 | I39: =H39-E39 -> -116.35 | J39: =IF(H39>0,C39-H39,F39) -> 242.69163 | N39: 0.005
A40: INDIRECT COSTS -- SPACE COSTS AND ALL OTHER ALLOWABLE INDIRECT (NON-Instructional) 12-MONTH COSTS
...

Sheet GL Q1
A1: URBAN LEAGUE OF ESSEX COUNTY
A2: General Ledger.111.Abbott PreSchool
A3: July - September, 2019
B5: Date | C5: Transaction Type | D5: Num | E5: Name | F5: Memo/Description | G5: Class | H5: Debit | I5: Credit
A6: 7200 Salaries & Related Expenses
A7: 7220 Salaries & Wages
A8: 7222 Staff
A9: 7222h Teacher
B10: Beginning Balance
B11: 07/31/2019 | C11: Journal Entry | D11: 00127 Salaries | F11: Salary Allocation - July | G11: 111 Abbott | H11: 8298.87
B12: 08/31/2019 | C12: Journal Entry | D12: 175 | F12: Salary Allocation - August | G12: 111 Abbott | H12: 8175.82
B13: 09/25/2019 | C13: Journal Entry | D13: 242 | F13: Salary Allocation - September | G13: 111 Abbott | H13: =25010.78-567.9 -> 24442.88
A14: Total for 7222h Teacher | H14: =SUM(H11:H13) -> 40917.57 | J14: 40917.57
A15: Total for 7222 Staff | H15: =SUM(H14) -> 40917.57
A16: Total for 7220 Salaries & Wages | H16: =SUM(H15) -> 40917.57
A17: 7240 Employee Benefits
A18: 7241 Health Insurance
B19: Beginning Balance
B20: 07/31/2019 | C20: Journal Entry | D20: 153 | G20: 111 Abbott | H20: 6712
B21: 08/30/2019 | C21: Journal Entry | D21: 202 | F21: Employee Health Insurance 08/15/19 - 09/15/19 | G21: 111 Abbott | H21: 6712
B22: 09/01/2019 | C22: Bill | D22: 292271815 | E22: Horizon Blue Cross Blue Shield of NJ | F22: To record Horizon Exp. Billing Period 9/15/19 - 10/15/19 | G22: 111 Abbott | H22: 6712
A23: Total for 7241 Health Insurance | H23: =SUM(H20:H22) -> 20136 | J23: 20135.58
A24: 7242 Life and Dental Insurance
B25: Beginning Balance
B26: 07/31/2019 | C26: Journal Entry | D26: 00132 Benefits | G26: 111 Abbott | H26: 454.62
B27: 08/31/2019 | C27: Journal Entry | D27: 208 | G27: 111 Abbott | H27: 454.62
B28: 09/01/2019 | C28: Bill | D28: 09.01.19PL | E28: Principal Financial Group | F28: Life, Dental & AD&D - ABBOTT | G28: 111 Abbott | H28: 390.74
A29: Total for 7242 Life and Dental Insurance | H29: =SUM(H26:H28) -> 1299.98 | J29: 1299.98
A30: Total for 7240 Employee Benefits | H30: =H23+H29 -> 21435.98 | I30: 3216.34
A31: 7250 Payroll Taxes, etc.
A32: 7245 Worker's Compensation Insurance
A33: 7248 Allocated W Comp
B34: Beginning Balance
B35: 07/31/2019 | C35: Journal Entry | D35: 139 | F35: Workers Comp Alloc | G35: 111 Abbott | H35: 324.42
B36: 08/31/2019 | C36: Journal Entry | D36: 192 | F36: Workers Comp Alloc | G36: 111 Abbott | H36: 235
B37: 09/30/2019 | C37: Journal Entry | D37: 272 | F37: Workers Comp Alloc | G37: 111 Abbott | H37: 782
A38: Total for 7248 Allocated W Comp | H38: 1341.42
A39: Total for 7245 Worker's Compensation Insurance | H39: 1341.42 | J39: 1227.53
A40: 7260 Payroll Service Fees
A41: 7260.1 Allocated Payroll Fees
...

Sheet Salary Alloc Q1
B1: Abbott Staffing
B3: For the Quarter ending September 30, 2019
I6: Total
N7: 0.03
E8: Annual Salary | F8: Budget | H8: July - Sept | I8: Abbott | J8: Other | K8: Food | L8: Facilites | M8: Wrap Around | N8: Workers Comp
B9: Teachers | C9: 3 | G9: =F9/E14 -> 0 | I9: =H9*K7 -> 0
D10: Jhonny Janvier | E10: 58583
D11: Bertrilla Simons | E11: 57717 | H11: 3452.38 | I11: 3452.38 | N11: =I11*$N$7 -> 103.5714
D12: Mellisa Thorpe | E12: 53261
D13: Quintella Hollins | H13: 2979.83 | I13: 2979.83
E14: =SUM(E10:E13) -> 169561 | F14: 169561
B15: Teacher Assistants | C15: 3 | D15: W Hill | G15: =F15/E19 -> 0
D16: R Stewart | E16: 34413 | H16: 2100.52 | I16: 2100.52 | N16: =I16*$N$7 -> 63.0156
D17: Niquita Loftin | E17: 25872 | H17: 975 | I17: 975 | N17: =I17*$N$7 -> 29.25
D18: R Bryant | E18: 26551 | H18: 1625.38 | I18: 1625.38 | N18: =I18*$N$7 -> 48.7614 | O18: =SUM(N11:N18) -> 244.5984
E19: =SUM(E15:E18) -> 86836 | F19: 86836
B20: Wrap Worker | D20: R Woodridge | H20: 3150 | M20: 3150
N22: =I22*$N$7 -> 0
B23: Floater | C23: 0.5 | D23: S Rambaran | E23: 19800 | F23: 19800 | G23: =F23/E23 -> 1 | H23: 862.54 | I23: 862.54 | N23: =I23*$N$7 -> 25.8762 | O23: =N23 -> 25.8762
N24: =I24*$N$7 -> 0
B25: Substitutes | D25: D Brown | G25: 1 | H25: 3337.5 | I25: 3337.5 | N25: =I25*$N$7 -> 100.125 | O25: =SUM(N23:N25) -> 126.0012 | P25: =SUM(O18:O25) -> 396.4758
N26: =I26*$N$7 -> 0
B27: Family Worker | C27: 1 | D27: Daphne McMillan | E27: 30076 | F27: 24552 | G27: =F27/E27 -> 0.81633196 | H27: 5965.44 | I27: =H27*G27 -> 4869.7793 | J27: =H27-I27 -> 1095.6607 | N27: =I27*$N$7 -> 146.09338 | O27: Unallow
J28: =H28*I1 -> 0 | N28: =I28*$N$7 -> 0
B29: Cook | C29: 0.5 | D29: P Tyler | E29: 19549 | F29: 7500 | G29: =F29/E29 -> 0.38365134 | H29: 1106.38 | I29: =H29*G29 -> 424.46417 | J29: =H29-I29 -> 681.91583 | N29: =I29*$N$7 -> 12.733925 | O29: Unallow
F30: =SUM(F9:F29) -> 308249 | H30: =SUM(H9:H29) -> 25554.97 | I30: =SUM(I9:I29) -> 20627.393 | J30: =SUM(J9:J29) -> 1777.5765 | K30: =SUM(K9:K29) -> 0 | M30: =SUM(M9:M29) -> 3150 | N30: =SUM(N9:N29) -> 529.4269
B33: Program Director | C33: 1 | D33: Heather Dance | E33: 70000 | F33: 57580 | G33: =F33/E33 -> 0.82257143 | H33: 16153.86 | I33: =H33*G33 -> 13287.704 | J33: =H33-I33 -> 2866.1563 | N33: =I33*$N$7 -> 398.63111 | O33: =N33*G33 -> 327.90256
J34: =H34*I7 -> 0 | N34: =I34*$N$7 -> 0
B35: Clerical | C35: 0.5 | D35: S Alford | E35: 10000 | F35: 3837 | G35: =F35/E35 -> 0.3837 | H35: 8676.96 | I35: =H35*G35 -> 3329.3496 | J35: =H35-I35 -> 5347.6104 | N35: =I35*$N$7 -> 99.880487 | O35: Unallow
N36: =I36*$N$7 -> 0
B37: Custodian | C37: 1 | D37: P Bennett | E37: 22000 | F37: 8441 | G37: =F37/E37 -> 0.38368182 | H37: 3900 | I37: =H37*G37 -> 1496.3591 | J37: =H37-I37 -> 2403.6409 | N37: =I37*$N$7 -> 44.890773 | O37: Unallow
N38: =I38*$N$7 -> 0
B39: Security Guard | D39: Cora Andrews | E39: 20000 | F39: 15347 | G39: =F39/E39 -> 0.76735 | H39: 6720 | I39: =H39*G39 -> 5156.592 | J39: =H39-I39 -> 1563.408 | N39: =I39*$N$7 -> 154.69776 | O39: Unallow
F40: =SUM(F33:F39) -> 85205 | H40: =SUM(H33:H39) -> 35450.82 | I40: =SUM(I33:I39) -> 23270.004 | J40: =SUM(J33:J39) -> 12180.816 | K40: =SUM(K33:K39) -> 0 | L40: =SUM(L33:L39) -> 0 | M40: =SUM(M33:M39) -> 0 | N40: =SUM(N33:N39) -> 698.10013
F45: =SUM(F42:F44) -> 0 | I45: =SUM(I42:I44) -> 0 | M45: =SUM(M42:M44) -> 0 | N45: =SUM(N42:N44) -> 0
F47: =F30+F40+F45 -> 393454 | H47: =H30+H40+H45 -> 61005.79 | I47: =I30+I40+I45 -> 43897.398 | J47: =J30+J40+J45 -> 13958.392 | K47: =K30+K40+K45 -> 0 | L47: =L30+L40+L45 -> 0 | M47: =M30+M40+M45 -> 3150 | N47: =N30+N40+N45 -> 1227.527
I48: Abbott | J48: Other | K48: Food | L48: =L8 -> Facilites | M48: Wrap Around
J50: =J47/$H$47 -> 0.22880438 | K50: =K47/$H$47 -> 0 | L50: =L47/$H$47 -> 0 | M50: =M47/$H$47 -> 0.051634443

Sheet Benefit Q1
B1: Abbott Staffing
B3: For the Quarter ending September 30, 2019
F6: Total | M6: =SUM(M9:M15) -> 281.69
E7: Health Ins | J7: Dental Ins | N7: Total | O7: Rate | P7: Allocated
D8: Budget | E8: Q1 | F8: July | G8: August | H8: Sept | J8: Q1 | K8: July | L8: August | M8: Sept | N8: Q1
B9: Teachers | C9: Johnny Javier | D9: 46750 | E9: =SUM(F9:H9) -> 1989.99 | F9: 663.33 | G9: 663.33 | H9: 663.33 | J9: =SUM(K9:M9) -> 236.67 | K9: 78.89 | L9: 78.89 | M9: 78.89 | N9: =E9+J9 -> 2226.66 | O9: 1 | P9: =N9*O9 -> 2226.66
C10: Bertrilla Simons | E10: =SUM(F10:H10) -> 2344.74 | F10: 781.58 | G10: 781.58 | H10: 781.58 | J10: =SUM(K10:M10) -> 233.13 | K10: 77.71 | L10: 77.71 | M10: 77.71 | N10: =E10+J10 -> 2577.87 | O10: 1 | P10: =N10*O10 -> 2577.87
C11: Rita Castellanos | E11: =SUM(F11:H11) -> 0 | J11: =SUM(K11:M11) -> 0 | N11: =E11+J11 -> 0 | P11: =N11*O11 -> 0
E12: =SUM(F12:H12) -> 0 | J12: =SUM(K12:M12) -> 0 | N12: =E12+J12 -> 0 | P12: =N12*O12 -> 0
B13: Teacher Assistants | C13: W Hill | D13: 0 | E13: =SUM(F13:H13) -> 0 | J13: =SUM(K13:M13) -> 182.07 | K13: 60.69 | L13: 60.69 | M13: 60.69 | N13: =E13+J13 -> 182.07 | O13: 1 | P13: =N13*O13 -> 182.07
C14: R Stewart | E14: =SUM(F14:H14) -> 3355.95 | F14: 1118.65 | G14: 1118.65 | H14: 1118.65 | J14: =SUM(K14:M14) -> 193.2 | K14: 64.4 | L14: 64.4 | M14: 64.4 | N14: =E14+J14 -> 3549.15 | O14: 1 | P14: =N14*O14 -> 3549.15
C15: R Bryant | E15: =SUM(F15:H15) -> 2637.63 | F15: 879.21 | G15: 879.21 | H15: 879.21 | J15: =SUM(K15:M15) -> 0 | N15: =E15+J15 -> 2637.63 | O15: 1 | P15: =N15*O15 -> 2637.63 | Q15: =SUM(P9:P15) -> 11173.38
E16: =SUM(F16:H16) -> 0 | J16: =SUM(K16:M16) -> 0 | N16: =E16+J16 -> 0 | P16: =N16*O16 -> 0 | Q16: =SUM(Q10:Q15) -> 11173.38
B17: Floater | C17: S Rambaran | D17: 0 | E17: =SUM(F17:H17) -> 0 | J17: =SUM(K17:M17) -> 0 | N17: =E17+J17 -> 0 | P17: =N17*O17 -> 0
C18: D Brown | E18: =SUM(F18:H18) -> 0 | J18: =SUM(K18:M18) -> 0 | N18: =E18+J18 -> 0 | P18: =N18*O18 -> 0
C19: R Woodridge | E19: =SUM(F19:H19) -> 0 | J19: =SUM(K19:M19) -> 0 | N19: =E19+J19 -> 0 | P19: =N19*O19 -> 0
E20: =SUM(F20:H20) -> 0 | J20: =SUM(K20:M20) -> 0 | N20: =E20+J20 -> 0 | P20: =N20*O20 -> 0
B21: Substitutes | C21: N Muhammad | D21: 0 | E21: =SUM(F21:H21) -> 0 | J21: =SUM(K21:M21) -> 0 | N21: =E21+J21 -> 0 | P21: =N21*O21 -> 0
E22: =SUM(F22:H22) -> 0 | J22: =SUM(K22:M22) -> 0 | N22: =E22+J22 -> 0 | P22: =N22*O22 -> 0
B23: Family Worker | C23: Daphne McMillan | D23: 0 | E23: =SUM(F23:H23) -> 2799.567 | F23: 933.189 | G23: 933.189 | H23: 933.189 | J23: =SUM(K23:M23) -> 0 | N23: =E23+J23 -> 2799.567 | O23: 1 | P23: =N23*O23 -> 2799.567 | Q23: Unallow
D24: 0 | E24: =SUM(F24:H24) -> 0 | J24: =SUM(K24:M24) -> 0 | N24: =E24+J24 -> 0 | P24: =N24*O24 -> 0
B25: Cook | C25: P Tyler | D25: 0 | E25: =SUM(F25:H25) -> 0 | J25: =SUM(K25:M25) -> 0 | N25: =E25+J25 -> 0 | P25: =N25*O25 -> 0
D26: =SUM(D9:D25) -> 46750 | E26: =SUM(E9:E25) -> 13127.877 | F26: =SUM(F9:F25) -> 4375.959 | G26: =SUM(G9:G25) -> 4375.959 | H26: =SUM(H9:H25) -> 4375.959 | J26: =SUM(J9:J25) -> 845.07 | K26: =SUM(K9:K25) -> 281.69 | L26: =SUM(L9:L25) -> 281.69 | M26: =SUM(M9:M25) -> 281.69 | N26: =SUM(N9:N25) -> 13972.947 | P26: =SUM(P9:P25) -> 13972.947
P27: =N27*O27 -> 0
N28: =E28+J28 -> 0 | P28: =N28*O28 -> 0
B29: Program Director | C29: Heather Dance | D29: 4220 | E29: =SUM(F29:H29) -> 4907.31 | F29: 1635.77 | G29: 1635.77 | H29: 1635.77 | J29: =SUM(K29:M29) -> 327.15 | K29: 109.05 | L29: 109.05 | M29: 109.05 | N29: =E29+J29 -> 5234.46 | O29: ='Salary Alloc Q1'!G33 -> 0.82257143 | P29: =N29*O29 -> 4305.7172
E30: =SUM(F30:H30) -> 0 | J30: =SUM(K30:M30) -> 0 | N30: =E30+J30 -> 0 | P30: =N30*O30 -> 0
B31: Clerical | C31: S Alford | D31: 2406 | E31: =SUM(F31:H31) -> 2100.39 | F31: 700.13 | G31: 700.13 | H31: 700.13 | J31: =SUM(K31:M31) -> 127.76 | K31: 63.88 | L31: 63.88 | N31: =E31+J31 -> 2228.15 | O31: ='Salary Alloc Q1'!G35 -> 0.3837 | P31: =N31*O31 -> 854.94115 | Q31: Unallow
E32: =SUM(F32:H32) -> 0 | J32: =SUM(K32:M32) -> 0 | N32: =E32+J32 -> 0 | P32: =N32*O32 -> 0
B33: Custodian | C33: Darnell Davis | E33: =SUM(F33:H33) -> 0 | J33: =SUM(K33:M33) -> 0 | N33: =E33+J33 -> 0 | P33: =N33*O33 -> 0
E34: =SUM(F34:H34) -> 0 | J34: =SUM(K34:M34) -> 0 | N34: =E34+J34 -> 0 | P34: =N34*O34 -> 0
B35: Security Guard | C35: Cora Andrews | E35: =SUM(F35:H35) -> 0 | J35: =SUM(K35:M35) -> 0 | N35: =E35+J35 -> 0 | P35: =N35*O35 -> 0
D36: =SUM(D29:D35) -> 6626 | E36: =SUM(E29:E35) -> 7007.7 | F36: =SUM(F29:F35) -> 2335.9 | G36: =SUM(G29:G35) -> 2335.9 | H36: =SUM(H29:H35) -> 2335.9 | J36: =SUM(J29:J35) -> 454.91 | K36: =SUM(K29:K35) -> 172.93 | L36: =SUM(L29:L35) -> 172.93 | M36: =SUM(M29:M35) -> 109.05 | N36: =SUM(N29:N35) -> 7462.61 | P36: =SUM(P29:P35) -> 5160.6584
P37: =N37*O37 -> 0
P38: =N38*O38 -> 0
P39: =N39*O39 -> 0
P40: =N40*O40 -> 0
D41: =SUM(D38:D40) -> 0 | F41: =SUM(F38:F40) -> 0 | K41: =SUM(K38:K40) -> 0
D43: =D26+D36+D41 -> 53376 | E43: =E26+E36+E41 -> 20135.577 | F43: =F26+F36+F41 -> 6711.859 | G43: =G26+G36+G41 -> 6711.859 | H43: =H26+H36+H41 -> 6711.859 | J43: =J26+J36+J41 -> 1299.98 | K43: =K26+K36+K41 -> 454.62 | L43: =L26+L36+L41 -> 454.62 | M43: =M26+M36+M41 -> 390.74 | N43: =N26+N36+N41 -> 21435.557 | O43: =O26+O36+O41 -> 0 | P43: =P26+P36+P41 -> 19133.605

Sheet Quarter 2
J1: Total Number of Abbott Children | M1: ='Quarter 1'!M1 -> 45
D2: October - December Under Enrollment | E2: Provider Reported Expenditures | F2: Provider Balance Prior to Ependiture Review | G2: Budget Modification Approved by the District | H2: District Calculated Expenditures 2nd Quarter | I2: Unapproved Funds Expended (Oct. - Dec.) | J2: DOE Share of DOE/DHS Shared Costs | M2: ='Quarter 1'!M2 -> 0.7673
A3: Report Due Wednesday JANUARY 15, 2020 by 3:00PM | J3: Change DOE Share of DOE/DHS Shared Costs | M3: ='Quarter 1'!M3 -> 0
C4: NPS Approved | J4: DOE Share of Center-Wide Costs
A5: EXPENDITURES (Cash Paid Out) | C5: 2018-19 Budget | D5: 0 | E5: (Oct. - Dec.) | F5: (Oct. - Dec.) | H5: (Oct. - Dec.) | I5: (District Use) | J5: Fund Balance | K5: Comments
A6: EDUCATIONAL PROGRAM COSTS (Instructional) 10-MONTH COST ONLY EXCLUDING BENEFITS
A7: Teacher Salary | C7: ='Quarter 1'!J7 -> 166109 | D7: =C7/(A$63-C$13-C$14)*D$5*D$65 -> 0 | E7: ='Salary Report Q2'!O14 -> 43622.68 | F7: =C7+D7-E7 -> 122486.32 | I7: =H7-E7 -> -43622.68 | J7: =IF(H7>0,(C7+D7+G7-H7),F7+G7) -> 122486.32
A8: Teacher Assistant Salary | C8: ='Quarter 1'!J8 -> 82136 | D8: =C8/(A$63-C$13-C$14)*D$5*D$65 -> 0 | E8: ='Salary Report Q2'!O19 -> 28009.65 | F8: =C8+D8-E8 -> 54126.35 | I8: =H8-E8 -> -28009.65 | J8: =IF(H8>0,(C8+D8+G8-H8),F8+G8) -> 54126.35
A9: Floating Teacher Assistant Salary | C9: ='Quarter 1'!J9 -> 18937 | D9: =C9/(A$63-C$13-C$14)*D$5*D$65 -> 0 | E9: ='Salary Report Q2'!I24 -> 6083.9 | F9: =C9+D9-E9 -> 12853.1 | I9: =H9-E9 -> -6083.9 | J9: =IF(H9>0,(C9+D9+G9-H9),F9+G9) -> 12853.1
A10: Teacher, Assistant and Floater Benefits | C10: ='Quarter 1'!J10 -> 27426.75 | D10: =C10/(A$63-C$13-C$14)*D$5*D$65 -> 0 | E10: 8202 | F10: =C10+D10-E10 -> 19224.75 | I10: =H10-E10 -> -8202 | J10: =IF(H10>0,(C10+D10+G10-H10),F10+G10) -> 19224.75
A11: Substitute Teacher Daily Rate (Stipend) | C11: ='Quarter 1'!J11 -> -338 | D11: =C11/(A$63-C$13-C$14)*D$5*D$65 -> 0 | F11: =C11+D11-E11 -> -338 | I11: =H11-E11 -> 0 | J11: =IF(H11>0,(C11+D11+G11-H11),F11+G11) -> -338
A12: Substitute Assistant Daily Rate (Stipend) | C12: ='Quarter 1'!J12 -> 4800 | D12: =C12/(A$63-C$13-C$14)*D$5*D$65 -> 0 | E12: ='Salary Report Q2'!I26 -> 3112.8 | F12: =C12+D12-E12 -> 1687.2 | I12: =H12-E12 -> -3112.8 | J12: =IF(H12>0,(C12+D12+G12-H12),F12+G12) -> 1687.2
A13: Classroom Materials and Supplies | C13: ='Quarter 1'!J13 -> 3969 | E13: 436 | F13: =C13+D13-E13 -> 3533 | I13: =H13-E13 -> -436 | J13: =IF(H13>0,(C13+D13+G13-H13),F13+G13) -> 3533
A14: Classroom Technology | C14: ='Quarter 1'!J14 -> 3000 | F14: =C14+D14-E14 -> 3000 | I14: =H14-E14 -> 0 | J14: =IF(H14>0,(C14+D14+G14-H14),F14+G14) -> 3000
A15: Field Trips w/ Transportation | C15: ='Quarter 1'!J15 -> 3940 | D15: =C15/(A$63-C$13-C$14)*D$5*D$65 -> 0 | E15: 600 | F15: =C15+D15-E15 -> 3340 | I15: =H15-E15 -> -600 | J15: =IF(H15>0,(C15+D15+G15-H15),F15+G15) -> 3340
A16: Family Worker Salary | C16: ='Quarter 1'!J16 -> 19681.798 | D16: =C16/(A$63-C$13-C$14)*D$5*D$65 -> 0 | E16: ='Salary Report Q2'!I28 -> 6493.5289 | F16: =C16+D16-E16 -> 13188.269 | I16: =H16-E16 -> -6493.5289 | J16: =IF(H16>0,(C16+D16+G16-H16),F16+G16) -> 13188.269
A17: Family Worker Benefits | C17: ='Quarter 1'!J17 -> 0 | D17: =C17/(A$63-C$13-C$14)*D$5*D$65 -> 0 | F17: =C17+D17-E17 -> 0 | I17: =H17-E17 -> 0 | J17: =IF(H17>0,(C17+D17+G17-H17),F17+G17) -> 0
A18: Food CACFP; September - June (for contracted preschool children only) | C18: ='Quarter 1'!J18 -> 0 | D18: =C18/(A$63-C$13-C$14)*D$5*D$65 -> 0 | F18: =C18+D18-E18 -> 0 | I18: =H18-E18 -> 0 | J18: =IF(H18>0,(C18+D18+G18-H18),F18+G18) -> 0
A19: Food Worker Salary (cook) | C19: ='Quarter 1'!J19 -> 7076.4588 | D19: =C19/(A$63-C$13-C$14)*D$5*D$65 -> 0 | E19: ='Salary Report Q2'!I30 -> 1426.1203 | F19: =C19+D19-E19 -> 5650.3385 | I19: =H19-E19 -> -1426.1203 | J19: =IF(H19>0,(C19+D19+G19-H19),F19+G19) -> 5650.3385
A20: Food Worker Salary (cook asst.) | C20: ='Quarter 1'!J20 -> 0 | D20: =C20/(A$63-C$13-C$14)*D$5*D$65 -> 0 | F20: =C20+D20-E20 -> 0 | I20: =H20-E20 -> 0 | J20: =IF(H20>0,(C20+D20+G20-H20),F20+G20) -> 0
A21: Food Worker Benefits (Cook & Assist. Cook) | C21: ='Quarter 1'!J21 -> 0 | D21: =C21/(A$63-C$13-C$14)*D$5*D$65 -> 0 | F21: =C21+D21-E21 -> 0 | I21: =H21-E21 -> 0 | J21: =IF(H21>0,(C21+D21+G21-H21),F21+G21) -> 0 | K21: =E7+E8+E9+E16+E19 -> 85635.879
A22: Social Security (6.20%) | C22: ='Quarter 1'!J22 -> 18500.816 | D22: =C22/(A$63-C$13-C$14)*D$5*D$65 -> 0 | E22: =K21*K22 -> 5309.4245 | F22: =C22+D22-E22 -> 13191.391 | I22: =H22-E22 -> -5309.4245 | J22: =IF(H22>0,(C22+D22+G22-H22),F22+G22) -> 13191.391 | K22: 0.062
A23: Medicare (1.45%) | C23: ='Quarter 1'!J23 -> 4326.8327 | D23: =C23/(A$63-C$13-C$14)*D$5*D$65 -> 0 | E23: =K21*K23 -> 1241.7202 | F23: =C23+D23-E23 -> 3085.1125 | I23: =H23-E23 -> -1241.7202 | J23: =IF(H23>0,(C23+D23+G23-H23),F23+G23) -> 3085.1125 | K23: 0.0145
A24: Unemployment (2.80%) | C24: ='Quarter 1'!J24 -> 8355.2632 | D24: =C24/(A$63-C$13-C$14)*D$5*D$65 -> 0 | E24: =K21*K24 -> 2397.8046 | F24: =C24+D24-E24 -> 5957.4586 | I24: =H24-E24 -> -2397.8046 | J24: =IF(H24>0,(C24+D24+G24-H24),F24+G24) -> 5957.4586 | K24: 0.028
A25: Disability (0.50%) | C25: ='Quarter 1'!J25 -> 1492.0113 | D25: =C25/(A$63-C$13-C$14)*D$5*D$65 -> 0 | E25: =K21*K25 -> 428.1794 | F25: =C25+D25-E25 -> 1063.8319 | I25: =H25-E25 -> -428.1794 | J25: =IF(H25>0,(C25+D25+G25-H25),F25+G25) -> 1063.8319 | K25: 0.005
A26: Sub-Total | C26: =SUM(C7:C25) -> 369412.93 | D26: =SUM(D7:D25) -> 0 | E26: =SUM(E7:E25) -> 107363.81 | F26: =SUM(F7:F25) -> 262049.12 | G26: =SUM(G7:G25) -> 0 | H26: =SUM(H7:H25) -> 0 | I26: =SUM(I7:I25) -> -107363.81 | J26: =SUM(J7:J25) -> 262049.12
A27: ADMINISTRATIVE SUPPORT COSTS (NON-Instructional) 12-MONTH COST ONLY EXCLUDING BENEFITS
A28: Director Salary | C28: ='Quarter 1'!J28 -> 30895.837 | D28: =C28/(A$63-C$13-C$14)*D$5*D$65 -> 0 | E28: ='Salary Report Q2'!I34 -> 15502.321 | F28: =C28+D28-E28 -> 15393.516 | I28: =H28-E28 -> -15502.321 | J28: =IF(H28>0,(C28+D28+G28-H28),F28+G28) -> 15393.516
A29: Director Benefits | C29: ='Quarter 1'!J29 -> 3797.1837 | D29: =C29/(A$63-C$13-C$14)*D$5*D$65 -> 0 | E29: 4135 | F29: =C29+D29-E29 -> -337.81633 | I29: =H29-E29 -> -4135 | J29: =IF(H29>0,(C29+D29+G29-H29),F29+G29) -> -337.81633
A30: Clerical Salary | C30: ='Quarter 1'!J30 -> 507.73469 | D30: =C30/(A$63-C$13-C$14)*D$5*D$65 -> 0 | E30: ='Salary Report Q2'!H36 -> 0 | F30: =C30+D30-E30 -> 507.73469 | I30: =H30-E30 -> 0 | J30: =IF(H30>0,(C30+D30+G30-H30),F30+G30) -> 507.73469
A31: Clerical Benefits | C31: ='Quarter 1'!J31 -> 0 | D31: =C31/(A$63-C$13-C$14)*D$5*D$65 -> 0 | F31: =C31+D31-E31 -> 0 | I31: =H31-E31 -> 0 | J31: =IF(H31>0,(C31+D31+G31-H31),F31+G31) -> 0
A32: Janitor Salary | C32: ='Quarter 1'!J32 -> 6944.8163 | D32: =C32/(A$63-C$13-C$14)*D$5*D$65 -> 0 | E32: ='Salary Report Q2'!I38 -> 1715.8251 | F32: =C32+D32-E32 -> 5228.9912 | I32: =H32-E32 -> -1715.8251 | J32: =IF(H32>0,(C32+D32+G32-H32),F32+G32) -> 5228.9912
A33: Janitor Benefits | C33: ='Quarter 1'!J33 -> 0 | D33: =C33/(A$63-C$13-C$14)*D$5*D$65 -> 0 | F33: =C33+D33-E33 -> 0 | I33: =H33-E33 -> 0 | J33: =IF(H33>0,(C33+D33+G33-H33),F33+G33) -> 0
A34: Security Guard Salary | C34: ='Quarter 1'!J34 -> 10189.939 | D34: =C34/(A$63-C$13-C$14)*D$5*D$65 -> 0 | E34: ='Salary Report Q2'!I40 -> 6016.024 | F34: =C34+D34-E34 -> 4173.9148 | I34: =H34-E34 -> -6016.024 | J34: =IF(H34>0,(C34+D34+G34-H34),F34+G34) -> 4173.9148
A35: Secufity Guard Benefits | C35: ='Quarter 1'!J35 -> 0 | D35: =C35/(A$63-C$13-C$14)*D$5*D$65 -> 0 | F35: =C35+D35-E35 -> 0 | I35: =H35-E35 -> 0 | J35: =IF(H35>0,(C35+D35+G35-H35),F35+G35) -> 0 | K35: =E28+E32+E34 -> 23234.17
A36: Social Security (6.20%) | C36: ='Quarter 1'!J36 -> 3009.3762 | D36: =C36/(A$63-C$13-C$14)*D$5*D$65 -> 0 | E36: =K35*K36 -> 1440.5185 | F36: =C36+D36-E36 -> 1568.8577 | I36: =H36-E36 -> -1440.5185 | J36: =IF(H36>0,(C36+D36+G36-H36),F36+G36) -> 1568.8577 | K36: 0.062
A37: Medicare (1.45%) | C37: ='Quarter 1'!J37 -> 703.80573 | D37: =C37/(A$63-C$13-C$14)*D$5*D$65 -> 0 | E37: =K35*K37 -> 336.89547 | F37: =C37+D37-E37 -> 366.91027 | I37: =H37-E37 -> -336.89547 | J37: =IF(H37>0,(C37+D37+G37-H37),F37+G37) -> 366.91027 | K37: 0.0145
A38: Unemployment (2.80%) | C38: ='Quarter 1'!J38 -> 1359.0731 | D38: =C38/(A$63-C$13-C$14)*D$5*D$65 -> 0 | E38: =K35*K38 -> 650.55676 | F38: =C38+D38-E38 -> 708.51638 | I38: =H38-E38 -> -650.55676 | J38: =IF(H38>0,(C38+D38+G38-H38),F38+G38) -> 708.51638 | K38: 0.028
A39: Disability (0.50%) | C39: ='Quarter 1'!J39 -> 242.69163 | D39: =C39/(A$63-C$13-C$14)*D$5*D$65 -> 0 | E39: =K35*K39 -> 116.17085 | F39: =C39+D39-E39 -> 126.52078 | I39: =H39-E39 -> -116.17085 | J39: =IF(H39>0,(C39+D39+G39-H39),F39+G39) -> 126.52078 | K39: 0.005
A40: INDIRECT COSTS -- SPACE COSTS AND ALL OTHER ALLOWABLE INDIRECT (NON-Instructional) 12-MONTH COSTS
...

Sheet GL Q2
A1: URBAN LEAGUE OF ESSEX COUNTY
A2: General Ledger.111 Abbott
A3: October - December, 2019
B5: Date | C5: Transaction Type | D5: Num | E5: Name | F5: Memo/Description | G5: Class | H5: Debit | I5: Credit | J5: Check #
A6: 7200 Salaries & Related Expenses
A7: 7220 Salaries & Wages
A8: 7222 Staff
A9: 7222h Teacher
B10: Beginning Balance
B11: 10/31/2019 | C11: Journal Entry | D11: 19-437 | F11: Salary Allocation - October | G11: 111 Abbott | H11: 31023.86
B12: 11/30/2019 | C12: Journal Entry | D12: 39 | F12: Salary Allocation - November | G12: 111 Abbott | H12: 46682
B13: 12/31/2019 | C13: Journal Entry | D13: 121 | F13: Salary Allocation - December | G13: 111 Abbott | H13: 31274
A14: Total for 7222h Teacher | H14: 108979.86
A15: Total for 7222 Staff | H15: 108979.86
A16: Total for 7220 Salaries & Wages | H16: 108979.86
A17: 7240 Employee Benefits
A18: 7241 Health Insurance
B19: Beginning Balance
B20: 10/11/2019 | C20: Bill | D20: 292534359 | E20: Horizon Blue Cross Blue Shield of NJ | F20: To record Horizon Exp. Billing Period10/15/19 - 11/15/19 | G20: 111 Abbott | H20: 6289.53 | J20: 12569
B21: 11/01/2019 | C21: Bill | D21: 292676700 | E21: Horizon Blue Cross Blue Shield of NJ | F21: To record Horizon Exp. Billing Period 11/15/19 - 12/15/19 | G21: 111 Abbott | H21: 6576.95 | J21: 12658
B22: 12/01/2019 | C22: Bill | D22: 292879522 | E22: Horizon Blue Cross Blue Shield of NJ | F22: To record Horizon Exp. Billing Period 12/15/19 - 01/15/20 | G22: 111 Abbott | H22: 6576.97 | J22: 12820
A23: Total for 7241 Health Insurance | H23: 19443.45
A24: 7242 Life and Dental Insurance
B25: Beginning Balance
B26: 10/01/2019 | C26: Bill | D26: 10.01.19PL | E26: Principal Financial Group | F26: Life, Dental & AD&D | G26: 111 Abbott | H26: 412.41 | J26: 12527
B27: 11/01/2019 | C27: Bill | D27: 11.01.19PG | E27: Principal Financial Group | F27: Life, Dental & AD&D | G27: 111 Abbott | H27: 2392.96 | J27: 12665
B28: 12/01/2019 | C28: Bill | D28: 12.01.19PG | E28: Principal Financial Group | F28: Life, Dental & AD&D | G28: 111 Abbott | H28: 439.2 | J28: 12822
A29: Total for 7242 Life and Dental Insurance | H29: 3244.57
A30: 7243 Disability Ins
B31: Beginning Balance
B32: 12/01/2019 | C32: Bill | D32: 12.01.19DN | E32: Dearborn Life Insurance Co. | F32: Life Insurance for the Period: 12/01/19 - 02/29/20 | G32: 111 Abbott | H32: 25.5 | J32: 12819
A33: Total for 7243 Disability Ins | H33: 25.5
A34: 7244 Employee Contrib - Health
B35: Beginning Balance
B36: 10/31/2019 | C36: Journal Entry | D36: 63 | F36: Employee Medical Contrib | G36: 111 Abbott | I36: 1084.8
B37: 11/30/2019 | C37: Journal Entry | D37: 64 | F37: Employee Medical Contrib | G37: 111 Abbott | I37: 2109.46
B38: 12/31/2019 | C38: Journal Entry | D38: 137 | F38: Employee Medical Contrib | G38: 111 Abbott | I38: 1406
A39: Total for 7244 Employee Contrib - Health | I39: 4600.26
A40: 7247 Emp-ee Contrib -Dental
B41: Beginning Balance
...

Sheet P and L 
A1: URBAN LEAGUE OF ESSEX COUNTY
A2: Profit and Loss. ABBOTT.19.20
A3: July 2019 - June 2020
B5: Jul - Sep, 2019 | C5: Oct - Dec, 2019 | D5: Jan - Mar, 2020 | E5: Apr - Jun, 2020 | F5: Total
A6: Income
A7: 4500 Revenue from Government Grants | F7: =(((B7)+(C7))+(D7))+(E7) -> 0
A8: 4530 State Grants | F8: =(((B8)+(C8))+(D8))+(E8) -> 0
A9: 4536 NPS - Abbott | F9: =(((B9)+(C9))+(D9))+(E9) -> 0
A10: 4536.1 Abbott Benefit Reimb | B10: =24567.67 -> 24567.67 | C10: =15583.44 -> 15583.44 | F10: =(((B10)+(C10))+(D10))+(E10) -> 40151.11
A11: Total 4536 NPS - Abbott | B11: =(B9)+(B10) -> 24567.67 | C11: =(C9)+(C10) -> 15583.44 | D11: =(D9)+(D10) -> 0 | E11: =(E9)+(E10) -> 0 | F11: =(((B11)+(C11))+(D11))+(E11) -> 40151.11
A12: 4537.1 Abbott FYE 19-20 | B12: =47988.45 -> 47988.45 | C12: =143980.79 -> 143980.79 | F12: =(((B12)+(C12))+(D12))+(E12) -> 191969.24
A13: Total 4530 State Grants | B13: =((B8)+(B11))+(B12) -> 72556.12 | C13: =((C8)+(C11))+(C12) -> 159564.23 | D13: =((D8)+(D11))+(D12) -> 0 | E13: =((E8)+(E11))+(E12) -> 0 | F13: =(((B13)+(C13))+(D13))+(E13) -> 232120.35
A14: Total 4500 Revenue from Government Grants | B14: =(B7)+(B13) -> 72556.12 | C14: =(C7)+(C13) -> 159564.23 | D14: =(D7)+(D13) -> 0 | E14: =(E7)+(E13) -> 0 | F14: =(((B14)+(C14))+(D14))+(E14) -> 232120.35
A15: 5000 Revenue from Government Agencies | F15: =(((B15)+(C15))+(D15))+(E15) -> 0
A16: 5030 State Contracts/PFP Fees | B16: =413.29 -> 413.29 | C16: =1538.89 -> 1538.89 | F16: =(((B16)+(C16))+(D16))+(E16) -> 1952.18
A17: Total 5000 Revenue from Government Agencies | B17: =(B15)+(B16) -> 413.29 | C17: =(C15)+(C16) -> 1538.89 | D17: =(D15)+(D16) -> 0 | E17: =(E15)+(E16) -> 0 | F17: =(((B17)+(C17))+(D17))+(E17) -> 1952.18
A18: 5100 Revenue from Sales & Fees | F18: =(((B18)+(C18))+(D18))+(E18) -> 0
A19: 5132 Private Pay Fees | B19: =0.02 -> 0.02 | F19: =(((B19)+(C19))+(D19))+(E19) -> 0.02
A20: Total 5100 Revenue from Sales & Fees | B20: =(B18)+(B19) -> 0.02 | C20: =(C18)+(C19) -> 0 | D20: =(D18)+(D19) -> 0 | E20: =(E18)+(E19) -> 0 | F20: =(((B20)+(C20))+(D20))+(E20) -> 0.02
A21: Total Income | B21: =((B14)+(B17))+(B20) -> 72969.43 | C21: =((C14)+(C17))+(C20) -> 161103.12 | D21: =((D14)+(D17))+(D20) -> 0 | E21: =((E14)+(E17))+(E20) -> 0 | F21: =(((B21)+(C21))+(D21))+(E21) -> 234072.55
A22: Gross Profit | B22: =(B21)-(0) -> 72969.43 | C22: =(C21)-(0) -> 161103.12 | D22: =(D21)-(0) -> 0 | E22: =(E21)-(0) -> 0 | F22: =(((B22)+(C22))+(D22))+(E22) -> 234072.55
A23: Expenses
A24: 7200 Salaries & Related Expenses | F24: =(((B24)+(C24))+(D24))+(E24) -> 0
A25: 7220 Salaries & Wages | F25: =(((B25)+(C25))+(D25))+(E25) -> 0
A26: 7222 Staff | F26: =(((B26)+(C26))+(D26))+(E26) -> 0
A27: 7222h Teacher | B27: =45929.7 -> 45929.7 | C27: =108979.86 -> 108979.86 | F27: =(((B27)+(C27))+(D27))+(E27) -> 154909.56
A28: Total 7222 Staff | B28: =(B26)+(B27) -> 45929.7 | C28: =(C26)+(C27) -> 108979.86 | D28: =(D26)+(D27) -> 0 | E28: =(E26)+(E27) -> 0 | F28: =(((B28)+(C28))+(D28))+(E28) -> 154909.56
A29: Total 7220 Salaries & Wages | B29: =(B25)+(B28) -> 45929.7 | C29: =(C25)+(C28) -> 108979.86 | D29: =(D25)+(D28) -> 0 | E29: =(E25)+(E28) -> 0 | F29: =(((B29)+(C29))+(D29))+(E29) -> 154909.56
A30: 7240 Employee Benefits | F30: =(((B30)+(C30))+(D30))+(E30) -> 0
A31: 7241 Health Insurance | B31: =16961.97 -> 16961.97 | C31: =19443.45 -> 19443.45 | D31: =6576.97 -> 6576.97 | F31: =(((B31)+(C31))+(D31))+(E31) -> 42982.39
A32: 7242 Life and Dental Insurance | B32: =977.18 -> 977.18 | C32: =3244.57 -> 3244.57 | D32: =441.72 -> 441.72 | F32: =(((B32)+(C32))+(D32))+(E32) -> 4663.47
A33: 7243 Disability Ins | B33: =25.5 -> 25.5 | C33: =25.5 -> 25.5 | F33: =(((B33)+(C33))+(D33))+(E33) -> 51
A34: 7244 Employee Contrib - Health | B34: =-3208.1 -> -3208.1 | C34: =-4600.26 -> -4600.26 | F34: =(((B34)+(C34))+(D34))+(E34) -> -7808.36
A35: 7247 Emp-ee Contrib -Dental | B35: =-38.97 -> -38.97 | C35: =-118.11 -> -118.11 | F35: =(((B35)+(C35))+(D35))+(E35) -> -157.08
A36: Total 7240 Employee Benefits | B36: =(((((B30)+(B31))+(B32))+(B33))+(B34))+(B35) -> 14717.58 | C36: =(((((C30)+(C31))+(C32))+(C33))+(C34))+(C35) -> 17995.15 | D36: =(((((D30)+(D31))+(D32))+(D33))+(D34))+(D35) -> 7018.69 | E36: =(((((E30)+(E31))+(E32))+(E33))+(E34))+(E35) -> 0 | F36: =(((B36)+(C36))+(D36))+(E36) -> 39731.42
A37: 7250 Payroll Taxes, etc. | F37: =(((B37)+(C37))+(D37))+(E37) -> 0
A38: 7245 Worker's Compensation Insurance | F38: =(((B38)+(C38))+(D38))+(E38) -> 0
A39: 7248 Allocated W Comp | B39: =1341.42 -> 1341.42 | C39: =2953 -> 2953 | F39: =(((B39)+(C39))+(D39))+(E39) -> 4294.42
A40: Total 7245 Worker's Compensation Insurance | B40: =(B38)+(B39) -> 1341.42 | C40: =(C38)+(C39) -> 2953 | D40: =(D38)+(D39) -> 0 | E40: =(E38)+(E39) -> 0 | F40: =(((B40)+(C40))+(D40))+(E40) -> 4294.42
A41: 7251 Social Security | B41: =2608.59 -> 2608.59 | C41: =6240 -> 6240 | F41: =(((B41)+(C41))+(D41))+(E41) -> 8848.59
...

Sheet Salary Report Q2
B1: Abbott Staffing
B3: For the Quarter ending December 31, 2019
I6: Total
N7: 0.03
E8: Annual Salary | F8: Budget | H8: Oct - Dec | I8: Abbott | J8: Other | K8: Food | L8: Facilites | M8: Wrap Around | N8: Workers Comp
B9: Teachers | C9: 3 | G9: =F9/E15 -> 0 | I9: =H9*K7 -> 0
D10: Jhonny Janvier | H10: 2361.16 | I10: 2361.16
D11: Bertrilla Simons | E11: 57717 | H11: 18825.24 | I11: 18825.24 | N11: =I11*$N$7 -> 564.7572
C12: 50000 | D12: Felicia Mitchell | E12: 50000 | H12: 6431.42 | I12: 6431.42
D13: Mellisa Thorpe | E13: 53261
D14: Quintella Hollins | H14: 16004.86 | I14: 16004.86 | O14: =SUM(I10:I14) -> 43622.68
E15: =SUM(E10:E14) -> 160978 | F15: 169561
B16: Teacher Assistants | C16: 3 | D16: W Hill | G16: =F16/E20 -> 0
D17: R Stewart | E17: 34413 | H17: 11295.73 | I17: 11295.73 | N17: =I17*$N$7 -> 338.8719
D18: Niquita Loftin | E18: 25872 | H18: 7816.23 | I18: 7816.23 | N18: =I18*$N$7 -> 234.4869
D19: R Bryant | E19: 26551 | H19: 8897.69 | I19: 8897.69 | N19: =I19*$N$7 -> 266.9307 | O19: =SUM(I17:I19) -> 28009.65
E20: =SUM(E16:E19) -> 86836 | F20: 86836 | O20: =SUM(O14:O19) -> 71632.33
B21: Wrap Worker | D21: R Woodridge | H21: 3302.5 | M21: =H21 -> 3302.5
N23: =I23*$N$7 -> 0
B24: Floater | C24: 0.5 | D24: S Rambaran | E24: 19800 | F24: 19800 | G24: =F24/E24 -> 1 | H24: 6083.9 | I24: 6083.9 | N24: =I24*$N$7 -> 182.517 | O24: =N24 -> 182.517
N25: =I25*$N$7 -> 0
B26: Substitutes | D26: D Brown | G26: 1 | H26: 3112.8 | I26: 3112.8 | N26: =I26*$N$7 -> 93.384 | O26: =SUM(N24:N26) -> 275.901 | P26: =SUM(O19:O26) -> 100100.4
N27: =I27*$N$7 -> 0
B28: Family Worker | C28: 1 | D28: Daphne McMillan | E28: 30076 | F28: 24552 | G28: =F28/E28 -> 0.81633196 | H28: 7954.52 | I28: =H28*G28 -> 6493.5289 | J28: =H28-I28 -> 1460.9911 | N28: =I28*$N$7 -> 194.80587 | O28: Unallow
N29: =I29*$N$7 -> 0
B30: Cook | C30: 0.5 | D30: P Tyler | E30: 19549 | F30: 7500 | G30: =F30/E30 -> 0.38365134 | H30: 3717.23 | I30: =H30*G30 -> 1426.1203 | J30: =H30-I30 -> 2291.1097 | N30: =I30*$N$7 -> 42.783608 | O30: Unallow
F31: =SUM(F9:F30) -> 308249 | H31: =SUM(H9:H30) -> 95803.28 | I31: =SUM(I9:I30) -> 88748.679 | J31: =SUM(J9:J30) -> 3752.1008 | K31: =SUM(K9:K30) -> 0 | M31: =SUM(M9:M30) -> 3302.5 | N31: =SUM(N9:N30) -> 1918.5372
B34: Program Director | C34: 1 | D34: Heather Dance | E34: 70000 | F34: 57580 | G34: =F34/E34 -> 0.82257143 | H34: 18846.17 | I34: =H34*G34 -> 15502.321 | J34: =H34-I34 -> 3343.849 | N34: =I34*$N$7 -> 465.06963 | O34: =N34*G34 -> 382.55299
N35: =I35*$N$7 -> 0
B36: Clerical | C36: 0.5 | D36: S Alford | E36: 10000 | F36: 3837 | G36: =F36/E36 -> 0.3837 | I36: =H36*G36 -> 0 | J36: =H36-I36 -> 0 | N36: =I36*$N$7 -> 0 | O36: Unallow
N37: =I37*$N$7 -> 0
B38: Custodian | C38: 1 | D38: P Bennett | E38: 22000 | F38: 8441 | G38: =F38/E38 -> 0.38368182 | H38: 4472 | I38: =H38*G38 -> 1715.8251 | J38: =H38-I38 -> 2756.1749 | N38: =I38*$N$7 -> 51.474753 | O38: Unallow
N39: =I39*$N$7 -> 0
B40: Security Guard | D40: Cora Andrews | E40: 20000 | F40: 15347 | G40: =F40/E40 -> 0.76735 | H40: 7840 | I40: =H40*G40 -> 6016.024 | J40: =H40-I40 -> 1823.976 | N40: =I40*$N$7 -> 180.48072 | O40: Unallow
F41: =SUM(F34:F40) -> 85205 | H41: =SUM(H34:H40) -> 31158.17 | I41: =SUM(I34:I40) -> 23234.17 | J41: =SUM(J34:J40) -> 7923.9999 | K41: =SUM(K34:K40) -> 0 | L41: =SUM(L34:L40) -> 0 | M41: =SUM(M34:M40) -> 0 | N41: =SUM(N34:N40) -> 697.0251
F46: =SUM(F43:F45) -> 0 | I46: =SUM(I43:I45) -> 0 | M46: =SUM(M43:M45) -> 0 | N46: =SUM(N43:N45) -> 0
F48: =F31+F41+F46 -> 393454 | H48: =H31+H41+H46 -> 126961.45 | I48: =I31+I41+I46 -> 111982.85 | J48: =J31+J41+J46 -> 11676.101 | K48: =K31+K41+K46 -> 0 | L48: =L31+L41+L46 -> 0 | M48: =M31+M41+M46 -> 3302.5 | N48: =N31+N41+N46 -> 2615.5623 | S48: 18009139000x
I49: Abbott | J49: Other | K49: Food | L49: =L8 -> Facilites | M49: Wrap Around | S49: Sandra Jerry
J51: =J48/$H$48 -> 0.091965717 | K51: =K48/$H$48 -> 0 | L51: =L48/$H$48 -> 0 | M51: =M48/$H$48 -> 0.026011833

Sheet Salary Details
C1: Urban League of Essex County
C2: Abbott Salaries
C3: 10/01/2019 - 12/31/2019
A5: Department_Desc | B5: Employee_Code | C5: Employee_Name | D5: Position | E5: Paydate | F5: Start_Date | G5: End_Date | H5: Gross Pay | I5: Hours | J5: Check_# | K5: Distribution | L5: Transaction_# | M5: Adjust
A6: Abbott | B6: A002 | C6: ANDREWS, CORA | D6: Security Guard | E6: 43742 | F6: 43723 | G6: 43736 | H6: 560 | I6: 40 | J6: 209886773 | K6: C3C5C41A7 - 209886773 - 000550 | L6: C3C5C41A7
A7: Abbott | B7: A002 | C7: ANDREWS, CORA | D7: Security Guard | E7: 43742 | F7: 43723 | G7: 43736 | H7: 560 | I7: 40 | J7: 209886773 | K7: C3C5C41A7 - 209886773 - 000570 | L7: C3C5C41A7
A8: Abbott | B8: A002 | C8: ANDREWS, CORA | D8: Security Guard | E8: 43756 | F8: 43737 | G8: 43750 | H8: 562.62 | I8: 40.12 | J8: 212386264 | K8: 498337E58 - 212386264 - 000550 | L8: 498337E58
A9: Abbott | B9: A002 | C9: ANDREWS, CORA | D9: Security Guard | E9: 43756 | F9: 43737 | G9: 43750 | H9: 562.63 | I9: 40.13 | J9: 212386264 | K9: 498337E58 - 212386264 - 000570 | L9: 498337E58
A10: Abbott | B10: A002 | C10: ANDREWS, CORA | D10: Security Guard | E10: 43770 | F10: 43751 | G10: 43764 | H10: 560 | I10: 40 | J10: 214643815 | K10: A7011EC06 - 214643815 - 000550 | L10: A7011EC06
A11: Abbott | B11: A002 | C11: ANDREWS, CORA | D11: Security Guard | E11: 43770 | F11: 43751 | G11: 43764 | H11: 560 | I11: 40 | J11: 214643815 | K11: A7011EC06 - 214643815 - 000570 | L11: A7011EC06
A12: Abbott | B12: A002 | C12: ANDREWS, CORA | D12: Security Guard | E12: 43784 | F12: 43765 | G12: 43778 | H12: 560 | I12: 40 | J12: 216803173 | K12: 2A0FE99C0 - 216803173 - 000550 | L12: 2A0FE99C0
A13: Abbott | B13: A002 | C13: ANDREWS, CORA | D13: Security Guard | E13: 43784 | F13: 43765 | G13: 43778 | H13: 560 | I13: 40 | J13: 216803173 | K13: 2A0FE99C0 - 216803173 - 000570 | L13: 2A0FE99C0
A14: Abbott | B14: A002 | C14: ANDREWS, CORA | D14: Security Guard | E14: 43798 | F14: 43779 | G14: 43792 | H14: 560 | I14: 40 | J14: 219435869 | K14: 80E3439F4 - 219435869 - 000550 | L14: 80E3439F4
A15: Abbott | B15: A002 | C15: ANDREWS, CORA | D15: Security Guard | E15: 43798 | F15: 43779 | G15: 43792 | H15: 560 | I15: 40 | J15: 219435869 | K15: 80E3439F4 - 219435869 - 000570 | L15: 80E3439F4
A16: Abbott | B16: A002 | C16: ANDREWS, CORA | D16: Security Guard | E16: 43812 | F16: 43793 | G16: 43806 | H16: 560 | I16: 40 | J16: 221999735 | K16: 24FE78CF5 - 221999735 - 000550 | L16: 24FE78CF5
A17: Abbott | B17: A002 | C17: ANDREWS, CORA | D17: Security Guard | E17: 43812 | F17: 43793 | G17: 43806 | H17: 560 | I17: 40 | J17: 221999735 | K17: 24FE78CF5 - 221999735 - 000570 | L17: 24FE78CF5
... A19: Abbott | B19: A002 | C19: ANDREWS, CORA | D19: Security Guard | E19: 43826 | F19: 43807 | G19: 43820 | H19: 562.63 | I19: 40.13 | J19: 223886743 | K19: 06DA7FE21 - 223886743 - 000570 | L19: 06DA7FE21
H20: =SUM(H6:H19) -> 7850.5
F21: Less: Overtime | H21: -10.5
H22: =SUM(H20:H21) -> 7840
A25: Abbott | B25: A06G | C25: BENNETT, PATRICIA A | D25: Custodian | E25: 43742 | F25: 43723 | G25: 43736 | H25: 650 | I25: 50 | J25: 209886774 | K25: C3C5C41A7 - 209886774 - 650 | L25: C3C5C41A7
A26: Abbott | B26: A06G | C26: BENNETT, PATRICIA A | D26: Custodian | E26: 43756 | F26: 43737 | G26: 43750 | H26: 650 | I26: 50 | J26: 212386265 | K26: 498337E58 - 212386265 - 650 | L26: 498337E58
A27: Abbott | B27: A06G | C27: BENNETT, PATRICIA A | D27: Custodian | E27: 43770 | F27: 43751 | G27: 43764 | H27: 650 | I27: 50 | J27: 214643816 | K27: A7011EC06 - 214643816 - 650 | L27: A7011EC06
A28: Abbott | B28: A06G | C28: BENNETT, PATRICIA A | D28: Custodian | E28: 43784 | F28: 43765 | G28: 43778 | H28: 650 | I28: 50 | J28: 216803174 | K28: 2A0FE99C0 - 216803174 - 650 | L28: 2A0FE99C0
A29: Abbott | B29: A06G | C29: BENNETT, PATRICIA A | D29: Custodian | E29: 43798 | F29: 43779 | G29: 43792 | H29: 650 | I29: 50 | J29: 219435870 | K29: 80E3439F4 - 219435870 - 650 | L29: 80E3439F4
A30: Abbott | B30: A06G | C30: BENNETT, PATRICIA A | D30: Custodian | E30: 43812 | F30: 43793 | G30: 43806 | H30: 572 | I30: 44 | J30: 221999736 | K30: 24FE78CF5 - 221999736 - 111 | L30: 24FE78CF5
A31: Abbott | B31: A06G | C31: BENNETT, PATRICIA A | D31: Custodian | E31: 43826 | F31: 43807 | G31: 43820 | H31: 650 | I31: 50 | J31: 223886744 | K31: 06DA7FE21 - 223886744 - 650 | L31: 06DA7FE21
H32: =SUM(H25:H31) -> 4472
A41: Abbott Wrap | B41: A03A | C41: BROWN, DENYSE | D41: WRAP AROUND STAFF | E41: 43742 | F41: 43723 | G41: 43736 | H41: 495 | I41: 49.5 | J41: 209886775 | K41: C3C5C41A7 - 209886775 - 111B | L41: C3C5C41A7
A42: Abbott Wrap | B42: A03A | C42: BROWN, DENYSE | D42: WRAP AROUND STAFF | E42: 43756 | F42: 43737 | G42: 43750 | H42: 617.5 | I42: 61.75 | J42: 212386266 | K42: 498337E58 - 212386266 - 111B | L42: 498337E58
A43: Abbott Wrap | B43: A03A | C43: BROWN, DENYSE | D43: WRAP AROUND STAFF | E43: 43770 | F43: 43751 | G43: 43764 | H43: 423.3 | I43: 42.33 | J43: 214643817 | K43: A7011EC06 - 214643817 - 111B | L43: A7011EC06
A44: Abbott Wrap | B44: A03A | C44: BROWN, DENYSE | D44: WRAP AROUND STAFF | E44: 43784 | F44: 43765 | G44: 43778 | H44: 460 | I44: 46 | J44: 216803175 | K44: 2A0FE99C0 - 216803175 - 111B | L44: 2A0FE99C0
A45: Abbott Wrap | B45: A03A | C45: BROWN, DENYSE | D45: WRAP AROUND STAFF | E45: 43798 | F45: 43779 | G45: 43792 | H45: 325 | I45: 32.5 | J45: 219435871 | K45: 80E3439F4 - 219435871 - 111B | L45: 80E3439F4
A46: Abbott Wrap | B46: A03A | C46: BROWN, DENYSE | D46: WRAP AROUND STAFF | E46: 43812 | F46: 43793 | G46: 43806 | H46: 282.5 | I46: 28.25 | J46: 221999737 | K46: 24FE78CF5 - 221999737 - 111B | L46: 24FE78CF5
A47: Abbott Wrap | B47: A03A | C47: BROWN, DENYSE | D47: WRAP AROUND STAFF | E47: 43826 | F47: 43807 | G47: 43820 | H47: 520 | I47: 52 | J47: 223886745 | K47: 06DA7FE21 - 223886745 - 111B | L47: 06DA7FE21
H48: =SUM(H41:H47) -> 3123.3
F49: Less: Overtime | H49: -10.5
H50: =SUM(H48:H49) -> 3112.8
A52: Abbott | B52: A009 | C52: BRYANT, RONI | D52: Teacher Assistant | E52: 43742 | F52: 43723 | G52: 43736 | H52: 1367.23 | I52: 65 | J52: 209886776 | K52: C3C5C41A7 - 209886776 - 111 | L52: C3C5C41A7
A53: Abbott | B53: A009 | C53: BRYANT, RONI | D53: Teacher Assistant | E53: 43756 | F53: 43737 | G53: 43750 | H53: 1357.23 | I53: 65 | J53: 212386267 | K53: 498337E58 - 212386267 - 111 | L53: 498337E58
...

Sheet Benefits Q2
B1: Abbott Staffing
B3: For the Quarter ending December 31, 2019
F6: Total | M6: =SUM(M9:M15) -> 181.3
E7: Health Ins | J7: Dental Ins | N7: Total | O7: Rate | P7: Allocated
D8: Budget | E8: Q2 | F8: Oct | G8: Nov | H8: Dec | J8: Q2 | K8: Oct | L8: Nov | M8: Dec | N8: Q2
B9: Teachers | C9: Johnny Javier | D9: 46750 | E9: =SUM(F9:H9) -> -287.44 | F9: -287.44 | J9: =SUM(K9:M9) -> 37.76 | K9: 37.76 | N9: =E9+J9 -> -249.68 | O9: 1 | P9: =N9*O9 -> -249.68
C10: Bertrilla Simons | E10: =SUM(F10:H10) -> 2306.82 | F10: 768.94 | G10: 768.94 | H10: 768.94 | J10: =SUM(K10:M10) -> 111.14 | K10: 37.76 | L10: 37.76 | M10: 35.62 | N10: =E10+J10 -> 2417.96 | O10: 1 | P10: =N10*O10 -> 2417.96
C11: Quintella Hollins | D11: Disability - Sept | E11: =SUM(F11:H11) -> 4040.1 | F11: 1346.7 | G11: 1346.7 | H11: 1346.7 | J11: =SUM(K11:M11) -> 64.35 | M11: 64.35 | N11: =E11+J11 -> 4104.45 | P11: =N11*O11 -> 0
E12: =SUM(F12:H12) -> 0 | J12: =SUM(K12:M12) -> 0 | N12: =E12+J12 -> 0 | P12: =N12*O12 -> 0
B13: Teacher Assistants | C13: W Hill | D13: Disability - August | E13: =SUM(F13:H13) -> 0 | J13: =SUM(K13:M13) -> 111.14 | K13: 37.76 | L13: 37.76 | M13: 35.62 | N13: =E13+J13 -> 111.14 | O13: 1 | P13: =N13*O13 -> 111.14
C14: R Stewart | E14: =SUM(F14:H14) -> 3205.05 | F14: 1068.35 | G14: 1068.35 | H14: 1068.35 | J14: =SUM(K14:M14) -> 121.23 | K14: 37.76 | L14: 37.76 | M14: 45.71 | N14: =E14+J14 -> 3326.28 | O14: 1 | P14: =N14*O14 -> 3326.28
C15: R Bryant | E15: =SUM(F15:H15) -> 2596.41 | F15: 865.47 | G15: 865.47 | H15: 865.47 | J15: =SUM(K15:M15) -> 0 | N15: =E15+J15 -> 2596.41 | O15: 1 | P15: =N15*O15 -> 2596.41 | Q15: =SUM(P9:P15) -> 8202.11
E16: =SUM(F16:H16) -> 0 | J16: =SUM(K16:M16) -> 0 | N16: =E16+J16 -> 0 | P16: =N16*O16 -> 0
B17: Floater | C17: S Rambaran | D17: 0 | E17: =SUM(F17:H17) -> 0 | J17: =SUM(K17:M17) -> 0 | N17: =E17+J17 -> 0 | P17: =N17*O17 -> 0
C18: D Brown | E18: =SUM(F18:H18) -> 0 | J18: =SUM(K18:M18) -> 0 | N18: =E18+J18 -> 0 | P18: =N18*O18 -> 0
C19: R Woodridge | E19: =SUM(F19:H19) -> 0 | J19: =SUM(K19:M19) -> 0 | N19: =E19+J19 -> 0 | P19: =N19*O19 -> 0
E20: =SUM(F20:H20) -> 0 | J20: =SUM(K20:M20) -> 0 | N20: =E20+J20 -> 0 | P20: =N20*O20 -> 0
B21: Substitutes | C21: N Muhammad | D21: 0 | E21: =SUM(F21:H21) -> 0 | J21: =SUM(K21:M21) -> 0 | N21: =E21+J21 -> 0 | P21: =N21*O21 -> 0
E22: =SUM(F22:H22) -> 0 | J22: =SUM(K22:M22) -> 0 | N22: =E22+J22 -> 0 | P22: =N22*O22 -> 0
B23: Family Worker | C23: Daphne McMillan | D23: 0 | E23: =SUM(F23:H23) -> 2756.64 | F23: 918.88 | G23: 918.88 | H23: 918.88 | J23: =SUM(K23:M23) -> 0 | N23: =E23+J23 -> 2756.64 | O23: 1 | P23: =N23*O23 -> 2756.64 | Q23: Unallow
D24: 0 | E24: =SUM(F24:H24) -> 0 | J24: =SUM(K24:M24) -> 0 | N24: =E24+J24 -> 0 | P24: =N24*O24 -> 0
B25: Cook | C25: P Tyler | D25: 0 | E25: =SUM(F25:H25) -> 0 | J25: =SUM(K25:M25) -> 0 | N25: =E25+J25 -> 0 | P25: =N25*O25 -> 0
D26: =SUM(D9:D25) -> 46750 | E26: =SUM(E9:E25) -> 14617.58 | F26: =SUM(F9:F25) -> 4680.9 | G26: =SUM(G9:G25) -> 4968.34 | H26: =SUM(H9:H25) -> 4968.34 | J26: =SUM(J9:J25) -> 445.62 | K26: =SUM(K9:K25) -> 151.04 | L26: =SUM(L9:L25) -> 113.28 | M26: =SUM(M9:M25) -> 181.3 | N26: =SUM(N9:N25) -> 15063.2 | P26: =SUM(P9:P25) -> 10958.75
P27: =N27*O27 -> 0
N28: =E28+J28 -> 0 | P28: =N28*O28 -> 0
B29: Program Director | C29: Heather Dance | D29: 4220 | E29: =SUM(F29:H29) -> 4825.89 | F29: 1608.63 | G29: 1608.63 | H29: 1608.63 | J29: =SUM(K29:M29) -> 200.77 | K29: 68.21 | L29: 68.21 | M29: 64.35 | N29: =E29+J29 -> 5026.66 | O29: ='Salary Alloc Q1'!G33 -> 0.82257143 | P29: =N29*O29 -> 4134.7869
E30: =SUM(F30:H30) -> 0 | J30: =SUM(K30:M30) -> 0 | N30: =E30+J30 -> 0 | P30: =N30*O30 -> 0
B31: Clerical | C31: S Alford | D31: 2406 | J31: =SUM(K31:M31) -> 0 | N31: =E31+J31 -> 0 | O31: ='Salary Alloc Q1'!G35 -> 0.3837 | P31: =N31*O31 -> 0 | Q31: Unallow
E32: =SUM(F32:H32) -> 0 | J32: =SUM(K32:M32) -> 0 | N32: =E32+J32 -> 0 | P32: =N32*O32 -> 0
B33: Custodian | C33: Darnell Davis | E33: =SUM(F33:H33) -> 0 | J33: =SUM(K33:M33) -> 0 | N33: =E33+J33 -> 0 | P33: =N33*O33 -> 0
E34: =SUM(F34:H34) -> 0 | J34: =SUM(K34:M34) -> 0 | N34: =E34+J34 -> 0 | P34: =N34*O34 -> 0
B35: Security Guard | C35: Cora Andrews | E35: =SUM(F35:H35) -> 0 | J35: =SUM(K35:M35) -> 0 | N35: =E35+J35 -> 0 | P35: =N35*O35 -> 0
D36: =SUM(D29:D35) -> 6626 | E36: =SUM(E29:E35) -> 4825.89 | F36: =SUM(F29:F35) -> 1608.63 | G36: =SUM(G29:G35) -> 1608.63 | H36: =SUM(H29:H35) -> 1608.63 | J36: =SUM(J29:J35) -> 200.77 | K36: =SUM(K29:K35) -> 68.21 | L36: =SUM(L29:L35) -> 68.21 | M36: =SUM(M29:M35) -> 64.35 | N36: =SUM(N29:N35) -> 5026.66 | P36: =SUM(P29:P35) -> 4134.7869
P37: =N37*O37 -> 0
P38: =N38*O38 -> 0
P39: =N39*O39 -> 0
P40: =N40*O40 -> 0
D41: =SUM(D38:D40) -> 0 | F41: =SUM(F38:F40) -> 0 | K41: =SUM(K38:K40) -> 0
D43: =D26+D36+D41 -> 53376 | E43: =E26+E36+E41 -> 19443.47 | F43: =F26+F36+F41 -> 6289.53 | G43: =G26+G36+G41 -> 6576.97 | H43: =H26+H36+H41 -> 6576.97 | J43: =J26+J36+J41 -> 646.39 | K43: =K26+K36+K41 -> 219.25 | L43: =L26+L36+L41 -> 181.49 | M43: =M26+M36+M41 -> 245.65 | N43: =N26+N36+N41 -> 20089.86 | O43: =O26+O36+O41 -> 0 | P43: =P26+P36+P41 -> 15093.537

Sheet Quarter 3
K1: Total Number of Abbott Children | N1: ='Quarter 1'!M1 -> 45
D2: January - March Under Enrollment | E2: Provider Reported Expenditures | F2: Provider Balance Prior to Ependiture Review | G2: Budget Modification Approved by the District | H2: Budget Modification Request | I2: District Calculated Expenditures 3rd Quarter | J2: Unapproved / Approved Funds Expended (Jan - March | K2: DOE Share of DOE/DHS Shared Costs | N2: ='Quarter 1'!M2 -> 0.7673
A3: Report Due Wednesday, April 15, 2020 by 3:00PM | K3: Change DOE Share of DOE/DHS Shared Costs | N3: ='Quarter 1'!M3 -> 0
C4: NPS Approved | K4: DOE Share of Center-Wide Costs
A5: EXPENDITURES (Cash Paid Out) | C5: 2018-19 Budget | E5: (Jan- March) | F5: (Jan- March) | I5: (Jan- March) | J5: (District Use) | K5: Fund Balance | L5: Comments
A6: EDUCATIONAL PROGRAM COSTS (Instructional) 10-MONTH COST ONLY EXCLUDING BENEFITS
A7: Teacher Salary | C7: ='Quarter 2'!J7 -> 122486.32 | D7: =C7/(A$63-C$13-C$14)*D$5*D$65 -> 0 | E7: 0 | F7: =SUM(C7:D7)-E7 -> 122486.32 | J7: =IF(I7>E7,0,I7-E7) -> 0 | K7: =IF(I7>0,(C7+D7+G7-I7),F7+G7) -> 122486.32
A8: Teacher Assistant Salary | C8: ='Quarter 2'!J8 -> 54126.35 | D8: =C8/(A$63-C$13-C$14)*D$5*D$65 -> 0 | E8: 0 | F8: =SUM(C8:D8)-E8 -> 54126.35 | J8: =IF(I8>E8,0,I8-E8) -> 0 | K8: =IF(I8>0,(C8+D8+G8-I8),F8+G8) -> 54126.35
A9: Floating Teacher Assistant Salary | C9: ='Quarter 2'!J9 -> 12853.1 | D9: =C9/(A$63-C$13-C$14)*D$5*D$65 -> 0 | E9: 0 | F9: =SUM(C9:D9)-E9 -> 12853.1 | J9: =IF(I9>E9,0,I9-E9) -> 0 | K9: =IF(I9>0,(C9+D9+G9-I9),F9+G9) -> 12853.1
A10: Teacher, Assistant and Floater Benefits | C10: ='Quarter 2'!J10 -> 19224.75 | D10: =C10/(A$63-C$13-C$14)*D$5*D$65 -> 0 | E10: 19065.57 | F10: =SUM(C10:D10)-E10 -> 159.18 | J10: =IF(I10>E10,0,I10-E10) -> -19065.57 | K10: =IF(I10>0,(C10+D10+G10-I10),F10+G10) -> 159.18
A11: Substitute Teacher Daily Rate (Stipend) | C11: ='Quarter 2'!J11 -> -338 | D11: =C11/(A$63-C$13-C$14)*D$5*D$65 -> 0 | E11: 0 | F11: =SUM(C11:D11)-E11 -> -338 | J11: =IF(I11>E11,0,I11-E11) -> 0 | K11: =IF(I11>0,(C11+D11+G11-I11),F11+G11) -> -338
A12: Substitute Assistant Daily Rate (Stipend) | C12: ='Quarter 2'!J12 -> 1687.2 | D12: =C12/(A$63-C$13-C$14)*D$5*D$65 -> 0 | E12: 0 | F12: =SUM(C12:D12)-E12 -> 1687.2 | J12: =IF(I12>E12,0,I12-E12) -> 0 | K12: =IF(I12>0,(C12+D12+G12-I12),F12+G12) -> 1687.2
A13: Classroom Materials and Supplies | C13: ='Quarter 2'!J13 -> 3533 | E13: 3573.47 | F13: =SUM(C13:D13)-E13 -> -40.47 | J13: =IF(I13>E13,0,I13-E13) -> -3573.47 | K13: =IF(I13>0,(C13+D13+G13-I13),F13+G13) -> -40.47
A14: Classroom Technology | C14: ='Quarter 2'!J14 -> 3000 | E14: 2195.95 | F14: =SUM(C14:D14)-E14 -> 804.05 | J14: =IF(I14>E14,0,I14-E14) -> -2195.95 | K14: =IF(I14>0,(C14+D14+G14-I14),F14+G14) -> 804.05
A15: Field Trips w/ Transportation | C15: ='Quarter 2'!J15 -> 3340 | D15: =C15/(A$63-C$13-C$14)*D$5*D$65 -> 0 | E15: 300 | F15: =SUM(C15:D15)-E15 -> 3040 | J15: =IF(I15>E15,0,I15-E15) -> -300 | K15: =IF(I15>0,(C15+D15+G15-I15),F15+G15) -> 3040
A16: Family Worker Salary | C16: ='Quarter 2'!J16 -> 13188.269 | D16: =C16/(A$63-C$13-C$14)*D$5*D$65 -> 0 | E16: 0 | F16: =SUM(C16:D16)-E16 -> 13188.269 | J16: =IF(I16>E16,0,I16-E16) -> 0 | K16: =IF(I16>0,(C16+D16+G16-I16),F16+G16) -> 13188.269
A17: Family Worker Benefits | C17: ='Quarter 2'!J17 -> 0 | D17: =C17/(A$63-C$13-C$14)*D$5*D$65 -> 0 | E17: 19065.57 | F17: =SUM(C17:D17)-E17 -> -19065.57 | J17: =IF(I17>E17,0,I17-E17) -> -19065.57 | K17: =IF(I17>0,(C17+D17+G17-I17),F17+G17) -> -19065.57
A18: Food CACFP; September - June (for contracted preschool children only) | C18: ='Quarter 2'!J18 -> 0 | D18: =C18/(A$63-C$13-C$14)*D$5*D$65 -> 0 | E18: 0 | F18: =SUM(C18:D18)-E18 -> 0 | J18: =IF(I18>E18,0,I18-E18) -> 0 | K18: =IF(I18>0,(C18+D18+G18-I18),F18+G18) -> 0
A19: Food Worker Salary (cook) | C19: ='Quarter 2'!J19 -> 5650.3385 | D19: =C19/(A$63-C$13-C$14)*D$5*D$65 -> 0 | E19: 0 | F19: =SUM(C19:D19)-E19 -> 5650.3385 | J19: =IF(I19>E19,0,I19-E19) -> 0 | K19: =IF(I19>0,(C19+D19+G19-I19),F19+G19) -> 5650.3385
A20: Food Worker Salary (cook asst.) | C20: ='Quarter 2'!J20 -> 0 | D20: =C20/(A$63-C$13-C$14)*D$5*D$65 -> 0 | E20: 0 | F20: =SUM(C20:D20)-E20 -> 0 | J20: =IF(I20>E20,0,I20-E20) -> 0 | K20: =IF(I20>0,(C20+D20+G20-I20),F20+G20) -> 0
A21: Food Worker Benefits (Cook & Assist. Cook) | C21: ='Quarter 2'!J21 -> 0 | D21: =C21/(A$63-C$13-C$14)*D$5*D$65 -> 0 | E21: 19065.57 | F21: =SUM(C21:D21)-E21 -> -19065.57 | J21: =IF(I21>E21,0,I21-E21) -> -19065.57 | K21: =IF(I21>0,(C21+D21+G21-I21),F21+G21) -> -19065.57
A22: Social Security (6.20%) | C22: ='Quarter 2'!J22 -> 13191.391 | D22: =C22/(A$63-C$13-C$14)*D$5*D$65 -> 0 | E22: 0 | F22: =SUM(C22:D22)-E22 -> 13191.391 | J22: =IF(I22>E22,0,I22-E22) -> 0 | K22: =IF(I22>0,(C22+D22+G22-I22),F22+G22) -> 13191.391
A23: Medicare (1.45%) | C23: ='Quarter 2'!J23 -> 3085.1125 | D23: =C23/(A$63-C$13-C$14)*D$5*D$65 -> 0 | E23: 0 | F23: =SUM(C23:D23)-E23 -> 3085.1125 | J23: =IF(I23>E23,0,I23-E23) -> 0 | K23: =IF(I23>0,(C23+D23+G23-I23),F23+G23) -> 3085.1125
A24: Unemployment (2.80%) | C24: ='Quarter 2'!J24 -> 5957.4586 | D24: =C24/(A$63-C$13-C$14)*D$5*D$65 -> 0 | E24: 0 | F24: =SUM(C24:D24)-E24 -> 5957.4586 | J24: =IF(I24>E24,0,I24-E24) -> 0 | K24: =IF(I24>0,(C24+D24+G24-I24),F24+G24) -> 5957.4586
A25: Disability (0.50%) | C25: ='Quarter 2'!J25 -> 1063.8319 | D25: =C25/(A$63-C$13-C$14)*D$5*D$65 -> 0 | E25: 0 | F25: =SUM(C25:D25)-E25 -> 1063.8319 | J25: =IF(I25>E25,0,I25-E25) -> 0 | K25: =IF(I25>0,(C25+D25+G25-I25),F25+G25) -> 1063.8319
A26: Sub-Total | C26: =SUM(C7:C25) -> 262049.12 | E26: =SUM(E7:E25) -> 63266.13 | F26: =SUM(F7:F25) -> 198782.99 | I26: =SUM(I7:I25) -> 0 | J26: =SUM(J7:J25) -> -63266.13 | K26: =SUM(K7:K25) -> 198782.99
A27: ADMINISTRATIVE SUPPORT COSTS (NON-Instructional) 12-MONTH COST ONLY EXCLUDING BENEFITS
A28: Director Salary | C28: ='Quarter 2'!J28 -> 15393.516 | D28: =C28/(A$63-C$13-C$14)*D$5*D$65 -> 0 | E28: 0 | F28: =SUM(C28:D28)-E28 -> 15393.516 | J28: =IF(I28>E28,0,I28-E28) -> 0 | K28: =IF(I28>0,(C28+D28+G28-I28),F28+G28) -> 15393.516
A29: Director Benefits | C29: ='Quarter 2'!J29 -> -337.81633 | D29: =C29/(A$63-C$13-C$14)*D$5*D$65 -> 0 | E29: 19065.57 | F29: =SUM(C29:D29)-E29 -> -19403.386 | J29: =IF(I29>E29,0,I29-E29) -> -19065.57 | K29: =IF(I29>0,(C29+D29+G29-I29),F29+G29) -> -19403.386
A30: Clerical Salary | C30: ='Quarter 2'!J30 -> 507.73469 | D30: =C30/(A$63-C$13-C$14)*D$5*D$65 -> 0 | E30: 0 | F30: =SUM(C30:D30)-E30 -> 507.73469 | J30: =IF(I30>E30,0,I30-E30) -> 0 | K30: =IF(I30>0,(C30+D30+G30-I30),F30+G30) -> 507.73469
A31: Clerical Benefits | C31: ='Quarter 2'!J31 -> 0 | D31: =C31/(A$63-C$13-C$14)*D$5*D$65 -> 0 | E31: 19065.57 | F31: =SUM(C31:D31)-E31 -> -19065.57 | J31: =IF(I31>E31,0,I31-E31) -> -19065.57 | K31: =IF(I31>0,(C31+D31+G31-I31),F31+G31) -> -19065.57
A32: Janitor Salary | C32: ='Quarter 2'!J32 -> 5228.9912 | D32: =C32/(A$63-C$13-C$14)*D$5*D$65 -> 0 | E32: 0 | F32: =SUM(C32:D32)-E32 -> 5228.9912 | J32: =IF(I32>E32,0,I32-E32) -> 0 | K32: =IF(I32>0,(C32+D32+G32-I32),F32+G32) -> 5228.9912
A33: Janitor Benefits | C33: ='Quarter 2'!J33 -> 0 | D33: =C33/(A$63-C$13-C$14)*D$5*D$65 -> 0 | E33: 19065.57 | F33: =SUM(C33:D33)-E33 -> -19065.57 | J33: =IF(I33>E33,0,I33-E33) -> -19065.57 | K33: =IF(I33>0,(C33+D33+G33-I33),F33+G33) -> -19065.57
A34: Security Guard Salary | C34: ='Quarter 2'!J34 -> 4173.9148 | D34: =C34/(A$63-C$13-C$14)*D$5*D$65 -> 0 | E34: 0 | F34: =SUM(C34:D34)-E34 -> 4173.9148 | J34: =IF(I34>E34,0,I34-E34) -> 0 | K34: =IF(I34>0,(C34+D34+G34-I34),F34+G34) -> 4173.9148
