Workbook

Sheet Salary Alloc
J2: Abbott | K2: EHS | L2: USJP | M2: Workforce/PACE | N2: Housing | O2: FOC | P2: Real Estate | Q2: Neigh- Coding | R2: Admin | S2: Opport | U2: Totals
E3: Donor name by prog year | H3: 0 | I3: Donor | J3: Newark Public Schools | L3: NUL | M3: Prudential | N3: CDBG | O3: Prudential | P3: NRTC | Q3: Wells Fargo | R3: Victoria Found | S3: Real Estate
I4: Donor | J4: Parent Co pay | K4: PFP | M4: NRTC | N4: SSH | O4: LISC | P4: Wells Fargo | Q4: NRTC | R4: Fundraising | S4: NRTC
I5: Donor | J5: PFP | K5: Parent Co pay | M5: Newark Alliance | N5: ESG | O5: Capital One | Q5: DCF | S5: Capital One
I6: Donor | M6: United Airlines | N6: NRTC | O6: NRTC | Q6: Verizon | S6: Wells Fargo
F7: Current | H7: Approved | I7: Donor | N7: NUL - HUD | O7: NUL - Esusu
B8: SALARIES 2020 | D8: Class Codes | F8: Bi Weekly | G8: Annual Budget | H8: Salary Adj | I8: Salary Revised
G9: 26
A10: 1 | B10: ANDREWS, Cora | C10: =A10 -> 1 | D10: Abbott | E10: Security | F10: 1120 | G10: =F10*$G$9 -> 29120 | I10: =SUM(G10:H10) -> 29120 | J10: =I10 -> 29120 | U10: =SUM(J10:T10) -> 29120 | V10: =I10-U10 -> 0
A11: 2 | B11: Bennett, Patricia A. | C11: =A11 -> 2 | D11: Abbott, Admin | E11: Custodian | F11: 650 | G11: =F11*$G$9 -> 16900 | I11: =SUM(G11:H11) -> 16900 | J11: =I11 -> 16900 | U11: =SUM(J11:T11) -> 16900 | V11: =I11-U11 -> 0
A12: 3 | B12: Bishop-Shakoor, Ayesha | C12: =A12 -> 3 | D12: Abbott, Admin | U12: =SUM(J12:T12) -> 0 | V12: =I12-U12 -> 0
A13: 4 | B13: BROWN,Denise- Wrap | C13: =A13 -> 4 | D13: Wrap | E13: Wrap Teacher | F13: 520 | G13: =F13*$G$9 -> 13520 | I13: =SUM(G13:H13) -> 13520 | J13: =I13 -> 13520 | U13: =SUM(J13:T13) -> 13520 | V13: =I13-U13 -> 0
A14: 5 | B14: BRYANT, Roni | C14: =A14 -> 5 | D14: Abbott | E14: Teacher Asst | F14: 1347.23 | G14: =F14*$G$9 -> 35027.98 | I14: =SUM(G14:H14) -> 35027.98 | J14: =I14 -> 35027.98 | U14: =SUM(J14:T14) -> 35027.98 | V14: =I14-U14 -> 0
A15: 6 | B15: CERNA, Irene | C15: =A15 -> 6 | D15: USJP | F15: 1153.85 | G15: =F15*$G$9 -> 30000.1 | I15: =SUM(G15:H15) -> 30000.1 | L15: =I15 -> 30000.1 | U15: =SUM(J15:T15) -> 30000.1 | V15: =I15-U15 -> 0
A16: 7 | B16: Cooper, Cassandra | C16: =A16 -> 7 | D16: FOC | E16: Clerical | U16: =SUM(J16:T16) -> 0 | V16: =I16-U16 -> 0
A17: 8 | B17: DANCE-WILSON, Heather | C17: =A17 -> 8 | D17: Abbott | E17: Director | F17: 2692.31 | G17: =F17*$G$9 -> 70000.06 | I17: =SUM(G17:H17) -> 70000.06 | J17: =I17 -> 70000.06 | U17: =SUM(J17:T17) -> 70000.06 | V17: =I17-U17 -> 0
A18: 9 | B18: FITZPATRICK, Cynthia E. - Toddlers | C18: =A18 -> 9 | D18: EHS/ Toddlers | F18: 969.96 | G18: =F18*$G$9 -> 25218.96 | I18: =SUM(G18:H18) -> 25218.96 | K18: =I18 -> 25218.96 | U18: =SUM(J18:T18) -> 25218.96 | V18: =I18-U18 -> 0
A19: 10 | B19: FRASER, Vivian Cox | C19: =A19 -> 10 | D19: Admin | F19: 5961.54 | G19: =F19*$G$9 -> 155000.04 | I19: =SUM(G19:H19) -> 155000.04 | R19: =I19 -> 155000.04 | U19: =SUM(J19:T19) -> 155000.04 | V19: =I19-U19 -> 0
A20: 11 | B20: FRAZIER, Alice | C20: =A20 -> 11 | D20: Workforce | F20: 3153.85 | G20: =F20*$G$9 -> 82000.1 | I20: =SUM(G20:H20) -> 82000.1 | M20: =I20 -> 82000.1 | U20: =SUM(J20:T20) -> 82000.1 | V20: =I20-U20 -> 0
A21: 12 | B21: GREEN, Yolanda - | C21: =A21 -> 12 | D21: EHS/ Toddlers | F21: 1278.88 | G21: =F21*$G$9 -> 33250.88 | I21: =SUM(G21:H21) -> 33250.88 | K21: =I21 -> 33250.88 | U21: =SUM(J21:T21) -> 33250.88 | V21: =I21-U21 -> 0
A22: 13 | B22: Guerra, Karime | C22: =A22 -> 13 | D22: Housing | F22: 1788.47 | G22: =F22*$G$9 -> 46500.22 | I22: =SUM(G22:H22) -> 46500.22 | N22: =I22 -> 46500.22 | U22: =SUM(J22:T22) -> 46500.22 | V22: =I22-U22 -> 0
A23: 14 | B23: HIGGINS, Rosa M. April | C23: =A23 -> 14 | D23: FOC | F23: 1538.46 | G23: =F23*$G$9 -> 39999.96 | I23: =SUM(G23:H23) -> 39999.96 | O23: =I23 -> 39999.96 | U23: =SUM(J23:T23) -> 39999.96 | V23: =I23-U23 -> 0
A24: 15 | B24: HOLLINS, QUINTELLA | C24: =A24 -> 15 | D24: Abbott | E24: Teacher | F24: 2305.82 | G24: =F24*$G$9 -> 59951.32 | I24: =SUM(G24:H24) -> 59951.32 | J24: =I24 -> 59951.32 | U24: =SUM(J24:T24) -> 59951.32 | V24: =I24-U24 -> 0
A25: 16 | B25: Howard, Theresa | C25: =A25 -> 16 | D25: United Airlines | F25: 2115.39 | G25: =F25*$G$9 -> 55000.14 | I25: =SUM(G25:H25) -> 55000.14 | M25: =I25 -> 55000.14 | U25: =SUM(J25:T25) -> 55000.14 | V25: =I25-U25 -> 0
A26: 17 | B26: Johnson, Amanda | C26: =A26 -> 17 | D26: USJP | F26: 721 | G26: =F26*$G$9 -> 18746 | I26: =SUM(G26:H26) -> 18746 | L26: =I26 -> 18746 | U26: =SUM(J26:T26) -> 18746 | V26: =I26-U26 -> 0
A27: 18 | B27: Leake, Rahmel | C27: =A27 -> 18 | D27: USJP | F27: 1538.47 | G27: =F27*$G$9 -> 40000.22 | I27: =SUM(G27:H27) -> 40000.22 | L27: =I27 -> 40000.22 | U27: =SUM(J27:T27) -> 40000.22 | V27: =I27-U27 -> 0
A28: 19 | B28: Lindsey, Victoria - July | C28: =A28 -> 19 | D28: NRTC, Housing, PARS, ESG | F28: 2500 | G28: =F28*$G$9 -> 65000 | I28: =SUM(G28:H28) -> 65000 | P28: =I28 -> 65000 | U28: =SUM(J28:T28) -> 65000 | V28: =I28-U28 -> 0
A29: 20 | B29: LOFTIN, NIQUITA | C29: =A29 -> 20 | D29: Abbott | E29: Teacher Asst | F29: 1176 | G29: =F29*$G$9 -> 30576 | I29: =SUM(G29:H29) -> 30576 | J29: =I29 -> 30576 | U29: =SUM(J29:T29) -> 30576 | V29: =I29-U29 -> 0
A30: 21 | B30: Love, Charles | C30: =A30 -> 21 | D30: PACE | F30: 1200 | G30: =F30*$G$9 -> 31200 | I30: =SUM(G30:H30) -> 31200 | M30: 31200 | U30: =SUM(J30:T30) -> 31200 | V30: =I30-U30 -> 0
A31: 22 | B31: MARTINEZ, Joanna | C31: =A31 -> 22 | D31: USJP | F31: 1538.47 | G31: =F31*$G$9 -> 40000.22 | I31: =SUM(G31:H31) -> 40000.22 | L31: 35000.22 | R31: 5000 | U31: =SUM(J31:T31) -> 40000.22 | V31: =I31-U31 -> 0
A32: 23 | B32: McDaniels, Curtis | C32: =A32 -> 23 | D32: Neigh Revit | F32: 1442.31 | G32: =F32*$G$9 -> 37500.06 | I32: =SUM(G32:H32) -> 37500.06 | Q32: 37500.06 | U32: =SUM(J32:T32) -> 37500.06 | V32: =I32-U32 -> 0
A33: 24 | B33: MCMILLIAN, Daphne L. | C33: =A33 -> 24 | D33: Abbott | E33: Family Worker | F33: 1216.36 | G33: =F33*$G$9 -> 31625.36 | I33: =SUM(G33:H33) -> 31625.36 | J33: =I33 -> 31625.36 | U33: =SUM(J33:T33) -> 31625.36 | V33: =I33-U33 -> 0
A34: 25 | B34: Mitchell, Felicia | C34: =A34 -> 25 | D34: Abbott | E34: Teacher | F34: 1114.7 | G34: =F34*$G$9 -> 28982.2 | I34: =SUM(G34:H34) -> 28982.2 | J34: =I34 -> 28982.2 | U34: =SUM(J34:T34) -> 28982.2 | V34: =I34-U34 -> 0
A35: 26 | B35: MORRIS, GWEN | C35: =A35 -> 26 | D35: USJP | F35: 2500 | G35: =F35*$G$9 -> 65000 | I35: =SUM(G35:H35) -> 65000 | L35: =I35 -> 65000 | U35: =SUM(J35:T35) -> 65000 | V35: =I35-U35 -> 0
A36: 27 | B36: RAMBARAN, Sharaini J. | C36: =A36 -> 27 | D36: Abbott | E36: Floater | F36: 996.3 | G36: =F36*$G$9 -> 25903.8 | I36: =SUM(G36:H36) -> 25903.8 | J36: =I36 -> 25903.8 | U36: =SUM(J36:T36) -> 25903.8 | V36: =I36-U36 -> 0
A37: 28 | B37: Robbins, Leonard | C37: =A37 -> 28 | D37: Opportunity Corp | F37: 2769.23 | G37: =F37*$G$9 -> 71999.98 | H37: 3076.93 | I37: =H37*$G$9 -> 80000.18 | S37: =I37 -> 80000.18 | U37: =SUM(J37:T37) -> 80000.18 | V37: =I37-U37 -> 0
A38: 29 | B38: SERMON, Patricia April | C38: =A38 -> 29 | D38: FOC, Housing, OICA, COO | F38: 3153.85 | G38: =F38*$G$9 -> 82000.1 | H38: 3461.54 | I38: =H38*$G$9 -> 90000.04 | L38: 16000.04 | M38: 16700 | N38: 25300 | O38: 32000 | U38: =SUM(J38:T38) -> 90000.04 | V38: =I38-U38 -> 0
A39: 30 | B39: SHARIF, Darrin S. - April | C39: =A39 -> 30 | D39: Admin, Coding, WF | F39: 3269 | G39: =F39*$G$9 -> 84994 | I39: =SUM(G39:H39) -> 84994 | P39: 23400 | Q39: 61594 | U39: =SUM(J39:T39) -> 84994 | V39: =I39-U39 -> 0
A40: 31 | B40: SIMMONS, Bertrilla R. | C40: =A40 -> 31 | D40: Abbott | E40: Teacher | F40: 2684.05 | G40: =F40*$G$9 -> 69785.3 | I40: =SUM(G40:H40) -> 69785.3 | J40: =I40 -> 69785.3 | U40: =SUM(J40:T40) -> 69785.3 | V40: =I40-U40 -> 0
A41: 32 | B41: STEWART, Robin D | C41: =A41 -> 32 | D41: Abbott | E41: Teacher Asst | F41: 1611.08 | G41: =F41*$G$9 -> 41888.08 | I41: =SUM(G41:H41) -> 41888.08 | J41: =I41 -> 41888.08 | U41: =SUM(J41:T41) -> 41888.08 | V41: =I41-U41 -> 0
...

Sheet Allocation %
I1: Donors | J1: NPS | K1: Private Pay | L1: Private pay | M1: Private pay | N1: NUL | O1: United Airlines | P1: Prudential | Q1: State of NJ - Pace | R1: City of Newark | S1: NRTC18 | T1: NRTC 20 | U1: City of Irvington | V1: NUL | W1: Capital One | X1: LISC | Y1: Prudential | Z1: NRTC 18 | AA1: NRTC | AB1: DCF | AC1: Wells Fargo | AD1: Victoria Foundation | AE1: Private Pay | AF1: Private Pay | AG1: Private Pay
B2: SALARIES 2020 | D2: Class Codes | F2: Bi Weekly | G2: Annual Budget | H2: Salary Adj | I2: Salary Revised | J2: Abbott | K2: Abbott - Other | L2: Wrap | M2: Toddlers | N2: USJP | O2: Workforce UA | P2: Pru -Workforce | Q2: PACE | R2: Housing ESG | S2: NRTC18 | T2: NRTC 20 | U2: CDBG | V2: PARS | W2: Save Up2 | X2: LISC 2020 | Y2: PRU -FOC | Z2: NRTC 18 | AA2: Real Estate/NRTC | AB2: Coding | AC2: Neigh Revit | AD2: CEO | AE2: CFO | AF2: Fundraising | AG2: Opprt Corp
G3: 26
A4: 1 | B4: ANDREWS, Cora | C4: =A4 -> 1 | D4: Abbott | E4: Security | F4: 1120 | G4: =F4*$G$3 -> 29120 | I4: =SUM(G4:H4) -> 29120 | J4: 1 | AI4: =SUM(J4:AH4) -> 1
A5: 2 | B5: Bennett, Patricia A. | C5: =A5 -> 2 | D5: Abbott, Admin | E5: Custodian | F5: 650 | G5: =F5*$G$3 -> 16900 | I5: =SUM(G5:H5) -> 16900 | J5: 1 | AI5: =SUM(J5:AH5) -> 1
A6: 3 | B6: Bishop-Shakoor, Ayesha | C6: =A6 -> 3 | D6: Abbott, Admin | J6: 1 | AI6: =SUM(J6:AH6) -> 1
A7: 4 | B7: BROWN,Denise- Wrap | C7: =A7 -> 4 | D7: Wrap | E7: Wrap Teacher | F7: 520 | G7: =F7*$G$3 -> 13520 | I7: =SUM(G7:H7) -> 13520 | L7: 1 | AI7: =SUM(J7:AH7) -> 1
A8: 5 | B8: BRYANT, Roni | C8: =A8 -> 5 | D8: Abbott | E8: Teacher Asst | F8: 1347.23 | G8: =F8*$G$3 -> 35027.98 | I8: =SUM(G8:H8) -> 35027.98 | J8: 1 | AI8: =SUM(J8:AH8) -> 1
A9: 6 | B9: CERNA, Irene | C9: =A9 -> 6 | D9: USJP | F9: 1153.85 | G9: =F9*$G$3 -> 30000.1 | I9: =SUM(G9:H9) -> 30000.1 | N9: 1 | AI9: =SUM(J9:AH9) -> 1
A10: 7 | B10: Cooper, Cassandra | C10: =A10 -> 7 | D10: FOC | E10: Clerical | Y10: 1 | AI10: =SUM(J10:AH10) -> 1
A11: 8 | B11: DANCE-WILSON, Heather | C11: =A11 -> 8 | D11: Abbott | E11: Director | F11: 2692.31 | G11: =F11*$G$3 -> 70000.06 | I11: =SUM(G11:H11) -> 70000.06 | J11: 0.72 | K11: 0.28 | AI11: =SUM(J11:AH11) -> 1
A12: 9 | B12: FITZPATRICK, Cynthia E. - Toddlers | C12: =A12 -> 9 | D12: EHS/ Toddlers | F12: 969.96 | G12: =F12*$G$3 -> 25218.96 | I12: =SUM(G12:H12) -> 25218.96 | M12: 1 | AI12: =SUM(J12:AH12) -> 1
A13: 10 | B13: FRASER, Vivian Cox | C13: =A13 -> 10 | D13: Admin | F13: 5961.54 | G13: =F13*$G$3 -> 155000.04 | I13: =SUM(G13:H13) -> 155000.04 | AD13: 0.9 | AF13: 0.1 | AI13: =SUM(J13:AH13) -> 1
A14: 11 | B14: FRAZIER, Alice | C14: =A14 -> 11 | D14: Workforce | F14: 3153.85 | G14: =F14*$G$3 -> 82000.1 | I14: =SUM(G14:H14) -> 82000.1 | O14: 0.33 | P14: 0.67 | AI14: =SUM(J14:AH14) -> 1
A15: 12 | B15: GREEN, Yolanda - | C15: =A15 -> 12 | D15: EHS/ Toddlers | F15: 1278.88 | G15: =F15*$G$3 -> 33250.88 | I15: =SUM(G15:H15) -> 33250.88 | M15: 1 | AI15: =SUM(J15:AH15) -> 1
A16: 13 | B16: Guerra, Karime | C16: =A16 -> 13 | D16: Housing | F16: 1788.47 | G16: =F16*$G$3 -> 46500.22 | I16: =SUM(G16:H16) -> 46500.22 | R16: 0.15 | T16: 0.74 | U16: 0.11 | AI16: =SUM(J16:AH16) -> 1
A17: 14 | B17: HIGGINS, Rosa M. | C17: =A17 -> 14 | D17: FOC | F17: 1538.46 | G17: =F17*$G$3 -> 39999.96 | I17: =SUM(G17:H17) -> 39999.96 | W17: 0.1 | X17: 0.45 | Y17: 0.18 | Z17: 0.27 | AI17: =SUM(J17:AH17) -> 1
A18: 15 | B18: HOLLINS, QUINTELLA | C18: =A18 -> 15 | D18: Abbott | E18: Teacher | F18: 2305.82 | G18: =F18*$G$3 -> 59951.32 | I18: =SUM(G18:H18) -> 59951.32 | J18: 1 | AI18: =SUM(J18:AH18) -> 1
A19: 16 | B19: Howard, Theresa | C19: =A19 -> 16 | D19: United Airlines | F19: 2115.39 | G19: =F19*$G$3 -> 55000.14 | I19: =SUM(G19:H19) -> 55000.14 | O19: 1 | AI19: =SUM(J19:AH19) -> 1
A20: 17 | B20: Johnson, Amanda | C20: =A20 -> 17 | D20: USJP | F20: 721 | G20: =F20*$G$3 -> 18746 | I20: =SUM(G20:H20) -> 18746 | N20: 1 | AI20: =SUM(J20:AH20) -> 1
A21: 18 | B21: Leake, Rahmel | C21: =A21 -> 18 | D21: USJP | F21: 1538.47 | G21: =F21*$G$3 -> 40000.22 | I21: =SUM(G21:H21) -> 40000.22 | N21: 1 | AI21: =SUM(J21:AH21) -> 1
A22: 19 | B22: Lindsey, Victoria - July | C22: =A22 -> 19 | D22: NRTC, Housing, PARS, ESG | F22: 2500 | G22: =F22*$G$3 -> 65000 | I22: =SUM(G22:H22) -> 65000 | R22: 0.25 | S22: 0.18 | T22: 0.07 | U22: 0.25 | V22: 0.25 | AI22: =SUM(J22:AH22) -> 1
A23: 20 | B23: LOFTIN, NIQUITA | C23: =A23 -> 20 | D23: Abbott | E23: Teacher Asst | F23: 1176 | G23: =F23*$G$3 -> 30576 | I23: =SUM(G23:H23) -> 30576 | J23: 1 | AI23: =SUM(J23:AH23) -> 1
A24: 21 | B24: Love, Charles | C24: =A24 -> 21 | D24: PACE | F24: 1200 | G24: =F24*$G$3 -> 31200 | I24: =SUM(G24:H24) -> 31200 | Q24: 1 | AI24: =SUM(J24:AH24) -> 1
A25: 22 | B25: MARTINEZ, Joanna | C25: =A25 -> 22 | D25: USJP | F25: 1538.47 | G25: =F25*$G$3 -> 40000.22 | I25: =SUM(G25:H25) -> 40000.22 | N25: 0.95 | AE25: 0.05 | AI25: =SUM(J25:AH25) -> 1
A26: 23 | B26: McDaniels, Curtis | C26: =A26 -> 23 | D26: Neigh Revit | F26: 1442.31 | G26: =F26*$G$3 -> 37500.06 | I26: =SUM(G26:H26) -> 37500.06 | AC26: 1 | AI26: =SUM(J26:AH26) -> 1
A27: 24 | B27: MCMILLIAN, Daphne L. | C27: =A27 -> 24 | D27: Abbott | E27: Family Worker | F27: 1216.36 | G27: =F27*$G$3 -> 31625.36 | I27: =SUM(G27:H27) -> 31625.36 | J27: 1 | AI27: =SUM(J27:AH27) -> 1
A28: 25 | B28: Mitchell, Felicia | C28: =A28 -> 25 | D28: Abbott | E28: Teacher | F28: 1114.7 | G28: =F28*$G$3 -> 28982.2 | I28: =SUM(G28:H28) -> 28982.2 | J28: 1 | AI28: =SUM(J28:AH28) -> 1
A29: 26 | B29: MORRIS, GWEN | C29: =A29 -> 26 | D29: USJP | F29: 2500 | G29: =F29*$G$3 -> 65000 | I29: =SUM(G29:H29) -> 65000 | N29: 1 | AI29: =SUM(J29:AH29) -> 1
A30: 27 | B30: RAMBARAN, Sharaini J. | C30: =A30 -> 27 | D30: Abbott | E30: Floater | F30: 996.3 | G30: =F30*$G$3 -> 25903.8 | I30: =SUM(G30:H30) -> 25903.8 | J30: 1 | AI30: =SUM(J30:AH30) -> 1
A31: 28 | B31: Robbins, Leonard | C31: =A31 -> 28 | D31: Opportunity Corp | F31: 2769.23 | G31: =F31*$G$3 -> 71999.98 | H31: 3076.93 | I31: =H31*$G$3 -> 80000.18 | AG31: 1 | AI31: =SUM(J31:AH31) -> 1
A32: 29 | B32: SERMON, Patricia April | C32: =A32 -> 29 | D32: FOC, Housing, OICA, COO | F32: 3153.85 | G32: =F32*$G$3 -> 82000.1 | H32: 3461.54 | I32: =H32*$G$3 -> 90000.04 | N32: 0.2 | P32: 0.24 | R32: 0 | T32: 0.05 | U32: 0.04 | V32: 0.02 | W32: 0.06 | X32: 0.39 | Y32: 0 | AI32: =SUM(J32:AH32) -> 1
A33: 30 | B33: SHARIF, Darrin S. - April | C33: =A33 -> 30 | D33: Admin, Coding, WF | F33: 3269 | G33: =F33*$G$3 -> 84994 | I33: =SUM(G33:H33) -> 84994 | AA33: 0.27 | AB33: 0.29 | AC33: 0.44 | AI33: =SUM(J33:AH33) -> 1
A34: 31 | B34: SIMMONS, Bertrilla R. | C34: =A34 -> 31 | D34: Abbott | E34: Teacher | F34: 2684.05 | G34: =F34*$G$3 -> 69785.3 | I34: =SUM(G34:H34) -> 69785.3 | J34: 1 | AI34: =SUM(J34:AH34) -> 1
A35: 32 | B35: STEWART, Robin D | C35: =A35 -> 32 | D35: Abbott | E35: Teacher Asst | F35: 1611.08 | G35: =F35*$G$3 -> 41888.08 | I35: =SUM(G35:H35) -> 41888.08 | J35: 1 | AI35: =SUM(J35:AH35) -> 1
A36: 33 | B36: TYLER, Patricia | C36: =A36 -> 33 | D36: Abbott | E36: Cook | F36: 454.96 | G36: =F36*$G$3 -> 11828.96 | I36: =SUM(G36:H36) -> 11828.96 | J36: 1 | AI36: =SUM(J36:AH36) -> 1
A37: 34 | B37: WARD, Richard G. - Off Jan 1 | C37: =A37 -> 34 | D37: Admin | F37: 4230.77 | G37: =F37*$G$3 -> 110000.02 | I37: =SUM(G37:H37) -> 110000.02 | N37: 0 | AA37: 0.02 | AB37: 0.09 | AE37: 0.89 | AI37: =SUM(J37:AH37) -> 1
A38: 35 | B38: Williams, Kyneisha - Career Coach | C38: =A38 -> 35 | D38: United Airlines, PACE June 30 | F38: 1538.47 | G38: =F38*$G$3 -> 40000.22 | I38: =SUM(G38:H38) -> 40000.22 | Q38: 1 | AI38: =SUM(J38:AH38) -> 1
A39: 36 | B39: WOODRIDGE, Rosalind | C39: =A39 -> 36 | D39: Wrap | E39: Wrap Teacher | F39: 510 | G39: =F39*$G$3 -> 13260 | I39: =SUM(G39:H39) -> 13260 | L39: 1 | AI39: =SUM(J39:AH39) -> 1
AI40: =SUM(J40:AH40) -> 0
...

Sheet Salary
B2: SALARIES 2020 | D2: Class Codes | F2: Bi Weekly | G2: Annual Budget | H2: Salary Adj | I2: Salary Revised | J2: 43840 | K2: 43854 | P2: Total | Q2: ='Allocation %'!J2 -> Abbott | R2: ='Allocation %'!K2 -> Abbott - Other | S2: Wrap | T2: ='Allocation %'!M2 -> Toddlers | U2: ='Allocation %'!N2 -> USJP | V2: ='Allocation %'!O2 -> Workforce UA | W2: ='Allocation %'!P2 -> Pru -Workforce | X2: ='Allocation %'!Q2 -> PACE | Y2: ='Allocation %'!R2 -> Housing ESG | Z2: ='Allocation %'!S2 -> NRTC18 | AA2: ='Allocation %'!T2 -> NRTC 20 | ... AN2: ='Allocation %'!AG2 -> Opprt Corp
G3: 26
A4: 1 | B4: ='Allocation %'!B4 -> ANDREWS, Cora | C4: 1 | D4: ='Allocation %'!D4 -> Abbott | E4: ='Allocation %'!E4 -> Security | F4: 1120 | G4: =F4*$G$3 -> 29120 | I4: =SUM(G4:H4) -> 29120 | J4: 1120 | K4: 1120 | P4: =SUM(J4:O4) -> 2240 | Q4: =$P4*'Allocation %'!J4 -> 2240 | R4: =$P4*'Allocation %'!K4 -> 0 | S4: =$P4*'Allocation %'!L4 -> 0 | T4: =$P4*'Allocation %'!M4 -> 0 | U4: =$P4*'Allocation %'!N4 -> 0 | V4: =$P4*'Allocation %'!O4 -> 0 | W4: =$P4*'Allocation %'!P4 -> 0 | X4: =$P4*'Allocation %'!Q4 -> 0 | ... AO4: =$P4*'Allocation %'!AH4 -> 0 | AP4: =SUM(Q4:AO4) -> 2240 | AQ4: =P4-AP4 -> 0
A5: 2 | B5: ='Allocation %'!B5 -> Bennett, Patricia A. | C5: 2 | D5: ='Allocation %'!D5 -> Abbott, Admin | E5: ='Allocation %'!E5 -> Custodian | F5: 650 | G5: =F5*$G$3 -> 16900 | I5: =SUM(G5:H5) -> 16900 | J5: 728 | K5: 650 | P5: =SUM(J5:O5) -> 1378 | Q5: =$P5*'Allocation %'!J5 -> 1378 | R5: =$P5*'Allocation %'!K5 -> 0 | S5: =$P5*'Allocation %'!L5 -> 0 | T5: =$P5*'Allocation %'!M5 -> 0 | U5: =$P5*'Allocation %'!N5 -> 0 | V5: =$P5*'Allocation %'!O5 -> 0 | W5: =$P5*'Allocation %'!P5 -> 0 | X5: =$P5*'Allocation %'!Q5 -> 0 | ... AO5: =$P5*'Allocation %'!AH5 -> 0 | AP5: =SUM(Q5:AO5) -> 1378 | AQ5: =P5-AP5 -> 0
A6: 3 | B6: ='Allocation %'!B6 -> Bishop-Shakoor, Ayesha | C6: 3 | D6: ='Allocation %'!D6 -> Abbott, Admin | E6: ='Allocation %'!E6 -> 0 | J6: 280.02 | K6: 1346.25 | P6: =SUM(J6:O6) -> 1626.27 | Q6: =$P6*'Allocation %'!J6 -> 1626.27 | R6: =$P6*'Allocation %'!K6 -> 0 | S6: =$P6*'Allocation %'!L6 -> 0 | T6: =$P6*'Allocation %'!M6 -> 0 | U6: =$P6*'Allocation %'!N6 -> 0 | V6: =$P6*'Allocation %'!O6 -> 0 | W6: =$P6*'Allocation %'!P6 -> 0 | X6: =$P6*'Allocation %'!Q6 -> 0 | ... AO6: =$P6*'Allocation %'!AH6 -> 0 | AP6: =SUM(Q6:AO6) -> 1626.27 | AQ6: =P6-AP6 -> 0
A7: 4 | B7: ='Allocation %'!B7 -> BROWN,Denise- Wrap | C7: 4 | D7: ='Allocation %'!D7 -> Wrap | E7: ='Allocation %'!E7 -> Wrap Teacher | F7: 520 | G7: =F7*$G$3 -> 13520 | I7: =SUM(G7:H7) -> 13520 | J7: 110 | K7: 497.75 | P7: =SUM(J7:O7) -> 607.75 | Q7: =$P7*'Allocation %'!J7 -> 0 | R7: =$P7*'Allocation %'!K7 -> 0 | S7: =$P7*'Allocation %'!L7 -> 607.75 | T7: =$P7*'Allocation %'!M7 -> 0 | U7: =$P7*'Allocation %'!N7 -> 0 | V7: =$P7*'Allocation %'!O7 -> 0 | W7: =$P7*'Allocation %'!P7 -> 0 | X7: =$P7*'Allocation %'!Q7 -> 0 | ... AO7: =$P7*'Allocation %'!AH7 -> 0 | AP7: =SUM(Q7:AO7) -> 607.75 | AQ7: =P7-AP7 -> 0
A8: 5 | B8: ='Allocation %'!B8 -> BRYANT, Roni | C8: 5 | D8: ='Allocation %'!D8 -> Abbott | E8: ='Allocation %'!E8 -> Teacher Asst | F8: 1347.23 | G8: =F8*$G$3 -> 35027.98 | I8: =SUM(G8:H8) -> 35027.98 | J8: 1287.23 | K8: 1367.23 | P8: =SUM(J8:O8) -> 2654.46 | Q8: =$P8*'Allocation %'!J8 -> 2654.46 | R8: =$P8*'Allocation %'!K8 -> 0 | S8: =$P8*'Allocation %'!L8 -> 0 | T8: =$P8*'Allocation %'!M8 -> 0 | U8: =$P8*'Allocation %'!N8 -> 0 | V8: =$P8*'Allocation %'!O8 -> 0 | W8: =$P8*'Allocation %'!P8 -> 0 | X8: =$P8*'Allocation %'!Q8 -> 0 | ... AO8: =$P8*'Allocation %'!AH8 -> 0 | AP8: =SUM(Q8:AO8) -> 2654.46 | AQ8: =P8-AP8 -> 0
A9: 6 | B9: ='Allocation %'!B9 -> CERNA, Irene | C9: 6 | D9: ='Allocation %'!D9 -> USJP | E9: ='Allocation %'!E9 -> 0 | F9: 1153.85 | G9: =F9*$G$3 -> 30000.1 | I9: =SUM(G9:H9) -> 30000.1 | J9: 1153.85 | K9: 1153.85 | P9: =SUM(J9:O9) -> 2307.7 | Q9: =$P9*'Allocation %'!J9 -> 0 | R9: =$P9*'Allocation %'!K9 -> 0 | S9: =$P9*'Allocation %'!L9 -> 0 | T9: =$P9*'Allocation %'!M9 -> 0 | U9: =$P9*'Allocation %'!N9 -> 2307.7 | V9: =$P9*'Allocation %'!O9 -> 0 | W9: =$P9*'Allocation %'!P9 -> 0 | X9: =$P9*'Allocation %'!Q9 -> 0 | ... AO9: =$P9*'Allocation %'!AH9 -> 0 | AP9: =SUM(Q9:AO9) -> 2307.7 | AQ9: =P9-AP9 -> 0
A10: 7 | B10: ='Allocation %'!B10 -> Cooper, Cassandra | C10: 7 | D10: ='Allocation %'!D10 -> FOC | E10: ='Allocation %'!E10 -> Clerical | J10: 600.04 | P10: =SUM(J10:O10) -> 600.04 | Q10: =$P10*'Allocation %'!J10 -> 0 | R10: =$P10*'Allocation %'!K10 -> 0 | S10: =$P10*'Allocation %'!L10 -> 0 | T10: =$P10*'Allocation %'!M10 -> 0 | U10: =$P10*'Allocation %'!N10 -> 0 | V10: =$P10*'Allocation %'!O10 -> 0 | W10: =$P10*'Allocation %'!P10 -> 0 | X10: =$P10*'Allocation %'!Q10 -> 0 | ... AO10: =$P10*'Allocation %'!AH10 -> 0 | AP10: =SUM(Q10:AO10) -> 600.04 | AQ10: =P10-AP10 -> 0
A11: 8 | B11: ='Allocation %'!B11 -> DANCE-WILSON, Heather | C11: 8 | D11: ='Allocation %'!D11 -> Abbott | E11: ='Allocation %'!E11 -> Director | F11: 2692.31 | G11: =F11*$G$3 -> 70000.06 | I11: =SUM(G11:H11) -> 70000.06 | J11: 2692.31 | K11: 2692.31 | P11: =SUM(J11:O11) -> 5384.62 | Q11: =$P11*'Allocation %'!J11 -> 3876.9264 | R11: =$P11*'Allocation %'!K11 -> 1507.6936 | S11: =$P11*'Allocation %'!L11 -> 0 | T11: =$P11*'Allocation %'!M11 -> 0 | U11: =$P11*'Allocation %'!N11 -> 0 | V11: =$P11*'Allocation %'!O11 -> 0 | W11: =$P11*'Allocation %'!P11 -> 0 | X11: =$P11*'Allocation %'!Q11 -> 0 | ... AO11: =$P11*'Allocation %'!AH11 -> 0 | AP11: =SUM(Q11:AO11) -> 5384.62 | AQ11: =P11-AP11 -> 0
A12: 9 | B12: ='Allocation %'!B12 -> FITZPATRICK, Cynthia E. - Toddlers | C12: 9 | D12: ='Allocation %'!D12 -> EHS/ Toddlers | E12: ='Allocation %'!E12 -> 0 | F12: 969.96 | G12: =F12*$G$3 -> 25218.96 | I12: =SUM(G12:H12) -> 25218.96 | J12: 960 | K12: 964.32 | P12: =SUM(J12:O12) -> 1924.32 | Q12: =$P12*'Allocation %'!J12 -> 0 | R12: =$P12*'Allocation %'!K12 -> 0 | S12: =$P12*'Allocation %'!L12 -> 0 | T12: =$P12*'Allocation %'!M12 -> 1924.32 | U12: =$P12*'Allocation %'!N12 -> 0 | V12: =$P12*'Allocation %'!O12 -> 0 | W12: =$P12*'Allocation %'!P12 -> 0 | X12: =$P12*'Allocation %'!Q12 -> 0 | ... AO12: =$P12*'Allocation %'!AH12 -> 0 | AP12: =SUM(Q12:AO12) -> 1924.32 | AQ12: =P12-AP12 -> 0
A13: 10 | B13: ='Allocation %'!B13 -> FRASER, Vivian Cox | C13: 10 | D13: ='Allocation %'!D13 -> Admin | E13: ='Allocation %'!E13 -> 0 | F13: 5961.54 | G13: =F13*$G$3 -> 155000.04 | I13: =SUM(G13:H13) -> 155000.04 | J13: 5961.54 | K13: 5961.54 | P13: =SUM(J13:O13) -> 11923.08 | Q13: =$P13*'Allocation %'!J13 -> 0 | R13: =$P13*'Allocation %'!K13 -> 0 | S13: =$P13*'Allocation %'!L13 -> 0 | T13: =$P13*'Allocation %'!M13 -> 0 | U13: =$P13*'Allocation %'!N13 -> 0 | V13: =$P13*'Allocation %'!O13 -> 0 | W13: =$P13*'Allocation %'!P13 -> 0 | X13: =$P13*'Allocation %'!Q13 -> 0 | ... AO13: =$P13*'Allocation %'!AH13 -> 0 | AP13: =SUM(Q13:AO13) -> 11923.08 | AQ13: =P13-AP13 -> 0
A14: 11 | B14: ='Allocation %'!B14 -> FRAZIER, Alice | C14: 11 | D14: ='Allocation %'!D14 -> Workforce | E14: ='Allocation %'!E14 -> 0 | F14: 3153.85 | G14: =F14*$G$3 -> 82000.1 | I14: =SUM(G14:H14) -> 82000.1 | J14: 3153.85 | K14: 3153.85 | P14: =SUM(J14:O14) -> 6307.7 | Q14: =$P14*'Allocation %'!J14 -> 0 | R14: =$P14*'Allocation %'!K14 -> 0 | S14: =$P14*'Allocation %'!L14 -> 0 | T14: =$P14*'Allocation %'!M14 -> 0 | U14: =$P14*'Allocation %'!N14 -> 0 | V14: =$P14*'Allocation %'!O14 -> 2081.541 | W14: =$P14*'Allocation %'!P14 -> 4226.159 | X14: =$P14*'Allocation %'!Q14 -> 0 | ... AO14: =$P14*'Allocation %'!AH14 -> 0 | AP14: =SUM(Q14:AO14) -> 6307.7 | AQ14: =P14-AP14 -> 0
A15: 12 | B15: ='Allocation %'!B15 -> GREEN, Yolanda - | C15: 12 | D15: ='Allocation %'!D15 -> EHS/ Toddlers | E15: ='Allocation %'!E15 -> 0 | F15: 1278.88 | G15: =F15*$G$3 -> 33250.88 | I15: =SUM(G15:H15) -> 33250.88 | J15: 1274.89 | K15: 1284.73 | P15: =SUM(J15:O15) -> 2559.62 | Q15: =$P15*'Allocation %'!J15 -> 0 | R15: =$P15*'Allocation %'!K15 -> 0 | S15: =$P15*'Allocation %'!L15 -> 0 | T15: =$P15*'Allocation %'!M15 -> 2559.62 | U15: =$P15*'Allocation %'!N15 -> 0 | V15: =$P15*'Allocation %'!O15 -> 0 | W15: =$P15*'Allocation %'!P15 -> 0 | X15: =$P15*'Allocation %'!Q15 -> 0 | ... AO15: =$P15*'Allocation %'!AH15 -> 0 | AP15: =SUM(Q15:AO15) -> 2559.62 | AQ15: =P15-AP15 -> 0
A16: 13 | B16: ='Allocation %'!B16 -> Guerra, Karime | C16: 13 | D16: ='Allocation %'!D16 -> Housing | E16: ='Allocation %'!E16 -> 0 | F16: 1788.47 | G16: =F16*$G$3 -> 46500.22 | I16: =SUM(G16:H16) -> 46500.22 | J16: 1788.47 | K16: 1788.47 | P16: =SUM(J16:O16) -> 3576.94 | Q16: =$P16*'Allocation %'!J16 -> 0 | R16: =$P16*'Allocation %'!K16 -> 0 | S16: =$P16*'Allocation %'!L16 -> 0 | T16: =$P16*'Allocation %'!M16 -> 0 | U16: =$P16*'Allocation %'!N16 -> 0 | V16: =$P16*'Allocation %'!O16 -> 0 | W16: =$P16*'Allocation %'!P16 -> 0 | X16: =$P16*'Allocation %'!Q16 -> 0 | ... AO16: =$P16*'Allocation %'!AH16 -> 0 | AP16: =SUM(Q16:AO16) -> 3576.94 | AQ16: =P16-AP16 -> 0
A17: 14 | B17: ='Allocation %'!B17 -> HIGGINS, Rosa M. | C17: 14 | D17: ='Allocation %'!D17 -> FOC | E17: ='Allocation %'!E17 -> 0 | F17: 1538.46 | G17: =F17*$G$3 -> 39999.96 | I17: =SUM(G17:H17) -> 39999.96 | J17: 1538.46 | K17: 1538.46 | P17: =SUM(J17:O17) -> 3076.92 | Q17: =$P17*'Allocation %'!J17 -> 0 | R17: =$P17*'Allocation %'!K17 -> 0 | S17: =$P17*'Allocation %'!L17 -> 0 | T17: =$P17*'Allocation %'!M17 -> 0 | U17: =$P17*'Allocation %'!N17 -> 0 | V17: =$P17*'Allocation %'!O17 -> 0 | W17: =$P17*'Allocation %'!P17 -> 0 | X17: =$P17*'Allocation %'!Q17 -> 0 | ... AO17: =$P17*'Allocation %'!AH17 -> 0 | AP17: =SUM(Q17:AO17) -> 3076.92 | AQ17: =P17-AP17 -> 0
A18: 15 | B18: ='Allocation %'!B18 -> HOLLINS, QUINTELLA | C18: 15 | D18: ='Allocation %'!D18 -> Abbott | E18: ='Allocation %'!E18 -> Teacher | F18: 2305.82 | G18: =F18*$G$3 -> 59951.32 | I18: =SUM(G18:H18) -> 59951.32 | P18: =SUM(J18:O18) -> 0 | Q18: =$P18*'Allocation %'!J18 -> 0 | R18: =$P18*'Allocation %'!K18 -> 0 | S18: =$P18*'Allocation %'!L18 -> 0 | T18: =$P18*'Allocation %'!M18 -> 0 | U18: =$P18*'Allocation %'!N18 -> 0 | V18: =$P18*'Allocation %'!O18 -> 0 | W18: =$P18*'Allocation %'!P18 -> 0 | X18: =$P18*'Allocation %'!Q18 -> 0 | ... AO18: =$P18*'Allocation %'!AH18 -> 0 | AP18: =SUM(Q18:AO18) -> 0 | AQ18: =P18-AP18 -> 0
A19: 16 | B19: ='Allocation %'!B19 -> Howard, Theresa | C19: 16 | D19: ='Allocation %'!D19 -> United Airlines | E19: ='Allocation %'!E19 -> 0 | F19: 2115.39 | G19: =F19*$G$3 -> 55000.14 | I19: =SUM(G19:H19) -> 55000.14 | J19: 2115.39 | K19: 2115.39 | P19: =SUM(J19:O19) -> 4230.78 | Q19: =$P19*'Allocation %'!J19 -> 0 | R19: =$P19*'Allocation %'!K19 -> 0 | S19: =$P19*'Allocation %'!L19 -> 0 | T19: =$P19*'Allocation %'!M19 -> 0 | U19: =$P19*'Allocation %'!N19 -> 0 | V19: =$P19*'Allocation %'!O19 -> 4230.78 | W19: =$P19*'Allocation %'!P19 -> 0 | X19: =$P19*'Allocation %'!Q19 -> 0 | ... AO19: =$P19*'Allocation %'!AH19 -> 0 | AP19: =SUM(Q19:AO19) -> 4230.78 | AQ19: =P19-AP19 -> 0
A20: 17 | B20: ='Allocation %'!B20 -> Johnson, Amanda | C20: 17 | D20: ='Allocation %'!D20 -> USJP | E20: ='Allocation %'!E20 -> 0 | F20: 721 | G20: =F20*$G$3 -> 18746 | I20: =SUM(G20:H20) -> 18746 | J20: 425.39 | K20: 749.84 | P20: =SUM(J20:O20) -> 1175.23 | Q20: =$P20*'Allocation %'!J20 -> 0 | R20: =$P20*'Allocation %'!K20 -> 0 | S20: =$P20*'Allocation %'!L20 -> 0 | T20: =$P20*'Allocation %'!M20 -> 0 | U20: =$P20*'Allocation %'!N20 -> 1175.23 | V20: =$P20*'Allocation %'!O20 -> 0 | W20: =$P20*'Allocation %'!P20 -> 0 | X20: =$P20*'Allocation %'!Q20 -> 0 | ... AO20: =$P20*'Allocation %'!AH20 -> 0 | AP20: =SUM(Q20:AO20) -> 1175.23 | AQ20: =P20-AP20 -> 0
A21: 18 | B21: ='Allocation %'!B21 -> Leake, Rahmel | C21: 18 | D21: ='Allocation %'!D21 -> USJP | E21: ='Allocation %'!E21 -> 0 | F21: 1538.47 | G21: =F21*$G$3 -> 40000.22 | I21: =SUM(G21:H21) -> 40000.22 | J21: 1538.47 | K21: 1538.47 | P21: =SUM(J21:O21) -> 3076.94 | Q21: =$P21*'Allocation %'!J21 -> 0 | R21: =$P21*'Allocation %'!K21 -> 0 | S21: =$P21*'Allocation %'!L21 -> 0 | T21: =$P21*'Allocation %'!M21 -> 0 | U21: =$P21*'Allocation %'!N21 -> 3076.94 | V21: =$P21*'Allocation %'!O21 -> 0 | W21: =$P21*'Allocation %'!P21 -> 0 | X21: =$P21*'Allocation %'!Q21 -> 0 | ... AO21: =$P21*'Allocation %'!AH21 -> 0 | AP21: =SUM(Q21:AO21) -> 3076.94 | AQ21: =P21-AP21 -> 0
A22: 19 | B22: ='Allocation %'!B22 -> Lindsey, Victoria - July | C22: 19 | D22: ='Allocation %'!D22 -> NRTC, Housing, PARS, ESG | E22: ='Allocation %'!E22 -> 0 | F22: 2500 | G22: =F22*$G$3 -> 65000 | I22: =SUM(G22:H22) -> 65000 | J22: 2500 | K22: 2500 | P22: =SUM(J22:O22) -> 5000 | Q22: =$P22*'Allocation %'!J22 -> 0 | R22: =$P22*'Allocation %'!K22 -> 0 | S22: =$P22*'Allocation %'!L22 -> 0 | T22: =$P22*'Allocation %'!M22 -> 0 | U22: =$P22*'Allocation %'!N22 -> 0 | V22: =$P22*'Allocation %'!O22 -> 0 | W22: =$P22*'Allocation %'!P22 -> 0 | X22: =$P22*'Allocation %'!Q22 -> 0 | ... AO22: =$P22*'Allocation %'!AH22 -> 0 | AP22: =SUM(Q22:AO22) -> 5000 | AQ22: =P22-AP22 -> 0
A23: 20 | B23: ='Allocation %'!B23 -> LOFTIN, NIQUITA | C23: 20 | D23: ='Allocation %'!D23 -> Abbott | E23: ='Allocation %'!E23 -> Teacher Asst | F23: 1176 | G23: =F23*$G$3 -> 30576 | I23: =SUM(G23:H23) -> 30576 | J23: 1176 | K23: 1176 | P23: =SUM(J23:O23) -> 2352 | Q23: =$P23*'Allocation %'!J23 -> 2352 | R23: =$P23*'Allocation %'!K23 -> 0 | S23: =$P23*'Allocation %'!L23 -> 0 | T23: =$P23*'Allocation %'!M23 -> 0 | U23: =$P23*'Allocation %'!N23 -> 0 | V23: =$P23*'Allocation %'!O23 -> 0 | W23: =$P23*'Allocation %'!P23 -> 0 | X23: =$P23*'Allocation %'!Q23 -> 0 | ... AO23: =$P23*'Allocation %'!AH23 -> 0 | AP23: =SUM(Q23:AO23) -> 2352 | AQ23: =P23-AP23 -> 0
A24: 21 | B24: ='Allocation %'!B24 -> Love, Charles | C24: 21 | D24: ='Allocation %'!D24 -> PACE | E24: ='Allocation %'!E24 -> 0 | F24: 1200 | G24: =F24*$G$3 -> 31200 | I24: =SUM(G24:H24) -> 31200 | J24: 810 | K24: 1080 | P24: =SUM(J24:O24) -> 1890 | Q24: =$P24*'Allocation %'!J24 -> 0 | R24: =$P24*'Allocation %'!K24 -> 0 | S24: =$P24*'Allocation %'!L24 -> 0 | T24: =$P24*'Allocation %'!M24 -> 0 | U24: =$P24*'Allocation %'!N24 -> 0 | V24: =$P24*'Allocation %'!O24 -> 0 | W24: =$P24*'Allocation %'!P24 -> 0 | X24: =$P24*'Allocation %'!Q24 -> 1890 | ... AO24: =$P24*'Allocation %'!AH24 -> 0 | AP24: =SUM(Q24:AO24) -> 1890 | AQ24: =P24-AP24 -> 0
A25: 22 | B25: ='Allocation %'!B25 -> MARTINEZ, Joanna | C25: 22 | D25: ='Allocation %'!D25 -> USJP | E25: ='Allocation %'!E25 -> 0 | F25: 1538.47 | G25: =F25*$G$3 -> 40000.22 | I25: =SUM(G25:H25) -> 40000.22 | J25: 1538.47 | K25: 1538.47 | P25: =SUM(J25:O25) -> 3076.94 | Q25: =$P25*'Allocation %'!J25 -> 0 | R25: =$P25*'Allocation %'!K25 -> 0 | S25: =$P25*'Allocation %'!L25 -> 0 | T25: =$P25*'Allocation %'!M25 -> 0 | U25: =$P25*'Allocation %'!N25 -> 2923.093 | V25: =$P25*'Allocation %'!O25 -> 0 | W25: =$P25*'Allocation %'!P25 -> 0 | X25: =$P25*'Allocation %'!Q25 -> 0 | ... AO25: =$P25*'Allocation %'!AH25 -> 0 | AP25: =SUM(Q25:AO25) -> 3076.94 | AQ25: =P25-AP25 -> 0
A26: 23 | B26: ='Allocation %'!B26 -> McDaniels, Curtis | C26: 23 | D26: ='Allocation %'!D26 -> Neigh Revit | E26: ='Allocation %'!E26 -> 0 | F26: 1442.31 | G26: =F26*$G$3 -> 37500.06 | I26: =SUM(G26:H26) -> 37500.06 | J26: 1442.31 | K26: 1442.31 | P26: =SUM(J26:O26) -> 2884.62 | Q26: =$P26*'Allocation %'!J26 -> 0 | R26: =$P26*'Allocation %'!K26 -> 0 | S26: =$P26*'Allocation %'!L26 -> 0 | T26: =$P26*'Allocation %'!M26 -> 0 | U26: =$P26*'Allocation %'!N26 -> 0 | V26: =$P26*'Allocation %'!O26 -> 0 | W26: =$P26*'Allocation %'!P26 -> 0 | X26: =$P26*'Allocation %'!Q26 -> 0 | ... AO26: =$P26*'Allocation %'!AH26 -> 0 | AP26: =SUM(Q26:AO26) -> 2884.62 | AQ26: =P26-AP26 -> 0
A27: 24 | B27: ='Allocation %'!B27 -> MCMILLIAN, Daphne L. | C27: 24 | D27: ='Allocation %'!D27 -> Abbott | E27: ='Allocation %'!E27 -> Family Worker | F27: 1216.36 | G27: =F27*$G$3 -> 31625.36 | I27: =SUM(G27:H27) -> 31625.36 | J27: 1136.36 | K27: 1196.36 | P27: =SUM(J27:O27) -> 2332.72 | Q27: =$P27*'Allocation %'!J27 -> 2332.72 | R27: =$P27*'Allocation %'!K27 -> 0 | S27: =$P27*'Allocation %'!L27 -> 0 | T27: =$P27*'Allocation %'!M27 -> 0 | U27: =$P27*'Allocation %'!N27 -> 0 | V27: =$P27*'Allocation %'!O27 -> 0 | W27: =$P27*'Allocation %'!P27 -> 0 | X27: =$P27*'Allocation %'!Q27 -> 0 | ... AO27: =$P27*'Allocation %'!AH27 -> 0 | AP27: =SUM(Q27:AO27) -> 2332.72 | AQ27: =P27-AP27 -> 0
A28: 25 | B28: ='Allocation %'!B28 -> Mitchell, Felicia | C28: 25 | D28: ='Allocation %'!D28 -> Abbott | E28: ='Allocation %'!E28 -> Teacher | F28: 1114.7 | G28: =F28*$G$3 -> 28982.2 | I28: =SUM(G28:H28) -> 28982.2 | J28: 2173.91 | K28: 2173.91 | P28: =SUM(J28:O28) -> 4347.82 | Q28: =$P28*'Allocation %'!J28 -> 4347.82 | R28: =$P28*'Allocation %'!K28 -> 0 | S28: =$P28*'Allocation %'!L28 -> 0 | T28: =$P28*'Allocation %'!M28 -> 0 | U28: =$P28*'Allocation %'!N28 -> 0 | V28: =$P28*'Allocation %'!O28 -> 0 | W28: =$P28*'Allocation %'!P28 -> 0 | X28: =$P28*'Allocation %'!Q28 -> 0 | ... AO28: =$P28*'Allocation %'!AH28 -> 0 | AP28: =SUM(Q28:AO28) -> 4347.82 | AQ28: =P28-AP28 -> 0
A29: 26 | B29: ='Allocation %'!B29 -> MORRIS, GWEN | C29: 26 | D29: ='Allocation %'!D29 -> USJP | E29: ='Allocation %'!E29 -> 0 | F29: 2500 | G29: =F29*$G$3 -> 65000 | I29: =SUM(G29:H29) -> 65000 | J29: 2500 | K29: 2500 | P29: =SUM(J29:O29) -> 5000 | Q29: =$P29*'Allocation %'!J29 -> 0 | R29: =$P29*'Allocation %'!K29 -> 0 | S29: =$P29*'Allocation %'!L29 -> 0 | T29: =$P29*'Allocation %'!M29 -> 0 | U29: =$P29*'Allocation %'!N29 -> 5000 | V29: =$P29*'Allocation %'!O29 -> 0 | W29: =$P29*'Allocation %'!P29 -> 0 | X29: =$P29*'Allocation %'!Q29 -> 0 | ... AO29: =$P29*'Allocation %'!AH29 -> 0 | AP29: =SUM(Q29:AO29) -> 5000 | AQ29: =P29-AP29 -> 0
A30: 27 | B30: ='Allocation %'!B30 -> RAMBARAN, Sharaini J. | C30: 27 | D30: ='Allocation %'!D30 -> Abbott | E30: ='Allocation %'!E30 -> Floater | F30: 996.3 | G30: =F30*$G$3 -> 25903.8 | I30: =SUM(G30:H30) -> 25903.8 | J30: 207.56 | K30: 899.44 | P30: =SUM(J30:O30) -> 1107 | Q30: =$P30*'Allocation %'!J30 -> 1107 | R30: =$P30*'Allocation %'!K30 -> 0 | S30: =$P30*'Allocation %'!L30 -> 0 | T30: =$P30*'Allocation %'!M30 -> 0 | U30: =$P30*'Allocation %'!N30 -> 0 | V30: =$P30*'Allocation %'!O30 -> 0 | W30: =$P30*'Allocation %'!P30 -> 0 | X30: =$P30*'Allocation %'!Q30 -> 0 | ... AO30: =$P30*'Allocation %'!AH30 -> 0 | AP30: =SUM(Q30:AO30) -> 1107 | AQ30: =P30-AP30 -> 0
A31: 28 | B31: ='Allocation %'!B31 -> Robbins, Leonard | C31: 28 | D31: ='Allocation %'!D31 -> Opportunity Corp | E31: ='Allocation %'!E31 -> 0 | F31: 2769.23 | G31: =F31*$G$3 -> 71999.98 | H31: 3076.93 | I31: =H31*$G$3 -> 80000.18 | P31: =SUM(J31:O31) -> 0 | Q31: =$P31*'Allocation %'!J31 -> 0 | R31: =$P31*'Allocation %'!K31 -> 0 | S31: =$P31*'Allocation %'!L31 -> 0 | T31: =$P31*'Allocation %'!M31 -> 0 | U31: =$P31*'Allocation %'!N31 -> 0 | V31: =$P31*'Allocation %'!O31 -> 0 | W31: =$P31*'Allocation %'!P31 -> 0 | X31: =$P31*'Allocation %'!Q31 -> 0 | ... AO31: =$P31*'Allocation %'!AH31 -> 0 | AP31: =SUM(Q31:AO31) -> 0 | AQ31: =P31-AP31 -> 0
A32: 29 | B32: ='Allocation %'!B32 -> SERMON, Patricia April | C32: 29 | D32: ='Allocation %'!D32 -> FOC, Housing, OICA, COO | E32: ='Allocation %'!E32 -> 0 | F32: 3153.85 | G32: =F32*$G$3 -> 82000.1 | H32: 3461.54 | I32: =H32*$G$3 -> 90000.04 | J32: 13246.39 | K32: 3461.54 | P32: =SUM(J32:O32) -> 16707.93 | Q32: =$P32*'Allocation %'!J32 -> 0 | R32: =$P32*'Allocation %'!K32 -> 0 | S32: =$P32*'Allocation %'!L32 -> 0 | T32: =$P32*'Allocation %'!M32 -> 0 | U32: =$P32*'Allocation %'!N32 -> 3341.586 | V32: =$P32*'Allocation %'!O32 -> 0 | W32: =$P32*'Allocation %'!P32 -> 4009.9032 | X32: =$P32*'Allocation %'!Q32 -> 0 | ... AO32: =$P32*'Allocation %'!AH32 -> 0 | AP32: =SUM(Q32:AO32) -> 16707.93 | AQ32: =P32-AP32 -> 0
A33: 30 | B33: ='Allocation %'!B33 -> SHARIF, Darrin S. - April | C33: 30 | D33: ='Allocation %'!D33 -> Admin, Coding, WF | E33: ='Allocation %'!E33 -> 0 | F33: 3269 | G33: =F33*$G$3 -> 84994 | I33: =SUM(G33:H33) -> 84994 | J33: 8269 | K33: 3269 | P33: =SUM(J33:O33) -> 11538 | Q33: =$P33*'Allocation %'!J33 -> 0 | R33: =$P33*'Allocation %'!K33 -> 0 | S33: =$P33*'Allocation %'!L33 -> 0 | T33: =$P33*'Allocation %'!M33 -> 0 | U33: =$P33*'Allocation %'!N33 -> 0 | V33: =$P33*'Allocation %'!O33 -> 0 | W33: =$P33*'Allocation %'!P33 -> 0 | X33: =$P33*'Allocation %'!Q33 -> 0 | ... AO33: =$P33*'Allocation %'!AH33 -> 0 | AP33: =SUM(Q33:AO33) -> 11538 | AQ33: =P33-AP33 -> 0
A34: 31 | B34: ='Allocation %'!B34 -> SIMMONS, Bertrilla R. | C34: 31 | D34: ='Allocation %'!D34 -> Abbott | E34: ='Allocation %'!E34 -> Teacher | F34: 2684.05 | G34: =F34*$G$3 -> 69785.3 | I34: =SUM(G34:H34) -> 69785.3 | J34: 2684.05 | K34: 2684.05 | P34: =SUM(J34:O34) -> 5368.1 | Q34: =$P34*'Allocation %'!J34 -> 5368.1 | R34: =$P34*'Allocation %'!K34 -> 0 | S34: =$P34*'Allocation %'!L34 -> 0 | T34: =$P34*'Allocation %'!M34 -> 0 | U34: =$P34*'Allocation %'!N34 -> 0 | V34: =$P34*'Allocation %'!O34 -> 0 | W34: =$P34*'Allocation %'!P34 -> 0 | X34: =$P34*'Allocation %'!Q34 -> 0 | ... AO34: =$P34*'Allocation %'!AH34 -> 0 | AP34: =SUM(Q34:AO34) -> 5368.1 | AQ34: =P34-AP34 -> 0
A35: 32 | B35: ='Allocation %'!B35 -> STEWART, Robin D | C35: 32 | D35: ='Allocation %'!D35 -> Abbott | E35: ='Allocation %'!E35 -> Teacher Asst | F35: 1611.08 | G35: =F35*$G$3 -> 41888.08 | I35: =SUM(G35:H35) -> 41888.08 | J35: 1629.78 | K35: 1579.24 | P35: =SUM(J35:O35) -> 3209.02 | Q35: =$P35*'Allocation %'!J35 -> 3209.02 | R35: =$P35*'Allocation %'!K35 -> 0 | S35: =$P35*'Allocation %'!L35 -> 0 | T35: =$P35*'Allocation %'!M35 -> 0 | U35: =$P35*'Allocation %'!N35 -> 0 | V35: =$P35*'Allocation %'!O35 -> 0 | W35: =$P35*'Allocation %'!P35 -> 0 | X35: =$P35*'Allocation %'!Q35 -> 0 | ... AO35: =$P35*'Allocation %'!AH35 -> 0 | AP35: =SUM(Q35:AO35) -> 3209.02 | AQ35: =P35-AP35 -> 0
A36: 33 | B36: ='Allocation %'!B36 -> TYLER, Patricia | C36: 33 | D36: ='Allocation %'!D36 -> Abbott | E36: ='Allocation %'!E36 -> Cook | F36: 454.96 | G36: =F36*$G$3 -> 11828.96 | I36: =SUM(G36:H36) -> 11828.96 | J36: 161.7 | K36: 605 | P36: =SUM(J36:O36) -> 766.7 | Q36: =$P36*'Allocation %'!J36 -> 766.7 | R36: =$P36*'Allocation %'!K36 -> 0 | S36: =$P36*'Allocation %'!L36 -> 0 | T36: =$P36*'Allocation %'!M36 -> 0 | U36: =$P36*'Allocation %'!N36 -> 0 | V36: =$P36*'Allocation %'!O36 -> 0 | W36: =$P36*'Allocation %'!P36 -> 0 | X36: =$P36*'Allocation %'!Q36 -> 0 | ... AO36: =$P36*'Allocation %'!AH36 -> 0 | AP36: =SUM(Q36:AO36) -> 766.7 | AQ36: =P36-AP36 -> 0
A37: 34 | B37: ='Allocation %'!B37 -> WARD, Richard G. - Off Jan 1 | C37: 34 | D37: ='Allocation %'!D37 -> Admin | E37: ='Allocation %'!E37 -> 0 | F37: 4230.77 | G37: =F37*$G$3 -> 110000.02 | I37: =SUM(G37:H37) -> 110000.02 | J37: 4230.77 | K37: 4230.77 | P37: =SUM(J37:O37) -> 8461.54 | Q37: =$P37*'Allocation %'!J37 -> 0 | R37: =$P37*'Allocation %'!K37 -> 0 | S37: =$P37*'Allocation %'!L37 -> 0 | T37: =$P37*'Allocation %'!M37 -> 0 | U37: =$P37*'Allocation %'!N37 -> 0 | V37: =$P37*'Allocation %'!O37 -> 0 | W37: =$P37*'Allocation %'!P37 -> 0 | X37: =$P37*'Allocation %'!Q37 -> 0 | ... AO37: =$P37*'Allocation %'!AH37 -> 0 | AP37: =SUM(Q37:AO37) -> 8461.54 | AQ37: =P37-AP37 -> 0
A38: 35 | B38: ='Allocation %'!B38 -> Williams, Kyneisha - Career Coach | C38: 35 | D38: ='Allocation %'!D38 -> United Airlines, PACE June 30 | E38: ='Allocation %'!E38 -> 0 | F38: 1538.47 | G38: =F38*$G$3 -> 40000.22 | I38: =SUM(G38:H38) -> 40000.22 | J38: 1538.47 | K38: 1538.47 | P38: =SUM(J38:O38) -> 3076.94 | Q38: =$P38*'Allocation %'!J38 -> 0 | R38: =$P38*'Allocation %'!K38 -> 0 | S38: =$P38*'Allocation %'!L38 -> 0 | T38: =$P38*'Allocation %'!M38 -> 0 | U38: =$P38*'Allocation %'!N38 -> 0 | V38: =$P38*'Allocation %'!O38 -> 0 | W38: =$P38*'Allocation %'!P38 -> 0 | X38: =$P38*'Allocation %'!Q38 -> 3076.94 | ... AO38: =$P38*'Allocation %'!AH38 -> 0 | AP38: =SUM(Q38:AO38) -> 3076.94 | AQ38: =P38-AP38 -> 0
A39: 36 | B39: ='Allocation %'!B39 -> WOODRIDGE, Rosalind | C39: 36 | D39: ='Allocation %'!D39 -> Wrap | E39: ='Allocation %'!E39 -> Wrap Teacher | F39: 510 | G39: =F39*$G$3 -> 13260 | I39: =SUM(G39:H39) -> 13260 | J39: 157.5 | K39: 528 | P39: =SUM(J39:O39) -> 685.5 | Q39: =$P39*'Allocation %'!J39 -> 0 | R39: =$P39*'Allocation %'!K39 -> 0 | S39: =$P39*'Allocation %'!L39 -> 685.5 | T39: =$P39*'Allocation %'!M39 -> 0 | U39: =$P39*'Allocation %'!N39 -> 0 | V39: =$P39*'Allocation %'!O39 -> 0 | W39: =$P39*'Allocation %'!P39 -> 0 | X39: =$P39*'Allocation %'!Q39 -> 0 | ... AO39: =$P39*'Allocation %'!AH39 -> 0 | AP39: =SUM(Q39:AO39) -> 685.5 | AQ39: =P39-AP39 -> 0
P40: =SUM(J40:O40) -> 0 | Q40: =$P40*'Allocation %'!J40 -> 0 | R40: =$P40*'Allocation %'!K40 -> 0 | S40: =$P40*'Allocation %'!L40 -> 0 | T40: =$P40*'Allocation %'!M40 -> 0 | U40: =$P40*'Allocation %'!N40 -> 0 | V40: =$P40*'Allocation %'!O40 -> 0 | W40: =$P40*'Allocation %'!P40 -> 0 | X40: =$P40*'Allocation %'!Q40 -> 0 | ... AO40: =$P40*'Allocation %'!AH40 -> 0 | AP40: =SUM(Q40:AO40) -> 0 | AQ40: =P40-AP40 -> 0
AP41: =SUM(Q41:AO41) -> 0 | AQ41: =P41-AP41 -> 0
...

Sheet Health
B2: SALARIES 2020 | D2: Class Codes | F2: Bi Weekly | G2: Annual Budget | H2: Salary Adj | I2: Salary Revised | J2: 43831 | K2: 43862 | P2: Total | Q2: =Salary!Q2 -> Abbott | R2: =Salary!R2 -> Abbott - Other | S2: =Salary!T2 -> Toddlers | T2: =Salary!U2 -> USJP | U2: =Salary!V2 -> Workforce UA | V2: =Salary!W2 -> Pru -Workforce | W2: =Salary!X2 -> PACE | X2: =Salary!Y2 -> Housing ESG | Y2: =Salary!Z2 -> NRTC18 | Z2: =Salary!AA2 -> NRTC 20 | ... AO2: =Salary!AP2 -> 0
G3: 26
A4: =Salary!A4 -> 1 | B4: ='Allocation %'!B4 -> ANDREWS, Cora | C4: 1 | D4: ='Allocation %'!D4 -> Abbott | E4: ='Allocation %'!E4 -> Security | F4: 1120 | G4: =F4*$G$3 -> 29120 | I4: =SUM(G4:H4) -> 29120 | P4: =SUM(J4:O4) -> 0 | Q4: =$P4*'Allocation %'!J4 -> 0 | R4: =$P4*'Allocation %'!K4 -> 0 | S4: =$P4*'Allocation %'!M4 -> 0 | T4: =$P4*'Allocation %'!N4 -> 0 | U4: =$P4*'Allocation %'!O4 -> 0 | V4: =$P4*'Allocation %'!P4 -> 0 | W4: =$P4*'Allocation %'!Q4 -> 0 | X4: =$P4*'Allocation %'!R4 -> 0 | Y4: =$P4*'Allocation %'!S4 -> 0 | Z4: =$P4*'Allocation %'!T4 -> 0 | ... AN4: =$P4*'Allocation %'!AH4 -> 0 | AO4: =SUM(Q4:AN4) -> 0 | AP4: =P4-AO4 -> 0
A5: =Salary!A5 -> 2 | B5: ='Allocation %'!B5 -> Bennett, Patricia A. | C5: 2 | D5: ='Allocation %'!D5 -> Abbott, Admin | E5: ='Allocation %'!E5 -> Custodian | F5: 650 | G5: =F5*$G$3 -> 16900 | I5: =SUM(G5:H5) -> 16900 | P5: =SUM(J5:O5) -> 0 | Q5: =$P5*'Allocation %'!J5 -> 0 | R5: =$P5*'Allocation %'!K5 -> 0 | S5: =$P5*'Allocation %'!M5 -> 0 | T5: =$P5*'Allocation %'!N5 -> 0 | U5: =$P5*'Allocation %'!O5 -> 0 | V5: =$P5*'Allocation %'!P5 -> 0 | W5: =$P5*'Allocation %'!Q5 -> 0 | X5: =$P5*'Allocation %'!R5 -> 0 | Y5: =$P5*'Allocation %'!S5 -> 0 | Z5: =$P5*'Allocation %'!T5 -> 0 | ... AN5: =$P5*'Allocation %'!AH5 -> 0 | AO5: =SUM(Q5:AN5) -> 0 | AP5: =P5-AO5 -> 0
A6: =Salary!A6 -> 3 | B6: ='Allocation %'!B6 -> Bishop-Shakoor, Ayesha | C6: 3 | D6: ='Allocation %'!D6 -> Abbott, Admin | E6: ='Allocation %'!E6 -> 0 | Q6: =$P6*'Allocation %'!J6 -> 0 | R6: =$P6*'Allocation %'!K6 -> 0 | S6: =$P6*'Allocation %'!M6 -> 0 | T6: =$P6*'Allocation %'!N6 -> 0 | U6: =$P6*'Allocation %'!O6 -> 0 | V6: =$P6*'Allocation %'!P6 -> 0 | W6: =$P6*'Allocation %'!Q6 -> 0 | X6: =$P6*'Allocation %'!R6 -> 0 | Y6: =$P6*'Allocation %'!S6 -> 0 | Z6: =$P6*'Allocation %'!T6 -> 0 | ... AN6: =$P6*'Allocation %'!AH6 -> 0 | AO6: =SUM(Q6:AN6) -> 0 | AP6: =P6-AO6 -> 0
A7: =Salary!A7 -> 4 | B7: ='Allocation %'!B7 -> BROWN,Denise- Wrap | C7: 4 | D7: ='Allocation %'!D7 -> Wrap | E7: ='Allocation %'!E7 -> Wrap Teacher | F7: 520 | G7: =F7*$G$3 -> 13520 | I7: =SUM(G7:H7) -> 13520 | P7: =SUM(J7:O7) -> 0 | Q7: =$P7*'Allocation %'!J7 -> 0 | R7: =$P7*'Allocation %'!K7 -> 0 | S7: =$P7*'Allocation %'!M7 -> 0 | T7: =$P7*'Allocation %'!N7 -> 0 | U7: =$P7*'Allocation %'!O7 -> 0 | V7: =$P7*'Allocation %'!P7 -> 0 | W7: =$P7*'Allocation %'!Q7 -> 0 | X7: =$P7*'Allocation %'!R7 -> 0 | Y7: =$P7*'Allocation %'!S7 -> 0 | Z7: =$P7*'Allocation %'!T7 -> 0 | ... AN7: =$P7*'Allocation %'!AH7 -> 0 | AO7: =SUM(Q7:AN7) -> 0 | AP7: =P7-AO7 -> 0
A8: =Salary!A8 -> 5 | B8: ='Allocation %'!B8 -> BRYANT, Roni | C8: 5 | D8: ='Allocation %'!D8 -> Abbott | E8: ='Allocation %'!E8 -> Teacher Asst | F8: 1347.23 | G8: =F8*$G$3 -> 35027.98 | I8: =SUM(G8:H8) -> 35027.98 | J8: 865.47 | K8: 865.47 | P8: =SUM(J8:O8) -> 1730.94 | Q8: =$P8*'Allocation %'!J8 -> 1730.94 | R8: =$P8*'Allocation %'!K8 -> 0 | S8: =$P8*'Allocation %'!M8 -> 0 | T8: =$P8*'Allocation %'!N8 -> 0 | U8: =$P8*'Allocation %'!O8 -> 0 | V8: =$P8*'Allocation %'!P8 -> 0 | W8: =$P8*'Allocation %'!Q8 -> 0 | X8: =$P8*'Allocation %'!R8 -> 0 | Y8: =$P8*'Allocation %'!S8 -> 0 | Z8: =$P8*'Allocation %'!T8 -> 0 | ... AN8: =$P8*'Allocation %'!AH8 -> 0 | AO8: =SUM(Q8:AN8) -> 1730.94 | AP8: =P8-AO8 -> 0
A9: =Salary!A9 -> 6 | B9: ='Allocation %'!B9 -> CERNA, Irene | C9: 6 | D9: ='Allocation %'!D9 -> USJP | E9: ='Allocation %'!E9 -> 0 | F9: 1153.85 | G9: =F9*$G$3 -> 30000.1 | I9: =SUM(G9:H9) -> 30000.1 | J9: 1068.35 | K9: 1068.35 | P9: =SUM(J9:O9) -> 2136.7 | Q9: =$P9*'Allocation %'!J9 -> 0 | R9: =$P9*'Allocation %'!K9 -> 0 | S9: =$P9*'Allocation %'!M9 -> 0 | T9: =$P9*'Allocation %'!N9 -> 2136.7 | U9: =$P9*'Allocation %'!O9 -> 0 | V9: =$P9*'Allocation %'!P9 -> 0 | W9: =$P9*'Allocation %'!Q9 -> 0 | X9: =$P9*'Allocation %'!R9 -> 0 | Y9: =$P9*'Allocation %'!S9 -> 0 | Z9: =$P9*'Allocation %'!T9 -> 0 | ... AN9: =$P9*'Allocation %'!AH9 -> 0 | AO9: =SUM(Q9:AN9) -> 2136.7 | AP9: =P9-AO9 -> 0
A10: =Salary!A10 -> 7 | B10: ='Allocation %'!B10 -> Cooper, Cassandra | C10: 7 | D10: ='Allocation %'!D10 -> FOC | E10: ='Allocation %'!E10 -> Clerical | Q10: =$P10*'Allocation %'!J10 -> 0 | R10: =$P10*'Allocation %'!K10 -> 0 | S10: =$P10*'Allocation %'!M10 -> 0 | T10: =$P10*'Allocation %'!N10 -> 0 | U10: =$P10*'Allocation %'!O10 -> 0 | V10: =$P10*'Allocation %'!P10 -> 0 | W10: =$P10*'Allocation %'!Q10 -> 0 | X10: =$P10*'Allocation %'!R10 -> 0 | Y10: =$P10*'Allocation %'!S10 -> 0 | Z10: =$P10*'Allocation %'!T10 -> 0 | ... AN10: =$P10*'Allocation %'!AH10 -> 0 | AO10: =SUM(Q10:AN10) -> 0 | AP10: =P10-AO10 -> 0
A11: =Salary!A11 -> 8 | B11: ='Allocation %'!B11 -> DANCE-WILSON, Heather | C11: 8 | D11: ='Allocation %'!D11 -> Abbott | E11: ='Allocation %'!E11 -> Director | F11: 2692.31 | G11: =F11*$G$3 -> 70000.06 | I11: =SUM(G11:H11) -> 70000.06 | J11: 1608.63 | K11: 1608.63 | P11: =SUM(J11:O11) -> 3217.26 | Q11: =$P11*'Allocation %'!J11 -> 2316.4272 | R11: =$P11*'Allocation %'!K11 -> 900.8328 | S11: =$P11*'Allocation %'!M11 -> 0 | T11: =$P11*'Allocation %'!N11 -> 0 | U11: =$P11*'Allocation %'!O11 -> 0 | V11: =$P11*'Allocation %'!P11 -> 0 | W11: =$P11*'Allocation %'!Q11 -> 0 | X11: =$P11*'Allocation %'!R11 -> 0 | Y11: =$P11*'Allocation %'!S11 -> 0 | Z11: =$P11*'Allocation %'!T11 -> 0 | ... AN11: =$P11*'Allocation %'!AH11 -> 0 | AO11: =SUM(Q11:AN11) -> 3217.26 | AP11: =P11-AO11 -> 0
A12: =Salary!A12 -> 9 | B12: ='Allocation %'!B12 -> FITZPATRICK, Cynthia E. - Toddlers | C12: 9 | D12: ='Allocation %'!D12 -> EHS/ Toddlers | E12: ='Allocation %'!E12 -> 0 | F12: 969.96 | G12: =F12*$G$3 -> 25218.96 | I12: =SUM(G12:H12) -> 25218.96 | J12: 1068.35 | K12: 1068.35 | P12: =SUM(J12:O12) -> 2136.7 | Q12: =$P12*'Allocation %'!J12 -> 0 | R12: =$P12*'Allocation %'!K12 -> 0 | S12: =$P12*'Allocation %'!M12 -> 2136.7 | T12: =$P12*'Allocation %'!N12 -> 0 | U12: =$P12*'Allocation %'!O12 -> 0 | V12: =$P12*'Allocation %'!P12 -> 0 | W12: =$P12*'Allocation %'!Q12 -> 0 | X12: =$P12*'Allocation %'!R12 -> 0 | Y12: =$P12*'Allocation %'!S12 -> 0 | Z12: =$P12*'Allocation %'!T12 -> 0 | ... AN12: =$P12*'Allocation %'!AH12 -> 0 | AO12: =SUM(Q12:AN12) -> 2136.7 | AP12: =P12-AO12 -> 0
A13: =Salary!A13 -> 10 | B13: ='Allocation %'!B13 -> FRASER, Vivian Cox | C13: 10 | D13: ='Allocation %'!D13 -> Admin | E13: ='Allocation %'!E13 -> 0 | F13: 5961.54 | G13: =F13*$G$3 -> 155000.04 | I13: =SUM(G13:H13) -> 155000.04 | P13: =SUM(J13:O13) -> 0 | Q13: =$P13*'Allocation %'!J13 -> 0 | R13: =$P13*'Allocation %'!K13 -> 0 | S13: =$P13*'Allocation %'!M13 -> 0 | T13: =$P13*'Allocation %'!N13 -> 0 | U13: =$P13*'Allocation %'!O13 -> 0 | V13: =$P13*'Allocation %'!P13 -> 0 | W13: =$P13*'Allocation %'!Q13 -> 0 | X13: =$P13*'Allocation %'!R13 -> 0 | Y13: =$P13*'Allocation %'!S13 -> 0 | Z13: =$P13*'Allocation %'!T13 -> 0 | ... AN13: =$P13*'Allocation %'!AH13 -> 0 | AO13: =SUM(Q13:AN13) -> 0 | AP13: =P13-AO13 -> 0
A14: =Salary!A14 -> 11 | B14: ='Allocation %'!B14 -> FRAZIER, Alice | C14: 11 | D14: ='Allocation %'!D14 -> Workforce | E14: ='Allocation %'!E14 -> 0 | F14: 3153.85 | G14: =F14*$G$3 -> 82000.1 | I14: =SUM(G14:H14) -> 82000.1 | P14: =SUM(J14:O14) -> 0 | Q14: =$P14*'Allocation %'!J14 -> 0 | R14: =$P14*'Allocation %'!K14 -> 0 | S14: =$P14*'Allocation %'!M14 -> 0 | T14: =$P14*'Allocation %'!N14 -> 0 | U14: =$P14*'Allocation %'!O14 -> 0 | V14: =$P14*'Allocation %'!P14 -> 0 | W14: =$P14*'Allocation %'!Q14 -> 0 | X14: =$P14*'Allocation %'!R14 -> 0 | Y14: =$P14*'Allocation %'!S14 -> 0 | Z14: =$P14*'Allocation %'!T14 -> 0 | ... AN14: =$P14*'Allocation %'!AH14 -> 0 | AO14: =SUM(Q14:AN14) -> 0 | AP14: =P14-AO14 -> 0
A15: =Salary!A15 -> 12 | B15: ='Allocation %'!B15 -> GREEN, Yolanda - | C15: 12 | D15: ='Allocation %'!D15 -> EHS/ Toddlers | E15: ='Allocation %'!E15 -> 0 | F15: 1278.88 | G15: =F15*$G$3 -> 33250.88 | I15: =SUM(G15:H15) -> 33250.88 | J15: 946.06 | K15: 946.06 | P15: =SUM(J15:O15) -> 1892.12 | Q15: =$P15*'Allocation %'!J15 -> 0 | R15: =$P15*'Allocation %'!K15 -> 0 | S15: =$P15*'Allocation %'!M15 -> 1892.12 | T15: =$P15*'Allocation %'!N15 -> 0 | U15: =$P15*'Allocation %'!O15 -> 0 | V15: =$P15*'Allocation %'!P15 -> 0 | W15: =$P15*'Allocation %'!Q15 -> 0 | X15: =$P15*'Allocation %'!R15 -> 0 | Y15: =$P15*'Allocation %'!S15 -> 0 | Z15: =$P15*'Allocation %'!T15 -> 0 | ... AN15: =$P15*'Allocation %'!AH15 -> 0 | AO15: =SUM(Q15:AN15) -> 1892.12 | AP15: =P15-AO15 -> 0
A16: =Salary!A16 -> 13 | B16: ='Allocation %'!B16 -> Guerra, Karime | C16: 13 | D16: ='Allocation %'!D16 -> Housing | E16: ='Allocation %'!E16 -> 0 | F16: 1788.47 | G16: =F16*$G$3 -> 46500.22 | I16: =SUM(G16:H16) -> 46500.22 | K16: 290.52 | P16: =SUM(J16:O16) -> 290.52 | Q16: =$P16*'Allocation %'!J16 -> 0 | R16: =$P16*'Allocation %'!K16 -> 0 | S16: =$P16*'Allocation %'!M16 -> 0 | T16: =$P16*'Allocation %'!N16 -> 0 | U16: =$P16*'Allocation %'!O16 -> 0 | V16: =$P16*'Allocation %'!P16 -> 0 | W16: =$P16*'Allocation %'!Q16 -> 0 | X16: =$P16*'Allocation %'!R16 -> 43.578 | Y16: =$P16*'Allocation %'!S16 -> 0 | Z16: =$P16*'Allocation %'!T16 -> 214.9848 | ... AN16: =$P16*'Allocation %'!AH16 -> 0 | AO16: =SUM(Q16:AN16) -> 290.52 | AP16: =P16-AO16 -> 0
A17: =Salary!A17 -> 14 | B17: ='Allocation %'!B17 -> HIGGINS, Rosa M. | C17: 14 | D17: ='Allocation %'!D17 -> FOC | E17: ='Allocation %'!E17 -> 0 | F17: 1538.46 | G17: =F17*$G$3 -> 39999.96 | I17: =SUM(G17:H17) -> 39999.96 | P17: =SUM(J17:O17) -> 0 | Q17: =$P17*'Allocation %'!J17 -> 0 | R17: =$P17*'Allocation %'!K17 -> 0 | S17: =$P17*'Allocation %'!M17 -> 0 | T17: =$P17*'Allocation %'!N17 -> 0 | U17: =$P17*'Allocation %'!O17 -> 0 | V17: =$P17*'Allocation %'!P17 -> 0 | W17: =$P17*'Allocation %'!Q17 -> 0 | X17: =$P17*'Allocation %'!R17 -> 0 | Y17: =$P17*'Allocation %'!S17 -> 0 | Z17: =$P17*'Allocation %'!T17 -> 0 | ... AN17: =$P17*'Allocation %'!AH17 -> 0 | AO17: =SUM(Q17:AN17) -> 0 | AP17: =P17-AO17 -> 0
A18: =Salary!A18 -> 15 | B18: ='Allocation %'!B18 -> HOLLINS, QUINTELLA | C18: 15 | D18: ='Allocation %'!D18 -> Abbott | E18: ='Allocation %'!E18 -> Teacher | F18: 2305.82 | G18: =F18*$G$3 -> 59951.32 | I18: =SUM(G18:H18) -> 59951.32 | J18: 1346.7 | K18: 1346.7 | P18: =SUM(J18:O18) -> 2693.4 | Q18: =$P18*'Allocation %'!J18 -> 2693.4 | R18: =$P18*'Allocation %'!K18 -> 0 | S18: =$P18*'Allocation %'!M18 -> 0 | T18: =$P18*'Allocation %'!N18 -> 0 | U18: =$P18*'Allocation %'!O18 -> 0 | V18: =$P18*'Allocation %'!P18 -> 0 | W18: =$P18*'Allocation %'!Q18 -> 0 | X18: =$P18*'Allocation %'!R18 -> 0 | Y18: =$P18*'Allocation %'!S18 -> 0 | Z18: =$P18*'Allocation %'!T18 -> 0 | ... AN18: =$P18*'Allocation %'!AH18 -> 0 | AO18: =SUM(Q18:AN18) -> 2693.4 | AP18: =P18-AO18 -> 0
A19: =Salary!A19 -> 16 | B19: ='Allocation %'!B19 -> Howard, Theresa | C19: 16 | D19: ='Allocation %'!D19 -> United Airlines | E19: ='Allocation %'!E19 -> 0 | F19: 2115.39 | G19: =F19*$G$3 -> 55000.14 | I19: =SUM(G19:H19) -> 55000.14 | J19: 746.45 | K19: 746.45 | P19: =SUM(J19:O19) -> 1492.9 | Q19: =$P19*'Allocation %'!J19 -> 0 | R19: =$P19*'Allocation %'!K19 -> 0 | S19: =$P19*'Allocation %'!M19 -> 0 | T19: =$P19*'Allocation %'!N19 -> 0 | U19: =$P19*'Allocation %'!O19 -> 1492.9 | V19: =$P19*'Allocation %'!P19 -> 0 | W19: =$P19*'Allocation %'!Q19 -> 0 | X19: =$P19*'Allocation %'!R19 -> 0 | Y19: =$P19*'Allocation %'!S19 -> 0 | Z19: =$P19*'Allocation %'!T19 -> 0 | ... AN19: =$P19*'Allocation %'!AH19 -> 0 | AO19: =SUM(Q19:AN19) -> 1492.9 | AP19: =P19-AO19 -> 0
A20: =Salary!A20 -> 17 | B20: ='Allocation %'!B20 -> Johnson, Amanda | C20: 17 | D20: ='Allocation %'!D20 -> USJP | E20: ='Allocation %'!E20 -> 0 | F20: 721 | G20: =F20*$G$3 -> 18746 | I20: =SUM(G20:H20) -> 18746 | P20: =SUM(J20:O20) -> 0 | Q20: =$P20*'Allocation %'!J20 -> 0 | R20: =$P20*'Allocation %'!K20 -> 0 | S20: =$P20*'Allocation %'!M20 -> 0 | T20: =$P20*'Allocation %'!N20 -> 0 | U20: =$P20*'Allocation %'!O20 -> 0 | V20: =$P20*'Allocation %'!P20 -> 0 | W20: =$P20*'Allocation %'!Q20 -> 0 | X20: =$P20*'Allocation %'!R20 -> 0 | Y20: =$P20*'Allocation %'!S20 -> 0 | Z20: =$P20*'Allocation %'!T20 -> 0 | ... AN20: =$P20*'Allocation %'!AH20 -> 0 | AO20: =SUM(Q20:AN20) -> 0 | AP20: =P20-AO20 -> 0
A21: =Salary!A21 -> 18 | B21: ='Allocation %'!B21 -> Leake, Rahmel | C21: 18 | D21: ='Allocation %'!D21 -> USJP | E21: ='Allocation %'!E21 -> 0 | F21: 1538.47 | G21: =F21*$G$3 -> 40000.22 | I21: =SUM(G21:H21) -> 40000.22 | P21: =SUM(J21:O21) -> 0 | Q21: =$P21*'Allocation %'!J21 -> 0 | R21: =$P21*'Allocation %'!K21 -> 0 | S21: =$P21*'Allocation %'!M21 -> 0 | T21: =$P21*'Allocation %'!N21 -> 0 | U21: =$P21*'Allocation %'!O21 -> 0 | V21: =$P21*'Allocation %'!P21 -> 0 | W21: =$P21*'Allocation %'!Q21 -> 0 | X21: =$P21*'Allocation %'!R21 -> 0 | Y21: =$P21*'Allocation %'!S21 -> 0 | Z21: =$P21*'Allocation %'!T21 -> 0 | ... AN21: =$P21*'Allocation %'!AH21 -> 0 | AO21: =SUM(Q21:AN21) -> 0 | AP21: =P21-AO21 -> 0
A22: =Salary!A22 -> 19 | B22: ='Allocation %'!B22 -> Lindsey, Victoria - July | C22: 19 | D22: ='Allocation %'!D22 -> NRTC, Housing, PARS, ESG | E22: ='Allocation %'!E22 -> 0 | F22: 2500 | G22: =F22*$G$3 -> 65000 | I22: =SUM(G22:H22) -> 65000 | J22: 1068.35 | K22: 1068.35 | P22: =SUM(J22:O22) -> 2136.7 | Q22: =$P22*'Allocation %'!J22 -> 0 | R22: =$P22*'Allocation %'!K22 -> 0 | S22: =$P22*'Allocation %'!M22 -> 0 | T22: =$P22*'Allocation %'!N22 -> 0 | U22: =$P22*'Allocation %'!O22 -> 0 | V22: =$P22*'Allocation %'!P22 -> 0 | W22: =$P22*'Allocation %'!Q22 -> 0 | X22: =$P22*'Allocation %'!R22 -> 534.175 | Y22: =$P22*'Allocation %'!S22 -> 384.606 | Z22: =$P22*'Allocation %'!T22 -> 149.569 | ... AN22: =$P22*'Allocation %'!AH22 -> 0 | AO22: =SUM(Q22:AN22) -> 2136.7 | AP22: =P22-AO22 -> 0
A23: =Salary!A23 -> 20 | B23: ='Allocation %'!B23 -> LOFTIN, NIQUITA | C23: 20 | D23: ='Allocation %'!D23 -> Abbott | E23: ='Allocation %'!E23 -> Teacher Asst | F23: 1176 | G23: =F23*$G$3 -> 30576 | I23: =SUM(G23:H23) -> 30576 | P23: =SUM(J23:O23) -> 0 | Q23: =$P23*'Allocation %'!J23 -> 0 | R23: =$P23*'Allocation %'!K23 -> 0 | S23: =$P23*'Allocation %'!M23 -> 0 | T23: =$P23*'Allocation %'!N23 -> 0 | U23: =$P23*'Allocation %'!O23 -> 0 | V23: =$P23*'Allocation %'!P23 -> 0 | W23: =$P23*'Allocation %'!Q23 -> 0 | X23: =$P23*'Allocation %'!R23 -> 0 | Y23: =$P23*'Allocation %'!S23 -> 0 | Z23: =$P23*'Allocation %'!T23 -> 0 | ... AN23: =$P23*'Allocation %'!AH23 -> 0 | AO23: =SUM(Q23:AN23) -> 0 | AP23: =P23-AO23 -> 0
A24: =Salary!A24 -> 21 | B24: ='Allocation %'!B24 -> Love, Charles | C24: 21 | D24: ='Allocation %'!D24 -> PACE | E24: ='Allocation %'!E24 -> 0 | F24: 1200 | G24: =F24*$G$3 -> 31200 | I24: =SUM(G24:H24) -> 31200 | P24: =SUM(J24:O24) -> 0 | Q24: =$P24*'Allocation %'!J24 -> 0 | R24: =$P24*'Allocation %'!K24 -> 0 | S24: =$P24*'Allocation %'!M24 -> 0 | T24: =$P24*'Allocation %'!N24 -> 0 | U24: =$P24*'Allocation %'!O24 -> 0 | V24: =$P24*'Allocation %'!P24 -> 0 | W24: =$P24*'Allocation %'!Q24 -> 0 | X24: =$P24*'Allocation %'!R24 -> 0 | Y24: =$P24*'Allocation %'!S24 -> 0 | Z24: =$P24*'Allocation %'!T24 -> 0 | ... AN24: =$P24*'Allocation %'!AH24 -> 0 | AO24: =SUM(Q24:AN24) -> 0 | AP24: =P24-AO24 -> 0
A25: =Salary!A25 -> 22 | B25: ='Allocation %'!B25 -> MARTINEZ, Joanna | C25: 22 | D25: ='Allocation %'!D25 -> USJP | E25: ='Allocation %'!E25 -> 0 | F25: 1538.47 | G25: =F25*$G$3 -> 40000.22 | I25: =SUM(G25:H25) -> 40000.22 | J25: 1332.17 | K25: 1332.17 | P25: =SUM(J25:O25) -> 2664.34 | Q25: =$P25*'Allocation %'!J25 -> 0 | R25: =$P25*'Allocation %'!K25 -> 0 | S25: =$P25*'Allocation %'!M25 -> 0 | T25: =$P25*'Allocation %'!N25 -> 2531.123 | U25: =$P25*'Allocation %'!O25 -> 0 | V25: =$P25*'Allocation %'!P25 -> 0 | W25: =$P25*'Allocation %'!Q25 -> 0 | X25: =$P25*'Allocation %'!R25 -> 0 | Y25: =$P25*'Allocation %'!S25 -> 0 | Z25: =$P25*'Allocation %'!T25 -> 0 | ... AN25: =$P25*'Allocation %'!AH25 -> 0 | AO25: =SUM(Q25:AN25) -> 2664.34 | AP25: =P25-AO25 -> 0
A26: =Salary!A26 -> 23 | B26: ='Allocation %'!B26 -> McDaniels, Curtis | C26: 23 | D26: ='Allocation %'!D26 -> Neigh Revit | E26: ='Allocation %'!E26 -> 0 | F26: 1442.31 | G26: =F26*$G$3 -> 37500.06 | I26: =SUM(G26:H26) -> 37500.06 | J26: 585.73 | K26: 585.73 | P26: =SUM(J26:O26) -> 1171.46 | Q26: =$P26*'Allocation %'!J26 -> 0 | R26: =$P26*'Allocation %'!K26 -> 0 | S26: =$P26*'Allocation %'!M26 -> 0 | T26: =$P26*'Allocation %'!N26 -> 0 | U26: =$P26*'Allocation %'!O26 -> 0 | V26: =$P26*'Allocation %'!P26 -> 0 | W26: =$P26*'Allocation %'!Q26 -> 0 | X26: =$P26*'Allocation %'!R26 -> 0 | Y26: =$P26*'Allocation %'!S26 -> 0 | Z26: =$P26*'Allocation %'!T26 -> 0 | ... AN26: =$P26*'Allocation %'!AH26 -> 0 | AO26: =SUM(Q26:AN26) -> 1171.46 | AP26: =P26-AO26 -> 0
A27: =Salary!A27 -> 24 | B27: ='Allocation %'!B27 -> MCMILLIAN, Daphne L. | C27: 24 | D27: ='Allocation %'!D27 -> Abbott | E27: ='Allocation %'!E27 -> Family Worker | F27: 1216.36 | G27: =F27*$G$3 -> 31625.36 | I27: =SUM(G27:H27) -> 31625.36 | J27: 918.88 | K27: 918.88 | P27: =SUM(J27:O27) -> 1837.76 | Q27: =$P27*'Allocation %'!J27 -> 1837.76 | R27: =$P27*'Allocation %'!K27 -> 0 | S27: =$P27*'Allocation %'!M27 -> 0 | T27: =$P27*'Allocation %'!N27 -> 0 | U27: =$P27*'Allocation %'!O27 -> 0 | V27: =$P27*'Allocation %'!P27 -> 0 | W27: =$P27*'Allocation %'!Q27 -> 0 | X27: =$P27*'Allocation %'!R27 -> 0 | Y27: =$P27*'Allocation %'!S27 -> 0 | Z27: =$P27*'Allocation %'!T27 -> 0 | ... AN27: =$P27*'Allocation %'!AH27 -> 0 | AO27: =SUM(Q27:AN27) -> 1837.76 | AP27: =P27-AO27 -> 0
A28: =Salary!A28 -> 25 | B28: ='Allocation %'!B28 -> Mitchell, Felicia | C28: 25 | D28: ='Allocation %'!D28 -> Abbott | E28: ='Allocation %'!E28 -> Teacher | F28: 1114.7 | G28: =F28*$G$3 -> 28982.2 | I28: =SUM(G28:H28) -> 28982.2 | P28: =SUM(J28:O28) -> 0 | Q28: =$P28*'Allocation %'!J28 -> 0 | R28: =$P28*'Allocation %'!K28 -> 0 | S28: =$P28*'Allocation %'!M28 -> 0 | T28: =$P28*'Allocation %'!N28 -> 0 | U28: =$P28*'Allocation %'!O28 -> 0 | V28: =$P28*'Allocation %'!P28 -> 0 | W28: =$P28*'Allocation %'!Q28 -> 0 | X28: =$P28*'Allocation %'!R28 -> 0 | Y28: =$P28*'Allocation %'!S28 -> 0 | Z28: =$P28*'Allocation %'!T28 -> 0 | ... AN28: =$P28*'Allocation %'!AH28 -> 0 | AO28: =SUM(Q28:AN28) -> 0 | AP28: =P28-AO28 -> 0
A29: =Salary!A29 -> 26 | B29: ='Allocation %'!B29 -> MORRIS, GWEN | C29: 26 | D29: ='Allocation %'!D29 -> USJP | E29: ='Allocation %'!E29 -> 0 | F29: 2500 | G29: =F29*$G$3 -> 65000 | I29: =SUM(G29:H29) -> 65000 | J29: 1033.68 | K29: 1033.68 | P29: =SUM(J29:O29) -> 2067.36 | Q29: =$P29*'Allocation %'!J29 -> 0 | R29: =$P29*'Allocation %'!K29 -> 0 | S29: =$P29*'Allocation %'!M29 -> 0 | T29: =$P29*'Allocation %'!N29 -> 2067.36 | U29: =$P29*'Allocation %'!O29 -> 0 | V29: =$P29*'Allocation %'!P29 -> 0 | W29: =$P29*'Allocation %'!Q29 -> 0 | X29: =$P29*'Allocation %'!R29 -> 0 | Y29: =$P29*'Allocation %'!S29 -> 0 | Z29: =$P29*'Allocation %'!T29 -> 0 | ... AN29: =$P29*'Allocation %'!AH29 -> 0 | AO29: =SUM(Q29:AN29) -> 2067.36 | AP29: =P29-AO29 -> 0
