Workbook

Sheet Allocations
B1: Urban League of Essex County 2019 Code 0297 | E1: 041 Social Enter Thriftworks | F1: 111 Abbott | G1: 111B Wrap Fees | H1: 111A Other | I1: 111F Food Prog | J1: 112 EHS/Toddler | K1: EHS 112 A Fees | L1: 114 Summer Camp | M1: 222 DCF Coding | N1: 223 OICA June 30 | O1: 225 Americorp | P1: 334 NRTC 18 40K | Q1: 335 NRTC 19 40K | R1: 339 ULEC OC | S1: 368 Wells Fargo 165K | T1: 451 SENIORS / USJP | U1: 452 PACE $211K | V1: 460 Ihop Training $34k | W1: 468 Nwk Alliance $95K | X1: 467 United Airlines 125K Business Dev | Y1: 502 ESG Housing $75 Salaries $18750 | Z1: 454 Prudential #1 18-19 Workforce | AA1: 515 NUL -HUD 2018 PARS $27.5k salaries | AB1: 525 CDBG -Irvington -Housing $19K | AC1: 560Capital 1 Save Up FOC $15K- $4k Salary KJ | AD1: 561 LISC FOC $50K | AE1: 567 Chase FOC Wksp 3K- Delete | AF1: 563 -Prudential #1 18-19 FOC | AG1: 600Admin | AH1: 610 CEO Victoria Fdn | AI1: 620 CFO | AJ1: 630 COO | AK1: 640 Development | AL1: 650 Facilities | AM1: Proof
C2: K Period | E2: % | F2: % | I2: % | J2: % | L2: % | M2: % | N2: % | O2: % | P2: % | Q2: % | S2: % | T2: % | X2: % | Y2: % | Z2: 90000 | AA2: % | AC2: % | AF2: 45000 | AH2: % | AI2: % | AJ2: % | AK2: % | AL2: %
D3: Contract | AA3: 09/30/19
D4: Percentage
E5: 1 | F5: 2 | G5: 3 | H5: 4 | I5: 5 | J5: 6 | K5: 7 | L5: 8 | M5: 9 | N5: 10 | O5: 11 | P5: 12 | Q5: 13 | R5: 14 | S5: 15 | T5: 16 | U5: 17 | V5: 18 | W5: 19 | X5: 20 | Y5: 21 | Z5: 22 | AA5: 23 | AB5: 24 | AC5: 25 | AD5: 26 | AE5: 27 | AF5: 28 | AG5: 29 | AH5: 30 | AI5: 31 | AJ5: 32 | AK5: 33 | AL5: 34
B6: 12 Month Projections | C6: PAYCOM DEPT.
A7: 1 | B7: AIKEN-SANZONE, Charlene | C7: Americorp | O7: 1 | AM7: =SUM(F7:AL7) -> 1 | AO7: =B7 -> AIKEN-SANZONE, Charlene
A8: 2 | B8: AIKEN-SANZONE, Charlene June 30 | C8: OICA | N8: 1 | AM8: =SUM(F8:AL8) -> 1 | AO8: =B8 -> AIKEN-SANZONE, Charlene June 30
A9: 3 | B9: ALFORD, Sebrania R. | C9: Abbott | F9: 0.65 | J9: 0.35 | AM9: =SUM(F9:AL9) -> 1 | AO9: =B9 -> ALFORD, Sebrania R.
A10: 4 | B10: ALMANZAR, Alberto | C10: USJP | T10: 1 | AM10: =SUM(F10:AL10) -> 1 | AO10: =B10 -> ALMANZAR, Alberto
A11: 5 | B11: ANDREWS, Cora - Summer | C11: Abbott | F11: 0.5 | L11: 0.5 | AM11: =SUM(F11:AL11) -> 1 | AO11: =B11 -> ANDREWS, Cora - Summer
A12: 6 | B12: ANDREWS, Cora | C12: Abbott | F12: 0.77 | J12: 0.23 | AM12: =SUM(F12:AL12) -> 1 | AO12: =B12 -> ANDREWS, Cora
A13: 7 | B13: ANDREWS, Courtney A. | C13: Americorp | O13: 1 | AM13: =SUM(F13:AL13) -> 1 | AO13: =B13 -> ANDREWS, Courtney A.
A14: 8 | B14: BIRDSONG, Rhonda June 30 | C14: OICA | N14: 1 | AM14: =SUM(F14:AL14) -> 1 | AO14: =B14 -> BIRDSONG, Rhonda June 30
A15: 9 | B15: Bizi, Raymond | C15: Americorp | O15: 1 | AM15: =SUM(F15:AL15) -> 1 | AO15: =B15 -> Bizi, Raymond
A16: 10 | B16: BROWN,Denise- Wrap | C16: Abbott | F16: 0 | G16: 1 | AM16: =SUM(F16:AL16) -> 1 | AO16: =B16 -> BROWN,Denise- Wrap
A17: 11 | B17: BROWN,Denise - Summer | C17: Abbott | L17: 1 | AM17: =SUM(F17:AL17) -> 1 | AO17: =B17 -> BROWN,Denise - Summer
A18: 12 | B18: BRYANT, Roni- Summer | C18: Abbott | F18: 0 | L18: 1 | AM18: =SUM(F18:AL18) -> 1 | AO18: =B18 -> BRYANT, Roni- Summer
A19: 13 | B19: BRYANT, Roni | C19: Abbott | F19: 1 | AM19: =SUM(F19:AL19) -> 1 | AO19: =B19 -> BRYANT, Roni
A20: 14 | B20: BUTLER, Ciji | C20: USJP | T20: 1 | AM20: =SUM(F20:AL20) -> 1 | AO20: =B20 -> BUTLER, Ciji
A21: 15 | B21: CAMPBELL, Nikiesha K. | C21: Americorp | O21: 1 | AM21: =SUM(F21:AL21) -> 1 | AO21: =B21 -> CAMPBELL, Nikiesha K.
A22: 16 | B22: CASTELLANOS, Rita J. | C22: Abbott | F22: 1 | AM22: =SUM(F22:AL22) -> 1 | AO22: =B22 -> CASTELLANOS, Rita J.
A23: 17 | B23: CERNA, Irene | C23: USJP | T23: 1 | AM23: =SUM(F23:AL23) -> 1 | AO23: =B23 -> CERNA, Irene
A24: 18 | B24: COLEMAN, Zabrina J. | C24: EHS | J24: 1 | AM24: =SUM(F24:AL24) -> 1 | AO24: =B24 -> COLEMAN, Zabrina J.
A25: 19 | B25: COOPER, Cassandra June 30 | C25: OICA | N25: 1 | AM25: =SUM(F25:AL25) -> 1 | AO25: =B25 -> COOPER, Cassandra June 30
A26: 20 | B26: COOPER, Cassandra July | C26: FOC, ESG | Y26: 0.25 | AF26: 0.75 | AM26: =SUM(F26:AL26) -> 1 | AO26: =B26 -> COOPER, Cassandra July
A27: 21 | B27: Counts, Monique Lamae | C27: Americorp | O27: 1 | AM27: =SUM(F27:AL27) -> 1 | AO27: =B27 -> Counts, Monique Lamae
A28: 22 | B28: DANCE-WILSON, Heather | C28: Abbott | F28: 0.77 | H28: 0.23 | J28: 0 | AM28: =SUM(F28:AL28) -> 1 | AO28: =B28 -> DANCE-WILSON, Heather
A29: 23 | B29: DANIELS-CRAFTON, Glenda | C29: EHS | J29: 1 | AM29: =SUM(F29:AL29) -> 1 | AO29: =B29 -> DANIELS-CRAFTON, Glenda
A30: 24 | B30: ELLIS, Joseph | C30: OICA | N30: 1 | AM30: =SUM(F30:AL30) -> 1 | AO30: =B30 -> ELLIS, Joseph
A31: 25 | B31: FITZPATRICK, Cynthia E. - Aug 31 | C31: EHS | J31: 1 | AM31: =SUM(F31:AL31) -> 1 | AO31: =B31 -> FITZPATRICK, Cynthia E. - Aug 31
A32: 26 | B32: FITZPATRICK, Cynthia E. - Toddlers | C32: EHS/ Toddlers | J32: 1 | AM32: =SUM(F32:AL32) -> 1 | AO32: =B32 -> FITZPATRICK, Cynthia E. - Toddlers
A33: 27 | B33: FRANCOIS, Darlene | C33: Americorp | O33: 1 | AM33: =SUM(F33:AL33) -> 1 | AO33: =B33 -> FRANCOIS, Darlene
A34: 28 | B34: FRASER, Vivian Cox | C34: Admin | P34: 0.18 | AH34: 0.82 | AM34: =SUM(F34:AL34) -> 1 | AO34: =B34 -> FRASER, Vivian Cox
A35: 29 | B35: FRASER, Vivian Cox- July | C35: Admin | AH35: 1 | AM35: =SUM(F35:AL35) -> 1 | AO35: =B35 -> FRASER, Vivian Cox- July
A36: 30 | B36: FRAZIER, Alice | C36: Workforce | W36: 1 | X36: 0 | AM36: =SUM(F36:AL36) -> 1 | AO36: =B36 -> FRAZIER, Alice
A37: 31 | B37: Freeman, Jibri | C37: Americorp | O37: 1 | AM37: =SUM(E37:AL37) -> 1 | AO37: =B37 -> Freeman, Jibri
A38: 32 | B38: GARRETT, Dorian S. | C38: EHS | J38: 1 | AM38: =SUM(E38:AL38) -> 1 | AO38: =B38 -> GARRETT, Dorian S.
A39: 33 | B39: GARRETT, Shakia | C39: EHS | J39: 1 | AM39: =SUM(E39:AL39) -> 1 | AO39: =B39 -> GARRETT, Shakia
A40: 34 | B40: GBAMOKOLLIE, Molly | C40: Facilities | AL40: 1 | AM40: =SUM(E40:AL40) -> 1 | AO40: =B40 -> GBAMOKOLLIE, Molly
...

Sheet 2019  SALARIES MASTER Salary 
F3: 0.05 | AW3: $180K to June 30
AN4: 10 months | AR4: 12 Months | AU4: 59300 | AW4: 60000 | BC4: $3k | BE4: $6k
B5: SALARIES 2019 | C5: 2018 FY BUDGET | D5: Bi Weekly | E5: Annual Budget | F5: Salary Adj | G5: Salary Revised | H5: 43476 | I5: 43490 | J5: 43504 | K5: 43518 | L5: 43532 | M5: 43546 | N5: 43560 | O5: 43574 | P5: 43588 | Q5: 43602 | R5: 43616 | S5: 43630 | T5: 43644 | U5: 43646 | W5: 43658 | X5: 43672 | Y5: 43686 | Z5: 43700 | AA5: 43714 | AB5: 43728 | AD5: 43742 | AE5: 43756 | AF5: 43770 | AG5: 43784 | AH5: 43798 | AI5: 43812 | AJ5: 43826 | AL5: TOTAL | AN5: =+Allocations!E1 -> 041 Social Enter Thriftworks | AO5: =+Allocations!F1 -> 111 Abbott | AP5: =+Allocations!G1 -> 111B Wrap Fees | AQ5: =+Allocations!H1 -> 111A Other | AR5: =+Allocations!I1 -> 111F Food Prog | AS5: =+Allocations!J1 -> 112 EHS/Toddler | AT5: =+Allocations!K1 -> EHS 112 A Fees | AU5: =+Allocations!L1 -> 114 Summer Camp | ... BV5: =+Allocations!AM1 -> Proof
B6: Salaried | E6: 26 | H6: 1 | I6: 2 | J6: 3 | K6: 4 | L6: 5 | M6: 6 | N6: 7 | O6: 8 | P6: 9 | Q6: 10 | R6: 11 | S6: 12 | T6: 13 | W6: 14 | X6: 15 | Y6: 16 | Z6: 17 | AA6: 18 | AB6: 19 | AD6: 20 | AE6: 21 | AF6: 22 | AG6: 23 | AH6: 24 | AI6: 25 | AJ6: 26 | AL6: 2 | AN6: =Allocations!E5 -> 1 | AO6: =Allocations!F5 -> 2 | AP6: =Allocations!G5 -> 3 | AQ6: =Allocations!H5 -> 4 | AR6: =Allocations!I5 -> 5 | AS6: =Allocations!J5 -> 6 | AT6: =Allocations!K5 -> 7 | AU6: =Allocations!L5 -> 8 | ... BU6: =Allocations!AL5 -> 34
A7: =Allocations!A7 -> 1 | B7: =Allocations!B7 -> AIKEN-SANZONE, Charlene | C7: =Allocations!C7 -> Americorp | D7: 234.685 | E7: =D7*$E$6 -> 6101.81 | G7: =SUM(E7:F7) -> 6101.81 | H7: 211.4 | I7: 211.4 | J7: 528.16 | K7: 528.16 | L7: 528.16 | M7: 528.16 | N7: 528.16 | O7: 528.16 | AL7: =SUM(P7:R7) -> 0 | AM7: =B7 -> AIKEN-SANZONE, Charlene | AN7: =Allocations!E7*$AL7 -> 0 | AO7: =T7+U7+V7 -> 0 | AP7: =U7+V7+W7 -> 0 | AQ7: =V7+W7+X7 -> 0 | AR7: =W7+X7+Y7 -> 0 | AS7: =X7+Y7+Z7 -> 0 | AT7: =Y7+Z7+AA7 -> 0 | AU7: =Allocations!L7*$AL7 -> 0 | AV7: =Allocations!M7*$AL7 -> 0 | AW7: =Allocations!N7*$AL7 -> 0 | AX7: =Allocations!O7*$AL7 -> 0 | AY7: =Allocations!P7*$AL7 -> 0 | AZ7: =Allocations!Q7*$AL7 -> 0 | BA7: =Allocations!R7*$AL7 -> 0 | BB7: =Allocations!S7*$AL7 -> 0 | ... BU7: =Allocations!AL7*$AL7 -> 0 | BV7: =SUM(AN7:BU7) -> 0 | BW7: =AL7-BV7 -> 0 | BX7: =B7 -> AIKEN-SANZONE, Charlene
A8: =Allocations!A8 -> 2 | B8: =Allocations!B8 -> AIKEN-SANZONE, Charlene June 30 | C8: =Allocations!C8 -> OICA | D8: 1080 | E8: =D8*$E$6/2 -> 14040 | G8: =SUM(E8:F8) -> 14040 | H8: 161.15 | I8: 316.76 | J8: 0 | O8: =SUM(O7) -> 528.16 | AL8: =SUM(P8:R8) -> 0 | AM8: =B8 -> AIKEN-SANZONE, Charlene June 30 | AN8: =Allocations!E8*$AL8 -> 0 | AO8: =Allocations!F8*$AL8 -> 0 | AP8: =Allocations!G8*$AL8 -> 0 | AQ8: =Allocations!H8*$AL8 -> 0 | AR8: =Allocations!I8*$AL8 -> 0 | AS8: =Allocations!J8*$AL8 -> 0 | AT8: =Allocations!K8*$AL8 -> 0 | AU8: =Allocations!L8*$AL8 -> 0 | ... BU8: =Allocations!AL8*$AL8 -> 0 | BV8: =SUM(AN8:BU8) -> 0 | BW8: =AL8-BV8 -> 0 | BX8: =B8 -> AIKEN-SANZONE, Charlene June 30
A9: =Allocations!A9 -> 3 | B9: =Allocations!B9 -> ALFORD, Sebrania R. | C9: =Allocations!C9 -> Abbott | D9: 1807.7 | E9: =D9*$E$6 -> 47000.2 | G9: =SUM(E9:F9) -> 47000.2 | H9: 1807.7 | I9: 1807.7 | J9: 1807.7 | K9: 1807.7 | L9: 1807.7 | M9: 1807.7 | N9: 1807.7 | O9: 1807.7 | P9: 1807.7 | Q9: 1807.7 | R9: 1807.7 | S9: 1807.7 | T9: 1817.7 | W9: 1817.7 | X9: 1867.7 | Y9: 1526.16 | Z9: 1807.7 | AA9: 1807.7 | AL9: =SUM(P9:R9) -> 5423.1 | AM9: =B9 -> ALFORD, Sebrania R. | AN9: =Allocations!E9*$AL9 -> 0 | AO9: =Allocations!F9*$AL9 -> 3525.015 | AP9: =Allocations!G9*$AL9 -> 0 | AQ9: =Allocations!H9*$AL9 -> 0 | AR9: =Allocations!I9*$AL9 -> 0 | AS9: =Allocations!J9*$AL9 -> 1898.085 | AT9: =Allocations!K9*$AL9 -> 0 | AU9: =Allocations!L9*$AL9 -> 0 | ... BU9: =Allocations!AL9*$AL9 -> 0 | BV9: =SUM(AN9:BU9) -> 5423.1 | BW9: =AL9-BV9 -> 0 | BX9: =B9 -> ALFORD, Sebrania R.
A10: =Allocations!A10 -> 4 | B10: =Allocations!B10 -> ALMANZAR, Alberto | C10: =Allocations!C10 -> USJP | D10: 865.2 | E10: =D10*$E$6 -> 22495.2 | G10: =SUM(E10:F10) -> 22495.2 | H10: 865.2 | I10: 865.2 | J10: 865.2 | K10: 432.6 | L10: 865.2 | M10: 865.2 | N10: 778.68 | O10: 865.2 | P10: 692.16 | Q10: 692.16 | R10: 865.2 | S10: 778.68 | T10: 865.2 | U10: 932.6 | W10: 346.08 | X10: 865.2 | Y10: 865.2 | Z10: 865.2 | AA10: 865.2 | AB10: 403.76 | AL10: =SUM(P10:R10) -> 2249.52 | AM10: =B10 -> ALMANZAR, Alberto | AN10: =Allocations!E10*$AL10 -> 0 | AO10: =Allocations!F10*$AL10 -> 0 | AP10: =Allocations!G10*$AL10 -> 0 | AQ10: =Allocations!H10*$AL10 -> 0 | AR10: =Allocations!I10*$AL10 -> 0 | AS10: =Allocations!J10*$AL10 -> 0 | AT10: =Allocations!K10*$AL10 -> 0 | AU10: =Allocations!L10*$AL10 -> 0 | ... BU10: =Allocations!AL10*$AL10 -> 0 | BV10: =SUM(AN10:BU10) -> 2249.52 | BW10: =AL10-BV10 -> 0 | BX10: =B10 -> ALMANZAR, Alberto
A11: =Allocations!A11 -> 5 | B11: =Allocations!B11 -> ANDREWS, Cora - Summer | C11: =Allocations!C11 -> Abbott | E11: =D11*$E$6 -> 0 | F11: =E11*$F$3 -> 0 | G11: =SUM(E11:F11) -> 0 | W11: 1120 | X11: 1120 | Y11: 1120 | Z11: 1120 | AL11: =SUM(P11:R11) -> 0 | AM11: =B11 -> ANDREWS, Cora - Summer | AN11: =Allocations!E11*$AL11 -> 0 | AO11: =Allocations!F11*$AL11 -> 0 | AP11: =Allocations!G11*$AL11 -> 0 | AQ11: =Allocations!H11*$AL11 -> 0 | AR11: =Allocations!I11*$AL11 -> 0 | AS11: =Allocations!J11*$AL11 -> 0 | AT11: =Allocations!K11*$AL11 -> 0 | AU11: =Allocations!L11*$AL11 -> 0 | ... BU11: =Allocations!AL11*$AL11 -> 0 | BV11: =SUM(AN11:BU11) -> 0 | BW11: =AL11-BV11 -> 0 | BX11: =B11 -> ANDREWS, Cora - Summer
A12: =Allocations!A12 -> 6 | B12: =Allocations!B12 -> ANDREWS, Cora | C12: =Allocations!C12 -> Abbott | D12: 760 | E12: =D12*$E$6 -> 19760 | G12: =SUM(E12:F12) -> 19760 | H12: 762.38 | I12: 760 | J12: 757.63 | K12: 763.56 | L12: 763.56 | M12: 767.13 | N12: 763.56 | O12: 763.56 | P12: 760 | Q12: 760 | R12: 760 | S12: 760 | T12: 760 | AA12: 1120 | AB12: 1120 | AD12: 1120 | AE12: 1125.25 | AF12: 1120 | AG12: 1120 | AH12: 1120 | AL12: =SUM(P12:R12) -> 2280 | AM12: =B12 -> ANDREWS, Cora | AN12: =Allocations!E12*$AL12 -> 0 | AO12: =Allocations!F12*$AL12 -> 1755.6 | AP12: =Allocations!G12*$AL12 -> 0 | AQ12: =Allocations!H12*$AL12 -> 0 | AR12: =Allocations!I12*$AL12 -> 0 | AS12: =Allocations!J12*$AL12 -> 524.4 | AT12: =Allocations!K12*$AL12 -> 0 | AU12: =Allocations!L12*$AL12 -> 0 | ... BU12: =Allocations!AL12*$AL12 -> 0 | BV12: =SUM(AN12:BU12) -> 2280 | BW12: =AL12-BV12 -> 0 | BX12: =B12 -> ANDREWS, Cora
A13: =Allocations!A13 -> 7 | B13: =Allocations!B13 -> ANDREWS, Courtney A. | C13: =Allocations!C13 -> Americorp | D13: 485.77 | E13: =D13*$E$6 -> 12630.02 | G13: =SUM(E13:F13) -> 12630.02 | AL13: =SUM(P13:R13) -> 0 | AM13: =B13 -> ANDREWS, Courtney A. | AN13: =Allocations!E13*$AL13 -> 0 | AO13: =Allocations!F13*$AL13 -> 0 | AP13: =Allocations!G13*$AL13 -> 0 | AQ13: =Allocations!H13*$AL13 -> 0 | AR13: =Allocations!I13*$AL13 -> 0 | AS13: =Allocations!J13*$AL13 -> 0 | AT13: =Allocations!K13*$AL13 -> 0 | AU13: =Allocations!L13*$AL13 -> 0 | ... BU13: =Allocations!AL13*$AL13 -> 0 | BV13: =SUM(AN13:BU13) -> 0 | BW13: =AL13-BV13 -> 0 | BX13: =B13 -> ANDREWS, Courtney A.
A14: =Allocations!A14 -> 8 | B14: =Allocations!B14 -> BIRDSONG, Rhonda June 30 | C14: =Allocations!C14 -> OICA | D14: 1884.62 | E14: =D14*$E$6/2 -> 24500.06 | G14: =SUM(E14:F14) -> 24500.06 | H14: 1884.62 | I14: 1884.62 | J14: 1884.62 | K14: 1884.62 | L14: 1884.62 | M14: 1884.62 | N14: 1884.62 | O14: 1884.62 | P14: 1884.62 | Q14: 1884.62 | R14: 1884.62 | S14: 1776.93 | T14: 1444.43 | AL14: =SUM(P14:R14) -> 5653.86 | AM14: =B14 -> BIRDSONG, Rhonda June 30 | AN14: =Allocations!E14*$AL14 -> 0 | AO14: =Allocations!F14*$AL14 -> 0 | AP14: =Allocations!G14*$AL14 -> 0 | AQ14: =Allocations!H14*$AL14 -> 0 | AR14: =Allocations!I14*$AL14 -> 0 | AS14: =Allocations!J14*$AL14 -> 0 | AT14: =Allocations!K14*$AL14 -> 0 | AU14: =Allocations!L14*$AL14 -> 0 | ... BU14: =Allocations!AL14*$AL14 -> 0 | BV14: =SUM(AN14:BU14) -> 5653.86 | BW14: =AL14-BV14 -> 0 | BX14: =B14 -> BIRDSONG, Rhonda June 30
A15: =Allocations!A15 -> 9 | B15: Bizi,Raymond | C15: =Allocations!C15 -> Americorp | D15: 211.26 | E15: =D15*$E$6 -> 5492.76 | G15: =SUM(E15:F15) -> 5492.76 | I15: 211.26 | J15: 528.16 | K15: 528.16 | L15: 528.16 | M15: 528.16 | N15: 528.16 | O15: 528.16 | S15: 528.16 | AL15: =SUM(P15:R15) -> 0 | AM15: =B15 -> Bizi,Raymond | AN15: =Allocations!E15*$AL15 -> 0 | AO15: =Allocations!F15*$AL15 -> 0 | AP15: =Allocations!G15*$AL15 -> 0 | AQ15: =Allocations!H15*$AL15 -> 0 | AR15: =Allocations!I15*$AL15 -> 0 | AS15: =Allocations!J15*$AL15 -> 0 | AT15: =Allocations!K15*$AL15 -> 0 | AU15: =Allocations!L15*$AL15 -> 0 | ... BU15: =Allocations!AL15*$AL15 -> 0 | BV15: =SUM(AN15:BU15) -> 0 | BW15: =AL15-BV15 -> 0 | BX15: =B15 -> Bizi,Raymond
A16: =Allocations!A16 -> 10 | B16: =Allocations!B16 -> BROWN,Denise- Wrap | C16: =Allocations!C16 -> Abbott | D16: 732.26 | E16: =D16*$E$6 -> 19038.76 | G16: =SUM(E16:F16) -> 19038.76 | H16: 733.88 | I16: 682.39 | J16: 500.37 | K16: 673.75 | L16: 708.61 | M16: 707.76 | N16: 774.25 | O16: 382.38 | P16: 185.25 | Q16: 646.01 | R16: 676.88 | S16: 467.88 | T16: 399 | AA16: 60 | AB16: 282.5 | AD16: 495 | AE16: 617.5 | AF16: 423.3 | AG16: 460 | AH16: 325 | AL16: =SUM(P16:R16) -> 1508.14 | AM16: =B16 -> BROWN,Denise- Wrap | AN16: =Allocations!E16*$AL16 -> 0 | AO16: =Allocations!F16*$AL16 -> 0 | AP16: =Allocations!G16*$AL16 -> 1508.14 | AQ16: =Allocations!H16*$AL16 -> 0 | AR16: =Allocations!I16*$AL16 -> 0 | AS16: =Allocations!J16*$AL16 -> 0 | AT16: =Allocations!K16*$AL16 -> 0 | AU16: =Allocations!L16*$AL16 -> 0 | ... BU16: =Allocations!AL16*$AL16 -> 0 | BV16: =SUM(AN16:BU16) -> 1508.14 | BW16: =AL16-BV16 -> 0 | BX16: =B16 -> BROWN,Denise- Wrap
A17: =Allocations!A17 -> 11 | B17: =Allocations!B17 -> BROWN,Denise - Summer | C17: =Allocations!C17 -> Abbott | W17: 687.5 | X17: 800 | Y17: 730 | Z17: 777.5 | AA17: 0 | AB17: 0 | AL17: =SUM(P17:R17) -> 0 | AM17: =B17 -> BROWN,Denise - Summer | AN17: =Allocations!E17*$AL17 -> 0 | AO17: =Allocations!F17*$AL17 -> 0 | AP17: =Allocations!G17*$AL17 -> 0 | AQ17: =Allocations!H17*$AL17 -> 0 | AR17: =Allocations!I17*$AL17 -> 0 | AS17: =Allocations!J17*$AL17 -> 0 | AT17: =Allocations!K17*$AL17 -> 0 | AU17: =Allocations!L17*$AL17 -> 0 | ... BU17: =Allocations!AL17*$AL17 -> 0 | BV17: =SUM(AN17:BU17) -> 0 | BW17: =AL17-BV17 -> 0 | BX17: =B17 -> BROWN,Denise - Summer
A18: =Allocations!A18 -> 12 | B18: =Allocations!B18 -> BRYANT, Roni- Summer | C18: =Allocations!C18 -> Abbott | E18: =D18*$E$6 -> 0 | F18: =E18*$F$3 -> 0 | G18: =SUM(E18:F18) -> 0 | W18: 1008 | X18: 1160 | Y18: 1120 | Z18: 1130 | AA18: 0 | AB18: 0 | AL18: =SUM(P18:R18) -> 0 | AM18: =B18 -> BRYANT, Roni- Summer | AN18: =Allocations!E18*$AL18 -> 0 | AO18: =Allocations!F18*$AL18 -> 0 | AP18: =Allocations!G18*$AL18 -> 0 | AQ18: =Allocations!H18*$AL18 -> 0 | AR18: =Allocations!I18*$AL18 -> 0 | AS18: =Allocations!J18*$AL18 -> 0 | AT18: =Allocations!K18*$AL18 -> 0 | AU18: =Allocations!L18*$AL18 -> 0 | ... BU18: =Allocations!AL18*$AL18 -> 0 | BV18: =SUM(AN18:BU18) -> 0 | BW18: =AL18-BV18 -> 0 | BX18: =B18 -> BRYANT, Roni- Summer
A19: =Allocations!A19 -> 13 | B19: BRYANT, Roni | C19: =Allocations!C19 -> Abbott | D19: 1279.14 | E19: =D19*$E$6 -> 33257.64 | G19: =SUM(E19:F19) -> 33257.64 | H19: 1208.14 | I19: 1268.14 | J19: 1248.14 | K19: 1268.14 | L19: 1258.14 | M19: 1268.14 | N19: 1268.14 | O19: 1268.14 | P19: 1208.14 | Q19: 1282.27 | R19: 1228.14 | S19: 1002.51 | T19: 1022.51 | AA19: 358.15 | AB19: 1337.23 | AD19: 1367.23 | AE19: 1357.23 | AF19: 1384.31 | AG19: 1327.23 | AH19: 1347.23 | AL19: =SUM(P19:R19) -> 3718.55 | AM19: =B19 -> BRYANT, Roni | AN19: =Allocations!E19*$AL19 -> 0 | AO19: =Allocations!F19*$AL19 -> 3718.55 | AP19: =Allocations!G19*$AL19 -> 0 | AQ19: =Allocations!H19*$AL19 -> 0 | AR19: =Allocations!I19*$AL19 -> 0 | AS19: =Allocations!J19*$AL19 -> 0 | AT19: =Allocations!K19*$AL19 -> 0 | AU19: =Allocations!L19*$AL19 -> 0 | ... BU19: =Allocations!AL19*$AL19 -> 0 | BV19: =SUM(AN19:BU19) -> 3718.55 | BW19: =AL19-BV19 -> 0 | BX19: =B19 -> BRYANT, Roni
A20: =Allocations!A20 -> 14 | B20: BUTLER, Ciji | C20: =Allocations!C20 -> USJP | D20: 1538.47 | E20: =D20*$E$6 -> 40000.22 | G20: =SUM(E20:F20) -> 40000.22 | H20: 1538.47 | I20: 1538.47 | J20: 1538.47 | K20: 1538.47 | L20: 1538.47 | M20: 1538.47 | N20: 1538.47 | O20: 1538.47 | P20: 1538.47 | Q20: 2051 | AL20: =SUM(P20:R20) -> 3589.47 | AM20: =B20 -> BUTLER, Ciji | AN20: =Allocations!E20*$AL20 -> 0 | AO20: =Allocations!F20*$AL20 -> 0 | AP20: =Allocations!G20*$AL20 -> 0 | AQ20: =Allocations!H20*$AL20 -> 0 | AR20: =Allocations!I20*$AL20 -> 0 | AS20: =Allocations!J20*$AL20 -> 0 | AT20: =Allocations!K20*$AL20 -> 0 | AU20: =Allocations!L20*$AL20 -> 0 | ... BU20: =Allocations!AL20*$AL20 -> 0 | BV20: =SUM(AN20:BU20) -> 3589.47 | BW20: =AL20-BV20 -> 0 | BX20: =B20 -> BUTLER, Ciji
A21: =Allocations!A21 -> 15 | B21: =Allocations!B21 -> CAMPBELL, Nikiesha K. | C21: =Allocations!C21 -> Americorp | D21: 485.77 | E21: =D21*$E$6 -> 12630.02 | G21: =SUM(E21:F21) -> 12630.02 | H21: 291.46 | AL21: =SUM(P21:R21) -> 0 | AM21: =B21 -> CAMPBELL, Nikiesha K. | AN21: =Allocations!E21*$AL21 -> 0 | AO21: =Allocations!F21*$AL21 -> 0 | AP21: =Allocations!G21*$AL21 -> 0 | AQ21: =Allocations!H21*$AL21 -> 0 | AR21: =Allocations!I21*$AL21 -> 0 | AS21: =Allocations!J21*$AL21 -> 0 | AT21: =Allocations!K21*$AL21 -> 0 | AU21: =Allocations!L21*$AL21 -> 0 | ... BU21: =Allocations!AL21*$AL21 -> 0 | BV21: =SUM(AN21:BU21) -> 0 | BW21: =AL21-BV21 -> 0 | BX21: =B21 -> CAMPBELL, Nikiesha K.
A22: =Allocations!A22 -> 16 | B22: =Allocations!B22 -> CASTELLANOS, Rita J. | C22: =Allocations!C22 -> Abbott | D22: 2278.37 | E22: =D22*$E$6 -> 59237.62 | G22: =SUM(E22:F22) -> 59237.62 | H22: 2354 | I22: 2330.17 | J22: 2363.45 | K22: 2363.45 | L22: 2325.64 | M22: 2344.55 | N22: 2363.45 | O22: 1796.22 | AL22: =SUM(P22:R22) -> 0 | AM22: =B22 -> CASTELLANOS, Rita J. | AN22: =Allocations!E22*$AL22 -> 0 | AO22: =Allocations!F22*$AL22 -> 0 | AP22: =Allocations!G22*$AL22 -> 0 | AQ22: =Allocations!H22*$AL22 -> 0 | AR22: =Allocations!I22*$AL22 -> 0 | AS22: =Allocations!J22*$AL22 -> 0 | AT22: =Allocations!K22*$AL22 -> 0 | AU22: =Allocations!L22*$AL22 -> 0 | ... BU22: =Allocations!AL22*$AL22 -> 0 | BV22: =SUM(AN22:BU22) -> 0 | BW22: =AL22-BV22 -> 0 | BX22: =B22 -> CASTELLANOS, Rita J.
A23: =Allocations!A23 -> 17 | B23: =Allocations!B23 -> CERNA, Irene | C23: =Allocations!C23 -> USJP | D23: 1153.85 | E23: =D23*$E$6 -> 30000.1 | G23: =SUM(E23:F23) -> 30000.1 | H23: 1153.85 | I23: 1153.85 | J23: 1153.85 | K23: 1153.85 | L23: 1153.85 | M23: 1153.85 | N23: 1153.85 | O23: 1153.85 | P23: 1153.85 | Q23: 1153.85 | R23: 1153.85 | S23: 1153.85 | T23: 1153.85 | U23: 461.44 | W23: 577.03 | X23: 1153.85 | Y23: 1153.85 | Z23: 1153.85 | AA23: 576.93 | AB23: 1153.85 | AD23: 1153.85 | AE23: 1038.47 | AF23: 1153.85 | AG23: 1153.85 | AH23: 1153.85 | AL23: =SUM(P23:R23) -> 3461.55 | AM23: =B23 -> CERNA, Irene | AN23: =Allocations!E23*$AL23 -> 0 | AO23: =Allocations!F23*$AL23 -> 0 | AP23: =Allocations!G23*$AL23 -> 0 | AQ23: =Allocations!H23*$AL23 -> 0 | AR23: =Allocations!I23*$AL23 -> 0 | AS23: =Allocations!J23*$AL23 -> 0 | AT23: =Allocations!K23*$AL23 -> 0 | AU23: =Allocations!L23*$AL23 -> 0 | ... BU23: =Allocations!AL23*$AL23 -> 0 | BV23: =SUM(AN23:BU23) -> 3461.55 | BW23: =AL23-BV23 -> 0 | BX23: =B23 -> CERNA, Irene
A24: =Allocations!A24 -> 18 | B24: =Allocations!B24 -> COLEMAN, Zabrina J. | C24: =Allocations!C24 -> EHS | D24: 960 | E24: =D24*$E$6 -> 24960 | G24: =SUM(E24:F24) -> 24960 | H24: 960 | I24: 960 | J24: 960 | K24: 960 | L24: 960 | M24: 960 | N24: 960 | O24: 933.84 | P24: 960 | Q24: 747.72 | R24: 960 | S24: 961.44 | T24: 960 | W24: 960 | X24: 864 | Y24: 987 | Z24: 960 | AL24: =SUM(P24:R24) -> 2667.72 | AM24: =B24 -> COLEMAN, Zabrina J. | AN24: =Allocations!E24*$AL24 -> 0 | AO24: =Allocations!F24*$AL24 -> 0 | AP24: =Allocations!G24*$AL24 -> 0 | AQ24: =Allocations!H24*$AL24 -> 0 | AR24: =Allocations!I24*$AL24 -> 0 | AS24: =Allocations!J24*$AL24 -> 2667.72 | AT24: =Allocations!K24*$AL24 -> 0 | AU24: =Allocations!L24*$AL24 -> 0 | ... BU24: =Allocations!AL24*$AL24 -> 0 | BV24: =SUM(AN24:BU24) -> 2667.72 | BW24: =AL24-BV24 -> 0 | BX24: =B24 -> COLEMAN, Zabrina J.
A25: =Allocations!A25 -> 19 | B25: =Allocations!B25 -> COOPER, Cassandra June 30 | C25: =Allocations!C25 -> OICA | D25: 1500 | E25: =D25*$E$6/2 -> 19500 | G25: =SUM(E25:F25) -> 19500 | H25: 1500 | I25: 1500 | J25: 1500 | K25: 1500 | L25: 1500 | M25: 1500 | N25: 1500 | O25: 1500 | P25: 1500 | Q25: 1500 | R25: 1500 | S25: 1285.71 | T25: 964.35 | AL25: =SUM(P25:R25) -> 4500 | AM25: =B25 -> COOPER, Cassandra June 30 | AN25: =Allocations!E25*$AL25 -> 0 | AO25: =Allocations!F25*$AL25 -> 0 | AP25: =Allocations!G25*$AL25 -> 0 | AQ25: =Allocations!H25*$AL25 -> 0 | AR25: =Allocations!I25*$AL25 -> 0 | AS25: =Allocations!J25*$AL25 -> 0 | AT25: =Allocations!K25*$AL25 -> 0 | AU25: =Allocations!L25*$AL25 -> 0 | ... BU25: =Allocations!AL25*$AL25 -> 0 | BV25: =SUM(AN25:BU25) -> 4500 | BW25: =AL25-BV25 -> 0 | BX25: =B25 -> COOPER, Cassandra June 30
A26: =Allocations!A26 -> 20 | B26: =Allocations!B26 -> COOPER, Cassandra July | C26: =Allocations!C26 -> FOC, ESG | W26: 685.76 | X26: 857.2 | Y26: 857.2 | Z26: 1135.79 | AA26: 857.2 | AB26: 857.2 | AD26: 857.2 | AE26: 771.48 | AF26: 857.2 | AG26: 857.2 | AH26: 857.2 | AL26: =SUM(P26:R26) -> 0 | AM26: =B26 -> COOPER, Cassandra July | AN26: =Allocations!E26*$AL26 -> 0 | AO26: =Allocations!F26*$AL26 -> 0 | AP26: =Allocations!G26*$AL26 -> 0 | AQ26: =Allocations!H26*$AL26 -> 0 | AR26: =Allocations!I26*$AL26 -> 0 | AS26: =Allocations!J26*$AL26 -> 0 | AT26: =Allocations!K26*$AL26 -> 0 | AU26: =Allocations!L26*$AL26 -> 0 | ... BU26: =Allocations!AL26*$AL26 -> 0 | BV26: =SUM(AN26:BU26) -> 0 | BW26: =AL26-BV26 -> 0 | BX26: =B26 -> COOPER, Cassandra July
A27: =Allocations!A27 -> 21 | B27: Counts, Monique Lamae | C27: =Allocations!C27 -> Americorp | D27: 528.16 | E27: =D27*$E$6 -> 13732.16 | G27: =SUM(E27:F27) -> 13732.16 | H27: 105.63 | I27: 528.16 | J27: 528.16 | K27: 528.16 | L27: 528.16 | M27: 528.16 | N27: 528.16 | O27: 528.16 | S27: 528.16 | T27: 528.16 | AL27: =SUM(P27:R27) -> 0 | AM27: =B27 -> Counts, Monique Lamae | AN27: =Allocations!E27*$AL27 -> 0 | AO27: =Allocations!F27*$AL27 -> 0 | AP27: =Allocations!G27*$AL27 -> 0 | AQ27: =Allocations!H27*$AL27 -> 0 | AR27: =Allocations!I27*$AL27 -> 0 | AS27: =Allocations!J27*$AL27 -> 0 | AT27: =Allocations!K27*$AL27 -> 0 | AU27: =Allocations!L27*$AL27 -> 0 | ... BU27: =Allocations!AL27*$AL27 -> 0 | BV27: =SUM(AN27:BU27) -> 0 | BW27: =AL27-BV27 -> 0 | BX27: =B27 -> Counts, Monique Lamae
A28: =Allocations!A28 -> 22 | B28: =Allocations!B28 -> DANCE-WILSON, Heather | C28: =Allocations!C28 -> Abbott | D28: 2692.31 | E28: =D28*$E$6 -> 70000.06 | F28: =E28*$F$3 -> 3500.003 | G28: =SUM(E28:F28) -> 73500.063 | H28: 2692.31 | I28: 2742.31 | J28: 2692.31 | K28: 2692.31 | L28: 2692.31 | M28: 2692.31 | N28: 2692.31 | O28: 2692.31 | P28: 2692.31 | Q28: 2692.31 | R28: 2692.31 | S28: 2692.31 | T28: 2692.31 | W28: 2692.31 | X28: 2692.31 | Y28: 2692.31 | Z28: 2692.31 | AA28: 2692.31 | AB28: 2692.31 | AD28: 2692.31 | AE28: 2692.31 | AF28: 2692.31 | AG28: 2692.31 | AH28: 2692.31 | AL28: =SUM(P28:R28) -> 8076.93 | AM28: =B28 -> DANCE-WILSON, Heather | AN28: =Allocations!E28*$AL28 -> 0 | AO28: =Allocations!F28*$AL28 -> 6219.2361 | AP28: =Allocations!G28*$AL28 -> 0 | AQ28: =Allocations!H28*$AL28 -> 1857.6939 | AR28: =Allocations!I28*$AL28 -> 0 | AS28: =Allocations!J28*$AL28 -> 0 | AT28: =Allocations!K28*$AL28 -> 0 | AU28: =Allocations!L28*$AL28 -> 0 | ... BU28: =Allocations!AL28*$AL28 -> 0 | BV28: =SUM(AN28:BU28) -> 8076.93 | BW28: =AL28-BV28 -> 0 | BX28: =B28 -> DANCE-WILSON, Heather | CI28: =Allocations!#REF! -> #REF! | CJ28: =Allocations!#REF! -> #REF! | CK28: =Allocations!#REF! -> #REF! | CL28: =Allocations!#REF! -> #REF! | CM28: =Allocations!#REF! -> #REF! | CN28: =Allocations!#REF! -> #REF! | CO28: =Allocations!#REF! -> #REF! | CP28: =Allocations!#REF! -> #REF! | ... XFA28: =Allocations!#REF! -> #REF!
A29: =Allocations!A29 -> 23 | B29: =Allocations!B29 -> DANIELS-CRAFTON, Glenda | C29: =Allocations!C29 -> EHS | D29: 960 | E29: =D29*$E$6 -> 24960 | G29: =SUM(E29:F29) -> 24960 | H29: 960 | I29: 964.5 | J29: 964.5 | K29: 960 | L29: 960 | M29: 960 | N29: 963.06 | O29: 960 | P29: 960 | Q29: 964.98 | R29: 963.06 | S29: 960 | T29: 960 | W29: 960 | X29: 960 | Y29: 1440 | Z29: 960 | AL29: =SUM(P29:R29) -> 2888.04 | AM29: =B29 -> DANIELS-CRAFTON, Glenda | AN29: =Allocations!E29*$AL29 -> 0 | AO29: =Allocations!F29*$AL29 -> 0 | AP29: =Allocations!G29*$AL29 -> 0 | AQ29: =Allocations!H29*$AL29 -> 0 | AR29: =Allocations!I29*$AL29 -> 0 | AS29: =Allocations!J29*$AL29 -> 2888.04 | AT29: =Allocations!K29*$AL29 -> 0 | AU29: =Allocations!L29*$AL29 -> 0 | ... BU29: =Allocations!AL29*$AL29 -> 0 | BV29: =SUM(AN29:BU29) -> 2888.04 | BW29: =AL29-BV29 -> 0 | BX29: =B29 -> DANIELS-CRAFTON, Glenda
A30: =Allocations!A30 -> 24 | B30: =Allocations!B30 -> ELLIS, Joseph | C30: =Allocations!C30 -> OICA | D30: 1400 | E30: =D30*$E$6/2 -> 18200 | G30: =SUM(E30:F30) -> 18200 | I30: 1600 | J30: 2800 | K30: 2800 | L30: 2520 | M30: 2800 | N30: 1400 | O30: 2000 | P30: 2000 | Q30: 2000 | AL30: =SUM(P30:R30) -> 4000 | AM30: =B30 -> ELLIS, Joseph | AN30: =Allocations!E30*$AL30 -> 0 | AO30: =Allocations!F30*$AL30 -> 0 | AP30: =Allocations!G30*$AL30 -> 0 | AQ30: =Allocations!H30*$AL30 -> 0 | AR30: =Allocations!I30*$AL30 -> 0 | AS30: =Allocations!J30*$AL30 -> 0 | AT30: =Allocations!K30*$AL30 -> 0 | AU30: =Allocations!L30*$AL30 -> 0 | ... BU30: =Allocations!AL30*$AL30 -> 0 | BV30: =SUM(AN30:BU30) -> 4000 | BW30: =AL30-BV30 -> 0 | BX30: =B30 -> ELLIS, Joseph
A31: =Allocations!A31 -> 25 | B31: =Allocations!B31 -> FITZPATRICK, Cynthia E. - Aug 31 | C31: =Allocations!C31 -> EHS | D31: 960 | E31: =D31*$E$6 -> 24960 | F31: =E31*$F$3 -> 1248 | G31: =SUM(E31:F31) -> 26208 | H31: 960 | I31: 960 | J31: 965.94 | K31: 963.84 | L31: 962.4 | M31: 961.44 | N31: 970.44 | O31: 967.98 | P31: 960.96 | Q31: 962.88 | R31: 977.82 | S31: 960 | T31: 960 | W31: 960 | X31: 960 | Y31: 961.44 | Z31: 967.2 | AL31: =SUM(P31:R31) -> 2901.66 | AM31: =B31 -> FITZPATRICK, Cynthia E. - Aug 31 | AN31: =Allocations!E31*$AL31 -> 0 | AO31: =Allocations!F31*$AL31 -> 0 | AP31: =Allocations!G31*$AL31 -> 0 | AQ31: =Allocations!H31*$AL31 -> 0 | AR31: =Allocations!I31*$AL31 -> 0 | AS31: =Allocations!J31*$AL31 -> 2901.66 | AT31: =Allocations!K31*$AL31 -> 0 | AU31: =Allocations!L31*$AL31 -> 0 | ... BU31: =Allocations!AL31*$AL31 -> 0 | BV31: =SUM(AN31:BU31) -> 2901.66 | BW31: =AL31-BV31 -> 0 | BX31: =B31 -> FITZPATRICK, Cynthia E. - Aug 31
A32: =Allocations!A32 -> 26 | B32: =Allocations!B32 -> FITZPATRICK, Cynthia E. - Toddlers | C32: =Allocations!C32 -> EHS/ Toddlers | AA32: 960 | AB32: 960 | AD32: 962.88 | AE32: 962.88 | AF32: 968.16 | AG32: 964.44 | AH32: 969.96 | AL32: =SUM(P32:R32) -> 0 | AM32: =B32 -> FITZPATRICK, Cynthia E. - Toddlers | AN32: =Allocations!E32*$AL32 -> 0 | AO32: =Allocations!F32*$AL32 -> 0 | AP32: =Allocations!G32*$AL32 -> 0 | AQ32: =Allocations!H32*$AL32 -> 0 | AR32: =Allocations!I32*$AL32 -> 0 | AS32: =Allocations!J32*$AL32 -> 0 | AT32: =Allocations!K32*$AL32 -> 0 | AU32: =Allocations!L32*$AL32 -> 0 | ... BU32: =Allocations!AL32*$AL32 -> 0 | BV32: =SUM(AN32:BU32) -> 0 | BW32: =AL32-BV32 -> 0 | BX32: =B32 -> FITZPATRICK, Cynthia E. - Toddlers
A33: =Allocations!A33 -> 27 | B33: =Allocations!B33 -> FRANCOIS, Darlene | C33: =Allocations!C33 -> Americorp | D33: 485.77 | E33: =D33*$E$6 -> 12630.02 | G33: =SUM(E33:F33) -> 12630.02 | H33: 502.86 | I33: 528.16 | J33: 528.16 | K33: 528.16 | L33: 528.16 | M33: 528.16 | N33: 528.16 | O33: 528.16 | S33: 528.16 | T33: 528.16 | AL33: =SUM(P33:R33) -> 0 | AM33: =B33 -> FRANCOIS, Darlene | AN33: =Allocations!E33*$AL33 -> 0 | AO33: =Allocations!F33*$AL33 -> 0 | AP33: =Allocations!G33*$AL33 -> 0 | AQ33: =Allocations!H33*$AL33 -> 0 | AR33: =Allocations!I33*$AL33 -> 0 | AS33: =Allocations!J33*$AL33 -> 0 | AT33: =Allocations!K33*$AL33 -> 0 | AU33: =Allocations!L33*$AL33 -> 0 | ... BU33: =Allocations!AL33*$AL33 -> 0 | BV33: =SUM(AN33:BU33) -> 0 | BW33: =AL33-BV33 -> 0 | BX33: =B33 -> FRANCOIS, Darlene
A34: =Allocations!A34 -> 28 | B34: =Allocations!B34 -> FRASER, Vivian Cox | C34: =Allocations!C34 -> Admin | D34: 5961.54 | E34: =D34*$E$6 -> 155000.04 | F34: =E34*$F$3 -> 7750.002 | G34: =SUM(E34:F34) -> 162750.04 | H34: 5192.31 | I34: 5192.31 | J34: 5192.31 | K34: 5192.31 | L34: 5192.31 | M34: 5192.31 | N34: 5192.31 | O34: 5961.54 | P34: 10115.38 | Q34: 5961.54 | R34: 5961.54 | S34: 5961.54 | T34: 5961.54 | W34: 5961.54 | X34: 5961.54 | AL34: =SUM(P34:R34) -> 22038.46 | AM34: =B34 -> FRASER, Vivian Cox | AN34: =Allocations!E34*$AL34 -> 0 | AO34: =Allocations!F34*$AL34 -> 0 | AP34: =Allocations!G34*$AL34 -> 0 | AQ34: =Allocations!H34*$AL34 -> 0 | AR34: =Allocations!I34*$AL34 -> 0 | AS34: =Allocations!J34*$AL34 -> 0 | AT34: =Allocations!K34*$AL34 -> 0 | AU34: =Allocations!L34*$AL34 -> 0 | ... BU34: =Allocations!AL34*$AL34 -> 0 | BV34: =SUM(AN34:BU34) -> 22038.46 | BW34: =AL34-BV34 -> 0 | BX34: =B34 -> FRASER, Vivian Cox
A35: =Allocations!A35 -> 29 | B35: =Allocations!B35 -> FRASER, Vivian Cox- July | Y35: 5961.54 | Z35: 5961.54 | AA35: 5961.54 | AB35: 5961.54 | AD35: 5961.54 | AE35: 5961.54 | AF35: 5961.54 | AG35: 5961.54 | AH35: 5961.54 | AL35: =SUM(P35:R35) -> 0 | AM35: =B35 -> FRASER, Vivian Cox- July | AN35: =Allocations!E35*$AL35 -> 0 | AO35: =Allocations!F35*$AL35 -> 0 | AP35: =Allocations!G35*$AL35 -> 0 | AQ35: =Allocations!H35*$AL35 -> 0 | AR35: =Allocations!I35*$AL35 -> 0 | AS35: =Allocations!J35*$AL35 -> 0 | AT35: =Allocations!K35*$AL35 -> 0 | AU35: =Allocations!L35*$AL35 -> 0 | ... BU35: =Allocations!AL35*$AL35 -> 0 | BV35: =SUM(AN35:BU35) -> 0 | BW35: =AL35-BV35 -> 0 | BX35: =B35 -> FRASER, Vivian Cox- July
A36: =Allocations!A36 -> 30 | B36: =Allocations!B36 -> FRAZIER, Alice | C36: =Allocations!C36 -> Workforce | D36: 3153.85 | E36: =D36*$E$6 -> 82000.1 | F36: =E36*$F$3 -> 4100.005 | G36: =SUM(E36:F36) -> 86100.105 | H36: 3153.85 | I36: 3153.85 | J36: 3153.85 | K36: 3153.85 | L36: 3153.85 | M36: 3153.85 | N36: 3153.85 | O36: 3153.85 | P36: 3153.85 | Q36: 3153.85 | R36: 3153.85 | S36: 3153.85 | T36: 3153.85 | W36: 3153.85 | X36: 3153.85 | Y36: 3153.85 | Z36: 3153.85 | AA36: 3153.85 | AB36: 3153.85 | AD36: 3153.85 | AE36: 3153.85 | AF36: 3153.85 | AG36: 3153.85 | AH36: 3153.85 | AL36: =SUM(P36:R36) -> 9461.55 | AM36: =B36 -> FRAZIER, Alice | AN36: =Allocations!E36*$AL36 -> 0 | AO36: =Allocations!F36*$AL36 -> 0 | AP36: =Allocations!G36*$AL36 -> 0 | AQ36: =Allocations!H36*$AL36 -> 0 | AR36: =Allocations!I36*$AL36 -> 0 | AS36: =Allocations!J36*$AL36 -> 0 | AT36: =Allocations!K36*$AL36 -> 0 | AU36: =Allocations!L36*$AL36 -> 0 | ... BU36: =Allocations!AL36*$AL36 -> 0 | BV36: =SUM(AN36:BU36) -> 9461.55 | BW36: =AL36-BV36 -> 0 | BX36: =B36 -> FRAZIER, Alice
A37: =Allocations!A37 -> 31 | B37: Freeman, Jibri | C37: =Allocations!C37 -> Americorp | D37: 528.16 | E37: =D37*$E$6 -> 13732.16 | G37: =SUM(E37:F37) -> 13732.16 | H37: 105.63 | I37: 528.16 | J37: 528.16 | K37: 528.16 | L37: 528.16 | M37: 528.16 | N37: 528.16 | O37: 528.16 | AL37: =SUM(P37:R37) -> 0 | AM37: =B37 -> Freeman, Jibri | AN37: =Allocations!E37*$AL37 -> 0 | AO37: =Allocations!F37*$AL37 -> 0 | AP37: =Allocations!G37*$AL37 -> 0 | AQ37: =Allocations!H37*$AL37 -> 0 | AR37: =Allocations!I37*$AL37 -> 0 | AS37: =Allocations!J37*$AL37 -> 0 | AT37: =Allocations!K37*$AL37 -> 0 | AU37: =Allocations!L37*$AL37 -> 0 | ... BU37: =Allocations!AL37*$AL37 -> 0 | BV37: =SUM(AN37:BU37) -> 0 | BW37: =AL37-BV37 -> 0 | BX37: =B37 -> Freeman, Jibri
A38: =Allocations!A38 -> 32 | B38: =Allocations!B38 -> GARRETT, Dorian S. | C38: =Allocations!C38 -> EHS | D38: 1227 | E38: =D38*$E$6 -> 31902 | G38: =SUM(E38:F38) -> 31902 | H38: 1064 | I38: 1264.72 | J38: 1129 | K38: 1285 | L38: 1277.08 | M38: 1273.84 | N38: 1283.92 | O38: 1284.1 | P38: 960.42 | Q38: 904.92 | R38: 738 | S38: 944.04 | T38: 960 | W38: 947.76 | X38: 942 | Y38: 903 | Z38: 960 | AL38: =SUM(P38:R38) -> 2603.34 | AM38: =B38 -> GARRETT, Dorian S. | AN38: =Allocations!E38*$AL38 -> 0 | AO38: =Allocations!F38*$AL38 -> 0 | AP38: =Allocations!G38*$AL38 -> 0 | AQ38: =Allocations!H38*$AL38 -> 0 | AR38: =Allocations!I38*$AL38 -> 0 | AS38: =Allocations!J38*$AL38 -> 2603.34 | AT38: =Allocations!K38*$AL38 -> 0 | AU38: =Allocations!L38*$AL38 -> 0 | ... BU38: =Allocations!AL38*$AL38 -> 0 | BV38: =SUM(AN38:BU38) -> 2603.34 | BW38: =AL38-BV38 -> 0 | BX38: =B38 -> GARRETT, Dorian S.
A39: =Allocations!A39 -> 33 | B39: =Allocations!B39 -> GARRETT, Shakia | C39: =Allocations!C39 -> EHS | D39: 700 | E39: =D39*$E$6 -> 18200 | G39: =SUM(E39:F39) -> 18200 | AL39: =SUM(P39:R39) -> 0 | AM39: =B39 -> GARRETT, Shakia | AN39: =Allocations!E39*$AL39 -> 0 | AO39: =Allocations!F39*$AL39 -> 0 | AP39: =Allocations!G39*$AL39 -> 0 | AQ39: =Allocations!H39*$AL39 -> 0 | AR39: =Allocations!I39*$AL39 -> 0 | AS39: =Allocations!J39*$AL39 -> 0 | AT39: =Allocations!K39*$AL39 -> 0 | AU39: =Allocations!L39*$AL39 -> 0 | ... BU39: =Allocations!AL39*$AL39 -> 0 | BV39: =SUM(AN39:BU39) -> 0 | BW39: =AL39-BV39 -> 0 | BX39: =B39 -> GARRETT, Shakia
A40: =Allocations!A40 -> 34 | B40: =Allocations!B40 -> GBAMOKOLLIE, Molly | C40: =Allocations!C40 -> Facilities | D40: 625 | E40: =D40*$E$6 -> 16250 | G40: =SUM(E40:F40) -> 16250 | H40: 437.5 | I40: 312.5 | AL40: =SUM(P40:R40) -> 0 | AM40: =B40 -> GBAMOKOLLIE, Molly | AN40: =Allocations!E40*$AL40 -> 0 | AO40: =Allocations!F40*$AL40 -> 0 | AP40: =Allocations!G40*$AL40 -> 0 | AQ40: =Allocations!H40*$AL40 -> 0 | AR40: =Allocations!I40*$AL40 -> 0 | AS40: =Allocations!J40*$AL40 -> 0 | AT40: =Allocations!K40*$AL40 -> 0 | AU40: =Allocations!L40*$AL40 -> 0 | ... BU40: =Allocations!AL40*$AL40 -> 0 | BV40: =SUM(AN40:BU40) -> 0 | BW40: =AL40-BV40 -> 0 | BX40: =B40 -> GBAMOKOLLIE, Molly
A41: =Allocations!A41 -> 35 | B41: =Allocations!B41 -> GREEN, Yolanda - | C41: =Allocations!C41 -> EHS | D41: 1225.86 | E41: =D41*$E$6 -> 31872.36 | F41: =E41*$F$3 -> 1593.618 | G41: =SUM(E41:F41) -> 33465.978 | H41: 1265.62 | I41: 1264.34 | J41: 1254.92 | K41: 1264.34 | L41: 1270.89 | M41: 1257.64 | N41: 1264.19 | O41: 1260.19 | P41: 1273.61 | Q41: 1263.06 | R41: 1259.07 | S41: 1253.65 | T41: 1265.62 | W41: 1277.6 | X41: 1279.52 | Y41: 1261.79 | Z41: 1277.6 | AL41: =SUM(P41:R41) -> 3795.74 | AM41: =B41 -> GREEN, Yolanda - | AN41: =Allocations!E41*$AL41 -> 0 | AO41: =Allocations!F41*$AL41 -> 0 | AP41: =Allocations!G41*$AL41 -> 0 | AQ41: =Allocations!H41*$AL41 -> 0 | AR41: =Allocations!I41*$AL41 -> 0 | AS41: =Allocations!J41*$AL41 -> 3795.74 | AT41: =Allocations!K41*$AL41 -> 0 | AU41: =Allocations!L41*$AL41 -> 0 | ... BU41: =Allocations!AL41*$AL41 -> 0 | BV41: =SUM(AN41:BU41) -> 3795.74 | BW41: =AL41-BV41 -> 0 | BX41: =B41 -> GREEN, Yolanda -
A42: =Allocations!A42 -> 36 | B42: =Allocations!B42 -> GREEN, Yolanda - Toddlers | C42: =Allocations!C42 -> EHS/ Toddlers | AA42: 1277.6 | AB42: 1280.15 | AD42: 1281.44 | AE42: 1284.89 | AF42: 1273.61 | AG42: 1294.52 | AH42: 1278.88 | AL42: =SUM(P42:R42) -> 0 | AM42: =B42 -> GREEN, Yolanda - Toddlers | AN42: =Allocations!E42*$AL42 -> 0 | AO42: =Allocations!F42*$AL42 -> 0 | AP42: =Allocations!G42*$AL42 -> 0 | AQ42: =Allocations!H42*$AL42 -> 0 | AR42: =Allocations!I42*$AL42 -> 0 | AS42: =Allocations!J42*$AL42 -> 0 | AT42: =Allocations!K42*$AL42 -> 0 | AU42: =Allocations!L42*$AL42 -> 0 | ... BU42: =Allocations!AL42*$AL42 -> 0 | BV42: =SUM(AN42:BU42) -> 0 | BW42: =AL42-BV42 -> 0 | BX42: =B42 -> GREEN, Yolanda - Toddlers
...

Sheet 2019 Health Ins 
T3: Contract
Q4: 12 | T4: Percentage | U4: 10 months | Y4: 12 Months
B5: SALARIES 2018 | C5: 2018 FY BUDGET | E5: Jan | F5: Feb | G5: Mar | H5: Apr | I5: May | J5: Jun | K5: July | L5: August | M5: Sept | N5: Oct | O5: Nov | P5: Dec | Q5: TOTAL | R5: .80.20 | S5: Variance | U5: =+Allocations!E1 -> 041 Social Enter Thriftworks | V5: =+Allocations!F1 -> 111 Abbott | W5: =+Allocations!G1 -> 111B Wrap Fees | X5: =+Allocations!H1 -> 111A Other | Y5: =+Allocations!I1 -> 111F Food Prog | Z5: =+Allocations!J1 -> 112 EHS/Toddler | AA5: =+Allocations!K1 -> EHS 112 A Fees | AB5: =+Allocations!L1 -> 114 Summer Camp | ... BC5: =+Allocations!AM1 -> Proof
B6: Salaried | E6: 1 | F6: 2 | G6: 3 | H6: 4 | I6: 5 | J6: 6 | U6: 1 | V6: 2 | W6: 3 | X6: 4 | Y6: 5 | Z6: 6 | AA6: 7 | AB6: 8 | AC6: 9 | AD6: 10 | AE6: 11 | AF6: 12 | AG6: 13 | AH6: 14 | AI6: 15 | AJ6: 16 | AL6: 17 | AM6: 18 | AN6: 19 | AO6: 20 | AP6: 21 | AQ6: 22 | AR6: 23 | AS6: 24 | AT6: 25 | AU6: 26 | AV6: 27 | AW6: 28 | AX6: 29 | AY6: 30 | AZ6: 31 | BA6: 32 | BB6: 33
A7: =Allocations!A7 -> 1 | B7: =Allocations!B7 -> AIKEN-SANZONE, Charlene | C7: =Allocations!C7 -> Americorp | D7: =Allocations!#REF! -> #REF! | Q7: =SUM(E7:J7) -> 0 | R7: =E7 -> 0 | S7: 0 | T7: 0 | U7: =Allocations!E7*$Q7 -> 0 | V7: =Allocations!F7*$Q7 -> 0 | W7: =Allocations!G7*$Q7 -> 0 | X7: =Allocations!H7*$Q7 -> 0 | Y7: =Allocations!I7*$Q7 -> 0 | Z7: =Allocations!J7*$Q7 -> 0 | AA7: =Allocations!K7*$Q7 -> 0 | AB7: =Allocations!L7*$Q7 -> 0 | ... AV7: =Allocations!AF7*$Q7 -> 0 | AW7: =Allocations!AF7*$Q7 -> 0 | AX7: =Allocations!AG7*$Q7 -> 0 | AY7: =Allocations!AH7*$Q7 -> 0 | AZ7: =Allocations!AI7*$Q7 -> 0 | BA7: =Allocations!AJ7*$Q7 -> 0 | BB7: =Allocations!AK7*$Q7 -> 0 | BC7: =SUM(U7:BB7) -> 0 | BD7: =Q7-BC7 -> 0 | BE7: =B7 -> AIKEN-SANZONE, Charlene
A8: =Allocations!A8 -> 2 | B8: =Allocations!B8 -> AIKEN-SANZONE, Charlene June 30 | C8: =Allocations!C8 -> OICA | D8: =Allocations!#REF! -> #REF! | Q8: =SUM(E8:J8) -> 0 | R8: =E8 -> 0 | S8: =R8/Q8 -> #DIV/0! | T8: 0 | U8: =Allocations!E8*$Q8 -> 0 | V8: =Allocations!F8*$Q8 -> 0 | W8: =Allocations!G8*$Q8 -> 0 | X8: =Allocations!H8*$Q8 -> 0 | Y8: =Allocations!I8*$Q8 -> 0 | Z8: =Allocations!J8*$Q8 -> 0 | AA8: =Allocations!K8*$Q8 -> 0 | AB8: =Allocations!L8*$Q8 -> 0 | ... AV8: =Allocations!AF8*$Q8 -> 0 | AW8: =Allocations!AF8*$Q8 -> 0 | AX8: =Allocations!AG8*$Q8 -> 0 | AY8: =Allocations!AH8*$Q8 -> 0 | AZ8: =Allocations!AI8*$Q8 -> 0 | BA8: =Allocations!AJ8*$Q8 -> 0 | BB8: =Allocations!AK8*$Q8 -> 0 | BC8: =SUM(U8:BB8) -> 0 | BD8: =Q8-BC8 -> 0 | BE8: =B8 -> AIKEN-SANZONE, Charlene June 30
A9: =Allocations!A9 -> 3 | B9: =Allocations!B9 -> ALFORD, Sebrania R. | C9: =Allocations!C9 -> Abbott | D9: =Allocations!#REF! -> #REF! | E9: 700.13 | F9: 700.13 | G9: 700.13 | H9: 700.13 | I9: 700.13 | J9: 700.13 | K9: 700.13 | L9: 700.13 | M9: 700.13 | Q9: =SUM(E9:J9) -> 4200.78 | R9: =E9 -> 700.13 | T9: 0 | U9: =Allocations!E9*$Q9 -> 0 | V9: =Allocations!F9*$Q9 -> 2730.507 | W9: =Allocations!G9*$Q9 -> 0 | X9: =Allocations!H9*$Q9 -> 0 | Y9: =Allocations!I9*$Q9 -> 0 | Z9: =Allocations!J9*$Q9 -> 1470.273 | AA9: =Allocations!K9*$Q9 -> 0 | AB9: =Allocations!L9*$Q9 -> 0 | ... AV9: =Allocations!AF9*$Q9 -> 0 | AW9: =Allocations!AF9*$Q9 -> 0 | AX9: =Allocations!AG9*$Q9 -> 0 | AY9: =Allocations!AH9*$Q9 -> 0 | AZ9: =Allocations!AI9*$Q9 -> 0 | BA9: =Allocations!AJ9*$Q9 -> 0 | BB9: =Allocations!AK9*$Q9 -> 0 | BC9: =SUM(U9:BB9) -> 4200.78 | BD9: =Q9-BC9 -> 0 | BE9: =B9 -> ALFORD, Sebrania R.
A10: =Allocations!A10 -> 4 | B10: =Allocations!B10 -> ALMANZAR, Alberto | C10: =Allocations!C10 -> USJP | D10: =Allocations!#REF! -> #REF! | Q10: =SUM(E10:J10) -> 0 | R10: =E10 -> 0 | S10: =R10/Q10 -> #DIV/0! | T10: 0 | U10: =Allocations!E10*$Q10 -> 0 | V10: =Allocations!F10*$Q10 -> 0 | W10: =Allocations!G10*$Q10 -> 0 | X10: =Allocations!H10*$Q10 -> 0 | Y10: =Allocations!I10*$Q10 -> 0 | Z10: =Allocations!J10*$Q10 -> 0 | AA10: =Allocations!K10*$Q10 -> 0 | AB10: =Allocations!L10*$Q10 -> 0 | ... AV10: =Allocations!AF10*$Q10 -> 0 | AW10: =Allocations!AF10*$Q10 -> 0 | AX10: =Allocations!AG10*$Q10 -> 0 | AY10: =Allocations!AH10*$Q10 -> 0 | AZ10: =Allocations!AI10*$Q10 -> 0 | BA10: =Allocations!AJ10*$Q10 -> 0 | BB10: =Allocations!AK10*$Q10 -> 0 | BC10: =SUM(U10:BB10) -> 0 | BD10: =Q10-BC10 -> 0 | BE10: =B10 -> ALMANZAR, Alberto
A11: =Allocations!A11 -> 5 | B11: =Allocations!B11 -> ANDREWS, Cora - Summer | C11: =Allocations!C11 -> Abbott | D11: =Allocations!#REF! -> #REF! | Q11: =SUM(E11:J11) -> 0 | R11: =E11 -> 0 | T11: 0 | U11: =Allocations!E11*$Q11 -> 0 | V11: =Allocations!F11*$Q11 -> 0 | W11: =Allocations!G11*$Q11 -> 0 | X11: =Allocations!H11*$Q11 -> 0 | Y11: =Allocations!I11*$Q11 -> 0 | Z11: =Allocations!J11*$Q11 -> 0 | AA11: =Allocations!K11*$Q11 -> 0 | AB11: =Allocations!L11*$Q11 -> 0 | ... AV11: =Allocations!AF11*$Q11 -> 0 | AW11: =Allocations!AF11*$Q11 -> 0 | AX11: =Allocations!AG11*$Q11 -> 0 | AY11: =Allocations!AH11*$Q11 -> 0 | AZ11: =Allocations!AI11*$Q11 -> 0 | BA11: =Allocations!AJ11*$Q11 -> 0 | BB11: =Allocations!AK11*$Q11 -> 0 | BC11: =SUM(U11:BB11) -> 0 | BD11: =Q11-BC11 -> 0 | BE11: =B11 -> ANDREWS, Cora - Summer
A12: =Allocations!A12 -> 6 | B12: =Allocations!B12 -> ANDREWS, Cora | C12: =Allocations!C12 -> Abbott | D12: E | Q12: =SUM(E12:J12) -> 0 | R12: =E12 -> 0 | T12: 0 | U12: =Allocations!E12*$Q12 -> 0 | V12: =Allocations!F12*$Q12 -> 0 | W12: =Allocations!G12*$Q12 -> 0 | X12: =Allocations!H12*$Q12 -> 0 | Y12: =Allocations!I12*$Q12 -> 0 | Z12: =Allocations!J12*$Q12 -> 0 | AA12: =Allocations!K12*$Q12 -> 0 | AB12: =Allocations!L12*$Q12 -> 0 | ... AV12: =Allocations!AF12*$Q12 -> 0 | AW12: =Allocations!AF12*$Q12 -> 0 | AX12: =Allocations!AG12*$Q12 -> 0 | AY12: =Allocations!AH12*$Q12 -> 0 | AZ12: =Allocations!AI12*$Q12 -> 0 | BA12: =Allocations!AJ12*$Q12 -> 0 | BB12: =Allocations!AK12*$Q12 -> 0 | BC12: =SUM(U12:BB12) -> 0 | BD12: =Q12-BC12 -> 0 | BE12: =B12 -> ANDREWS, Cora
A13: =Allocations!A13 -> 7 | B13: =Allocations!B13 -> ANDREWS, Courtney A. | C13: =Allocations!C13 -> Americorp | D13: =Allocations!#REF! -> #REF! | Q13: =SUM(E13:J13) -> 0 | R13: =E13 -> 0 | T13: 0 | U13: =Allocations!E13*$Q13 -> 0 | V13: =Allocations!F13*$Q13 -> 0 | W13: =Allocations!G13*$Q13 -> 0 | X13: =Allocations!H13*$Q13 -> 0 | Y13: =Allocations!I13*$Q13 -> 0 | Z13: =Allocations!J13*$Q13 -> 0 | AA13: =Allocations!K13*$Q13 -> 0 | AB13: =Allocations!L13*$Q13 -> 0 | ... AV13: =Allocations!AF13*$Q13 -> 0 | AW13: =Allocations!AF13*$Q13 -> 0 | AX13: =Allocations!AG13*$Q13 -> 0 | AY13: =Allocations!AH13*$Q13 -> 0 | AZ13: =Allocations!AI13*$Q13 -> 0 | BA13: =Allocations!AJ13*$Q13 -> 0 | BB13: =Allocations!AK13*$Q13 -> 0 | BC13: =SUM(U13:BB13) -> 0 | BD13: =Q13-BC13 -> 0 | BE13: =B13 -> ANDREWS, Courtney A.
A14: =Allocations!A14 -> 8 | B14: =Allocations!B14 -> BIRDSONG, Rhonda June 30 | C14: =Allocations!C14 -> OICA | Q14: =SUM(E14:J14) -> 0 | R14: =E14 -> 0 | U14: =Allocations!E14*$Q14 -> 0 | V14: =Allocations!F14*$Q14 -> 0 | W14: =Allocations!G14*$Q14 -> 0 | X14: =Allocations!H14*$Q14 -> 0 | Y14: =Allocations!I14*$Q14 -> 0 | Z14: =Allocations!J14*$Q14 -> 0 | AA14: =Allocations!K14*$Q14 -> 0 | AB14: =Allocations!L14*$Q14 -> 0 | ... AV14: =Allocations!AF14*$Q14 -> 0 | AW14: =Allocations!AF14*$Q14 -> 0 | AX14: =Allocations!AG14*$Q14 -> 0 | AY14: =Allocations!AH14*$Q14 -> 0 | AZ14: =Allocations!AI14*$Q14 -> 0 | BA14: =Allocations!AJ14*$Q14 -> 0 | BB14: =Allocations!AK14*$Q14 -> 0 | BC14: =SUM(U14:BB14) -> 0 | BD14: =Q14-BC14 -> 0 | BE14: =B14 -> BIRDSONG, Rhonda June 30
A15: =Allocations!A15 -> 9 | B15: =Allocations!B15 -> Bizi, Raymond | C15: =Allocations!C15 -> Americorp | D15: =Allocations!#REF! -> #REF! | Q15: =SUM(E15:J15) -> 0 | R15: =E15 -> 0 | T15: 0 | U15: =Allocations!E15*$Q15 -> 0 | V15: =Allocations!F15*$Q15 -> 0 | W15: =Allocations!G15*$Q15 -> 0 | X15: =Allocations!H15*$Q15 -> 0 | Y15: =Allocations!I15*$Q15 -> 0 | Z15: =Allocations!J15*$Q15 -> 0 | AA15: =Allocations!K15*$Q15 -> 0 | AB15: =Allocations!L15*$Q15 -> 0 | ... AV15: =Allocations!AF15*$Q15 -> 0 | AW15: =Allocations!AF15*$Q15 -> 0 | AX15: =Allocations!AG15*$Q15 -> 0 | AY15: =Allocations!AH15*$Q15 -> 0 | AZ15: =Allocations!AI15*$Q15 -> 0 | BA15: =Allocations!AJ15*$Q15 -> 0 | BB15: =Allocations!AK15*$Q15 -> 0 | BC15: =SUM(U15:BB15) -> 0 | BD15: =Q15-BC15 -> 0 | BE15: =B15 -> Bizi, Raymond
A16: =Allocations!A16 -> 10 | B16: =Allocations!B16 -> BROWN,Denise- Wrap | C16: =Allocations!C16 -> Abbott | D16: =Allocations!#REF! -> #REF! | Q16: =SUM(E16:J16) -> 0 | R16: =E16 -> 0 | T16: 0 | U16: =Allocations!E16*$Q16 -> 0 | V16: =Allocations!F16*$Q16 -> 0 | W16: =Allocations!G16*$Q16 -> 0 | X16: =Allocations!H16*$Q16 -> 0 | Y16: =Allocations!I16*$Q16 -> 0 | Z16: =Allocations!J16*$Q16 -> 0 | AA16: =Allocations!K16*$Q16 -> 0 | AB16: =Allocations!L16*$Q16 -> 0 | ... AV16: =Allocations!AF16*$Q16 -> 0 | AW16: =Allocations!AF16*$Q16 -> 0 | AX16: =Allocations!AG16*$Q16 -> 0 | AY16: =Allocations!AH16*$Q16 -> 0 | AZ16: =Allocations!AI16*$Q16 -> 0 | BA16: =Allocations!AJ16*$Q16 -> 0 | BB16: =Allocations!AK16*$Q16 -> 0 | BC16: =SUM(U16:BB16) -> 0 | BD16: =Q16-BC16 -> 0 | BE16: =B16 -> BROWN,Denise- Wrap
A17: =Allocations!A17 -> 11 | B17: =Allocations!B17 -> BROWN,Denise - Summer | C17: =Allocations!C17 -> Abbott | Q17: =SUM(E17:J17) -> 0 | R17: =E17 -> 0 | U17: =Allocations!E17*$Q17 -> 0 | V17: =Allocations!F17*$Q17 -> 0 | W17: =Allocations!G17*$Q17 -> 0 | X17: =Allocations!H17*$Q17 -> 0 | Y17: =Allocations!I17*$Q17 -> 0 | Z17: =Allocations!J17*$Q17 -> 0 | AA17: =Allocations!K17*$Q17 -> 0 | AB17: =Allocations!L17*$Q17 -> 0 | ... AV17: =Allocations!AF17*$Q17 -> 0 | AW17: =Allocations!AF17*$Q17 -> 0 | AX17: =Allocations!AG17*$Q17 -> 0 | AY17: =Allocations!AH17*$Q17 -> 0 | AZ17: =Allocations!AI17*$Q17 -> 0 | BA17: =Allocations!AJ17*$Q17 -> 0 | BB17: =Allocations!AK17*$Q17 -> 0 | BC17: =SUM(U17:BB17) -> 0 | BD17: =Q17-BC17 -> 0 | BE17: =B17 -> BROWN,Denise - Summer
A18: =Allocations!A18 -> 12 | B18: =Allocations!B18 -> BRYANT, Roni- Summer | C18: =Allocations!C18 -> Abbott | D18: =Allocations!#REF! -> #REF! | Q18: =SUM(E18:J18) -> 0 | R18: =E18 -> 0 | T18: 0 | U18: =Allocations!E18*$Q18 -> 0 | V18: =Allocations!F18*$Q18 -> 0 | W18: =Allocations!G18*$Q18 -> 0 | X18: =Allocations!H18*$Q18 -> 0 | Y18: =Allocations!I18*$Q18 -> 0 | Z18: =Allocations!J18*$Q18 -> 0 | AA18: =Allocations!K18*$Q18 -> 0 | AB18: =Allocations!L18*$Q18 -> 0 | ... AV18: =Allocations!AF18*$Q18 -> 0 | AW18: =Allocations!AF18*$Q18 -> 0 | AX18: =Allocations!AG18*$Q18 -> 0 | AY18: =Allocations!AH18*$Q18 -> 0 | AZ18: =Allocations!AI18*$Q18 -> 0 | BA18: =Allocations!AJ18*$Q18 -> 0 | BB18: =Allocations!AK18*$Q18 -> 0 | BC18: =SUM(U18:BB18) -> 0 | BD18: =Q18-BC18 -> 0 | BE18: =B18 -> BRYANT, Roni- Summer
A19: =Allocations!A19 -> 13 | B19: =Allocations!B19 -> BRYANT, Roni | C19: =Allocations!C19 -> Abbott | E19: 879.21 | F19: 879.21 | G19: 879.21 | H19: 879.21 | I19: 879.21 | J19: 879.21 | K19: 879.21 | L19: 879.21 | M19: 879.21 | N19: 879.21 | O19: 865.47 | P19: 865.47 | Q19: =SUM(E19:J19) -> 5275.26 | R19: =E19 -> 879.21 | T19: 1 | U19: =Allocations!E19*$Q19 -> 0 | V19: =Allocations!F19*$Q19 -> 5275.26 | W19: =Allocations!G19*$Q19 -> 0 | X19: =Allocations!H19*$Q19 -> 0 | Y19: =Allocations!I19*$Q19 -> 0 | Z19: =Allocations!J19*$Q19 -> 0 | AA19: =Allocations!K19*$Q19 -> 0 | AB19: =Allocations!L19*$Q19 -> 0 | ... AV19: =Allocations!AF19*$Q19 -> 0 | AW19: =Allocations!AF19*$Q19 -> 0 | AX19: =Allocations!AG19*$Q19 -> 0 | AY19: =Allocations!AH19*$Q19 -> 0 | AZ19: =Allocations!AI19*$Q19 -> 0 | BA19: =Allocations!AJ19*$Q19 -> 0 | BB19: =Allocations!AK19*$Q19 -> 0 | BC19: =SUM(U19:BB19) -> 5275.26 | BD19: =Q19-BC19 -> 0 | BE19: =B19 -> BRYANT, Roni
A20: =Allocations!A20 -> 14 | B20: =Allocations!B20 -> BUTLER, Ciji | C20: =Allocations!C20 -> USJP | D20: =Allocations!#REF! -> #REF! | G20: 1370.88 | H20: 663.33 | I20: 663.33 | J20: -685.44 | K20: -685.44 | Q20: =SUM(E20:J20) -> 2012.1 | R20: =E20 -> 0 | T20: 0 | U20: =Allocations!E20*$Q20 -> 0 | V20: =Allocations!F20*$Q20 -> 0 | W20: =Allocations!G20*$Q20 -> 0 | X20: =Allocations!H20*$Q20 -> 0 | Y20: =Allocations!I20*$Q20 -> 0 | Z20: =Allocations!J20*$Q20 -> 0 | AA20: =Allocations!K20*$Q20 -> 0 | AB20: =Allocations!L20*$Q20 -> 0 | ... AV20: =Allocations!AF20*$Q20 -> 0 | AW20: =Allocations!AF20*$Q20 -> 0 | AX20: =Allocations!AG20*$Q20 -> 0 | AY20: =Allocations!AH20*$Q20 -> 0 | AZ20: =Allocations!AI20*$Q20 -> 0 | BA20: =Allocations!AJ20*$Q20 -> 0 | BB20: =Allocations!AK20*$Q20 -> 0 | BC20: =SUM(U20:BB20) -> 2012.1 | BD20: =Q20-BC20 -> 0 | BE20: =B20 -> BUTLER, Ciji
A21: =Allocations!A21 -> 15 | B21: =Allocations!B21 -> CAMPBELL, Nikiesha K. | C21: =Allocations!C21 -> Americorp | D21: =Allocations!#REF! -> #REF! | Q21: =SUM(E21:J21) -> 0 | R21: =E21 -> 0 | T21: 0 | U21: =Allocations!E21*$Q21 -> 0 | V21: =Allocations!F21*$Q21 -> 0 | W21: =Allocations!G21*$Q21 -> 0 | X21: =Allocations!H21*$Q21 -> 0 | Y21: =Allocations!I21*$Q21 -> 0 | Z21: =Allocations!J21*$Q21 -> 0 | AA21: =Allocations!K21*$Q21 -> 0 | AB21: =Allocations!L21*$Q21 -> 0 | ... AV21: =Allocations!AF21*$Q21 -> 0 | AW21: =Allocations!AF21*$Q21 -> 0 | AX21: =Allocations!AG21*$Q21 -> 0 | AY21: =Allocations!AH21*$Q21 -> 0 | AZ21: =Allocations!AI21*$Q21 -> 0 | BA21: =Allocations!AJ21*$Q21 -> 0 | BB21: =Allocations!AK21*$Q21 -> 0 | BC21: =SUM(U21:BB21) -> 0 | BD21: =Q21-BC21 -> 0 | BE21: =B21 -> CAMPBELL, Nikiesha K.
A22: =Allocations!A22 -> 16 | B22: =Allocations!B22 -> CASTELLANOS, Rita J. | C22: =Allocations!C22 -> Abbott | D22: =Allocations!#REF! -> #REF! | Q22: =SUM(E22:J22) -> 0 | R22: =E22 -> 0 | S22: =R22/Q22 -> #DIV/0! | T22: 0 | U22: =Allocations!E22*$Q22 -> 0 | V22: =Allocations!F22*$Q22 -> 0 | W22: =Allocations!G22*$Q22 -> 0 | X22: =Allocations!H22*$Q22 -> 0 | Y22: =Allocations!I22*$Q22 -> 0 | Z22: =Allocations!J22*$Q22 -> 0 | AA22: =Allocations!K22*$Q22 -> 0 | AB22: =Allocations!L22*$Q22 -> 0 | ... AV22: =Allocations!AF22*$Q22 -> 0 | AW22: =Allocations!AF22*$Q22 -> 0 | AX22: =Allocations!AG22*$Q22 -> 0 | AY22: =Allocations!AH22*$Q22 -> 0 | AZ22: =Allocations!AI22*$Q22 -> 0 | BA22: =Allocations!AJ22*$Q22 -> 0 | BB22: =Allocations!AK22*$Q22 -> 0 | BC22: =SUM(U22:BB22) -> 0 | BD22: =Q22-BC22 -> 0 | BE22: =B22 -> CASTELLANOS, Rita J.
A23: =Allocations!A23 -> 17 | B23: =Allocations!B23 -> CERNA, Irene | C23: =Allocations!C23 -> USJP | D23: =Allocations!#REF! -> #REF! | E23: 1118.65 | F23: 1118.65 | G23: 1118.65 | H23: 1118.65 | I23: 1118.65 | J23: 1118.65 | K23: 1118.65 | L23: 1118.65 | M23: 1118.65 | N23: 1118.65 | O23: 1068.35 | P23: 1068.35 | Q23: =SUM(E23:J23) -> 6711.9 | R23: =E23 -> 1118.65 | T23: 0 | U23: =Allocations!E23*$Q23 -> 0 | V23: =Allocations!F23*$Q23 -> 0 | W23: =Allocations!G23*$Q23 -> 0 | X23: =Allocations!H23*$Q23 -> 0 | Y23: =Allocations!I23*$Q23 -> 0 | Z23: =Allocations!J23*$Q23 -> 0 | AA23: =Allocations!K23*$Q23 -> 0 | AB23: =Allocations!L23*$Q23 -> 0 | ... AV23: =Allocations!AF23*$Q23 -> 0 | AW23: =Allocations!AF23*$Q23 -> 0 | AX23: =Allocations!AG23*$Q23 -> 0 | AY23: =Allocations!AH23*$Q23 -> 0 | AZ23: =Allocations!AI23*$Q23 -> 0 | BA23: =Allocations!AJ23*$Q23 -> 0 | BB23: =Allocations!AK23*$Q23 -> 0 | BC23: =SUM(U23:BB23) -> 6711.9 | BD23: =Q23-BC23 -> 0 | BE23: =B23 -> CERNA, Irene
A24: =Allocations!A24 -> 18 | B24: =Allocations!B24 -> COLEMAN, Zabrina J. | C24: =Allocations!C24 -> EHS | E24: 760.48 | F24: 760.48 | G24: 760.48 | H24: 760.48 | I24: 760.48 | J24: 760.48 | K24: 760.48 | L24: 760.48 | M24: 760.48 | Q24: =SUM(E24:J24) -> 4562.88 | R24: =E24 -> 760.48 | T24: 1 | U24: =Allocations!E24*$Q24 -> 0 | V24: =Allocations!F24*$Q24 -> 0 | W24: =Allocations!G24*$Q24 -> 0 | X24: =Allocations!H24*$Q24 -> 0 | Y24: =Allocations!I24*$Q24 -> 0 | Z24: =Allocations!J24*$Q24 -> 4562.88 | AA24: =Allocations!K24*$Q24 -> 0 | AB24: =Allocations!L24*$Q24 -> 0 | ... AV24: =Allocations!AF24*$Q24 -> 0 | AW24: =Allocations!AF24*$Q24 -> 0 | AX24: =Allocations!AG24*$Q24 -> 0 | AY24: =Allocations!AH24*$Q24 -> 0 | AZ24: =Allocations!AI24*$Q24 -> 0 | BA24: =Allocations!AJ24*$Q24 -> 0 | BB24: =Allocations!AK24*$Q24 -> 0 | BC24: =SUM(U24:BB24) -> 4562.88 | BD24: =Q24-BC24 -> 0 | BE24: =B24 -> COLEMAN, Zabrina J.
A25: =Allocations!A25 -> 19 | B25: =Allocations!B25 -> COOPER, Cassandra June 30 | C25: =Allocations!C25 -> OICA | D25: =Allocations!#REF! -> #REF! | Q25: =SUM(E25:J25) -> 0 | R25: =E25 -> 0 | S25: =R25/Q25 -> #DIV/0! | T25: 0 | U25: =Allocations!E25*$Q25 -> 0 | V25: =Allocations!F25*$Q25 -> 0 | W25: =Allocations!G25*$Q25 -> 0 | X25: =Allocations!H25*$Q25 -> 0 | Y25: =Allocations!I25*$Q25 -> 0 | Z25: =Allocations!J25*$Q25 -> 0 | AA25: =Allocations!K25*$Q25 -> 0 | AB25: =Allocations!L25*$Q25 -> 0 | ... AV25: =Allocations!AF25*$Q25 -> 0 | AW25: =Allocations!AF25*$Q25 -> 0 | AX25: =Allocations!AG25*$Q25 -> 0 | AY25: =Allocations!AH25*$Q25 -> 0 | AZ25: =Allocations!AI25*$Q25 -> 0 | BA25: =Allocations!AJ25*$Q25 -> 0 | BB25: =Allocations!AK25*$Q25 -> 0 | BC25: =SUM(U25:BB25) -> 0 | BD25: =Q25-BC25 -> 0 | BE25: =B25 -> COOPER, Cassandra June 30 | BT25: =Allocations!#REF! -> #REF! | BU25: =Allocations!#REF! -> #REF! | BV25: =Allocations!#REF! -> #REF! | BW25: =Allocations!#REF! -> #REF! | BX25: =Allocations!#REF! -> #REF! | BY25: =Allocations!#REF! -> #REF! | BZ25: =Allocations!#REF! -> #REF! | CA25: =Allocations!#REF! -> #REF! | ... XEH25: =Allocations!#REF! -> #REF!
A26: =Allocations!A26 -> 20 | B26: =Allocations!B26 -> COOPER, Cassandra July | C26: =Allocations!C26 -> FOC, ESG | Q26: =SUM(E26:J26) -> 0 | R26: =E26 -> 0 | U26: =Allocations!E26*$Q26 -> 0 | V26: =Allocations!F26*$Q26 -> 0 | W26: =Allocations!G26*$Q26 -> 0 | X26: =Allocations!H26*$Q26 -> 0 | Y26: =Allocations!I26*$Q26 -> 0 | Z26: =Allocations!J26*$Q26 -> 0 | AA26: =Allocations!K26*$Q26 -> 0 | AB26: =Allocations!L26*$Q26 -> 0 | ... AV26: =Allocations!AF26*$Q26 -> 0 | AW26: =Allocations!AF26*$Q26 -> 0 | AX26: =Allocations!AG26*$Q26 -> 0 | AY26: =Allocations!AH26*$Q26 -> 0 | AZ26: =Allocations!AI26*$Q26 -> 0 | BA26: =Allocations!AJ26*$Q26 -> 0 | BB26: =Allocations!AK26*$Q26 -> 0 | BC26: =SUM(U26:BB26) -> 0 | BD26: =Q26-BC26 -> 0 | BE26: =B26 -> COOPER, Cassandra July
A27: =Allocations!A27 -> 21 | B27: =Allocations!B27 -> Counts, Monique Lamae | C27: =Allocations!C27 -> Americorp | D27: =Allocations!#REF! -> #REF! | Q27: =SUM(E27:J27) -> 0 | R27: =E27 -> 0 | T27: 0 | U27: =Allocations!E27*$Q27 -> 0 | V27: =Allocations!F27*$Q27 -> 0 | W27: =Allocations!G27*$Q27 -> 0 | X27: =Allocations!H27*$Q27 -> 0 | Y27: =Allocations!I27*$Q27 -> 0 | Z27: =Allocations!J27*$Q27 -> 0 | AA27: =Allocations!K27*$Q27 -> 0 | AB27: =Allocations!L27*$Q27 -> 0 | ... AV27: =Allocations!AF27*$Q27 -> 0 | AW27: =Allocations!AF27*$Q27 -> 0 | AX27: =Allocations!AG27*$Q27 -> 0 | AY27: =Allocations!AH27*$Q27 -> 0 | AZ27: =Allocations!AI27*$Q27 -> 0 | BA27: =Allocations!AJ27*$Q27 -> 0 | BB27: =Allocations!AK27*$Q27 -> 0 | BC27: =SUM(U27:BB27) -> 0 | BD27: =Q27-BC27 -> 0 | BE27: =B27 -> Counts, Monique Lamae
A28: =Allocations!A28 -> 22 | B28: =Allocations!B28 -> DANCE-WILSON, Heather | C28: =Allocations!C28 -> Abbott | D28: =Allocations!#REF! -> #REF! | E28: 1635.77 | F28: 1635.77 | G28: 1635.77 | H28: 1635.77 | I28: 1635.77 | J28: 1635.77 | K28: 1635.77 | L28: 1635.77 | M28: 1635.77 | N28: 1635.77 | O28: 1608.63 | P28: 1608.63 | Q28: =SUM(E28:J28) -> 9814.62 | R28: =E28 -> 1635.77 | S28: =R28/Q28 -> 0.16666667 | T28: 0 | U28: =Allocations!E28*$Q28 -> 0 | V28: =Allocations!F28*$Q28 -> 7557.2574 | W28: =Allocations!G28*$Q28 -> 0 | X28: =Allocations!H28*$Q28 -> 2257.3626 | Y28: =Allocations!I28*$Q28 -> 0 | Z28: =Allocations!J28*$Q28 -> 0 | AA28: =Allocations!K28*$Q28 -> 0 | AB28: =Allocations!L28*$Q28 -> 0 | ... AV28: =Allocations!AF28*$Q28 -> 0 | AW28: =Allocations!AF28*$Q28 -> 0 | AX28: =Allocations!AG28*$Q28 -> 0 | AY28: =Allocations!AH28*$Q28 -> 0 | AZ28: =Allocations!AI28*$Q28 -> 0 | BA28: =Allocations!AJ28*$Q28 -> 0 | BB28: =Allocations!AK28*$Q28 -> 0 | BC28: =SUM(U28:BB28) -> 9814.62 | BD28: =Q28-BC28 -> 0 | BE28: =B28 -> DANCE-WILSON, Heather
A29: =Allocations!A29 -> 23 | B29: =Allocations!B29 -> DANIELS-CRAFTON, Glenda | C29: =Allocations!C29 -> EHS | E29: 2200.98 | F29: 2200.98 | G29: 2200.98 | H29: 2200.98 | I29: 2200.98 | J29: 2200.98 | K29: 2200.98 | L29: 2200.98 | M29: 2200.98 | Q29: =SUM(E29:J29) -> 13205.88 | R29: =E29 -> 2200.98 | U29: =Allocations!E29*$Q29 -> 0 | V29: =Allocations!F29*$Q29 -> 0 | W29: =Allocations!G29*$Q29 -> 0 | X29: =Allocations!H29*$Q29 -> 0 | Y29: =Allocations!I29*$Q29 -> 0 | Z29: =Allocations!J29*$Q29 -> 13205.88 | AA29: =Allocations!K29*$Q29 -> 0 | AB29: =Allocations!L29*$Q29 -> 0 | ... AV29: =Allocations!AF29*$Q29 -> 0 | AW29: =Allocations!AF29*$Q29 -> 0 | AX29: =Allocations!AG29*$Q29 -> 0 | AY29: =Allocations!AH29*$Q29 -> 0 | AZ29: =Allocations!AI29*$Q29 -> 0 | BA29: =Allocations!AJ29*$Q29 -> 0 | BB29: =Allocations!AK29*$Q29 -> 0 | BC29: =SUM(U29:BB29) -> 13205.88 | BD29: =Q29-BC29 -> 0 | BE29: =B29 -> DANIELS-CRAFTON, Glenda
A30: =Allocations!A30 -> 24 | B30: =Allocations!B30 -> ELLIS, Joseph | C30: =Allocations!C30 -> OICA | Q30: =SUM(E30:J30) -> 0 | R30: =E30 -> 0 | U30: =Allocations!E30*$Q30 -> 0 | V30: =Allocations!F30*$Q30 -> 0 | W30: =Allocations!G30*$Q30 -> 0 | X30: =Allocations!H30*$Q30 -> 0 | Y30: =Allocations!I30*$Q30 -> 0 | Z30: =Allocations!J30*$Q30 -> 0 | AA30: =Allocations!K30*$Q30 -> 0 | AB30: =Allocations!L30*$Q30 -> 0 | ... AV30: =Allocations!AF30*$Q30 -> 0 | AW30: =Allocations!AF30*$Q30 -> 0 | AX30: =Allocations!AG30*$Q30 -> 0 | AY30: =Allocations!AH30*$Q30 -> 0 | AZ30: =Allocations!AI30*$Q30 -> 0 | BA30: =Allocations!AJ30*$Q30 -> 0 | BB30: =Allocations!AK30*$Q30 -> 0 | BC30: =SUM(U30:BB30) -> 0 | BD30: =Q30-BC30 -> 0 | BE30: =B30 -> ELLIS, Joseph
