Workbook

Sheet Nov 2019 Alloc 
B1: November Cost Allocations | M1: 7251 | N1: 7252 | O1: 7253 | P1: 7254 | Q1: 7260.1 | R1: 8140 | S1: 7515.5 | T1: 7521 | U1: 7521 | V1: 8112 | W1: 8135.5 | X1: 8191 | Y1: 8210.5 | Z1: 8229.1 | AA1: 8239 | AB1: 8265 | AC1: 8266 | AF1: 7248
M2: FICA | N2: MEDI | O2: SUI | P2: Disability | Q2: Payroll Fees | R2: Postage | S2: IT Consultants | T2: Audit Fees | U2: Acctg Fees | V2: Supplies | W2: Telephone | X2: Web Hosting | Y2: Utilities | Z2: Eq Lease | AA2: Repairs | AB2: Mortgage Int | AC2: Gen Insur | AF2: W/ Comp
M3: =M46 -> 10024 | N3: =N46 -> 2446 | O3: =O46 -> 2449 | P3: =P46 -> 481 | Q3: =Q46 -> 1981 | S3: 3006 | T3: 6000 | U3: =10655-6000 -> 4655 | V3: 2022 | W3: 733 | X3: 312 | Y3: 1261 | Z3: 2637 | AA3: 765 | AB3: 1985 | AC3: 4654 | AF3: 6787
G4: headcount | M4: 1 | N4: 2 | O4: 3 | P4: 4 | Q4: 5 | R4: 6 | S4: 7 | T4: 8 | U4: 8 | V4: 9 | W4: 10 | X4: 11 | Y4: 12 | Z4: 13 | AA4: 14 | AB4: 15 | AC4: 15 | AF4: 0.04
D5: 7222 | E5: Taxes | F5: W/C | J5: Taxes | K5: Salary | L5: Headcount
B6: 41 | C6: Thriftworks | H6: 0 | J6: =H6/$I$35 -> 0 | K6: =H6/$I$37 -> 0 | L6: =G6/$G$38 -> 0 | M6: =J6*$M$3 -> 0 | N6: =J6*$N$3 -> 0 | O6: =J6*$O$3 -> 0 | P6: =J6*$P$3 -> 0 | Q6: =K6*$Q$3 -> 0 | R6: =K6*$R$3 -> 0 | S6: =K6*$S$3 -> 0 | T6: =K6*$T$3 -> 0 | U6: =K6*$U$3 -> 0 | V6: =K6*$V$3 -> 0 | W6: =K6*$W$3 -> 0 | X6: =K6*$X$3 -> 0 | Y6: =K6*$Y$3 -> 0 | Z6: =K6*$Z$3 -> 0 | AA6: =K6*$AA$3 -> 0 | AB6: =J6*$AB$3 -> 0 | AC6: =K6*$AC$3 -> 0 | AE6: =H6/$H$39 -> 0 | AF6: =AE6*$AF$3 -> 0
B7: 111 | C7: Abbott | G7: 8 | H7: 46682 | J7: =H7/$I$35 -> 0.26998327 | K7: =H7/$I$37 -> 0.24606292 | L7: =G7/$G$38 -> 0.22857143 | M7: =J7*$M$3 -> 2706.3123 | N7: =J7*$N$3 -> 660.37908 | O7: =J7*$O$3 -> 661.18903 | P7: =J7*$P$3 -> 129.86195 | Q7: =K7*$Q$3 -> 487.45065 | R7: =K7*$R$3 -> 0 | S7: =K7*$S$3 -> 739.66515 | T7: =K7*$T$3 -> 1476.3775 | U7: =K7*$U$3 -> 1145.4229 | V7: =K7*$V$3 -> 497.53923 | W7: =K7*$W$3 -> 180.36412 | X7: =K7*$X$3 -> 76.771633 | Y7: =K7*$Y$3 -> 310.28535 | Z7: =K7*$Z$3 -> 648.86793 | AA7: =K7*$AA$3 -> 188.23814 | AB7: =J7*$AB$3 -> 535.91679 | AC7: =K7*$AC$3 -> 1145.1769 | AE7: =H7/$H$39 -> 0.16288621 | AF7: =AE7*$AF$3 -> 1105.5087
B8: 111B | C8: Abbott Fees | G8: 1 | H8: 2588 | J8: =H8/$I$35 -> 0.014967583 | K8: =H8/$I$37 -> 0.013641465 | L8: =G8/$G$38 -> 0.028571429 | M8: =J8*$M$3 -> 150.03505 | N8: =J8*$N$3 -> 36.610708 | O8: =J8*$O$3 -> 36.65561 | P8: =J8*$P$3 -> 7.1994074 | Q8: =K8*$Q$3 -> 27.023741 | R8: =K8*$R$3 -> 0 | S8: =K8*$S$3 -> 41.006242 | T8: =K8*$T$3 -> 81.848787 | U8: =K8*$U$3 -> 63.501018 | V8: =K8*$V$3 -> 27.583041 | W8: =K8*$W$3 -> 9.9991935 | X8: =K8*$X$3 -> 4.2561369 | Y8: =K8*$Y$3 -> 17.201887 | Z8: =K8*$Z$3 -> 35.972542 | AA8: =K8*$AA$3 -> 10.43572 | AB8: =J8*$AB$3 -> 29.710652 | AC8: =K8*$AC$3 -> 63.487376 | AE8: =H8/$H$39 -> 0.009030237 | AF8: =AE8*$AF$3 -> 61.288218
B9: 111A | C9: Abbott - Other | G9: 1 | H9: 3654 | J9: =H9/$I$35 -> 0.021132746 | K9: =H9/$I$37 -> 0.019260399 | L9: =G9/$G$38 -> 0.028571429 | M9: =J9*$M$3 -> 211.83465 | N9: =J9*$N$3 -> 51.690698 | O9: =J9*$O$3 -> 51.754096 | P9: =J9*$P$3 -> 10.164851 | Q9: =K9*$Q$3 -> 38.15485 | R9: =K9*$R$3 -> 0 | S9: =K9*$S$3 -> 57.896758 | T9: =K9*$T$3 -> 115.56239 | U9: =K9*$U$3 -> 89.657155 | V9: =K9*$V$3 -> 38.944526 | W9: =K9*$W$3 -> 14.117872 | X9: =K9*$X$3 -> 6.0092444 | Y9: =K9*$Y$3 -> 24.287363 | Z9: =K9*$Z$3 -> 50.789671 | AA9: =K9*$AA$3 -> 14.734205 | AB9: =J9*$AB$3 -> 41.948502 | AC9: =K9*$AC$3 -> 89.637895 | AE9: =H9/$H$39 -> 0.012749801 | AF9: =AE9*$AF$3 -> 86.532902
B10: 111F | C10: Abbott Food | G10: 0 | H10: 358 | J10: =H10/$I$35 -> 0.0020704771 | K10: =H10/$I$37 -> 0.0018870341 | L10: =G10/$G$38 -> 0 | M10: =J10*$M$3 -> 20.754462 | N10: =J10*$N$3 -> 5.0643869 | O10: =J10*$O$3 -> 5.0705984 | P10: =J10*$P$3 -> 0.99589947 | Q10: =K10*$Q$3 -> 3.7382146 | R10: =K10*$R$3 -> 0 | S10: =K10*$S$3 -> 5.6724246 | T10: =K10*$T$3 -> 11.322205 | U10: =K10*$U$3 -> 8.7841439 | V10: =K10*$V$3 -> 3.815583 | W10: =K10*$W$3 -> 1.383196 | X10: =K10*$X$3 -> 0.58875465 | Y10: =K10*$Y$3 -> 2.37955 | Z10: =K10*$Z$3 -> 4.976109 | AA10: =K10*$AA$3 -> 1.4435811 | AB10: =J10*$AB$3 -> 4.109897 | AC10: =K10*$AC$3 -> 8.7822568 | AE10: =H10/$H$39 -> 0.0012491595 | AF10: =AE10*$AF$3 -> 8.4780457
B11: 112 | C11: EHS | G11: 1 | H11: 7522 | J11: =H11/$I$35 -> 0.043503152 | K11: =H11/$I$37 -> 0.039648801 | L11: =G11/$G$38 -> 0.028571429 | M11: =J11*$M$3 -> 436.0756 | N11: =J11*$N$3 -> 106.40871 | O11: =J11*$O$3 -> 106.53922 | P11: =J11*$P$3 -> 20.925016 | Q11: =K11*$Q$3 -> 78.544274 | R11: =K11*$R$3 -> 0 | S11: =K11*$S$3 -> 119.1843 | T11: =K11*$T$3 -> 237.8928 | U11: =K11*$U$3 -> 184.56517 | V11: =K11*$V$3 -> 80.169875 | W11: =K11*$W$3 -> 29.062571 | X11: =K11*$X$3 -> 12.370426 | Y11: =K11*$Y$3 -> 49.997138 | Z11: =K11*$Z$3 -> 104.55389 | AA11: =K11*$AA$3 -> 30.331333 | AB11: =J11*$AB$3 -> 86.353757 | AC11: =K11*$AC$3 -> 184.52552 | AE11: =H11/$H$39 -> 0.026246307 | AF11: =AE11*$AF$3 -> 178.13369
B12: 114 | C12: Summer Camp | H12: 0 | J12: =H12/$I$35 -> 0 | K12: =H12/$I$37 -> 0 | L12: =G12/$G$38 -> 0 | M12: =J12*$M$3 -> 0 | N12: =J12*$N$3 -> 0 | O12: =J12*$O$3 -> 0 | P12: =J12*$P$3 -> 0 | Q12: =K12*$Q$3 -> 0 | R12: =K12*$R$3 -> 0 | S12: =K12*$S$3 -> 0 | T12: =K12*$T$3 -> 0 | U12: =K12*$U$3 -> 0 | V12: =K12*$V$3 -> 0 | W12: =K12*$W$3 -> 0 | X12: =K12*$X$3 -> 0 | Y12: =K12*$Y$3 -> 0 | Z12: =K12*$Z$3 -> 0 | AA12: =K12*$AA$3 -> 0 | AB12: =J12*$AB$3 -> 0 | AC12: =K12*$AC$3 -> 0 | AE12: =H12/$H$39 -> 0 | AF12: =AE12*$AF$3 -> 0
B13: 222 | C13: DCF- Coding | G13: 0.5 | H13: 5481 | J13: =H13/$I$35 -> 0.03169912 | K13: =H13/$I$37 -> 0.028890598 | L13: =G13/$G$38 -> 0.014285714 | M13: =J13*$M$3 -> 317.75198 | N13: =J13*$N$3 -> 77.536047 | O13: =J13*$O$3 -> 77.631144 | P13: =J13*$P$3 -> 15.247277 | Q13: =K13*$Q$3 -> 57.232274 | R13: =K13*$R$3 -> 0 | S13: =K13*$S$3 -> 86.845137 | T13: =K13*$T$3 -> 173.34359 | U13: =K13*$U$3 -> 134.48573 | V13: =K13*$V$3 -> 58.416789 | W13: =K13*$W$3 -> 21.176808 | X13: =K13*$X$3 -> 9.0138665 | Y13: =K13*$Y$3 -> 36.431044 | Z13: =K13*$Z$3 -> 76.184507 | AA13: =K13*$AA$3 -> 22.101307 | AB13: =J13*$AB$3 -> 62.922753 | AC13: =K13*$AC$3 -> 134.45684 | AE13: =H13/$H$39 -> 0.019124702 | AF13: =AE13*$AF$3 -> 129.79935
B14: 223 | C14: OICA | H14: 0 | J14: =H14/$I$35 -> 0 | K14: =H14/$I$37 -> 0 | L14: =G14/$G$38 -> 0 | M14: =J14*$M$3 -> 0 | N14: =J14*$N$3 -> 0 | O14: =J14*$O$3 -> 0 | P14: =J14*$P$3 -> 0 | Q14: =K14*$Q$3 -> 0 | R14: =K14*$R$3 -> 0 | S14: =K14*$S$3 -> 0 | T14: =K14*$T$3 -> 0 | U14: =K14*$U$3 -> 0 | V14: =K14*$V$3 -> 0 | W14: =K14*$W$3 -> 0 | X14: =K14*$X$3 -> 0 | Y14: =K14*$Y$3 -> 0 | Z14: =K14*$Z$3 -> 0 | AA14: =K14*$AA$3 -> 0 | AB14: =J14*$AB$3 -> 0 | AC14: =K14*$AC$3 -> 0 | AE14: =H14/$H$39 -> 0 | AF14: =AE14*$AF$3 -> 0
B15: 334 | C15: NRTC - Admin | H15: 0 | J15: =H15/$I$35 -> 0 | K15: =H15/$I$37 -> 0 | L15: =G15/$G$38 -> 0 | M15: =J15*$M$3 -> 0 | N15: =J15*$N$3 -> 0 | O15: =J15*$O$3 -> 0 | P15: =J15*$P$3 -> 0 | Q15: =K15*$Q$3 -> 0 | R15: =K15*$R$3 -> 0 | S15: =K15*$S$3 -> 0 | T15: =K15*$T$3 -> 0 | U15: =K15*$U$3 -> 0 | V15: =K15*$V$3 -> 0 | W15: =K15*$W$3 -> 0 | X15: =K15*$X$3 -> 0 | Y15: =K15*$Y$3 -> 0 | Z15: =K15*$Z$3 -> 0 | AA15: =K15*$AA$3 -> 0 | AB15: =J15*$AB$3 -> 0 | AC15: =K15*$AC$3 -> 0 | AE15: =H15/$H$39 -> 0 | AF15: =AE15*$AF$3 -> 0
B16: 334H | C16: NRTC - Housing | G16: 0.5 | H16: 1725 | J16: =H16/$I$35 -> 0.0099764608 | K16: =H16/$I$37 -> 0.0090925527 | L16: =G16/$G$38 -> 0.014285714 | M16: =J16*$M$3 -> 100.00404 | N16: =J16*$N$3 -> 24.402423 | O16: =J16*$O$3 -> 24.432352 | P16: =J16*$P$3 -> 4.7986776 | Q16: =K16*$Q$3 -> 18.012347 | R16: =K16*$R$3 -> 0 | S16: =K16*$S$3 -> 27.332213 | T16: =K16*$T$3 -> 54.555316 | U16: =K16*$U$3 -> 42.325833 | V16: =K16*$V$3 -> 18.385142 | W16: =K16*$W$3 -> 6.6648411 | X16: =K16*$X$3 -> 2.8368764 | Y16: =K16*$Y$3 -> 11.465709 | Z16: =K16*$Z$3 -> 23.977061 | AA16: =K16*$AA$3 -> 6.9558028 | AB16: =J16*$AB$3 -> 19.803275 | AC16: =K16*$AC$3 -> 42.31674 | AE16: =H16/$H$39 -> 0.0060189949 | AF16: =AE16*$AF$3 -> 40.850918
B17: 334F | C17: NRTC FOC | H17: 0 | J17: =H17/$I$35 -> 0 | K17: =H17/$I$37 -> 0 | L17: =G17/$G$38 -> 0 | M17: =J17*$M$3 -> 0 | N17: =J17*$N$3 -> 0 | O17: =J17*$O$3 -> 0 | P17: =J17*$P$3 -> 0 | Q17: =K17*$Q$3 -> 0 | R17: =K17*$R$3 -> 0 | S17: =K17*$S$3 -> 0 | T17: =K17*$T$3 -> 0 | U17: =K17*$U$3 -> 0 | V17: =K17*$V$3 -> 0 | W17: =K17*$W$3 -> 0 | X17: =K17*$X$3 -> 0 | Y17: =K17*$Y$3 -> 0 | Z17: =K17*$Z$3 -> 0 | AA17: =K17*$AA$3 -> 0 | AB17: =J17*$AB$3 -> 0 | AC17: =K17*$AC$3 -> 0 | AE17: =H17/$H$39 -> 0 | AF17: =AE17*$AF$3 -> 0
B18: 335 | C18: NRTC 19 | G18: 0.5 | H18: 1269 | J18: =H18/$I$35 -> 0.007339205 | K18: =H18/$I$37 -> 0.0066889562 | L18: =G18/$G$38 -> 0.014285714 | M18: =J18*$M$3 -> 73.568191 | N18: =J18*$N$3 -> 17.951696 | O18: =J18*$O$3 -> 17.973713 | P18: =J18*$P$3 -> 3.5301576 | Q18: =K18*$Q$3 -> 13.250822 | R18: =K18*$R$3 -> 0 | S18: =K18*$S$3 -> 20.107002 | T18: =K18*$T$3 -> 40.133737 | U18: =K18*$U$3 -> 31.137091 | V18: =K18*$V$3 -> 13.525069 | W18: =K18*$W$3 -> 4.9030049 | X18: =K18*$X$3 -> 2.0869543 | Y18: =K18*$Y$3 -> 8.4347737 | Z18: =K18*$Z$3 -> 17.638777 | AA18: =K18*$AA$3 -> 5.1170515 | AB18: =J18*$AB$3 -> 14.568322 | AC18: =K18*$AC$3 -> 31.130402 | AE18: =H18/$H$39 -> 0.0044278867 | AF18: =AE18*$AF$3 -> 30.052067
B19: 368 | C19: Wells Fargo | G19: 1.5 | H19: 9028 | J19: =H19/$I$35 -> 0.052213036 | K19: =H19/$I$37 -> 0.047586995 | L19: =G19/$G$38 -> 0.042857143 | M19: =J19*$M$3 -> 523.38348 | N19: =J19*$N$3 -> 127.71309 | O19: =J19*$O$3 -> 127.86973 | P19: =J19*$P$3 -> 25.11447 | Q19: =K19*$Q$3 -> 94.269836 | R19: =K19*$R$3 -> 0 | S19: =K19*$S$3 -> 143.04651 | T19: =K19*$T$3 -> 285.52197 | U19: =K19*$U$3 -> 221.51746 | V19: =K19*$V$3 -> 96.220903 | W19: =K19*$W$3 -> 34.881267 | X19: =K19*$X$3 -> 14.847142 | Y19: =K19*$Y$3 -> 60.0072 | Z19: =K19*$Z$3 -> 125.4869 | AA19: =K19*$AA$3 -> 36.404051 | AB19: =J19*$AB$3 -> 103.64288 | AC19: =K19*$AC$3 -> 221.46987 | AE19: =H19/$H$39 -> 0.031501151 | AF19: =AE19*$AF$3 -> 213.79831
B20: 451 | C20: USJP | G20: 5.5 | H20: 24343 | J20: =H20/$I$35 -> 0.14078666 | K20: =H20/$I$37 -> 0.12831305 | L20: =G20/$G$38 -> 0.15714286 | M20: =J20*$M$3 -> 1411.2455 | N20: =J20*$N$3 -> 344.36416 | O20: =J20*$O$3 -> 344.78652 | P20: =J20*$P$3 -> 67.718382 | Q20: =K20*$Q$3 -> 254.18815 | R20: =K20*$R$3 -> 0 | S20: =K20*$S$3 -> 385.70903 | T20: =K20*$T$3 -> 769.8783 | U20: =K20*$U$3 -> 597.29725 | V20: =K20*$V$3 -> 259.44899 | W20: =K20*$W$3 -> 94.053465 | X20: =K20*$X$3 -> 40.033671 | Y20: =K20*$Y$3 -> 161.80276 | Z20: =K20*$Z$3 -> 338.36151 | AA20: =K20*$AA$3 -> 98.159483 | AB20: =J20*$AB$3 -> 279.46152 | AC20: =K20*$AC$3 -> 597.16893 | AE20: =H20/$H$39 -> 0.084939358 | AF20: =AE20*$AF$3 -> 576.48342
B21: 452 | C21: PACE | G21: 2 | H21: 3660 | J21: =H21/$I$35 -> 0.021167447 | K21: =H21/$I$37 -> 0.019292025 | L21: =G21/$G$38 -> 0.057142857 | M21: =J21*$M$3 -> 212.18249 | N21: =J21*$N$3 -> 51.775576 | O21: =J21*$O$3 -> 51.839078 | P21: =J21*$P$3 -> 10.181542 | Q21: =K21*$Q$3 -> 38.217501 | R21: =K21*$R$3 -> 0 | S21: =K21*$S$3 -> 57.991827 | T21: =K21*$T$3 -> 115.75215 | U21: =K21*$U$3 -> 89.804376 | V21: =K21*$V$3 -> 39.008474 | W21: =K21*$W$3 -> 14.141054 | X21: =K21*$X$3 -> 6.0191118 | Y21: =K21*$Y$3 -> 24.327243 | Z21: =K21*$Z$3 -> 50.87307 | AA21: =K21*$AA$3 -> 14.758399 | AB21: =J21*$AB$3 -> 42.017383 | AC21: =K21*$AC$3 -> 89.785084 | AE21: =H21/$H$39 -> 0.012770737 | AF21: =AE21*$AF$3 -> 86.674992
B22: 454 | C22: Prudential #1 Workforce | K22: =H22/$I$37 -> 0 | L22: =G22/$G$38 -> 0 | Q22: =K22*$Q$3 -> 0 | R22: =K22*$R$3 -> 0 | S22: =K22*$S$3 -> 0 | T22: =K22*$T$3 -> 0 | U22: =K22*$U$3 -> 0 | V22: =K22*$V$3 -> 0 | W22: =K22*$W$3 -> 0 | X22: =K22*$X$3 -> 0 | Y22: =K22*$Y$3 -> 0 | Z22: =K22*$Z$3 -> 0 | AA22: =K22*$AA$3 -> 0 | AB22: =J22*$AB$3 -> 0 | AC22: =K22*$AC$3 -> 0
B23: 467 | C23: WF - United Airlines | G23: 2 | H23: 10250 | J23: =H23/$I$35 -> 0.059280419 | K23: =H23/$I$37 -> 0.054028212 | L23: =G23/$G$38 -> 0.057142857 | M23: =J23*$M$3 -> 594.22692 | N23: =J23*$N$3 -> 144.9999 | O23: =J23*$O$3 -> 145.17775 | P23: =J23*$P$3 -> 28.513882 | Q23: =K23*$Q$3 -> 107.02989 | R23: =K23*$R$3 -> 0 | S23: =K23*$S$3 -> 162.4088 | T23: =K23*$T$3 -> 324.16927 | U23: =K23*$U$3 -> 251.50133 | V23: =K23*$V$3 -> 109.24504 | W23: =K23*$W$3 -> 39.602679 | X23: =K23*$X$3 -> 16.856802 | Y23: =K23*$Y$3 -> 68.129575 | Z23: =K23*$Z$3 -> 142.47239 | AA23: =K23*$AA$3 -> 41.331582 | AB23: =J23*$AB$3 -> 117.67163 | AC23: =K23*$AC$3 -> 251.4473 | AE23: =H23/$H$39 -> 0.035765042 | AF23: =AE23*$AF$3 -> 242.73734
B24: 468 | C24: Newark Alliance | G24: 1 | H24: 9462 | J24: =H24/$I$35 -> 0.054723056 | K24: =H24/$I$37 -> 0.049874628 | L24: =G24/$G$38 -> 0.028571429 | M24: =J24*$M$3 -> 548.54391 | N24: =J24*$N$3 -> 133.8526 | O24: =J24*$O$3 -> 134.01676 | P24: =J24*$P$3 -> 26.32179 | Q24: =K24*$Q$3 -> 98.801638 | R24: =K24*$R$3 -> 0 | S24: =K24*$S$3 -> 149.92313 | T24: =K24*$T$3 -> 299.24777 | U24: =K24*$U$3 -> 232.16639 | V24: =K24*$V$3 -> 100.8465 | W24: =K24*$W$3 -> 36.558102 | X24: =K24*$X$3 -> 15.560884 | Y24: =K24*$Y$3 -> 62.891906 | Z24: =K24*$Z$3 -> 131.51939 | AA24: =K24*$AA$3 -> 38.154091 | AB24: =J24*$AB$3 -> 108.62527 | AC24: =K24*$AC$3 -> 232.11652 | AE24: =H24/$H$39 -> 0.033015496 | AF24: =AE24*$AF$3 -> 224.07617
B25: 502 | C25: ESG | G25: 1.5 | H25: 2518 | J25: =H25/$I$35 -> 0.014562741 | K25: =H25/$I$37 -> 0.013272491 | L25: =G25/$G$38 -> 0.042857143 | M25: =J25*$M$3 -> 145.97692 | N25: =J25*$N$3 -> 35.620464 | O25: =J25*$O$3 -> 35.664153 | P25: =J25*$P$3 -> 7.0046784 | Q25: =K25*$Q$3 -> 26.292805 | R25: =K25*$R$3 -> 0 | S25: =K25*$S$3 -> 39.897109 | T25: =K25*$T$3 -> 79.634949 | U25: =K25*$U$3 -> 61.783448 | V25: =K25*$V$3 -> 26.836978 | W25: =K25*$W$3 -> 9.7287362 | X25: =K25*$X$3 -> 4.1410173 | Y25: =K25*$Y$3 -> 16.736612 | Z25: =K25*$Z$3 -> 34.99956 | AA25: =K25*$AA$3 -> 10.153456 | AB25: =J25*$AB$3 -> 28.907041 | AC25: =K25*$AC$3 -> 61.770175 | AE25: =H25/$H$39 -> 0.0087859879 | AF25: =AE25*$AF$3 -> 59.6305
B26: 515 | C26: FOC - HUD NUL PARS | G26: 1.5 | H26: 2596 | J26: =H26/$I$35 -> 0.015013851 | K26: =H26/$I$37 -> 0.013683633 | L26: =G26/$G$38 -> 0.042857143 | M26: =J26*$M$3 -> 150.49884 | N26: =J26*$N$3 -> 36.723878 | O26: =J26*$O$3 -> 36.76892 | P26: =J26*$P$3 -> 7.2216621 | Q26: =K26*$Q$3 -> 27.107277 | R26: =K26*$R$3 -> 0 | S26: =K26*$S$3 -> 41.133001 | T26: =K26*$T$3 -> 82.101798 | U26: =K26*$U$3 -> 63.697311 | V26: =K26*$V$3 -> 27.668306 | W26: =K26*$W$3 -> 10.030103 | X26: =K26*$X$3 -> 4.2692935 | Y26: =K26*$Y$3 -> 17.255061 | Z26: =K26*$Z$3 -> 36.08374 | AA26: =K26*$AA$3 -> 10.467979 | AB26: =J26*$AB$3 -> 29.802493 | AC26: =K26*$AC$3 -> 63.683628 | AE26: =H26/$H$39 -> 0.0090581512 | AF26: =AE26*$AF$3 -> 61.477672
B27: 525 | C27: CDBG - Housing | G27: 1 | H27: 4350 | J27: =H27/$I$35 -> 0.025158031 | K27: =H27/$I$37 -> 0.022929046 | L27: =G27/$G$38 -> 0.028571429 | M27: =J27*$M$3 -> 252.18411 | N27: =J27*$N$3 -> 61.536545 | O27: =J27*$O$3 -> 61.612019 | P27: =J27*$P$3 -> 12.101013 | Q27: =K27*$Q$3 -> 45.42244 | R27: =K27*$R$3 -> 0 | S27: =K27*$S$3 -> 68.924712 | T27: =K27*$T$3 -> 137.57428 | U27: =K27*$U$3 -> 106.73471 | V27: =K27*$V$3 -> 46.362531 | W27: =K27*$W$3 -> 16.806991 | X27: =K27*$X$3 -> 7.1538623 | Y27: =K27*$Y$3 -> 28.913527 | Z27: =K27*$Z$3 -> 60.463894 | AA27: =K27*$AA$3 -> 17.54072 | AB27: =J27*$AB$3 -> 49.938692 | AC27: =K27*$AC$3 -> 106.71178 | AE27: =H27/$H$39 -> 0.015178335 | AF27: =AE27*$AF$3 -> 103.01536
B28: 560 | C28: CAP 1 - Save Up | H28: 0 | J28: =H28/$I$35 -> 0 | K28: =H28/$I$37 -> 0 | L28: =G28/$G$38 -> 0 | M28: =J28*$M$3 -> 0 | N28: =J28*$N$3 -> 0 | O28: =J28*$O$3 -> 0 | P28: =J28*$P$3 -> 0 | Q28: =K28*$Q$3 -> 0 | R28: =K28*$R$3 -> 0 | S28: =K28*$S$3 -> 0 | T28: =K28*$T$3 -> 0 | U28: =K28*$U$3 -> 0 | V28: =K28*$V$3 -> 0 | W28: =K28*$W$3 -> 0 | X28: =K28*$X$3 -> 0 | Y28: =K28*$Y$3 -> 0 | Z28: =K28*$Z$3 -> 0 | AA28: =K28*$AA$3 -> 0 | AB28: =J28*$AB$3 -> 0 | AC28: =K28*$AC$3 -> 0 | AE28: =H28/$H$39 -> 0 | AF28: =AE28*$AF$3 -> 0
B29: 561 | C29: LISC FOC 2019 | G29: 1 | H29: 6577 | J29: =H29/$I$35 -> 0.038037787 | K29: =H29/$I$37 -> 0.034667663 | L29: =G29/$G$38 -> 0.028571429 | M29: =J29*$M$3 -> 381.29078 | N29: =J29*$N$3 -> 93.040427 | O29: =J29*$O$3 -> 93.15454 | P29: =J29*$P$3 -> 18.296175 | Q29: =K29*$Q$3 -> 68.676641 | R29: =K29*$R$3 -> 0 | S29: =K29*$S$3 -> 104.211 | T29: =K29*$T$3 -> 208.00598 | U29: =K29*$U$3 -> 161.37797 | V29: =K29*$V$3 -> 70.098015 | W29: =K29*$W$3 -> 25.411397 | X29: =K29*$X$3 -> 10.816311 | Y29: =K29*$Y$3 -> 43.715923 | Z29: =K29*$Z$3 -> 91.418628 | AA29: =K29*$AA$3 -> 26.520762 | AB29: =J29*$AB$3 -> 75.505007 | AC29: =K29*$AC$3 -> 161.3433 | AE29: =H29/$H$39 -> 0.022948945 | AF29: =AE29*$AF$3 -> 155.75449
B30: 563 | C30: Prudential #1 FOC | G30: 1 | H30: 4490 | J30: =H30/$I$35 -> 0.025967715 | K30: =H30/$I$37 -> 0.023666992 | L30: =G30/$G$38 -> 0.028571429 | M30: =J30*$M$3 -> 260.30038 | N30: =J30*$N$3 -> 63.517031 | O30: =J30*$O$3 -> 63.594935 | P30: =J30*$P$3 -> 12.490471 | Q30: =K30*$Q$3 -> 46.884312 | R30: =K30*$R$3 -> 0 | S30: =K30*$S$3 -> 71.142979 | T30: =K30*$T$3 -> 142.00195 | U30: =K30*$U$3 -> 110.16985 | V30: =K30*$V$3 -> 47.854658 | W30: =K30*$W$3 -> 17.347905 | X30: =K30*$X$3 -> 7.3841016 | Y30: =K30*$Y$3 -> 29.844077 | Z30: =K30*$Z$3 -> 62.409859 | AA30: =K30*$AA$3 -> 18.105249 | AB30: =J30*$AB$3 -> 51.545915 | AC30: =K30*$AC$3 -> 110.14618 | AE30: =H30/$H$39 -> 0.015666833 | AF30: =AE30*$AF$3 -> 106.3308
B31: 610 | C31: CEO | G31: 1 | H31: 17885 | J31: =H31/$I$35 -> 0.1034371 | K31: =H31/$I$37 -> 0.094272641 | L31: =G31/$G$38 -> 0.028571429 | M31: =J31*$M$3 -> 1036.8535 | N31: =J31*$N$3 -> 253.00715 | O31: =J31*$O$3 -> 253.31746 | P31: =J31*$P$3 -> 49.753246 | Q31: =K31*$Q$3 -> 186.7541 | R31: =K31*$R$3 -> 0 | S31: =K31*$S$3 -> 283.38356 | T31: =K31*$T$3 -> 565.63584 | U31: =K31*$U$3 -> 438.83914 | V31: =K31*$V$3 -> 190.61928 | W31: =K31*$W$3 -> 69.101846 | X31: =K31*$X$3 -> 29.413064 | Y31: =K31*$Y$3 -> 118.8778 | Z31: =K31*$Z$3 -> 248.59695 | AA31: =K31*$AA$3 -> 72.11857 | AB31: =J31*$AB$3 -> 205.32265 | AC31: =K31*$AC$3 -> 438.74487 | AE31: =H31/$H$39 -> 0.062405637 | AF31: =AE31*$AF$3 -> 423.54706
B32: 620 | C32: CFO | G32: 1 | H32: 8020 | J32: =H32/$I$35 -> 0.046383313 | K32: =H32/$I$37 -> 0.042273781 | L32: =G32/$G$38 -> 0.028571429 | M32: =J32*$M$3 -> 464.94633 | N32: =J32*$N$3 -> 113.45358 | O32: =J32*$O$3 -> 113.59273 | P32: =J32*$P$3 -> 22.310374 | Q32: =K32*$Q$3 -> 83.744361 | R32: =K32*$R$3 -> 0 | S32: =K32*$S$3 -> 127.07499 | T32: =K32*$T$3 -> 253.64269 | U32: =K32*$U$3 -> 196.78445 | V32: =K32*$V$3 -> 85.477586 | W32: =K32*$W$3 -> 30.986682 | X32: =K32*$X$3 -> 13.18942 | Y32: =K32*$Y$3 -> 53.307238 | Z32: =K32*$Z$3 -> 111.47596 | AA32: =K32*$AA$3 -> 32.339443 | AB32: =J32*$AB$3 -> 92.070877 | AC32: =K32*$AC$3 -> 196.74218 | AE32: =H32/$H$39 -> 0.027983965 | AF32: =AE32*$AF$3 -> 189.92717
B33: 630 | C33: COO | G33: 1 | H33: 0 | J33: =H33/$I$35 -> 0 | K33: =H33/$I$37 -> 0 | L33: =G33/$G$38 -> 0.028571429 | M33: =J33*$M$3 -> 0 | N33: =J33*$N$3 -> 0 | O33: =J33*$O$3 -> 0 | P33: =J33*$P$3 -> 0 | Q33: =K33*$Q$3 -> 0 | R33: =K33*$R$3 -> 0 | S33: =K33*$S$3 -> 0 | T33: =K33*$T$3 -> 0 | U33: =K33*$U$3 -> 0 | V33: =K33*$V$3 -> 0 | W33: =K33*$W$3 -> 0 | X33: =K33*$X$3 -> 0 | Y33: =K33*$Y$3 -> 0 | Z33: =K33*$Z$3 -> 0 | AA33: =K33*$AA$3 -> 0 | AB33: =J33*$AB$3 -> 0 | AC33: =K33*$AC$3 -> 0 | AE33: =H33/$H$39 -> 0 | AF33: =AE33*$AF$3 -> 0
B34: 650 | C34: Facilities | H34: 449 | J34: =H34/$I$35 -> 0.0025967715 | K34: =H34/$I$37 -> 0.0023666992 | L34: =G34/$G$38 -> 0 | M34: =J34*$M$3 -> 26.030038 | N34: =J34*$N$3 -> 6.3517031 | O34: =J34*$O$3 -> 6.3594935 | P34: =J34*$P$3 -> 1.2490471 | Q34: =K34*$Q$3 -> 4.6884312 | R34: =K34*$R$3 -> 0 | S34: =K34*$S$3 -> 7.1142979 | T34: =K34*$T$3 -> 14.200195 | U34: =K34*$U$3 -> 11.016985 | V34: =K34*$V$3 -> 4.7854658 | W34: =K34*$W$3 -> 1.7347905 | X34: =K34*$X$3 -> 0.73841016 | Y34: =K34*$Y$3 -> 2.9844077 | Z34: =K34*$Z$3 -> 6.2409859 | AA34: =K34*$AA$3 -> 1.8105249 | AB34: =J34*$AB$3 -> 5.1545915 | AC34: =K34*$AC$3 -> 11.014618 | AE34: =H34/$H$39 -> 0.0015666833 | AF34: =AE34*$AF$3 -> 10.63308
B35: 600 | C35: Admin | H35: 0.01 | I35: =SUM(H6:H35) -> 172907.01 | J35: =H35/$I$35 -> 5.7834555e-08 | K35: =H35/$I$37 -> 5.271045e-08 | L35: =G35/$G$38 -> 0 | M35: =J35*$M$3 -> 0.00057973358 | N35: =J35*$N$3 -> 0.00014146332 | O35: =J35*$O$3 -> 0.00014163683 | P35: =J35*$P$3 -> 2.7818421e-05 | Q35: =K35*$Q$3 -> 0.0001044194 | R35: =K35*$R$3 -> 0 | S35: =K35*$S$3 -> 0.00015844761 | T35: =K35*$T$3 -> 0.0003162627 | U35: =K35*$U$3 -> 0.00024536715 | V35: =K35*$V$3 -> 0.00010658053 | W35: =K35*$W$3 -> 3.863676e-05 | X35: =K35*$X$3 -> 1.6445661e-05 | Y35: =K35*$Y$3 -> 6.6467878e-05 | Z35: =K35*$Z$3 -> 0.00013899746 | AA35: =K35*$AA$3 -> 4.0323495e-05 | AB35: =J35*$AB$3 -> 0.00011480159 | AC35: =K35*$AC$3 -> 0.00024531444 | AE35: =H35/$H$39 -> 3.4892724e-08 | AF35: =AE35*$AF$3 -> 0.00023681692
B36: 339 | C36: Opport Corp | G36: 1.5 | H36: =I56 -> 10470.69 | K36: =H36/$I$37 -> 0.055191479 | L36: =G36/$G$38 -> 0.042857143 | M36: =J36*$M$3 -> 0 | N36: =J36*$N$3 -> 0 | O36: =J36*$O$3 -> 0 | P36: =J36*$P$3 -> 0 | Q36: =K36*$Q$3 -> 109.33432 | R36: =K36*$R$3 -> 0 | S36: =K36*$S$3 -> 165.90558 | T36: =K36*$T$3 -> 331.14887 | U36: =K36*$U$3 -> 256.91633 | V36: =K36*$V$3 -> 111.59717 | W36: =K36*$W$3 -> 40.455354 | X36: =K36*$X$3 -> 17.219741 | Y36: =K36*$Y$3 -> 69.596455 | Z36: =K36*$Z$3 -> 145.53993 | AA36: =K36*$AA$3 -> 42.221481 | AB36: =J36*$AB$3 -> 0 | AC36: =K36*$AC$3 -> 256.86114 | AE36: =H36/$H$39 -> 0.03653509 | AF36: =AE36*$AF$3 -> 247.96365
B37: 225 | C37: AmeriCorp | G37: 0 | H37: =J54 -> 6338 | I37: =I35+H36+H37 -> 189715.7 | K37: =H37/$I$37 -> 0.033407883 | L37: =G37/$G$38 -> 0 | Q37: =K37*$Q$3 -> 66.181017 | R37: =K37*$R$3 -> 0 | S37: =K37*$S$3 -> 100.4241 | T37: =K37*$T$3 -> 200.4473 | U37: =K37*$U$3 -> 155.5137 | V37: =K37*$V$3 -> 67.55074 | W37: =K37*$W$3 -> 24.487979 | X37: =K37*$X$3 -> 10.42326 | Y37: =K37*$Y$3 -> 42.127341 | Z37: =K37*$Z$3 -> 88.096589 | AA37: =K37*$AA$3 -> 25.557031 | AB37: =J37*$AB$3 -> 0 | AC37: =K37*$AC$3 -> 155.48029 | AE37: =H37/$H$39 -> 0.022115009 | AF37: =AE37*$AF$3 -> 150.09456
B38: 451 | C38: USJP - Participants | F38: 96842 | G38: =SUM(G6:G37) -> 35 | H38: 96877 | Q38: =K38*$Q$3 -> 0 | AE38: =H38/$H$39 -> 0.33803024 | AF38: =AE38*$AF$3 -> 2294.2113
H39: =SUM(H6:H38) -> 286592.7 | J39: =SUM(J6:J38) -> 1 | K39: =SUM(K6:K38) -> 1 | L39: =SUM(L6:L38) -> 1 | M39: =SUM(M6:M38) -> 10024 | N39: =SUM(N6:N38) -> 2446 | O39: =SUM(O6:O38) -> 2449 | P39: =SUM(P6:P38) -> 481 | Q39: =SUM(Q6:Q38) -> 1981 | ... AC39: =SUM(AC6:AC38) -> 4654 | AE39: =SUM(AE6:AE38) -> 1 | AF39: =SUM(AF6:AF38) -> 6787
H40: Salary | J40: Hourly | M40: =M3-M39 -> 0 | N40: =N3-N39 -> 0 | O40: =O3-O39 -> 0 | P40: =P3-P39 -> 0 | Q40: =Q3-Q39 -> 0 | R40: =R3-R39 -> 0 | S40: =S3-S39 -> 0 | T40: =T3-T39 -> 0 | ... AA40: =AA3-AA39 -> 0 | AC40: =AC3-AC39 -> 0 | AE40: =AE3-AE39 -> -1 | AF40: =AF3-AF39 -> 0
...

Sheet Oct 2019 Alloc
B1: October Cost Allocations | M1: 7251 | N1: 7252 | O1: 7253 | P1: 7254 | Q1: 7260.1 | R1: 8140 | S1: 7515.5 | T1: 7521 | U1: 8112 | V1: 8135.5 | W1: 8191 | X1: 8210.5 | Y1: 8229.1 | Z1: 8239 | AA1: 8265 | AB1: 8266 | AE1: 7248
M2: FICA | N2: MEDI | O2: SUI | P2: Disability | Q2: Payroll Fees | R2: Postage | S2: IT Consultants | T2: Acctg Fees | U2: Supplies | V2: Telephone | W2: Web Hosting | X2: Utilities | Y2: Eq Lease | Z2: Repairs | AA2: Mortgage Int | AB2: General Insurance | AE2: W/ Comp
M3: 6886 | N3: 1610 | O3: 1649 | P3: 324 | Q3: 1268 | R3: 302 | S3: 3006 | T3: 6125 | U3: 2281 | V3: 1420 | W3: 312 | X3: 1301 | Y3: 2456 | Z3: 1170 | AA3: 1927 | AB3: 4654 | AE3: 6787
G4: headcount | M4: 1 | N4: 2 | O4: 3 | P4: 4 | Q4: 5 | R4: 6 | S4: 7 | T4: 8 | U4: 9 | V4: 10 | W4: 11 | X4: 12 | Y4: 13 | Z4: 14 | AA4: 15 | AB4: 15 | AE4: 0.04
D5: 7222 | E5: Taxes | F5: W/C | J5: Taxes | K5: Salary | L5: Headcount
B6: 41 | C6: Thriftworks | H6: 0 | J6: =H6/$I$35 -> 0 | K6: =H6/$I$37 -> 0 | L6: =G6/$G$38 -> 0 | M6: =J6*$M$3 -> 0 | N6: =J6*$N$3 -> 0 | O6: =J6*$O$3 -> 0 | P6: =J6*$P$3 -> 0 | Q6: =K6*$Q$3 -> 0 | R6: =K6*$R$3 -> 0 | S6: =K6*$S$3 -> 0 | T6: =K6*$T$3 -> 0 | U6: =K6*$U$3 -> 0 | V6: =K6*$V$3 -> 0 | W6: =K6*$W$3 -> 0 | X6: =K6*$X$3 -> 0 | Y6: =K6*$Y$3 -> 0 | Z6: =K6*$Z$3 -> 0 | AA6: =J6*$AA$3 -> 0 | AB6: =K6*$AB$3 -> 0 | AD6: =H6/$H$39 -> 0 | AE6: =AD6*$AE$3 -> 0
B7: 111 | C7: Abbott | G7: 8 | H7: 30054.56 | J7: =H7/$I$35 -> 0.26608178 | K7: =H7/$I$37 -> 0.2400242 | L7: =G7/$G$38 -> 0.22857143 | M7: =J7*$M$3 -> 1832.2392 | N7: =J7*$N$3 -> 428.39167 | O7: =J7*$O$3 -> 438.76886 | P7: =J7*$P$3 -> 86.210498 | Q7: =K7*$Q$3 -> 304.35068 | R7: =K7*$R$3 -> 72.487307 | S7: =K7*$S$3 -> 721.51273 | T7: =K7*$T$3 -> 1470.1482 | U7: =K7*$U$3 -> 547.49519 | V7: =K7*$V$3 -> 340.83436 | W7: =K7*$W$3 -> 74.887549 | X7: =K7*$X$3 -> 312.27148 | Y7: =K7*$Y$3 -> 589.49942 | Z7: =K7*$Z$3 -> 280.82831 | AA7: =J7*$AA$3 -> 512.7396 | AB7: =K7*$AB$3 -> 1117.0726 | AD7: =H7/$H$39 -> 0.13534633 | AE7: =AD7*$AE$3 -> 918.59552
B8: 111B | C8: Abbott Fees | G8: 1 | H8: 3231.11 | J8: =H8/$I$35 -> 0.028605959 | K8: =H8/$I$37 -> 0.025804556 | L8: =G8/$G$38 -> 0.028571429 | M8: =J8*$M$3 -> 196.98063 | N8: =J8*$N$3 -> 46.055594 | O8: =J8*$O$3 -> 47.171226 | P8: =J8*$P$3 -> 9.2683307 | Q8: =K8*$Q$3 -> 32.720177 | R8: =K8*$R$3 -> 7.7929759 | S8: =K8*$S$3 -> 77.568495 | T8: =K8*$T$3 -> 158.05291 | U8: =K8*$U$3 -> 58.860192 | V8: =K8*$V$3 -> 36.64247 | W8: =K8*$W$3 -> 8.0510215 | X8: =K8*$X$3 -> 33.571727 | Y8: =K8*$Y$3 -> 63.37599 | Z8: =K8*$Z$3 -> 30.191331 | AA8: =J8*$AA$3 -> 55.123683 | AB8: =K8*$AB$3 -> 120.0944 | AD8: =H8/$H$39 -> 0.014550833 | AE8: =AD8*$AE$3 -> 98.7565
B9: 111A | C9: Abbott - Other | G9: 1 | H9: 2702.31 | J9: =H9/$I$35 -> 0.023924338 | K9: =H9/$I$37 -> 0.02158141 | L9: =G9/$G$38 -> 0.028571429 | M9: =J9*$M$3 -> 164.74299 | N9: =J9*$N$3 -> 38.518185 | O9: =J9*$O$3 -> 39.451234 | P9: =J9*$P$3 -> 7.7514856 | Q9: =K9*$Q$3 -> 27.365228 | R9: =K9*$R$3 -> 6.5175858 | S9: =K9*$S$3 -> 64.873719 | T9: =K9*$T$3 -> 132.18614 | U9: =K9*$U$3 -> 49.227196 | V9: =K9*$V$3 -> 30.645602 | W9: =K9*$W$3 -> 6.7333999 | X9: =K9*$X$3 -> 28.077414 | Y9: =K9*$Y$3 -> 53.003943 | Z9: =K9*$Z$3 -> 25.25025 | AA9: =J9*$AA$3 -> 46.1022 | AB9: =K9*$AB$3 -> 100.43988 | AD9: =H9/$H$39 -> 0.012169459 | AE9: =AD9*$AE$3 -> 82.594117
B10: 111F | C10: Abbott Food | G10: 0 | H10: 261.6 | J10: =H10/$I$35 -> 0.0023160211 | K10: =H10/$I$37 -> 0.0020892114 | L10: =G10/$G$38 -> 0 | M10: =J10*$M$3 -> 15.948121 | N10: =J10*$N$3 -> 3.7287939 | O10: =J10*$O$3 -> 3.8191188 | P10: =J10*$P$3 -> 0.75039083 | Q10: =K10*$Q$3 -> 2.6491201 | R10: =K10*$R$3 -> 0.63094184 | S10: =K10*$S$3 -> 6.2801695 | T10: =K10*$T$3 -> 12.79642 | U10: =K10*$U$3 -> 4.7654912 | V10: =K10*$V$3 -> 2.9666802 | W10: =K10*$W$3 -> 0.65183396 | X10: =K10*$X$3 -> 2.718064 | Y10: =K10*$Y$3 -> 5.1311032 | Z10: =K10*$Z$3 -> 2.4443773 | AA10: =J10*$AA$3 -> 4.4629726 | AB10: =K10*$AB$3 -> 9.7231899 | AD10: =H10/$H$39 -> 0.0011780774 | AE10: =AD10*$AE$3 -> 7.9956116
B11: 112 | C11: EHS | G11: 1 | H11: 5008.5 | J11: =H11/$I$35 -> 0.044341711 | K11: =H11/$I$37 -> 0.039999294 | L11: =G11/$G$38 -> 0.028571429 | M11: =J11*$M$3 -> 305.33702 | N11: =J11*$N$3 -> 71.390154 | O11: =J11*$O$3 -> 73.119481 | P11: =J11*$P$3 -> 14.366714 | Q11: =K11*$Q$3 -> 50.719105 | R11: =K11*$R$3 -> 12.079787 | S11: =K11*$S$3 -> 120.23788 | T11: =K11*$T$3 -> 244.99568 | U11: =K11*$U$3 -> 91.23839 | V11: =K11*$V$3 -> 56.798997 | W11: =K11*$W$3 -> 12.47978 | X11: =K11*$X$3 -> 52.039082 | Y11: =K11*$Y$3 -> 98.238266 | Z11: =K11*$Z$3 -> 46.799174 | AA11: =J11*$AA$3 -> 85.446477 | AB11: =K11*$AB$3 -> 186.15671 | AD11: =H11/$H$39 -> 0.022555049 | AE11: =AD11*$AE$3 -> 153.08112
B12: 114 | C12: Summer Camp | H12: 0 | J12: =H12/$I$35 -> 0 | K12: =H12/$I$37 -> 0 | L12: =G12/$G$38 -> 0 | M12: =J12*$M$3 -> 0 | N12: =J12*$N$3 -> 0 | O12: =J12*$O$3 -> 0 | P12: =J12*$P$3 -> 0 | Q12: =K12*$Q$3 -> 0 | R12: =K12*$R$3 -> 0 | S12: =K12*$S$3 -> 0 | T12: =K12*$T$3 -> 0 | U12: =K12*$U$3 -> 0 | V12: =K12*$V$3 -> 0 | W12: =K12*$W$3 -> 0 | X12: =K12*$X$3 -> 0 | Y12: =K12*$Y$3 -> 0 | Z12: =K12*$Z$3 -> 0 | AA12: =J12*$AA$3 -> 0 | AB12: =K12*$AB$3 -> 0 | AD12: =H12/$H$39 -> 0 | AE12: =AD12*$AE$3 -> 0
B13: 222 | C13: DCF- Coding | G13: 0.5 | H13: 3653.71 | J13: =H13/$I$35 -> 0.03234736 | K13: =H13/$I$37 -> 0.029179559 | L13: =G13/$G$38 -> 0.014285714 | M13: =J13*$M$3 -> 222.74392 | N13: =J13*$N$3 -> 52.07925 | O13: =J13*$O$3 -> 53.340797 | P13: =J13*$P$3 -> 10.480545 | Q13: =K13*$Q$3 -> 36.999681 | R13: =K13*$R$3 -> 8.8122268 | S13: =K13*$S$3 -> 87.713754 | T13: =K13*$T$3 -> 178.7248 | U13: =K13*$U$3 -> 66.558574 | V13: =K13*$V$3 -> 41.434974 | W13: =K13*$W$3 -> 9.1040224 | X13: =K13*$X$3 -> 37.962606 | Y13: =K13*$Y$3 -> 71.664997 | Z13: =K13*$Z$3 -> 34.140084 | AA13: =J13*$AA$3 -> 62.333363 | AB13: =K13*$AB$3 -> 135.80167 | AD13: =H13/$H$39 -> 0.01645395 | AE13: =AD13*$AE$3 -> 111.67296
B14: 223 | C14: OICA | H14: 0 | J14: =H14/$I$35 -> 0 | K14: =H14/$I$37 -> 0 | L14: =G14/$G$38 -> 0 | M14: =J14*$M$3 -> 0 | N14: =J14*$N$3 -> 0 | O14: =J14*$O$3 -> 0 | P14: =J14*$P$3 -> 0 | Q14: =K14*$Q$3 -> 0 | R14: =K14*$R$3 -> 0 | S14: =K14*$S$3 -> 0 | T14: =K14*$T$3 -> 0 | U14: =K14*$U$3 -> 0 | V14: =K14*$V$3 -> 0 | W14: =K14*$W$3 -> 0 | X14: =K14*$X$3 -> 0 | Y14: =K14*$Y$3 -> 0 | Z14: =K14*$Z$3 -> 0 | AA14: =J14*$AA$3 -> 0 | AB14: =K14*$AB$3 -> 0 | AD14: =H14/$H$39 -> 0 | AE14: =AD14*$AE$3 -> 0
B15: 334 | C15: NRTC - Admin | H15: 0 | J15: =H15/$I$35 -> 0 | K15: =H15/$I$37 -> 0 | L15: =G15/$G$38 -> 0 | M15: =J15*$M$3 -> 0 | N15: =J15*$N$3 -> 0 | O15: =J15*$O$3 -> 0 | P15: =J15*$P$3 -> 0 | Q15: =K15*$Q$3 -> 0 | R15: =K15*$R$3 -> 0 | S15: =K15*$S$3 -> 0 | T15: =K15*$T$3 -> 0 | U15: =K15*$U$3 -> 0 | V15: =K15*$V$3 -> 0 | W15: =K15*$W$3 -> 0 | X15: =K15*$X$3 -> 0 | Y15: =K15*$Y$3 -> 0 | Z15: =K15*$Z$3 -> 0 | AA15: =J15*$AA$3 -> 0 | AB15: =K15*$AB$3 -> 0 | AD15: =H15/$H$39 -> 0 | AE15: =AD15*$AE$3 -> 0
B16: 334H | C16: NRTC - Housing | G16: 0.5 | H16: 1150 | J16: =H16/$I$35 -> 0.010181285 | K16: =H16/$I$37 -> 0.0091842244 | L16: =G16/$G$38 -> 0.014285714 | M16: =J16*$M$3 -> 70.108331 | N16: =J16*$N$3 -> 16.391869 | O16: =J16*$O$3 -> 16.788939 | P16: =J16*$P$3 -> 3.2987364 | Q16: =K16*$Q$3 -> 11.645597 | R16: =K16*$R$3 -> 2.7736358 | S16: =K16*$S$3 -> 27.607779 | T16: =K16*$T$3 -> 56.253375 | U16: =K16*$U$3 -> 20.949216 | V16: =K16*$V$3 -> 13.041599 | W16: =K16*$W$3 -> 2.865478 | X16: =K16*$X$3 -> 11.948676 | Y16: =K16*$Y$3 -> 22.556455 | Z16: =K16*$Z$3 -> 10.745543 | AA16: =J16*$AA$3 -> 19.619337 | AB16: =K16*$AB$3 -> 42.743381 | AD16: =H16/$H$39 -> 0.0051788572 | AE16: =AD16*$AE$3 -> 35.148904
B17: 334F | C17: NRTC FOC | H17: 0 | J17: =H17/$I$35 -> 0 | K17: =H17/$I$37 -> 0 | L17: =G17/$G$38 -> 0 | M17: =J17*$M$3 -> 0 | N17: =J17*$N$3 -> 0 | O17: =J17*$O$3 -> 0 | P17: =J17*$P$3 -> 0 | Q17: =K17*$Q$3 -> 0 | R17: =K17*$R$3 -> 0 | S17: =K17*$S$3 -> 0 | T17: =K17*$T$3 -> 0 | U17: =K17*$U$3 -> 0 | V17: =K17*$V$3 -> 0 | W17: =K17*$W$3 -> 0 | X17: =K17*$X$3 -> 0 | Y17: =K17*$Y$3 -> 0 | Z17: =K17*$Z$3 -> 0 | AA17: =J17*$AA$3 -> 0 | AB17: =K17*$AB$3 -> 0 | AD17: =H17/$H$39 -> 0 | AE17: =AD17*$AE$3 -> 0
B18: 335 | C18: NRTC 19 | G18: 0.5 | H18: 846.15 | J18: =H18/$I$35 -> 0.0074912127 | K18: =H18/$I$37 -> 0.0067575926 | L18: =G18/$G$38 -> 0.014285714 | M18: =J18*$M$3 -> 51.58449 | N18: =J18*$N$3 -> 12.060852 | O18: =J18*$O$3 -> 12.35301 | P18: =J18*$P$3 -> 2.4271529 | Q18: =K18*$Q$3 -> 8.5686274 | R18: =K18*$R$3 -> 2.040793 | S18: =K18*$S$3 -> 20.313323 | T18: =K18*$T$3 -> 41.390255 | U18: =K18*$U$3 -> 15.414069 | V18: =K18*$V$3 -> 9.5957815 | W18: =K18*$W$3 -> 2.1083689 | X18: =K18*$X$3 -> 8.791628 | Y18: =K18*$Y$3 -> 16.596647 | Z18: =K18*$Z$3 -> 7.9063834 | AA18: =J18*$AA$3 -> 14.435567 | AB18: =K18*$AB$3 -> 31.449836 | AD18: =H18/$H$39 -> 0.0038105131 | AE18: =AD18*$AE$3 -> 25.861952
B19: 368 | C19: Wells Fargo | G19: 1.5 | H19: 6018.91 | J19: =H19/$I$35 -> 0.053287165 | K19: =H19/$I$37 -> 0.048068713 | L19: =G19/$G$38 -> 0.042857143 | M19: =J19*$M$3 -> 366.93542 | N19: =J19*$N$3 -> 85.792336 | O19: =J19*$O$3 -> 87.870535 | P19: =J19*$P$3 -> 17.265042 | Q19: =K19*$Q$3 -> 60.951129 | R19: =K19*$R$3 -> 14.516751 | S19: =K19*$S$3 -> 144.49455 | T19: =K19*$T$3 -> 294.42087 | U19: =K19*$U$3 -> 109.64474 | V19: =K19*$V$3 -> 68.257573 | W19: =K19*$W$3 -> 14.997439 | X19: =K19*$X$3 -> 62.537396 | Y19: =K19*$Y$3 -> 118.05676 | Z19: =K19*$Z$3 -> 56.240395 | AA19: =J19*$AA$3 -> 102.68437 | AB19: =K19*$AB$3 -> 223.71179 | AD19: =H19/$H$39 -> 0.027105283 | AE19: =AD19*$AE$3 -> 183.96356
B20: 451 | C20: USJP | G20: 5.5 | H20: 13963.15 | J20: =H20/$I$35 -> 0.12361984 | K20: =H20/$I$37 -> 0.11151366 | L20: =G20/$G$38 -> 0.15714286 | M20: =J20*$M$3 -> 851.24621 | N20: =J20*$N$3 -> 199.02794 | O20: =J20*$O$3 -> 203.84911 | P20: =J20*$P$3 -> 40.052828 | Q20: =K20*$Q$3 -> 141.39931 | R20: =K20*$R$3 -> 33.677124 | S20: =K20*$S$3 -> 335.21005 | T20: =K20*$T$3 -> 683.02114 | U20: =K20*$U$3 -> 254.36265 | V20: =K20*$V$3 -> 158.34939 | W20: =K20*$W$3 -> 34.79226 | X20: =K20*$X$3 -> 145.07927 | Y20: =K20*$Y$3 -> 273.87754 | Z20: =K20*$Z$3 -> 130.47098 | AA20: =J20*$AA$3 -> 238.21543 | AB20: =K20*$AB$3 -> 518.98455 | AD20: =H20/$H$39 -> 0.062881009 | AE20: =AD20*$AE$3 -> 426.77341
B21: 452 | C21: PACE | G21: 2 | H21: 1950 | J21: =H21/$I$35 -> 0.017263919 | K21: =H21/$I$37 -> 0.01557325 | L21: =G21/$G$38 -> 0.057142857 | M21: =J21*$M$3 -> 118.87934 | N21: =J21*$N$3 -> 27.794909 | O21: =J21*$O$3 -> 28.468202 | P21: =J21*$P$3 -> 5.5935096 | Q21: =K21*$Q$3 -> 19.746881 | R21: =K21*$R$3 -> 4.7031215 | S21: =K21*$S$3 -> 46.81319 | T21: =K21*$T$3 -> 95.386157 | U21: =K21*$U$3 -> 35.522584 | V21: =K21*$V$3 -> 22.114015 | W21: =K21*$W$3 -> 4.858854 | X21: =K21*$X$3 -> 20.260798 | Y21: =K21*$Y$3 -> 38.247902 | Z21: =K21*$Z$3 -> 18.220703 | AA21: =J21*$AA$3 -> 33.267571 | AB21: =K21*$AB$3 -> 72.477906 | AD21: =H21/$H$39 -> 0.0087815405 | AE21: =AD21*$AE$3 -> 59.600316
B22: 454 | C22: Prudential #1 Workforce | K22: =H22/$I$37 -> 0 | L22: =G22/$G$38 -> 0 | Q22: =K22*$Q$3 -> 0 | R22: =K22*$R$3 -> 0 | S22: =K22*$S$3 -> 0 | T22: =K22*$T$3 -> 0 | U22: =K22*$U$3 -> 0 | V22: =K22*$V$3 -> 0 | W22: =K22*$W$3 -> 0 | X22: =K22*$X$3 -> 0 | Y22: =K22*$Y$3 -> 0 | Z22: =K22*$Z$3 -> 0 | AA22: =J22*$AA$3 -> 0 | AB22: =K22*$AB$3 -> 0
B23: 467 | C23: WF - United Airlines | G23: 2 | H23: 6903.87 | J23: =H23/$I$35 -> 0.061121974 | K23: =H23/$I$37 -> 0.055136254 | L23: =G23/$G$38 -> 0.057142857 | M23: =J23*$M$3 -> 420.88591 | N23: =J23*$N$3 -> 98.406378 | O23: =J23*$O$3 -> 100.79014 | P23: =J23*$P$3 -> 19.80352 | Q23: =K23*$Q$3 -> 69.91277 | R23: =K23*$R$3 -> 16.651149 | S23: =K23*$S$3 -> 165.73958 | T23: =K23*$T$3 -> 337.70955 | U23: =K23*$U$3 -> 125.76579 | V23: =K23*$V$3 -> 78.29348 | W23: =K23*$W$3 -> 17.202511 | X23: =K23*$X$3 -> 71.732266 | Y23: =K23*$Y$3 -> 135.41464 | Z23: =K23*$Z$3 -> 64.509417 | AA23: =J23*$AA$3 -> 117.78204 | AB23: =K23*$AB$3 -> 256.60412 | AD23: =H23/$H$39 -> 0.031090571 | AE23: =AD23*$AE$3 -> 211.01171
B24: 468 | C24: Newark Alliance | G24: 1 | H24: 6307.7 | J24: =H24/$I$35 -> 0.055843907 | K24: =H24/$I$37 -> 0.050375072 | L24: =G24/$G$38 -> 0.028571429 | M24: =J24*$M$3 -> 384.54115 | N24: =J24*$N$3 -> 89.908691 | O24: =J24*$O$3 -> 92.086603 | P24: =J24*$P$3 -> 18.093426 | Q24: =K24*$Q$3 -> 63.875591 | R24: =K24*$R$3 -> 15.213272 | S24: =K24*$S$3 -> 151.42747 | T24: =K24*$T$3 -> 308.54731 | U24: =K24*$U$3 -> 114.90554 | V24: =K24*$V$3 -> 71.532602 | W24: =K24*$W$3 -> 15.717022 | X24: =K24*$X$3 -> 65.537968 | Y24: =K24*$Y$3 -> 123.72118 | Z24: =K24*$Z$3 -> 58.938834 | AA24: =J24*$AA$3 -> 107.61121 | AB24: =K24*$AB$3 -> 234.44558 | AD24: =H24/$H$39 -> 0.028405807 | AE24: =AD24*$AE$3 -> 192.79021
B25: 502 | C25: ESG | G25: 1.5 | H25: 1657.17 | J25: =H25/$I$35 -> 0.014671409 | K25: =H25/$I$37 -> 0.013234627 | L25: =G25/$G$38 -> 0.042857143 | M25: =J25*$M$3 -> 101.02732 | N25: =J25*$N$3 -> 23.620969 | O25: =J25*$O$3 -> 24.193154 | P25: =J25*$P$3 -> 4.7535366 | Q25: =K25*$Q$3 -> 16.781507 | R25: =K25*$R$3 -> 3.9968574 | S25: =K25*$S$3 -> 39.783289 | T25: =K25*$T$3 -> 81.062091 | U25: =K25*$U$3 -> 30.188185 | V25: =K25*$V$3 -> 18.793171 | W25: =K25*$W$3 -> 4.1292037 | X25: =K25*$X$3 -> 17.21825 | Y25: =K25*$Y$3 -> 32.504244 | Z25: =K25*$Z$3 -> 15.484514 | AA25: =J25*$AA$3 -> 28.271806 | AB25: =K25*$AB$3 -> 61.593955 | AD25: =H25/$H$39 -> 0.0074628233 | AE25: =AD25*$AE$3 -> 50.650182
B26: 515 | C26: FOC - HUD NUL PARS | G26: 1.5 | H26: 1730.77 | J26: =H26/$I$35 -> 0.015323011 | K26: =H26/$I$37 -> 0.013822418 | L26: =G26/$G$38 -> 0.042857143 | M26: =J26*$M$3 -> 105.51426 | N26: =J26*$N$3 -> 24.670048 | O26: =J26*$O$3 -> 25.267646 | P26: =J26*$P$3 -> 4.9646557 | Q26: =K26*$Q$3 -> 17.526825 | R26: =K26*$R$3 -> 4.1743701 | S26: =K26*$S$3 -> 41.550187 | T26: =K26*$T$3 -> 84.662307 | U26: =K26*$U$3 -> 31.528934 | V26: =K26*$V$3 -> 19.627833 | W26: =K26*$W$3 -> 4.3125943 | X26: =K26*$X$3 -> 17.982965 | Y26: =K26*$Y$3 -> 33.947857 | Z26: =K26*$Z$3 -> 16.172228 | AA26: =J26*$AA$3 -> 29.527443 | AB26: =K26*$AB$3 -> 64.329531 | AD26: =H26/$H$39 -> 0.0077942702 | AE26: =AD26*$AE$3 -> 52.899712
B27: 525 | C27: CDBG - Housing | G27: 1 | H27: 2900 | J27: =H27/$I$35 -> 0.025674546 | K27: =H27/$I$37 -> 0.023160218 | L27: =G27/$G$38 -> 0.028571429 | M27: =J27*$M$3 -> 176.79492 | N27: =J27*$N$3 -> 41.336018 | O27: =J27*$O$3 -> 42.337326 | P27: =J27*$P$3 -> 8.3185528 | Q27: =K27*$Q$3 -> 29.367157 | R27: =K27*$R$3 -> 6.9943859 | S27: =K27*$S$3 -> 69.619616 | T27: =K27*$T$3 -> 141.85634 | U27: =K27*$U$3 -> 52.828458 | V27: =K27*$V$3 -> 32.88751 | W27: =K27*$W$3 -> 7.2259881 | X27: =K27*$X$3 -> 30.131444 | Y27: =K27*$Y$3 -> 56.881496 | Z27: =K27*$Z$3 -> 27.097455 | AA27: =J27*$AA$3 -> 49.474849 | AB27: =K27*$AB$3 -> 107.78766 | AD27: =H27/$H$39 -> 0.013059727 | AE27: =AD27*$AE$3 -> 88.636367
B28: 560 | C28: CAP 1 - Save Up | H28: 0 | J28: =H28/$I$35 -> 0 | K28: =H28/$I$37 -> 0 | L28: =G28/$G$38 -> 0 | M28: =J28*$M$3 -> 0 | N28: =J28*$N$3 -> 0 | O28: =J28*$O$3 -> 0 | P28: =J28*$P$3 -> 0 | Q28: =K28*$Q$3 -> 0 | R28: =K28*$R$3 -> 0 | S28: =K28*$S$3 -> 0 | T28: =K28*$T$3 -> 0 | U28: =K28*$U$3 -> 0 | V28: =K28*$V$3 -> 0 | W28: =K28*$W$3 -> 0 | X28: =K28*$X$3 -> 0 | Y28: =K28*$Y$3 -> 0 | Z28: =K28*$Z$3 -> 0 | AA28: =J28*$AA$3 -> 0 | AB28: =K28*$AB$3 -> 0 | AD28: =H28/$H$39 -> 0 | AE28: =AD28*$AE$3 -> 0
B29: 561 | C29: LISC FOC 2019 | G29: 1 | H29: 4384.62 | J29: =H29/$I$35 -> 0.038818319 | K29: =H29/$I$37 -> 0.035016812 | L29: =G29/$G$38 -> 0.028571429 | M29: =J29*$M$3 -> 267.30295 | N29: =J29*$N$3 -> 62.497494 | O29: =J29*$O$3 -> 64.011409 | P29: =J29*$P$3 -> 12.577135 | Q29: =K29*$Q$3 -> 44.401318 | R29: =K29*$R$3 -> 10.575077 | S29: =K29*$S$3 -> 105.26054 | T29: =K29*$T$3 -> 214.47798 | U29: =K29*$U$3 -> 79.873349 | V29: =K29*$V$3 -> 49.723873 | W29: =K29*$W$3 -> 10.925245 | X29: =K29*$X$3 -> 45.556873 | Y29: =K29*$Y$3 -> 86.001291 | Z29: =K29*$Z$3 -> 40.96967 | AA29: =J29*$AA$3 -> 74.802901 | AB29: =K29*$AB$3 -> 162.96824 | AD29: =H29/$H$39 -> 0.019745497 | AE29: =AD29*$AE$3 -> 134.01269
B30: 563 | C30: Prudential #1 FOC | G30: 1 | H30: 2929.2 | J30: =H30/$I$35 -> 0.025933062 | K30: =H30/$I$37 -> 0.023393418 | L30: =G30/$G$38 -> 0.028571429 | M30: =J30*$M$3 -> 178.57506 | N30: =J30*$N$3 -> 41.752229 | O30: =J30*$O$3 -> 42.763619 | P30: =J30*$P$3 -> 8.402312 | Q30: =K30*$Q$3 -> 29.662854 | R30: =K30*$R$3 -> 7.0648121 | S30: =K30*$S$3 -> 70.320613 | T30: =K30*$T$3 -> 143.28468 | U30: =K30*$U$3 -> 53.360386 | V30: =K30*$V$3 -> 33.218653 | W30: =K30*$W$3 -> 7.2987463 | X30: =K30*$X$3 -> 30.434836 | Y30: =K30*$Y$3 -> 57.454234 | Z30: =K30*$Z$3 -> 27.370299 | AA30: =J30*$AA$3 -> 49.97301 | AB30: =K30*$AB$3 -> 108.87297 | AD30: =H30/$H$39 -> 0.013191225 | AE30: =AD30*$AE$3 -> 89.528843
B31: 610 | C31: CEO | G31: 1 | H31: 11923.08 | J31: =H31/$I$35 -> 0.1055585 | K31: =H31/$I$37 -> 0.095221081 | L31: =G31/$G$38 -> 0.028571429 | M31: =J31*$M$3 -> 726.87586 | N31: =J31*$N$3 -> 169.94919 | O31: =J31*$O$3 -> 174.06597 | P31: =J31*$P$3 -> 34.200955 | Q31: =K31*$Q$3 -> 120.74033 | R31: =K31*$R$3 -> 28.756766 | S31: =K31*$S$3 -> 286.23457 | T31: =K31*$T$3 -> 583.22912 | U31: =K31*$U$3 -> 217.19928 | V31: =K31*$V$3 -> 135.21393 | W31: =K31*$W$3 -> 29.708977 | X31: =K31*$X$3 -> 123.88263 | Y31: =K31*$Y$3 -> 233.86297 | Z31: =K31*$Z$3 -> 111.40866 | AA31: =J31*$AA$3 -> 203.41124 | AB31: =K31*$AB$3 -> 443.15891 | AD31: =H31/$H$39 -> 0.053693851 | AE31: =AD31*$AE$3 -> 364.42017
B32: 620 | C32: CFO | G32: 1 | H32: 5076.92 | J32: =H32/$I$35 -> 0.044947453 | K32: =H32/$I$37 -> 0.040545715 | L32: =G32/$G$38 -> 0.028571429 | M32: =J32*$M$3 -> 309.50816 | N32: =J32*$N$3 -> 72.365399 | O32: =J32*$O$3 -> 74.11835 | P32: =J32*$P$3 -> 14.562975 | Q32: =K32*$Q$3 -> 51.411967 | R32: =K32*$R$3 -> 12.244806 | S32: =K32*$S$3 -> 121.88042 | T32: =K32*$T$3 -> 248.34251 | U32: =K32*$U$3 -> 92.484777 | V32: =K32*$V$3 -> 57.574916 | W32: =K32*$W$3 -> 12.650263 | X32: =K32*$X$3 -> 52.749976 | Y32: =K32*$Y$3 -> 99.580277 | Z32: =K32*$Z$3 -> 47.438487 | AA32: =J32*$AA$3 -> 86.613742 | AB32: =K32*$AB$3 -> 188.69976 | AD32: =H32/$H$39 -> 0.022863169 | AE32: =AD32*$AE$3 -> 155.17233
B33: 630 | C33: COO | G33: 1 | H33: 0 | J33: =H33/$I$35 -> 0 | K33: =H33/$I$37 -> 0 | L33: =G33/$G$38 -> 0.028571429 | M33: =J33*$M$3 -> 0 | N33: =J33*$N$3 -> 0 | O33: =J33*$O$3 -> 0 | P33: =J33*$P$3 -> 0 | Q33: =K33*$Q$3 -> 0 | R33: =K33*$R$3 -> 0 | S33: =K33*$S$3 -> 0 | T33: =K33*$T$3 -> 0 | U33: =K33*$U$3 -> 0 | V33: =K33*$V$3 -> 0 | W33: =K33*$W$3 -> 0 | X33: =K33*$X$3 -> 0 | Y33: =K33*$Y$3 -> 0 | Z33: =K33*$Z$3 -> 0 | AA33: =J33*$AA$3 -> 0 | AB33: =K33*$AB$3 -> 0 | AD33: =H33/$H$39 -> 0 | AE33: =AD33*$AE$3 -> 0
B34: 650 | C34: Facilities | H34: 299 | J34: =H34/$I$35 -> 0.0026471342 | K34: =H34/$I$37 -> 0.0023878984 | L34: =G34/$G$38 -> 0 | M34: =J34*$M$3 -> 18.228166 | N34: =J34*$N$3 -> 4.261886 | O34: =J34*$O$3 -> 4.3651243 | P34: =J34*$P$3 -> 0.85767147 | Q34: =K34*$Q$3 -> 3.0278551 | R34: =K34*$R$3 -> 0.7211453 | S34: =K34*$S$3 -> 7.1780225 | T34: =K34*$T$3 -> 14.625877 | U34: =K34*$U$3 -> 5.4467961 | V34: =K34*$V$3 -> 3.3908157 | W34: =K34*$W$3 -> 0.74502429 | X34: =K34*$X$3 -> 3.1066558 | Y34: =K34*$Y$3 -> 5.8646784 | Z34: =K34*$Z$3 -> 2.7938411 | AA34: =J34*$AA$3 -> 5.1010276 | AB34: =K34*$AB$3 -> 11.113279 | AD34: =H34/$H$39 -> 0.0013465029 | AE34: =AD34*$AE$3 -> 9.1387151
B35: 600 | C35: Admin | H35: 0.01 | I35: =SUM(H6:H35) -> 112952.34 | J35: =H35/$I$35 -> 8.8532916e-08 | K35: =H35/$I$37 -> 7.9862821e-08 | L35: =G35/$G$38 -> 0 | M35: =J35*$M$3 -> 0.00060963766 | N35: =J35*$N$3 -> 0.00014253799 | O35: =J35*$O$3 -> 0.00014599078 | P35: =J35*$P$3 -> 2.8684665e-05 | Q35: =K35*$Q$3 -> 0.00010126606 | R35: =K35*$R$3 -> 2.4118572e-05 | S35: =K35*$S$3 -> 0.00024006764 | T35: =K35*$T$3 -> 0.00048915978 | U35: =K35*$U$3 -> 0.0001821671 | V35: =K35*$V$3 -> 0.00011340521 | W35: =K35*$W$3 -> 2.49172e-05 | X35: =K35*$X$3 -> 0.00010390153 | Y35: =K35*$Y$3 -> 0.00019614309 | Z35: =K35*$Z$3 -> 9.3439501e-05 | AA35: =J35*$AA$3 -> 0.00017060293 | AB35: =K35*$AB$3 -> 0.00037168157 | AD35: =H35/$H$39 -> 4.5033541e-08 | AE35: =AD35*$AE$3 -> 0.00030564264
B36: 339 | C36: Opport Corp | G36: 1.5 | H36: =I55 -> 6980.77 | K36: =H36/$I$37 -> 0.055750399 | L36: =G36/$G$38 -> 0.042857143 | M36: =J36*$M$3 -> 0 | N36: =J36*$N$3 -> 0 | O36: =J36*$O$3 -> 0 | P36: =J36*$P$3 -> 0 | Q36: =K36*$Q$3 -> 70.691505 | R36: =K36*$R$3 -> 16.83662 | S36: =K36*$S$3 -> 167.5857 | T36: =K36*$T$3 -> 341.47119 | U36: =K36*$U$3 -> 127.16666 | V36: =K36*$V$3 -> 79.165566 | W36: =K36*$W$3 -> 17.394124 | X36: =K36*$X$3 -> 72.531269 | Y36: =K36*$Y$3 -> 136.92298 | Z36: =K36*$Z$3 -> 65.227966 | AA36: =J36*$AA$3 -> 0 | AB36: =K36*$AB$3 -> 259.46236 | AD36: =H36/$H$39 -> 0.031436879 | AE36: =AD36*$AE$3 -> 213.3621
B37: 225 | C37: AmeriCorp | G37: 0 | H37: =J53 -> 5281.6 | I37: =I35+H36+H37 -> 125214.71 | K37: =H37/$I$37 -> 0.042180348 | L37: =G37/$G$38 -> 0 | Q37: =K37*$Q$3 -> 53.484681 | R37: =K37*$R$3 -> 12.738465 | S37: =K37*$S$3 -> 126.79413 | T37: =K37*$T$3 -> 258.35463 | U37: =K37*$U$3 -> 96.213373 | V37: =K37*$V$3 -> 59.896094 | W37: =K37*$W$3 -> 13.160268 | X37: =K37*$X$3 -> 54.876632 | Y37: =K37*$Y$3 -> 103.59493 | Z37: =K37*$Z$3 -> 49.351007 | AA37: =J37*$AA$3 -> 0 | AB37: =K37*$AB$3 -> 196.30734 | AD37: =H37/$H$39 -> 0.023784915 | AE37: =AD37*$AE$3 -> 161.42822
B38: 451 | C38: USJP - Participants | F38: 96842 | G38: =SUM(G6:G37) -> 35 | H38: 96842 | Q38: =K38*$Q$3 -> 0 | AD38: =H38/$H$39 -> 0.43611382 | AE38: =AD38*$AE$3 -> 2959.9045
H39: =SUM(H6:H38) -> 222056.71 | J39: =SUM(J6:J38) -> 1 | K39: =SUM(K6:K38) -> 1 | L39: =SUM(L6:L38) -> 1 | M39: =SUM(M6:M38) -> 6886 | N39: =SUM(N6:N38) -> 1610 | O39: =SUM(O6:O38) -> 1649 | P39: =SUM(P6:P38) -> 324 | Q39: =SUM(Q6:Q38) -> 1268 | ... AE39: =SUM(AE6:AE38) -> 6787
H40: Salary | J40: Hourly | M40: =M3-M39 -> 0 | N40: =N3-N39 -> 0 | O40: =O3-O39 -> 0 | P40: =P3-P39 -> 0 | Q40: =Q3-Q39 -> 0 | R40: =R3-R39 -> 0 | S40: =S3-S39 -> 0 | T40: =T3-T39 -> 0 | ... Z40: =Z3-Z39 -> 0 | AB40: =AB3-AB39 -> 0 | AC40: =AC3-AC39 -> 0 | AD40: =AD3-AD39 -> -1 | AE40: =AE3-AE39 -> 0
...

Sheet Sept 2019 Alloc  (2)
B1: September Cost Allocations | L1: 7251 | M1: 7252 | N1: 7253 | O1: 7254 | P1: 7260.1 | Q1: 8140 | R1: 7515.5 | S1: 7521 | T1: 8112 | U1: 8135.5 | V1: 8191 | W1: 8210.5 | X1: 8229.1 | Y1: 8239 | Z1: 8266 | AC1: 7248
L2: FICA | M2: MEDI | N2: SUI | O2: Disability | P2: Payroll Fees | Q2: Postage | R2: IT Consultants | S2: Acctg Fees | T2: Supplies | U2: Telephone | V2: Web Hosting | W2: Utilities | X2: Eq Lease | Y2: Repairs | Z2: General Insurance | AC2: W/ Comp
L3: 6530.93 | M3: 1527.46 | N3: 1598.57 | O3: 313.99 | P3: 1330.76 | R3: 3006 | S3: 4900 | U3: 640.74 | V3: 312 | W3: 1092 | X3: 2321.34 | Y3: 764.51 | Z3: 3972.48 | AC3: 6645.7
L4: 1 | M4: 2 | N4: 3 | O4: 4 | P4: 5 | Q4: 6 | R4: 7 | S4: 8 | T4: 9 | U4: 10 | V4: 11 | W4: 12 | X4: 13 | Y4: 14 | Z4: 15 | AC4: 0.04
D5: 7222 | E5: Taxes | F5: W/C | J5: Taxes | K5: Expenses
B6: 41 | C6: Thriftworks | H6: 0 | J6: =H6/$I$35 -> 0 | K6: =H6/$I$37 -> 0 | L6: =J6*$L$3 -> 0 | M6: =J6*$M$3 -> 0 | N6: =J6*$N$3 -> 0 | O6: =J6*$O$3 -> 0 | P6: =J6*$P$3 -> 0 | Q6: =K6*$Q$3 -> 0 | R6: =K6*$R$3 -> 0 | S6: =K6*$S$3 -> 0 | T6: =K6*$T$3 -> 0 | U6: =K6*$U$3 -> 0 | V6: =K6*$V$3 -> 0 | W6: =K6*$W$3 -> 0 | X6: =K6*$X$3 -> 0 | Y6: =K6*$Y$3 -> 0 | Z6: =K6*$Z$3 -> 0 | AB6: =H6/$H$39 -> 0 | AC6: =AB6*$AC$3 -> 0
B7: 111 | C7: Abbott | H7: 25010.78 | J7: =H7/$I$35 -> 0.2318441 | K7: =H7/$I$37 -> 0.20698113 | L7: =J7*$L$3 -> 1514.1576 | M7: =J7*$M$3 -> 354.13258 | N7: =J7*$N$3 -> 370.61902 | O7: =J7*$O$3 -> 72.796728 | P7: =J7*$P$3 -> 308.52885 | Q7: =K7*$Q$3 -> 0 | R7: =K7*$R$3 -> 622.18527 | S7: =K7*$S$3 -> 1014.2075 | T7: =K7*$T$3 -> 0 | U7: =K7*$U$3 -> 132.62109 | V7: =K7*$V$3 -> 64.578112 | W7: =K7*$W$3 -> 226.02339 | X7: =K7*$X$3 -> 480.47357 | Y7: =K7*$Y$3 -> 158.23914 | Z7: =K7*$Z$3 -> 822.2284 | AB7: =H7/$H$39 -> 0.11765538 | AC7: =AB7*$AC$3 -> 781.90234
B8: 111A | C8: Abbott - Other | H8: 2617.28 | J8: =H8/$I$35 -> 0.024261575 | K8: =H8/$I$37 -> 0.021659763 | L8: =J8*$L$3 -> 158.45065 | M8: =J8*$M$3 -> 37.058585 | N8: =J8*$N$3 -> 38.783826 | O8: =J8*$O$3 -> 7.6178919 | P8: =J8*$P$3 -> 32.286334 | Q8: =K8*$Q$3 -> 0 | R8: =K8*$R$3 -> 65.109248 | S8: =K8*$S$3 -> 106.13284 | T8: =K8*$T$3 -> 0 | U8: =K8*$U$3 -> 13.878277 | V8: =K8*$V$3 -> 6.7578461 | W8: =K8*$W$3 -> 23.652461 | X8: =K8*$X$3 -> 50.279674 | Y8: =K8*$Y$3 -> 16.559105 | Z8: =K8*$Z$3 -> 86.042976 | AB8: =H8/$H$39 -> 0.012312174 | AC8: =AB8*$AC$3 -> 81.823012
B9: 111B | C9: Abbott Fees | H9: 1203.77 | J9: =H9/$I$35 -> 0.011158667 | K9: =H9/$I$37 -> 0.0099620113 | L9: =J9*$L$3 -> 72.876474 | M9: =J9*$M$3 -> 17.044418 | N9: =J9*$N$3 -> 17.83791 | O9: =J9*$O$3 -> 3.5037099 | P9: =J9*$P$3 -> 14.849508 | Q9: =K9*$Q$3 -> 0 | R9: =K9*$R$3 -> 29.945806 | S9: =K9*$S$3 -> 48.813856 | T9: =K9*$T$3 -> 0 | U9: =K9*$U$3 -> 6.3830591 | V9: =K9*$V$3 -> 3.1081475 | W9: =K9*$W$3 -> 10.878516 | X9: =K9*$X$3 -> 23.125215 | Y9: =K9*$Y$3 -> 7.6160573 | Z9: =K9*$Z$3 -> 39.573891 | AB9: =H9/$H$39 -> 0.0056627587 | AC9: =AB9*$AC$3 -> 37.632996
B10: 111F | C10: Abbott Food | H10: 254.47 | J10: =H10/$I$35 -> 0.0023588775 | K10: =H10/$I$37 -> 0.0021059114 | L10: =J10*$L$3 -> 15.405664 | M10: =J10*$M$3 -> 3.6030911 | N10: =J10*$N$3 -> 3.7708309 | O10: =J10*$O$3 -> 0.74066396 | P10: =J10*$P$3 -> 3.1390999 | Q10: =K10*$Q$3 -> 0 | R10: =K10*$R$3 -> 6.3303698 | S10: =K10*$S$3 -> 10.318966 | T10: =K10*$T$3 -> 0 | U10: =K10*$U$3 -> 1.3493417 | V10: =K10*$V$3 -> 0.65704437 | W10: =K10*$W$3 -> 2.2996553 | X10: =K10*$X$3 -> 4.8885365 | Y10: =K10*$Y$3 -> 1.6099904 | Z10: =K10*$Z$3 -> 8.3656911 | AB10: =H10/$H$39 -> 0.0011970744 | AC10: =AB10*$AC$3 -> 7.9553972
B11: 112 | C11: EHS | H11: 5625.65 | J11: =H11/$I$35 -> 0.052148463 | K11: =H11/$I$37 -> 0.046556061 | L11: =J11*$L$3 -> 340.57796 | M11: =J11*$M$3 -> 79.654691 | N11: =J11*$N$3 -> 83.362969 | O11: =J11*$O$3 -> 16.374096 | P11: =J11*$P$3 -> 69.397089 | Q11: =K11*$Q$3 -> 0 | R11: =K11*$R$3 -> 139.94752 | S11: =K11*$S$3 -> 228.1247 | T11: =K11*$T$3 -> 0 | U11: =K11*$U$3 -> 29.83033 | V11: =K11*$V$3 -> 14.525491 | W11: =K11*$W$3 -> 50.839218 | X11: =K11*$X$3 -> 108.07245 | Y11: =K11*$Y$3 -> 35.592574 | Z11: =K11*$Z$3 -> 184.94302 | AB11: =H11/$H$39 -> 0.026464108 | AC11: =AB11*$AC$3 -> 175.87252
B12: 114 | C12: Summer Camp | H12: 0 | J12: =H12/$I$35 -> 0 | K12: =H12/$I$37 -> 0 | L12: =J12*$L$3 -> 0 | M12: =J12*$M$3 -> 0 | N12: =J12*$N$3 -> 0 | O12: =J12*$O$3 -> 0 | P12: =J12*$P$3 -> 0 | Q12: =K12*$Q$3 -> 0 | R12: =K12*$R$3 -> 0 | S12: =K12*$S$3 -> 0 | T12: =K12*$T$3 -> 0 | U12: =K12*$U$3 -> 0 | V12: =K12*$V$3 -> 0 | W12: =K12*$W$3 -> 0 | X12: =K12*$X$3 -> 0 | Y12: =K12*$Y$3 -> 0 | Z12: =K12*$Z$3 -> 0 | AB12: =H12/$H$39 -> 0 | AC12: =AB12*$AC$3 -> 0
B13: 222 | C13: DCF- Coding | H13: 2480.65 | J13: =H13/$I$35 -> 0.022995047 | K13: =H13/$I$37 -> 0.020529057 | L13: =J13*$L$3 -> 150.17904 | M13: =J13*$M$3 -> 35.124014 | N13: =J13*$N$3 -> 36.759192 | O13: =J13*$O$3 -> 7.2202147 | P13: =J13*$P$3 -> 30.600888 | Q13: =K13*$Q$3 -> 0 | R13: =K13*$R$3 -> 61.710347 | S13: =K13*$S$3 -> 100.59238 | T13: =K13*$T$3 -> 0 | U13: =K13*$U$3 -> 13.153788 | V13: =K13*$V$3 -> 6.4050659 | W13: =K13*$W$3 -> 22.417731 | X13: =K13*$X$3 -> 47.654922 | Y13: =K13*$Y$3 -> 15.69467 | Z13: =K13*$Z$3 -> 81.55127 | AB13: =H13/$H$39 -> 0.011669441 | AC13: =AB13*$AC$3 -> 77.551601
B14: 223 | C14: OICA | H14: 0 | J14: =H14/$I$35 -> 0 | K14: =H14/$I$37 -> 0 | L14: =J14*$L$3 -> 0 | M14: =J14*$M$3 -> 0 | N14: =J14*$N$3 -> 0 | O14: =J14*$O$3 -> 0 | P14: =J14*$P$3 -> 0 | Q14: =K14*$Q$3 -> 0 | R14: =K14*$R$3 -> 0 | S14: =K14*$S$3 -> 0 | T14: =K14*$T$3 -> 0 | U14: =K14*$U$3 -> 0 | V14: =K14*$V$3 -> 0 | W14: =K14*$W$3 -> 0 | X14: =K14*$X$3 -> 0 | Y14: =K14*$Y$3 -> 0 | Z14: =K14*$Z$3 -> 0 | AB14: =H14/$H$39 -> 0 | AC14: =AB14*$AC$3 -> 0
B15: 334 | C15: NRTC - Admin | H15: 0 | J15: =H15/$I$35 -> 0 | K15: =H15/$I$37 -> 0 | L15: =J15*$L$3 -> 0 | M15: =J15*$M$3 -> 0 | N15: =J15*$N$3 -> 0 | O15: =J15*$O$3 -> 0 | P15: =J15*$P$3 -> 0 | Q15: =K15*$Q$3 -> 0 | R15: =K15*$R$3 -> 0 | S15: =K15*$S$3 -> 0 | T15: =K15*$T$3 -> 0 | U15: =K15*$U$3 -> 0 | V15: =K15*$V$3 -> 0 | W15: =K15*$W$3 -> 0 | X15: =K15*$X$3 -> 0 | Y15: =K15*$Y$3 -> 0 | Z15: =K15*$Z$3 -> 0 | AB15: =H15/$H$39 -> 0 | AC15: =AB15*$AC$3 -> 0
B16: 334H | C16: NRTC - Housing | H16: 1150 | J16: =H16/$I$35 -> 0.010660232 | K16: =H16/$I$37 -> 0.0095170282 | L16: =J16*$L$3 -> 69.621227 | M16: =J16*$M$3 -> 16.283078 | N16: =J16*$N$3 -> 17.041127 | O16: =J16*$O$3 -> 3.3472062 | P16: =J16*$P$3 -> 14.18621 | Q16: =K16*$Q$3 -> 0 | R16: =K16*$R$3 -> 28.608187 | S16: =K16*$S$3 -> 46.633438 | T16: =K16*$T$3 -> 0 | U16: =K16*$U$3 -> 6.0979406 | V16: =K16*$V$3 -> 2.9693128 | W16: =K16*$W$3 -> 10.392595 | X16: =K16*$X$3 -> 22.092258 | Y16: =K16*$Y$3 -> 7.2758632 | Z16: =K16*$Z$3 -> 37.806204 | AB16: =H16/$H$39 -> 0.0054098146 | AC16: =AB16*$AC$3 -> 35.952005
B17: 334F | C17: NRTC FOC | H17: 0 | J17: =H17/$I$35 -> 0 | K17: =H17/$I$37 -> 0 | L17: =J17*$L$3 -> 0 | M17: =J17*$M$3 -> 0 | N17: =J17*$N$3 -> 0 | O17: =J17*$O$3 -> 0 | P17: =J17*$P$3 -> 0 | Q17: =K17*$Q$3 -> 0 | R17: =K17*$R$3 -> 0 | S17: =K17*$S$3 -> 0 | T17: =K17*$T$3 -> 0 | U17: =K17*$U$3 -> 0 | V17: =K17*$V$3 -> 0 | W17: =K17*$W$3 -> 0 | X17: =K17*$X$3 -> 0 | Y17: =K17*$Y$3 -> 0 | Z17: =K17*$Z$3 -> 0 | AB17: =H17/$H$39 -> 0 | AC17: =AB17*$AC$3 -> 0
B18: 335 | C18: NRTC 19 | H18: 846.15 | J18: =H18/$I$35 -> 0.0078436131 | K18: =H18/$I$37 -> 0.0070024638 | L18: =J18*$L$3 -> 51.226088 | M18: =J18*$M$3 -> 11.980805 | N18: =J18*$N$3 -> 12.538565 | O18: =J18*$O$3 -> 2.4628161 | P18: =J18*$P$3 -> 10.437967 | Q18: =K18*$Q$3 -> 0 | R18: =K18*$R$3 -> 21.049406 | S18: =K18*$S$3 -> 34.312073 | T18: =K18*$T$3 -> 0 | U18: =K18*$U$3 -> 4.4867587 | V18: =K18*$V$3 -> 2.1847687 | W18: =K18*$W$3 -> 7.6466905 | X18: =K18*$X$3 -> 16.255099 | Y18: =K18*$Y$3 -> 5.3534536 | Z18: =K18*$Z$3 -> 27.817148 | AB18: =H18/$H$39 -> 0.0039804475 | AC18: =AB18*$AC$3 -> 26.45286
B19: 368 | C19: Wells Fargo | H19: 5985.24 | J19: =H19/$I$35 -> 0.055481779 | K19: =H19/$I$37 -> 0.049531911 | L19: =J19*$L$3 -> 362.34761 | M19: =J19*$M$3 -> 84.746197 | N19: =J19*$N$3 -> 88.691507 | O19: =J19*$O$3 -> 17.420724 | P19: =J19*$P$3 -> 73.832932 | Q19: =K19*$Q$3 -> 0 | R19: =K19*$R$3 -> 148.89292 | S19: =K19*$S$3 -> 242.70636 | T19: =K19*$T$3 -> 0 | U19: =K19*$U$3 -> 31.737077 | V19: =K19*$V$3 -> 15.453956 | W19: =K19*$W$3 -> 54.088847 | X19: =K19*$X$3 -> 114.98041 | Y19: =K19*$Y$3 -> 37.867641 | Z19: =K19*$Z$3 -> 196.76453 | AB19: =H19/$H$39 -> 0.028155686 | AC19: =AB19*$AC$3 -> 187.11424
B20: 451 | C20: USJP | H20: 14938.24 | J20: =H20/$I$35 -> 0.138474 | K20: =H20/$I$37 -> 0.12362404 | L20: =J20*$L$3 -> 904.364 | M20: =J20*$M$3 -> 211.5135 | N20: =J20*$N$3 -> 221.36038 | O20: =J20*$O$3 -> 43.479451 | P20: =J20*$P$3 -> 184.27566 | Q20: =K20*$Q$3 -> 0 | R20: =K20*$R$3 -> 371.61388 | S20: =K20*$S$3 -> 605.75782 | T20: =K20*$T$3 -> 0 | U20: =K20*$U$3 -> 79.21087 | V20: =K20*$V$3 -> 38.570702 | W20: =K20*$W$3 -> 134.99746 | X20: =K20*$X$3 -> 286.97344 | Y20: =K20*$Y$3 -> 94.511818 | Z20: =K20*$Z$3 -> 491.09404 | AB20: =H20/$H$39 -> 0.070272269 | AC20: =AB20*$AC$3 -> 467.00842
B21: 452 | C21: PACE | H21: 0 | J21: =H21/$I$35 -> 0 | K21: =H21/$I$37 -> 0 | L21: =J21*$L$3 -> 0 | M21: =J21*$M$3 -> 0 | N21: =J21*$N$3 -> 0 | O21: =J21*$O$3 -> 0 | P21: =J21*$P$3 -> 0 | Q21: =K21*$Q$3 -> 0 | R21: =K21*$R$3 -> 0 | S21: =K21*$S$3 -> 0 | T21: =K21*$T$3 -> 0 | U21: =K21*$U$3 -> 0 | V21: =K21*$V$3 -> 0 | W21: =K21*$W$3 -> 0 | X21: =K21*$X$3 -> 0 | Y21: =K21*$Y$3 -> 0 | Z21: =K21*$Z$3 -> 0 | AB21: =H21/$H$39 -> 0 | AC21: =AB21*$AC$3 -> 0
B22: 454 | C22: Prudential #1 Workforce | K22: =H22/$I$37 -> 0 | Q22: =K22*$Q$3 -> 0 | R22: =K22*$R$3 -> 0 | S22: =K22*$S$3 -> 0 | T22: =K22*$T$3 -> 0 | U22: =K22*$U$3 -> 0 | V22: =K22*$V$3 -> 0 | W22: =K22*$W$3 -> 0 | X22: =K22*$X$3 -> 0 | Y22: =K22*$Y$3 -> 0 | Z22: =K22*$Z$3 -> 0
B23: 467 | C23: WF - United Airlines | H23: 9532.71 | J23: =H23/$I$35 -> 0.088365998 | K23: =H23/$I$37 -> 0.078889626 | L23: =J23*$L$3 -> 577.11215 | M23: =J23*$M$3 -> 134.97553 | N23: =J23*$N$3 -> 141.25923 | O23: =J23*$O$3 -> 27.74604 | P23: =J23*$P$3 -> 117.59394 | Q23: =K23*$Q$3 -> 0 | R23: =K23*$R$3 -> 237.14222 | S23: =K23*$S$3 -> 386.55917 | T23: =K23*$T$3 -> 0 | U23: =K23*$U$3 -> 50.547739 | V23: =K23*$V$3 -> 24.613563 | W23: =K23*$W$3 -> 86.147472 | X23: =K23*$X$3 -> 183.12964 | Y23: =K23*$Y$3 -> 60.311908 | Z23: =K23*$Z$3 -> 313.38746 | AB23: =H23/$H$39 -> 0.044843647 | AC23: =AB23*$AC$3 -> 298.01742
B24: 468 | C24: Newark Alliance | H24: 6307.7 | J24: =H24/$I$35 -> 0.058470907 | K24: =H24/$I$37 -> 0.052200486 | L24: =J24*$L$3 -> 381.8694 | M24: =J24*$M$3 -> 89.311972 | N24: =J24*$N$3 -> 93.469839 | O24: =J24*$O$3 -> 18.35928 | P24: =J24*$P$3 -> 77.810745 | Q24: =K24*$Q$3 -> 0 | R24: =K24*$R$3 -> 156.91466 | S24: =K24*$S$3 -> 255.78238 | T24: =K24*$T$3 -> 0 | U24: =K24*$U$3 -> 33.446939 | V24: =K24*$V$3 -> 16.286552 | W24: =K24*$W$3 -> 57.002931 | X24: =K24*$X$3 -> 121.17508 | Y24: =K24*$Y$3 -> 39.907793 | Z24: =K24*$Z$3 -> 207.36539 | AB24: =H24/$H$39 -> 0.029672598 | AC24: =AB24*$AC$3 -> 197.19518
B25: 502 | C25: ESG | H25: 1678.6 | J25: =H25/$I$35 -> 0.01556023 | K25: =H25/$I$37 -> 0.013891551 | L25: =J25*$L$3 -> 101.62278 | M25: =J25*$M$3 -> 23.76763 | N25: =J25*$N$3 -> 24.874118 | O25: =J25*$O$3 -> 4.8857567 | P25: =J25*$P$3 -> 20.706932 | Q25: =K25*$Q$3 -> 0 | R25: =K25*$R$3 -> 41.758002 | S25: =K25*$S$3 -> 68.068599 | T25: =K25*$T$3 -> 0 | U25: =K25*$U$3 -> 8.9008723 | V25: =K25*$V$3 -> 4.3341639 | W25: =K25*$W$3 -> 15.169574 | X25: =K25*$X$3 -> 32.247013 | Y25: =K25*$Y$3 -> 10.62023 | Z25: =K25*$Z$3 -> 55.183908 | AB25: =H25/$H$39 -> 0.0078964477 | AC25: =AB25*$AC$3 -> 52.477422
B26: 515 | C26: FOC - HUD NUL PARS | H26: 1730.77 | J26: =H26/$I$35 -> 0.016043834 | K26: =H26/$I$37 -> 0.014323293 | L26: =J26*$L$3 -> 104.78116 | M26: =J26*$M$3 -> 24.506315 | N26: =J26*$N$3 -> 25.647192 | O26: =J26*$O$3 -> 5.0376035 | P26: =J26*$P$3 -> 21.350493 | Q26: =K26*$Q$3 -> 0 | R26: =K26*$R$3 -> 43.055819 | S26: =K26*$S$3 -> 70.184135 | T26: =K26*$T$3 -> 0 | U26: =K26*$U$3 -> 9.1775067 | V26: =K26*$V$3 -> 4.4688674 | W26: =K26*$W$3 -> 15.641036 | X26: =K26*$X$3 -> 33.249233 | Y26: =K26*$Y$3 -> 10.950301 | Z26: =K26*$Z$3 -> 56.898995 | AB26: =H26/$H$39 -> 0.0081418651 | AC26: =AB26*$AC$3 -> 54.108393
B27: 525 | C27: CDBG - Housing | H27: 2900 | J27: =H27/$I$35 -> 0.026882323 | K27: =H27/$I$37 -> 0.023999462 | L27: =J27*$L$3 -> 175.56657 | M27: =J27*$M$3 -> 41.061674 | N27: =J27*$N$3 -> 42.973276 | O27: =J27*$O$3 -> 8.4407807 | P27: =J27*$P$3 -> 35.773921 | Q27: =K27*$Q$3 -> 0 | R27: =K27*$R$3 -> 72.142384 | S27: =K27*$S$3 -> 117.59737 | T27: =K27*$T$3 -> 0 | U27: =K27*$U$3 -> 15.377416 | V27: =K27*$V$3 -> 7.4878323 | W27: =K27*$W$3 -> 26.207413 | X27: =K27*$X$3 -> 55.710912 | Y27: =K27*$Y$3 -> 18.347829 | Z27: =K27*$Z$3 -> 95.337384 | AB27: =H27/$H$39 -> 0.013642141 | AC27: =AB27*$AC$3 -> 90.661578
B28: 560 | C28: CAP 1 - Save Up | H28: 0 | J28: =H28/$I$35 -> 0 | K28: =H28/$I$37 -> 0 | L28: =J28*$L$3 -> 0 | M28: =J28*$M$3 -> 0 | N28: =J28*$N$3 -> 0 | O28: =J28*$O$3 -> 0 | P28: =J28*$P$3 -> 0 | Q28: =K28*$Q$3 -> 0 | R28: =K28*$R$3 -> 0 | S28: =K28*$S$3 -> 0 | T28: =K28*$T$3 -> 0 | U28: =K28*$U$3 -> 0 | V28: =K28*$V$3 -> 0 | W28: =K28*$W$3 -> 0 | X28: =K28*$X$3 -> 0 | Y28: =K28*$Y$3 -> 0 | Z28: =K28*$Z$3 -> 0 | AB28: =H28/$H$39 -> 0 | AC28: =AB28*$AC$3 -> 0
B29: 561 | C29: LISC FOC 2019 | H29: 4384.62 | J29: =H29/$I$35 -> 0.040644405 | K29: =H29/$I$37 -> 0.036285698 | L29: =J29*$L$3 -> 265.44576 | M29: =J29*$M$3 -> 62.082702 | N29: =J29*$N$3 -> 64.972926 | O29: =J29*$O$3 -> 12.761937 | P29: =J29*$P$3 -> 54.087948 | Q29: =K29*$Q$3 -> 0 | R29: =K29*$R$3 -> 109.07481 | S29: =K29*$S$3 -> 177.79992 | T29: =K29*$T$3 -> 0 | U29: =K29*$U$3 -> 23.249698 | V29: =K29*$V$3 -> 11.321138 | W29: =K29*$W$3 -> 39.623982 | X29: =K29*$X$3 -> 84.231441 | Y29: =K29*$Y$3 -> 27.740779 | Z29: =K29*$Z$3 -> 144.14421 | AB29: =H29/$H$39 -> 0.020626071 | AC29: =AB29*$AC$3 -> 137.07468
B30: 563 | C30: Prudential #1 FOC | H30: 2993.49 | J30: =H30/$I$35 -> 0.027748954 | K30: =H30/$I$37 -> 0.024773155 | L30: =J30*$L$3 -> 181.22648 | M30: =J30*$M$3 -> 42.385417 | N30: =J30*$N$3 -> 44.358645 | O30: =J30*$O$3 -> 8.7128941 | P30: =J30*$P$3 -> 36.927198 | Q30: =K30*$Q$3 -> 0 | R30: =K30*$R$3 -> 74.468105 | S30: =K30*$S$3 -> 121.38846 | T30: =K30*$T$3 -> 0 | U30: =K30*$U$3 -> 15.873152 | V30: =K30*$V$3 -> 7.7292245 | W30: =K30*$W$3 -> 27.052286 | X30: =K30*$X$3 -> 57.506917 | Y30: =K30*$Y$3 -> 18.939325 | Z30: =K30*$Z$3 -> 98.410864 | AB30: =H30/$H$39 -> 0.014081936 | AC30: =AB30*$AC$3 -> 93.58432
