Workbook

Sheet June Salary & Benefits 
B2: Payroll Register Attached | K2: Check Date | L2: Pay Period
K3: 43658 | L3: 06/23/19 - 07/06/19
K4: 43672 | L4: 07/07/19 - 07/20/19
B8: Salary Breakdown | C8: 43658 | D8: 43672 | F8: Total | G8: USJP Hours | H8: Allocation Rate
J9: Report | K9: GL
B10: COO Patricia Sermon | C10: 0 | D10: 0 | E10: 0 | F10: =SUM(C10:E10) -> 0 | H10: 0.5 | I10: =F10*H10 -> 0
B11: Director Gwendolyn Morris | F11: =SUM(C11:E11) -> 0 | H11: 1 | I11: =F11*H11 -> 0
B12: Director Gwendolyn Morris - Program | F12: =SUM(C12:E12) -> 0 | H12: 1 | I12: =F12*H12 -> 0
B13: Site Coordinator (Essex) Rahmel Leake - Program | F13: =SUM(C13:E13) -> 0 | H13: 0.2 | I13: =F13*H13 -> 0 | J13: =SUM(I10:I13) -> 0 | K13: =SUM(I10:I13) -> 0
B14: Site Coordinator (Passaic) Irene Cerna - Program
B15: Site Coordinator (Morris) Alberto Almanzar - Program | F15: =SUM(C15:E15) -> 0 | H15: 1 | I15: =F15*H15 -> 0 | J15: =I15 -> 0 | K15: =I15 -> 0 | L15: Educational Services
B16: Program Assistant Joanna Martinez - Admin
B17: Program Assistant Joanna Martinez - Program
B18: Staff Accountant - TBH | F18: =SUM(C18:E18) -> 0
F19: =SUM(C19:E19) -> 0
C20: =SUM(C10:C19) -> 0 | D20: =SUM(D10:D19) -> 0 | E20: =SUM(E10:E19) -> 0 | F20: =SUM(F10:F19) -> 0 | I20: =SUM(I10:I19) -> 0 | J20: =SUM(J10:J19) -> 0 | K20: =SUM(K10:K19) -> 0
B22: Payroll Taxes | I22: 0
B23: Payroll Fee Allocation | I23: 0 | J23: =SUM(I22:I23) -> 0 | K23: =J23 -> 0
B26: Benefits | C26: Medical | D26: Dental | F26: Total | H26: Allocation Rate
J27: Report | K27: GL
B28: Sermon | C28: 1118.65 | D28: 63.88 | F28: =SUM(C28:E28) -> 1182.53 | H28: 0.5 | I28: 0 | J28: =SUM(I28:I30) -> 0 | K28: =J28 -> 0
B29: Birdsong | F29: =SUM(C29:E29) -> 0 | H29: 1 | I29: =F29*H29 -> 0
B30: Cooper | F30: =SUM(C30:E30) -> 0 | H30: 1 | I30: =F30*H30 -> 0
B31: Johnson | C31: 1073.08 | D31: 67.82 | F31: =SUM(C31:E31) -> 1140.9 | H31: 0.2 | I31: 0 | J31: =I31 -> 0 | K31: =J31 -> 0
B32: Johnson | F32: =SUM(C32:E32) -> 0 | H32: 1 | I32: =F32*H32 -> 0 | J32: =I32 -> 0 | K32: =J32 -> 0
B33: Aikens | F33: =SUM(C33:E33) -> 0 | H33: 1 | I33: 0 | J33: =I33 -> 0 | K33: =J33 -> 0
F34: =SUM(C34:E34) -> 0 | J34: =SUM(J28:J33) -> 0 | K34: =SUM(K28:K33) -> 0
F35: =SUM(C35:E35) -> 0
F36: =SUM(C36:E36) -> 0
C37: =SUM(C28:C36) -> 2191.73 | D37: =SUM(D28:D36) -> 131.7 | F37: =SUM(F28:F36) -> 2323.43 | I37: =SUM(I28:I36) -> 0
I39: =I22+I37+I23 -> 0 | J39: =J34+J23 -> 0 | K39: =K34+K23 -> 0

Sheet Salaries & Fringe Allocations
A1: Urban Seniors Jobs Program PY 19 | D1: Month | E1: September
A2: ='Jul-2019'!A2 -> Urban League of Essex County | D2: Year | E2: 2019
A4: Payroll Period 07/01/19 - 07/06/19 | B4: Check Date | D4: 43658
A5: Staff Member | B5: USJP HOURS | C5: Total Hours | D5: Time Allocation (%) | E5: Total Salary | F5: USJP Salary | H5: ER Taxes Monthly Allocation | I5: Payroll Fees Monthly Allocation | J5: Monthly Health Ins. Medical | K5: Bi-weekly Medical Deduction | L5: Dental & Life Insurance | M5: Biweekly Dental Insur Deduction | N5: W/Comp Monthly Allocation | O5: Pension | P5: Enter other | Q5: Total Benefits
A6: COO Patricia Sermon - Admin | B6: 7 | C6: 35 | D6: =B6/C6 -> 0.2 | E6: =3153.85-1576.93 -> 1576.92 | F6: =ROUND(D6*E6,2) -> 315.38 | K6: =-103.26*D6 -> -20.652 | M6: =-3.37*D6 -> -0.674 | Q6: =SUM(H6:P6) -> -21.326
A7: Director Gwendolyn Morris - Admin | B7: 14.5 | C7: 35 | D7: =B7/C7 -> 0.41428571 | E7: =2500/2 -> 1250 | F7: =ROUND(D7*E7,2) -> 517.86 | K7: =-94.11*D7 -> -38.988429 | M7: =-3.37*D7 -> -1.3961429 | Q7: =SUM(H7:P7) -> -40.384571
A8: Director Gwendolyn Morris - Program | B8: 20.5 | C8: 35 | D8: =B8/C8 -> 0.58571429 | F8: =ROUND(D8*E7,2) -> 732.14 | K8: =-94.11*D8 -> -55.121571 | M8: =-3.37*D8 -> -1.9738571 | Q8: =SUM(H8:P8) -> -57.095429
A9: Site Coordinator (Essex) Rahmel Leake - Program | B9: 0 | C9: 0 | D9: 0 | E9: 0 | F9: =ROUND(E9,2) -> 0 | K9: 0 | Q9: =SUM(H9:P9) -> 0
A10: Site Coordinator (Passaic) Irene Cerna - Program | B10: 35 | C10: 35 | D10: =B10/C10 -> 1 | E10: =1038.47-461.44 -> 577.03 | F10: =ROUND(E10,2) -> 577.03 | K10: =-103.26*D10 -> -103.26 | Q10: =SUM(H10:P10) -> -103.26
A11: Site Coordinator (Morris) Alberto Almanzar - Program | B11: 24 | C11: =+B11 -> 24 | D11: =B11/C11 -> 1 | E11: =1278.68-932.6 -> 346.08 | F11: =ROUND(E11,2) -> 346.08 | K11: 0 | Q11: =SUM(H11:P11) -> 0
A12: Program Assistant Joanna Martinez - Admin | B12: 15 | C12: 35 | D12: =B12/C12 -> 0.42857143 | E12: =2538.47-1769.23 -> 769.24 | F12: =ROUND(D12*E12,2) -> 329.67 | K12: =-191.25*D12 -> -81.964286 | M12: =-6.08*D12 -> -2.6057143 | Q12: =SUM(H12:P12) -> -84.57
A13: Program Assistant Joanna Martinez - Program | B13: 20 | C13: 35 | D13: =B13/C13 -> 0.57142857 | F13: =ROUND(D13*E12,2) -> 439.57 | K13: =-191.25*D13 -> -109.28571 | M13: =-6.08*D13 -> -3.4742857 | Q13: =SUM(H13:P13) -> -112.76
A14: Staff Accountant - TBH | Q14: =SUM(H14:P14) -> 0
A15: Total | C15: =SUM(C6:C14) -> 234 | E15: =SUBTOTAL(109,'Salaries & Fringe Allocations'!E6:E14) -> 4519.27 | F15: =SUBTOTAL(109,'Salaries & Fringe Allocations'!F6:F14) -> 3257.73 | H15: =SUBTOTAL(109,'Salaries & Fringe Allocations'!H6:H14) -> 0 | I15: =SUBTOTAL(109,'Salaries & Fringe Allocations'!I6:I14) -> 0 | J15: =SUBTOTAL(109,'Salaries & Fringe Allocations'!J6:J14) -> 0 | K15: =SUBTOTAL(109,'Salaries & Fringe Allocations'!K6:K14) -> -409.272 | L15: =SUBTOTAL(109,'Salaries & Fringe Allocations'!L6:L14) -> 0 | M15: =SUBTOTAL(109,'Salaries & Fringe Allocations'!M6:M14) -> -10.124 | N15: =SUBTOTAL(109,'Salaries & Fringe Allocations'!N6:N14) -> 0 | O15: =SUBTOTAL(109,'Salaries & Fringe Allocations'!O6:O14) -> 0 | ... Q15: =SUBTOTAL(109,'Salaries & Fringe Allocations'!Q6:Q14) -> -419.396
A17: Payroll Period Ending 07/07/19 - 07/20/19 | B17: Check Date | D17: 43672
A18: Staff Member | B18: USJP HOURS | C18: Total Hours | D18: Time Allocation (%) | E18: Total Salary | F18: USJP Salary | H18: ER Taxes Monthly Allocation | I18: Payroll Fees Monthly Allocation | J18: Monthly Health Ins. Medical | K18: Bi-weekly Medical Deduction | L18: Dental & Life Insurance | M18: Biweekly Dental Insur Deduction | N18: W/Comp Monthly Allocation | O18: Pension | P18: Enter other | Q18: Total Benefits
A19: COO Patricia Sermon - Admin | B19: 14 | C19: 70 | D19: =B19/C19 -> 0.2 | E19: 3153.85 | F19: =ROUND(D19*E19,2) -> 630.77 | K19: =-103.26*D19 -> -20.652 | M19: =-3.37*D19 -> -0.674 | Q19: =SUM(H19:P19) -> -21.326
A20: Director Gwendolyn Morris - Admin | B20: =14+15 -> 29 | C20: 70 | D20: =B20/C20 -> 0.41428571 | E20: 2500 | F20: =ROUND(D20*E20,2) -> 1035.71 | K20: =-97.01*D20 -> -40.189857 | M20: =-3.37*D20 -> -1.3961429 | Q20: =SUM(H20:P20) -> -41.586
A21: Director Gwendolyn Morris - Program | B21: =21+20 -> 41 | D21: =B21/C20 -> 0.58571429 | E21: 0 | F21: =ROUND(D21*E20,2) -> 1464.29 | K21: =-97.01*D21 -> -56.820143 | M21: =-3.37*D21 -> -1.9738571 | Q21: =SUM(H21:P21) -> -58.794
A22: Site Coordinator (Essex) Rahmel Leake - Program | B22: 35 | C22: 35 | D22: =B22/C22 -> 1 | E22: 769.24 | F22: =ROUND(D22*E22,2) -> 769.24 | K22: 0 | Q22: =SUM(H22:P22) -> 0
A23: Site Coordinator (Passaic) Irene Cerna - Program | B23: 70 | C23: 70 | D23: =B23/C23 -> 1 | E23: 1153.85 | F23: =ROUND(D23*E23,2) -> 1153.85 | K23: =-103.26*D23 -> -103.26 | Q23: =SUM(H23:P23) -> -103.26
A24: Site Coordinator (Morris) Alberto Almanzar - Program | B24: 60 | C24: 60 | D24: =B24/C24 -> 1 | E24: 865.2 | F24: =ROUND(D24*E24,2) -> 865.2 | K24: 0 | Q24: =SUM(H24:P24) -> 0
A25: Program Assistant Joanna Martinez - Admin | B25: 30 | C25: 70 | D25: =B25/C25 -> 0.42857143 | E25: 1538.47 | F25: =ROUND(D25*E25,2) -> 659.34 | K25: =-127.17*D25 -> -54.501429 | M25: =-6.08*D25 -> -2.6057143 | Q25: =SUM(H25:P25) -> -57.107143
A26: Program Assistant Joanna Martinez - Program | B26: 40 | D26: =B26/C25 -> 0.57142857 | E26: 0 | F26: =ROUND(D26*E25,2) -> 879.13 | K26: =-127.17*D26 -> -72.668571 | M26: =-6.08*D26 -> -3.4742857 | Q26: =SUM(H26:P26) -> -76.142857
A27: Staff Accountant - TBH | Q27: =SUM(H27:P27) -> 0
A28: Total | C28: =SUM(C19:C27) -> 375 | E28: =SUBTOTAL(109,'Salaries & Fringe Allocations'!E19:E27) -> 9980.61 | F28: =SUBTOTAL(109,'Salaries & Fringe Allocations'!F19:F27) -> 7457.53 | H28: =SUBTOTAL(109,'Salaries & Fringe Allocations'!H19:H27) -> 0 | I28: =SUBTOTAL(109,'Salaries & Fringe Allocations'!I19:I27) -> 0 | J28: =SUBTOTAL(109,'Salaries & Fringe Allocations'!J19:J27) -> 0 | K28: =SUBTOTAL(109,'Salaries & Fringe Allocations'!K19:K27) -> -348.092 | L28: =SUBTOTAL(109,'Salaries & Fringe Allocations'!L19:L27) -> 0 | M28: =SUBTOTAL(109,'Salaries & Fringe Allocations'!M19:M27) -> -10.124 | N28: =SUBTOTAL(109,'Salaries & Fringe Allocations'!N19:N27) -> 0 | O28: =SUBTOTAL(109,'Salaries & Fringe Allocations'!O19:O27) -> 0 | ... Q28: =SUBTOTAL(109,'Salaries & Fringe Allocations'!Q19:Q27) -> -358.216
A30: Monthly Total for July 2019
A31: Staff Member | B31: USJP HOURS | C31: Total Hours | D31: Time Allocation (%) | E31: Total Salary | F31: USJP Salary | G31: Allocation % | H31: ER Taxes Monthly Allocation | I31: Payroll Fees Monthly Allocation | J31: Monthly Health Ins. Medical | K31: Bi-weekly Medical Deduction | L31: Dental & Life Insurance | M31: Biweekly Dental Insur Deduction | N31: W/Comp Monthly Allocation | O31: Pension | P31: Enter other | Q31: Total Benefits
A32: COO Patricia Sermon - Admin | B32: =+B6+B19 -> 21 | C32: =+C6+C19 -> 105 | D32: =B32/C32 -> 0.2 | E32: =+E6+E19 -> 4730.77 | F32: =ROUND(D32*E32,2) -> 946.15 | G32: =+F32/$F$41 -> 0.088299304 | H32: =+G32*'Jul-2019 GL'!$G$60 -> 94.950891 | I32: =+G32*'Jul-2019 GL'!$G$63 -> 12.40252 | J32: =1118.65*D32 -> 223.73 | K32: =+K6+K19 -> -41.304 | L32: =63.88*D32 -> 12.776 | M32: =+M6+M19 -> -1.348 | N32: =+$G32*'Jul-2019 GL'!$G$45 -> 32.767872 | O32: =+O6+O19 -> 0 | P32: =+P6+P19 -> 0 | Q32: =SUM(H32:P32) -> 333.97528 | R32: ADMIN
A33: Director Gwendolyn Morris - Admin | B33: =+B7+B20 -> 43.5 | C33: =+C7+C20 -> 105 | D33: =B33/C33 -> 0.41428571 | E33: =+E7+E20 -> 3750 | F33: =ROUND(D33*E33,2) -> 1553.57 | G33: =+F33/$F$41 -> 0.14498668 | H33: =+G33*'Jul-2019 GL'!$G$60 -> 155.90853 | I33: =+G33*'Jul-2019 GL'!$G$63 -> 20.364829 | J33: =1050.94*D33 -> 435.38943 | K33: =+K7+K20 -> -79.178286 | L33: =79.63*D33 -> 32.989571 | M33: =+M7+M20 -> -2.7922857 | N33: =+$G33*'Jul-2019 GL'!$G$45 -> 53.804558 | O33: =+O7+O20 -> 0 | P33: =+P7+P20 -> 0 | Q33: =SUM(H33:P33) -> 616.48635 | R33: ADMIN
A34: Director Gwendolyn Morris - Program | B34: =+B8+B21 -> 61.5 | D34: =B34/C33 -> 0.58571429 | E34: =+E8+E21 -> 0 | F34: =ROUND(D34*E33,2) -> 2196.43 | G34: =+F34/$F$41 -> 0.20498149 | H34: =+G34*'Jul-2019 GL'!$G$60 -> 220.42275 | I34: =+G34*'Jul-2019 GL'!$G$63 -> 28.791701 | J34: =1050.94*D34 -> 615.55057 | K34: =+K8+K21 -> -111.94171 | L34: =79.63*D34 -> 46.640429 | M34: =+M8+M21 -> -3.9477143 | N34: =+$G34*'Jul-2019 GL'!$G$45 -> 76.068632 | O34: =+O8+O21 -> 0 | P34: =+P8+P21 -> 0 | Q34: =SUM(H34:P34) -> 871.58465
A35: Site Coordinator (Essex) Rahmel Leake - Program | B35: =+B9+B22 -> 35 | C35: =+C9+C22 -> 35 | D35: =B35/C35 -> 1 | E35: =+E9+E22 -> 769.24 | F35: =ROUND(D35*E35,2) -> 769.24 | G35: =+F35/$F$41 -> 0.071789205 | H35: =+G35*'Jul-2019 GL'!$G$60 -> 77.197086 | I35: =+G35*'Jul-2019 GL'!$G$63 -> 10.083512 | J35: 0 | K35: =+K9+K22 -> 0 | L35: 0 | M35: =+M9+M22 -> 0 | N35: =+$G35*'Jul-2019 GL'!$G$45 -> 26.640974 | O35: =+O9+O22 -> 0 | P35: =+P9+P22 -> 0 | Q35: =SUM(H35:P35) -> 113.92157
A36: Site Coordinator (Passaic) Irene Cerna - Program | B36: =+B10+B23 -> 105 | C36: =+C10+C23 -> 105 | D36: =B36/C36 -> 1 | E36: =+E10+E23 -> 1730.88 | F36: =ROUND(D36*E36,2) -> 1730.88 | G36: =+F36/$F$41 -> 0.16153411 | H36: =+G36*'Jul-2019 GL'!$G$60 -> 173.70248 | I36: =+G36*'Jul-2019 GL'!$G$63 -> 22.689081 | J36: 1118.65 | K36: =+K10+K23 -> -206.52 | L36: 0 | M36: =+M10+M23 -> 0 | N36: =+$G36*'Jul-2019 GL'!$G$45 -> 59.945309 | O36: =+O10+O23 -> 0 | P36: =+P10+P23 -> 0 | Q36: =SUM(H36:P36) -> 1168.4669
A37: Site Coordinator (Morris) Alberto Almanzar - Program | B37: =+B11+B24 -> 84 | C37: =+C11+C24 -> 84 | D37: =B37/C37 -> 1 | E37: =+E11+E24 -> 1211.28 | F37: =ROUND(D37*E37,2) -> 1211.28 | G37: =+F37/$F$41 -> 0.11304252 | H37: =+G37*'Jul-2019 GL'!$G$60 -> 121.55801 | I37: =+G37*'Jul-2019 GL'!$G$63 -> 15.877952 | J37: 0 | K37: =+K11+K24 -> 0 | L37: 0 | M37: =+M11+M24 -> 0 | N37: =+$G37*'Jul-2019 GL'!$G$45 -> 41.950079 | O37: =+O11+O24 -> 0 | P37: =+P11+P24 -> 0 | Q37: =SUM(H37:P37) -> 179.38605
A38: Program Assistant Joanna Martinez - Admin | B38: =+B12+B25 -> 45 | C38: =+C12+C25 -> 105 | D38: =B38/C38 -> 0.42857143 | E38: =+E12+E25 -> 2307.71 | F38: =ROUND(D38*E38,2) -> 989.02 | G38: =+F38/$F$41 -> 0.09230014 | H38: =+G38*'Jul-2019 GL'!$G$60 -> 99.25311 | I38: =+G38*'Jul-2019 GL'!$G$63 -> 12.964478 | J38: =1377.69*D38 -> 590.43857 | K38: =+K12+K25 -> -136.46571 | L38: =77.55*D38 -> 33.235714 | M38: =+M12+M25 -> -5.2114286 | N38: =+$G38*'Jul-2019 GL'!$G$45 -> 34.252582 | O38: =+O12+O25 -> 0 | P38: =+P12+P25 -> 0 | Q38: =SUM(H38:P38) -> 628.46731 | R38: ADMIN
A39: Program Assistant Joanna Martinez - Program | B39: =+B13+B26 -> 60 | D39: =B39/C38 -> 0.57142857 | E39: =+E13+E26 -> 0 | F39: =ROUND(D39*E38,2) -> 1318.69 | G39: =+F39/$F$41 -> 0.12306654 | H39: =+G39*'Jul-2019 GL'!$G$60 -> 132.33715 | I39: =+G39*'Jul-2019 GL'!$G$63 -> 17.285927 | J39: =1377.69*D39 -> 787.25143 | K39: =+K13+K26 -> -181.95429 | L39: =77.55*D39 -> 44.314286 | M39: =+M13+M26 -> -6.9485714 | N39: =+$G39*'Jul-2019 GL'!$G$45 -> 45.669994 | O39: =+O13+O26 -> 0 | P39: =+P13+P26 -> 0 | Q39: =SUM(H39:P39) -> 837.95592
A40: Staff Accountant - TBH | Q40: =SUM(H40:P40) -> 0 | R40: ADMIN
A41: Total per USJP Report | C41: =SUM(C32:C40) -> 539 | E41: =SUBTOTAL(109,'Salaries & Fringe Allocations'!E32:E40) -> 14499.88 | F41: =SUBTOTAL(109,'Salaries & Fringe Allocations'!F32:F40) -> 10715.26 | G41: =SUM(G32:G40) -> 1 | H41: =SUBTOTAL(109,'Salaries & Fringe Allocations'!H32:H40) -> 1075.33 | I41: =SUBTOTAL(109,'Salaries & Fringe Allocations'!I32:I40) -> 140.46 | J41: =SUBTOTAL(109,'Salaries & Fringe Allocations'!J32:J40) -> 3771.01 | K41: =SUBTOTAL(109,'Salaries & Fringe Allocations'!K32:K40) -> -757.364 | L41: =SUBTOTAL(109,'Salaries & Fringe Allocations'!L32:L40) -> 169.956 | M41: =SUBTOTAL(109,'Salaries & Fringe Allocations'!M32:M40) -> -20.248 | N41: =SUBTOTAL(109,'Salaries & Fringe Allocations'!N32:N40) -> 371.1 | O41: =SUBTOTAL(109,'Salaries & Fringe Allocations'!O32:O40) -> 0 | ... Q41: =SUBTOTAL(109,'Salaries & Fringe Allocations'!Q32:Q40) -> 4750.244
A45: Payroll Period 07/21/19 - 08/03/19 | B45: Check Date | D45: 43686
A46: Staff Member | B46: USJP HOURS | C46: Total Hours | D46: Time Allocation (%) | E46: Total Salary | F46: USJP Salary | H46: ER Taxes Monthly Allocation | I46: Payroll Fees Monthly Allocation | J46: Monthly Health Ins. Medical | K46: Bi-weekly Medical Deduction | L46: Dental & Life Insurance | M46: Biweekly Dental Insur Deduction | N46: W/Comp Monthly Allocation | O46: Pension | P46: Enter other | Q46: Total Benefits
...

Sheet Jul-2019
A1: Urban Seniors Jobs Program PY 19 | E1: Invoice # 1 | G1: 43647 | I1: %
A2: Urban League of Essex County | I2: Spent
A3: 1. PERSONNEL | E3: TOTAL
C4: ENROLLEE | D4: OPC | E4: MONTHLY | F4: CUMULATIVE | G4: TOTAL | H4: BUDGET
A5: POSITION TITLE | B5: ADMIN | C5: WAGES & FB | D5: PROGRAM | E5: AMOUNT | F5: EXPENSES | G5: BUDGET | H5: REMAINING
A6: COO Patricia Sermon | B6: =+'Salaries & Fringe Allocations'!F32 -> 946.15 | E6: =SUM(B6:D6) -> 946.15 | F6: =E6 -> 946.15 | G6: 16400 | H6: =G6-F6 -> 15453.85 | I6: =F6/G6 -> 0.057692073
A7: Director Gwendolyn Morris | B7: =+'Salaries & Fringe Allocations'!F33 -> 1553.57 | D7: =+'Salaries & Fringe Allocations'!F34 -> 2196.43 | E7: =SUM(B7:D7) -> 3750 | F7: =E7 -> 3750 | G7: 66000 | H7: =G7-F7 -> 62250 | I7: =F7/G7 -> 0.056818182
A8: Prog Site Coordinator (Essex) Rahmel Leake | D8: =+'Salaries & Fringe Allocations'!F35 -> 769.24 | E8: =SUM(B8:D8) -> 769.24 | F8: =E8 -> 769.24 | G8: 40000 | H8: =G8-F8 -> 39230.76 | I8: =F8/G8 -> 0.019231
A9: Prog Site Coordinator (Passaic) Irene Cerna | D9: =+'Salaries & Fringe Allocations'!F36 -> 1730.88 | E9: =SUM(B9:D9) -> 1730.88 | F9: =E9 -> 1730.88 | G9: 30000 | H9: =G9-F9 -> 28269.12 | I9: =F9/G9 -> 0.057696
A10: Prog Site Coordinator (Morris) Alberto Almanzar | D10: =+'Salaries & Fringe Allocations'!F37 -> 1211.28 | E10: =SUM(B10:D10) -> 1211.28 | F10: =E10 -> 1211.28 | G10: 21500 | H10: =G10-F10 -> 20288.72 | I10: =F10/G10 -> 0.056338605
A11: Program Assistant Joanna Martinez | B11: =+'Salaries & Fringe Allocations'!F38 -> 989.02 | D11: =+'Salaries & Fringe Allocations'!F39 -> 1318.69 | E11: =SUM(B11:D11) -> 2307.71 | F11: =E11 -> 2307.71 | G11: 36000 | H11: =G11-F11 -> 33692.29 | I11: =F11/G11 -> 0.064103056
A12: Staff Accountant - TBH | E12: =SUM(B12:D12) -> 0 | F12: =E12 -> 0 | G12: 4000 | H12: =G12-F12 -> 4000 | I12: =F12/G12 -> 0
A16: Total Salaries | B16: =SUM(B6:B15) -> 3488.74 | C16: =SUM(C6:C15) -> 0 | D16: =SUM(D6:D15) -> 7226.52 | E16: =SUM(E6:E15) -> 10715.26 | F16: =SUM(F6:F15) -> 10715.26 | G16: =SUM(G6:G15) -> 213900 | H16: =SUM(H6:H15) -> 203184.74 | I16: =F16/G16 -> 0.050094717
A18: Fringe Benefits Rate | B18: =+'Salaries & Fringe Allocations'!Q32+'Salaries & Fringe Allocations'!Q33+'Salaries & Fringe Allocations'!Q38+'Salaries & Fringe Allocations'!Q40 -> 1578.9289 | D18: =+'Salaries & Fringe Allocations'!Q34+'Salaries & Fringe Allocations'!Q35+'Salaries & Fringe Allocations'!Q36+'Salaries & Fringe Allocations'!Q37+'Salaries & Fringe Allocations'!Q39 -> 3171.3151 | E18: =SUM(B18:D18) -> 4750.244 | F18: =E18 -> 4750.244 | G18: 68136 | H18: =G18-F18 -> 63385.756 | I18: =F18/G18 -> 0.069717095
A20: TOTAL PERSONNEL (Salaries + Fringe Benefits) | B20: =B16+B18 -> 5067.6689 | C20: =C16+C18 -> 0 | D20: =D16+D18 -> 10397.835 | E20: =E16+E18 -> 15465.504 | F20: =F16+F18 -> 15465.504 | G20: =G16+G18 -> 282036 | H20: =H16+H18 -> 266570.5 | I20: =F20/G20 -> 0.054835213
A22: 2. Non-Personnel Operating Costs
A23: Travel | D23: =+'Jul-2019 GL'!G72 -> 268.02 | E23: =SUM(B23:D23) -> 268.02 | F23: =E23 -> 268.02 | G23: 4000 | H23: =G23-F23 -> 3731.98 | I23: =F23/G23 -> 0.067005
A24: Supplies | B24: =+'Jul-2019 GL'!G76 -> 55.59 | E24: =SUM(B24:D24) -> 55.59 | F24: =E24 -> 55.59 | G24: 7000 | H24: =G24-F24 -> 6944.41 | I24: =F24/G24 -> 0.0079414286
A25: Staff Development | E25: =SUM(B25:D25) -> 0 | F25: =E25 -> 0 | G25: 2000 | H25: =G25-F25 -> 2000 | I25: =F25/G25 -> 0
A26: Contractual/Consultants | B26: =+'Jul-2019 GL'!G81 -> 361.69 | E26: =SUM(B26:D26) -> 361.69 | F26: =E26 -> 361.69 | G26: 13200 | H26: =G26-F26 -> 12838.31 | I26: =F26/G26 -> 0.027400758
A27: Occupancy | B27: =+'Jul-2019 GL'!G94 -> 332.27 | D27: =+'Jul-2019 GL'!G86 -> 648 | E27: =SUM(B27:D27) -> 980.27 | F27: =E27 -> 980.27 | G27: 12000 | H27: =G27-F27 -> 11019.73 | I27: =F27/G27 -> 0.081689167
A28: Audit (100% Admin) | B28: =+'Jul-2019 GL'!G101 -> 1130.29 | E28: =SUM(B28:D28) -> 1130.29 | F28: =E28 -> 1130.29 | G28: 6000 | H28: =G28-F28 -> 4869.71 | I28: =F28/G28 -> 0.18838167
A29: Marketing and Outreach | E29: =SUM(B29:D29) -> 0 | F29: =E29 -> 0 | G29: 570 | H29: =G29-F29 -> 570 | I29: =F29/G29 -> 0
A30: Rental Equipment | B30: =+'Jul-2019 GL'!G106 -> 200.95 | E30: =SUM(B30:D30) -> 200.95 | F30: =E30 -> 200.95 | G30: 6475 | H30: =G30-F30 -> 6274.05 | I30: =F30/G30 -> 0.031034749
A31: Participant Payroll fees | B31: =+'Jul-2019 GL'!G25 -> 872.26 | E31: =SUM(B31:D31) -> 872.26 | F31: =E31 -> 872.26 | G31: 13000 | H31: =G31-F31 -> 12127.74 | I31: =F31/G31 -> 0.067096923
A32: Infrastructure Costs | E32: =SUM(B32:D32) -> 0 | F32: =E32 -> 0 | G32: 1500 | H32: =G32-F32 -> 1500 | I32: =F32/G32 -> 0
A33: Other Operating costs | B33: =+'Jul-2019 GL'!G115 -> 267.88 | E33: =SUM(B33:D33) -> 267.88 | F33: =E33 -> 267.88 | G33: 3000.7 | H33: =G33-F33 -> 2732.82 | I33: =F33/G33 -> 0.089272503
A34: Communications | B34: =+'Jul-2019 GL'!G129 -> 182.85 | E34: =SUM(B34:D34) -> 182.85 | F34: =E34 -> 182.85 | G34: 3000 | H34: =G34-F34 -> 2817.15 | I34: =F34/G34 -> 0.06095
A35: Insurance | B35: =+'Jul-2019 GL'!G134 -> 320.72 | E35: =SUM(B35:D35) -> 320.72 | F35: =E35 -> 320.72 | G35: 4000 | H35: =G35-F35 -> 3679.28 | I35: =F35/G35 -> 0.08018
A36: Postage | E36: =SUM(B36:D36) -> 0 | F36: =E36 -> 0 | G36: 1000 | H36: =G36-F36 -> 1000 | I36: =F36/G36 -> 0
A37: Total NPOC | B37: =SUM(B23:B36) -> 3724.5 | C37: =SUM(C23:C36) -> 0 | D37: =SUM(D23:D36) -> 916.02 | E37: =SUM(E23:E36) -> 4640.52 | F37: =SUM(F23:F36) -> 4640.52 | G37: =SUM(G23:G36) -> 76745.7 | H37: =SUM(H23:H36) -> 72105.18 | I37: =F37/G37 -> 0.060466189
A40: 3. Participant Costs
A41: Participant Wages | C41: =+'Jul-2019 GL'!G10 -> 58923.44 | E41: =SUM(B41:D41) -> 58923.44 | F41: =E41 -> 58923.44 | G41: 1452829.2 | H41: =G41-F41-F42 -> 1393905.8 | I41: =F41/G41 -> 0.040557719
A42: Reimbursable Participant Wage(Paid by Affiliate) | C42: 0 | E42: =SUM(B42:D42) -> 0 | F42: =E42 -> 0 | I42: =F42/G42 -> #DIV/0!
A43: Participant Specialized Training Wage | C43: 0 | E43: =SUM(B43:D43) -> 0 | F43: =E43 -> 0 | G43: 12820 | H43: =G43-F43 -> 12820 | I43: =F43/G43 -> 0
A44: Participant FICA and other taxes | C44: =+'Jul-2019 GL'!G18 -> 4535.75 | E44: =SUM(B44:D44) -> 4535.75 | F44: =E44 -> 4535.75 | G44: 111141.44 | H44: =G44-F44 -> 106605.69 | I44: =F44/G44 -> 0.04081061
A45: Workers compensation | C45: =+'Jul-2019 GL'!G20 -> 2049.2 | E45: =SUM(B45:D45) -> 2049.2 | F45: =E45 -> 2049.2 | G45: 22373.57 | H45: =G45-F45 -> 20324.37 | I45: =F45/G45 -> 0.091590211
A46: Support Services | C46: 0 | E46: =SUM(B46:D46) -> 0 | F46: =E46 -> 0 | G46: 8500 | H46: =G46-F46 -> 8500 | I46: =F46/G46 -> 0
A47: Specialized Training vendor | C47: 0 | E47: =SUM(B47:D47) -> 0 | F47: =E47 -> 0 | G47: 29630 | H47: =G47-F47 -> 29630 | I47: =F47/G47 -> 0
A48: Total Participant Costs | B48: =SUM(B41:B47) -> 0 | C48: =SUM(C41:C47) -> 65508.39 | D48: =SUM(D41:D47) -> 0 | E48: =SUM(E41:E47) -> 65508.39 | F48: =SUM(F41:F47) -> 65508.39 | G48: =SUM(G41:G47) -> 1637294.2 | H48: =SUM(H41:H47) -> 1571785.9 | I48: =F48/G48 -> 0.040010151
...

Sheet Jul-2019 GL
A1: URBAN LEAGUE OF ESSEX COUNTY
A2: 451 USJP Program Transaction Detail by Account
A3: July 2019
B5: Date | C5: Trans Type | D5: Num | E5: Name | F5: Memo/Description | G5: Amount | H5: Check #
A6: 7100 Participant Salaries & Wages
A7: 7112 Participant Wages - USJP
B8: 07/15/2019 | C8: Journal Entry | D8: 00122 USJP | F8: USJP Participant Salaries 07/15 | G8: 13768.8
B9: 07/29/2019 | C9: Journal Entry | D9: 00123 USJP | F9: USJP Participant Salaries 07/29 | G9: 45154.64
A10: Total for 7112 Participant Wages - USJP | G10: =SUM(G8:G9) -> 58923.44
A11: 7112.1 USJP Manual Checks
B12: 07/29/2019 | C12: Journal Entry | D12: 00123 USJP | F12: USJP Participant Salaries 07/29 PY 2018 | G12: 284.81
B13: 07/30/2019 | C13: Deposit | E13: Paycom Payroll, LLC | F13: Paycheck/Salary Refund - Pamela flagg PY 2018 19-50-07 | G13: -38.76
A14: Total for 7112.1 USJP Manual Checks | G14: =SUM(G12:G13) -> 246.05
A15: 7120 Payroll Taxes
B16: 07/15/2019 | C16: Journal Entry | D16: 00122 USJP | F16: USJP Participant Salaries 07/15 | G16: 1052.81
B17: 07/29/2019 | C17: Journal Entry | D17: 00123 USJP | F17: USJP Participant Salaries 07/29 | G17: 3482.94
A18: Total for 7120 Payroll Taxes | G18: =SUM(G16:G17) -> 4535.75
A19: 7130 Worker's Compensation - USJP
B20: 07/31/2019 | C20: Journal Entry | D20: 139 | F20: Workers Comp Alloc - Participants | G20: 2049.2
A21: Total for 7130 Worker's Compensation - USJP | G21: =SUM(G20) -> 2049.2
A22: 7132 Payroll Expenses - Fees
B23: 07/15/2019 | C23: Journal Entry | D23: 00122 USJP | F23: USJP Participant Salaries 07/15 | G23: 393.64
B24: 07/29/2019 | C24: Journal Entry | D24: 00123 USJP | F24: USJP Participant Salaries 07/29 | G24: 478.62
A25: Total for 7132 Payroll Expenses - Fees | G25: =SUM(G23:G24) -> 872.26
A26: 7220 Salaries & Wages
B27: 07/31/2019 | C27: Journal Entry | D27: 00127 Salaries | F27: Salary Allocation - July | G27: 10715.26
A28: Total for 7220 Salaries & Wages | G28: =SUM(G27:G27) -> 10715.26
A29: 7240 Employee Benefits
A30: 7241 Health Insurance
B31: 07/31/2019 | C31: Journal Entry | D31: 153 | E31: Horizon Bluecross Blueshield | F31: Employee Health Insurance - Patricia Sermon | G31: 223.73 | H31: Online
B32: 07/31/2019 | C32: Journal Entry | D32: 153 | E32: Horizon Bluecross Blueshield | F32: Employee Health Insurance - USJP Staff | G32: 3547.28 | H32: Online
A33: Total for 7241 Health Insurance | G33: =SUM(G31:G32) -> 3771.01
A34: 7242 Life and Dental Insurance
B35: 07/01/2019 | C35: Bill | D35: 7.1.19PL | E35: Principal Financial Group | F35: Life, Dental & AD&D - USJP | G35: 169.96 | H35: 12274
A36: Total for 7242 Life and Dental Insurance | G36: =SUM(G35) -> 169.96
A37: 7244 Employee Contrib - Health
B38: 07/31/2019 | C38: Journal Entry | D38: 154 | F38: Employee Medical Contrib | G38: -757.36
A39: Total for 7244 Employee Contrib - Health | G39: =SUM(G38) -> -757.36
A40: 7247 Emp-ee Contrib -Dental
B41: 07/31/2019 | C41: Journal Entry | D41: 155 | F41: Employee Dental Contrib | G41: -20.25
...

Sheet JULY FR
A1: National Urban League Financial Report
A2: 1. Funding Agency- National Urban League | I2: 2. Federal Grant Name - Urban Seniors Jobs Program CFDA 17.235 | N2: PY 19
A3: 3. Recipient Organization - URBAN LEAGUE OF ESSEX COUNTY
A4: 508 CENTRAL AVENUE, NEWARK NJ 07107 | M4: 4. Final Report (mark X) Yes No | N4: 5. Basis of Reporting □ Accrual
A5: 6. Project/Grant Period From: July 1-2019 | H5: To: June 31, 2020 | M5: 7. Reporting Period End Date 7/31/2019
A6: 8. Transactions | M6: Cumulative
A7: Federal Cash:
A8: a. Cash Receipts
A9: b. Cash Disbursements | M9: =M8 -> 0
A10: c. Cash on Hand (line a minus b) | M10: =M8-M9 -> 0
A11: Federal Expenditures and Unobligated Balance:
A12: d. Approved Budget | M12: =+'Jul-2019'!G56 -> 2256075.9
A13: e. Federal Share of Expenditures -Program Costs | M13: =M9 -> 0
A14: f. Federal Share of Expenditures -Administrative Costs | M14: 0
A15: g. Federal Share of Unliquidated Obligations ( ACCRUALS) | M15: 0
A16: h. Total Federal Obligations (sum of lines e and g) | M16: =M13+M14+M15 -> 0
A17: i. Unobligated Balance of Federal Funds (line d minus h) | M17: =M12-M16 -> 2256075.9
A18: Recipient Share: Cost Sharing/ Matching/ In-Kind Costs
A19: j. Total Match and Inkind Required if Applicable | M19: =+'Jul-2019'!G54 -> 242467.32
A20: k. Total Receipient share reported if Applicable | M20: =+'Jul-2019'!E54 -> 7492.14
A21: l. Remaining Recipient Share to Be Provided (line j minus k) | M21: =M19-M20 -> 234975.18
A22: Program Income:
A23: m. Total Program Income Earned if applicable | M23: 0
A24: n. Program Income Expended in Accordance with the Addition Method | M24: 0
A25: o. Unexpended Program Income (line m minus line n) | M25: =M23-M24 -> 0
A26: 9. Remarks: (Attach any explanations deemed necessary or information required by Federal sponsoring agency in compliance with governing legislation.)
A28: 10. Indirect Expenditures
A29: a. Type of Rate | C29: b. Rate | D29: c. Rate Approval Date | G29: d. Period From (MM/DD/YYYY) | I29: Period To (MM/DD/YYYY) | J29: e. Base | M29: f. Amount Charged | N29: g. Federal Share
A32: 11. Certification: By signing this report, I certify to the best of my knowledge and belief that the report is true, complete, and accurate, and the expenditures, disbursements and cash receipts are for the purposes and objectives set forth in the terms and conditions of the Federal award. I am aware that any false, fictitious, or fraudulent information, or the omission of any material fact, may subject me to criminal, civil or administrative penalties for fraud, false statements, false claims or otherwise. (U.S. Code Title 18, Section 1001 and Title 31, Sections 3729–3730 and 3801–3812).
A33: a. Typed or Printed Name and Title of Authorized Certifying Official | M33: c. Telephone (Area code, number, and extension)
M34: d. Email Address
A35: b. Signature of Authorized Certifying Official | M35: e. Date Report Submitted (MM/DD/YYYY)

Sheet Aug-2019
A1: Urban Seniors Jobs Program PY 19 | G1: 43678 | I1: %
A2: Urban League of Essex County | E2: Invoice # 2 | I2: Spent
A3: 1. PERSONNEL | E3: TOTAL
C4: ENROLLEE | D4: OPC | E4: MONTHLY | F4: CUMULATIVE | G4: TOTAL | H4: BUDGET
A5: POSITION TITLE | B5: ADMIN | C5: WAGES & FB | D5: PROGRAM | E5: AMOUNT | F5: EXPENSES | G5: BUDGET | H5: REMAINING
A6: COO Patricia Sermon | B6: =+'Salaries & Fringe Allocations'!F73 -> 1261.54 | E6: =SUM(B6:D6) -> 1261.54 | F6: =E6+'Jul-2019'!F6 -> 2207.69 | G6: 16400 | H6: =G6-F6 -> 14192.31 | I6: =F6/G6 -> 0.13461524
A7: Director Gwendolyn Morris | B7: =+'Salaries & Fringe Allocations'!F74 -> 2107.14 | D7: =+'Salaries & Fringe Allocations'!F75 -> 2892.86 | E7: =SUM(B7:D7) -> 5000 | F7: =E7+'Jul-2019'!F7 -> 8750 | G7: 66000 | H7: =G7-F7 -> 57250 | I7: =F7/G7 -> 0.13257576
A8: Prog Site Coordinator (Essex) Rahmel Leake | D8: =+'Salaries & Fringe Allocations'!F76 -> 3076.94 | E8: =SUM(B8:D8) -> 3076.94 | F8: =E8+'Jul-2019'!F8 -> 3846.18 | G8: 40000 | H8: =G8-F8 -> 36153.82 | I8: =F8/G8 -> 0.0961545
A9: Prog Site Coordinator (Passaic) Irene Cerna | D9: =+'Salaries & Fringe Allocations'!F77 -> 2307.7 | E9: =SUM(B9:D9) -> 2307.7 | F9: =E9+'Jul-2019'!F9 -> 4038.58 | G9: 30000 | H9: =G9-F9 -> 25961.42 | I9: =F9/G9 -> 0.13461933
A10: Prog Site Coordinator (Morris) Alberto Almanzar | D10: =+'Salaries & Fringe Allocations'!F78 -> 1730.4 | E10: =SUM(B10:D10) -> 1730.4 | F10: =E10+'Jul-2019'!F10 -> 2941.68 | G10: 21500 | H10: =G10-F10 -> 18558.32 | I10: =F10/G10 -> 0.13682233
A11: Program Assistant Joanna Martinez | B11: =+'Salaries & Fringe Allocations'!F79 -> 1318.69 | D11: =+'Salaries & Fringe Allocations'!F80 -> 1604.4 | E11: =SUM(B11:D11) -> 2923.09 | F11: =E11+'Jul-2019'!F11 -> 5230.8 | G11: 36000 | H11: =G11-F11 -> 30769.2 | I11: =F11/G11 -> 0.1453
A12: Staff Accountant - Gregory Ward | B12: =+'Salaries & Fringe Allocations'!F81 -> 846.15 | E12: =SUM(B12:D12) -> 846.15 | F12: =E12+'Jul-2019'!F12 -> 846.15 | G12: 4000 | H12: =G12-F12 -> 3153.85 | I12: =F12/G12 -> 0.2115375
A16: Total Salaries | B16: =SUM(B6:B15) -> 5533.52 | C16: =SUM(C6:C15) -> 0 | D16: =SUM(D6:D15) -> 11612.3 | E16: =SUM(E6:E15) -> 17145.82 | F16: =SUM(F6:F15) -> 27861.08 | G16: =SUM(G6:G15) -> 213900 | H16: =SUM(H6:H15) -> 186038.92 | I16: =F16/G16 -> 0.13025283
A18: Fringe Benefits Rate | B18: =+'Salaries & Fringe Allocations'!Q73+'Salaries & Fringe Allocations'!Q74+'Salaries & Fringe Allocations'!Q79+'Salaries & Fringe Allocations'!Q81 -> 2040.4429 | D18: =+'Salaries & Fringe Allocations'!Q75+'Salaries & Fringe Allocations'!Q76+'Salaries & Fringe Allocations'!Q77+'Salaries & Fringe Allocations'!Q78+'Salaries & Fringe Allocations'!Q80 -> 3853.1845 | E18: =SUM(B18:D18) -> 5893.6274 | F18: =E18+'Jul-2019'!F18 -> 10643.871 | G18: 68136 | H18: =G18-F18 -> 57492.129 | I18: =F18/G18 -> 0.15621509
H19: =G19-F19 -> 0
A20: TOTAL PERSONNEL (Salaries + Fringe Benefits) | B20: =B16+B18 -> 7573.9629 | C20: =C16+C18 -> 0 | D20: =D16+D18 -> 15465.484 | E20: =E16+E18 -> 23039.447 | F20: =F16+F18 -> 38504.951 | G20: =G16+G18 -> 282036 | H20: =H16+H18 -> 243531.05 | I20: =F20/G20 -> 0.13652495
A22: 2. Non-Personnel Operating Costs
A23: Travel | D23: =+'Aug 2019 GL'!G77 -> 287.13 | E23: =SUM(B23:D23) -> 287.13 | F23: =E23+'Jul-2019'!F23 -> 555.15 | G23: 4000 | H23: =G23-F23 -> 3444.85 | I23: =F23/G23 -> 0.1387875
A24: ='Jul-2019'!A24 -> Supplies | B24: =+'Aug 2019 GL'!G85 -> 86 | D24: =+'Aug 2019 GL'!G81 -> 329.9 | E24: =SUM(B24:D24) -> 415.9 | F24: =E24+'Jul-2019'!F24 -> 471.49 | G24: 7000 | H24: =G24-F24 -> 6528.51 | I24: =F24/G24 -> 0.067355714
A25: ='Jul-2019'!A25 -> Staff Development | E25: =SUM(B25:D25) -> 0 | F25: =E25+'Jul-2019'!F25 -> 0 | G25: 2000 | H25: =G25-F25 -> 2000 | I25: =F25/G25 -> 0
A26: ='Jul-2019'!A26 -> Contractual/Consultants | B26: =+'Aug 2019 GL'!G92 -> 496 | E26: =SUM(B26:D26) -> 496 | F26: =E26+'Jul-2019'!F26 -> 857.69 | G26: 13200 | H26: =G26-F26 -> 12342.31 | I26: =F26/G26 -> 0.064976515
A27: ='Jul-2019'!A27 -> Occupancy | B27: =+'Aug 2019 GL'!G105 -> 273 | D27: =+'Aug 2019 GL'!G97 -> 648 | E27: =SUM(B27:D27) -> 921 | F27: =E27+'Jul-2019'!F27 -> 1901.27 | G27: 12000 | H27: =G27-F27 -> 10098.73 | I27: =F27/G27 -> 0.15843917
A28: ='Jul-2019'!A28 -> Audit (100% Admin) | E28: =SUM(B28:D28) -> 0 | F28: =E28+'Jul-2019'!F28 -> 1130.29 | G28: 6000 | H28: =G28-F28 -> 4869.71 | I28: =F28/G28 -> 0.18838167
A29: ='Jul-2019'!A29 -> Marketing and Outreach | E29: =SUM(B29:D29) -> 0 | F29: =E29+'Jul-2019'!F29 -> 0 | G29: 570 | H29: =G29-F29 -> 570 | I29: =F29/G29 -> 0
A30: ='Jul-2019'!A30 -> Rental Equipment | B30: =+'Aug 2019 GL'!G116 -> 522 | E30: =SUM(B30:D30) -> 522 | F30: =E30+'Jul-2019'!F30 -> 722.95 | G30: 6475 | H30: =G30-F30 -> 5752.05 | I30: =F30/G30 -> 0.11165251
A31: ='Jul-2019'!A31 -> Participant Payroll fees | B31: =+'Aug 2019 GL'!G25 -> 1001.69 | E31: =SUM(B31:D31) -> 1001.69 | F31: =E31+'Jul-2019'!F31 -> 1873.95 | G31: 13000 | H31: =G31-F31 -> 11126.05 | I31: =F31/G31 -> 0.14415
A32: ='Jul-2019'!A32 -> Infrastructure Costs | E32: =SUM(B32:D32) -> 0 | F32: =E32+'Jul-2019'!F32 -> 0 | G32: 1500 | H32: =G32-F32 -> 1500 | I32: =F32/G32 -> 0
A33: ='Jul-2019'!A33 -> Other Operating costs | B33: =+'Aug 2019 GL'!G132 -> 575.94 | E33: =SUM(B33:D33) -> 575.94 | F33: =E33+'Jul-2019'!F33 -> 843.82 | G33: 3000.7 | H33: =G33-F33 -> 2156.88 | I33: =F33/G33 -> 0.28120772
A34: Communications | B34: =+'Aug 2019 GL'!G141 -> 272 | E34: =SUM(B34:D34) -> 272 | F34: =E34+'Jul-2019'!F34 -> 454.85 | G34: 3000 | H34: =G34-F34 -> 2545.15 | I34: =F34/G34 -> 0.15161667
A35: Insurance | B35: =+'Aug 2019 GL'!G147 -> 503 | E35: =SUM(B35:D35) -> 503 | F35: =E35+'Jul-2019'!F35 -> 823.72 | G35: 4000 | H35: =G35-F35 -> 3176.28 | I35: =F35/G35 -> 0.20593
A36: Postage | B36: =+'Aug 2019 GL'!G152 -> 38 | E36: =SUM(B36:D36) -> 38 | F36: =E36+'Jul-2019'!F36 -> 38 | G36: 1000 | H36: =G36-F36 -> 962 | I36: =F36/G36 -> 0.038
A37: Total NPOC | B37: =SUM(B23:B36) -> 3767.63 | C37: =SUM(C23:C36) -> 0 | D37: =SUM(D23:D36) -> 1265.03 | E37: =SUM(E23:E36) -> 5032.66 | F37: =SUM(F23:F36) -> 9673.18 | G37: =SUM(G23:G36) -> 76745.7 | H37: =SUM(H23:H36) -> 67072.52 | I37: =F37/G37 -> 0.12604198
A40: 3. Participant Costs
A41: Participant Wages | C41: =+'Aug 2019 GL'!G9-C42 -> 94574.04 | E41: =SUM(B41:D41) -> 94574.04 | F41: =E41+'Jul-2019'!F41 -> 153497.48 | G41: 1452829.2 | H41: =G41-F41-F42 -> 1298821.8 | I41: =F41/G41 -> 0.10565418
A42: Reimbursable Participant Wage(Paid by Affiliate) | C42: =SUM('Aug 2019 GL'!G11:G12) -> 509.96 | E42: =SUM(B42:D42) -> 509.96 | F42: =E42+'Jul-2019'!F42 -> 509.96 | I42: =F42/G42 -> #DIV/0!
A43: Participant Specialized Training Wage | E43: =SUM(B43:D43) -> 0 | F43: =E43+'Jul-2019'!F43 -> 0 | G43: 12820 | H43: =G43-F43 -> 12820 | I43: =F43/G43 -> 0
A44: Participant FICA and other taxes | C44: =+'Aug 2019 GL'!G18 -> 7276 | E44: =SUM(B44:D44) -> 7276 | F44: =E44+'Jul-2019'!F44 -> 11811.75 | G44: 111141.44 | H44: =G44-F44 -> 99329.69 | I44: =F44/G44 -> 0.10627674
A45: Workers compensation | C45: =+'Aug 2019 GL'!G21 -> 2741 | E45: =SUM(B45:D45) -> 2741 | F45: =E45+'Jul-2019'!F45 -> 4790.2 | G45: 22373.57 | H45: =G45-F45 -> 17583.37 | I45: =F45/G45 -> 0.21410083
A46: Support Services | E46: =SUM(B46:D46) -> 0 | F46: =E46+'Jul-2019'!F46 -> 0 | G46: 8500 | H46: =G46-F46 -> 8500 | I46: =F46/G46 -> 0
A47: Specialized Training vendor | E47: =SUM(B47:D47) -> 0 | F47: =E47+'Jul-2019'!F47 -> 0 | G47: 29630 | H47: =G47-F47 -> 29630 | I47: =F47/G47 -> 0
...

Sheet Aug 2019 GL
A1: URBAN LEAGUE OF ESSEX COUNTY
A2: 451 USJP Program Transaction Detail by Account
A3: August 2019
B5: Date | C5: Transaction Type | D5: Num | E5: Name | F5: Memo/Description | G5: Amount | H5: Check #
A6: 7100 Participant Salaries & Wages
B7: 08/12/2019 | C7: Journal Entry | D7: 00124 USJP | F7: USJP Participant Salaries 08/12 | G7: 46610
B8: 08/26/2019 | C8: Journal Entry | D8: 162 | F8: USJP Participant Salaries 08/26 | G8: 48474
A9: Total for 7112 Participant Wages - USJP | G9: =SUM(G7:G8) -> 95084
A10: 7112.1 USJP Manual Checks
B11: 08/13/2019 | C11: Bill | D11: 08.13.19RP | E11: Renee Portee | F11: Renee Portee owed hours for non-payment- 07/18/19 - 07/31/19 | G11: 236.8 | H11: 12375
B12: 08/13/2019 | C12: Bill | D12: 08.13.19KP | E12: Karen Peterson | F12: Hours owed for non payment - 07/18/19 - 07/31/19 | G12: 273.16 | H12: 12376
A13: Total for 7112.1 USJP Manual Checks | G13: =SUM(G11:G12) -> 509.96
A14: Total for 7112 Participant Wages - USJP with subs | G14: =+G13+G9 -> 95593.96
A15: 7120 Payroll Taxes
B16: 08/12/2019 | C16: Journal Entry | D16: 00124 USJP | F16: Employer Liability | G16: 3565.8
B17: 08/26/2019 | C17: Journal Entry | D17: 162 | F17: Employer Liability | G17: 3710.2
A18: Total for 7120 Payroll Taxes | G18: 7276
A19: 7130 Worker's Compensation - USJP
B20: 08/31/2019 | C20: Journal Entry | D20: 192 | F20: Workers Comp Alloc | G20: 2741
A21: Total for 7130 Worker's Compensation - USJP | G21: =SUM(G20) -> 2741
A22: 7132 Payroll Expenses - Fees
B23: 08/12/2019 | C23: Journal Entry | D23: 00124 USJP | F23: USJP Payroll Fee | G23: 401.87
B24: 08/26/2019 | C24: Journal Entry | D24: 162 | F24: USJP Payroll Fee | G24: 599.82
A25: Total for 7132 Payroll Expenses - Fees | G25: =SUM(G23:G24) -> 1001.69
A26: 7200 Salaries & Related Expenses
A27: 7220 Salaries & Wages
B28: 08/31/2019 | C28: Journal Entry | D28: 175 | F28: USJP Staff Salary Allocation - August | G28: 17145.83
A29: Total for 7220 Salaries & Wages | G29: =SUM(G28) -> 17145.83
A30: 7240 Employee Benefits
A31: 7241 Health Insurance
B32: 08/30/2019 | C32: Journal Entry | D32: 202 | F32: Horizon Health Insurance | G32: 3813.99 | H32: ONLINE
A33: Total for 7241 Health Insurance | G33: =SUM(G32) -> 3813.99
A34: 7242 Life and Dental Insurance
B35: 08/09/2019 | C35: Bill | E35: Principal Financial Group | F35: Life, Dental & AD&D - USJP | G35: 171.06 | H35: 12345
A36: Total for 7242 Life and Dental Insurance | G36: =SUM(G35) -> 171.06
A37: 7244 Employee Contrib - Health
B38: 43708 | C38: Journal Entry | D38: 154 | F38: Employee Medical Contrib | G38: -704.12
A39: Total for 7244 Employee Contrib - Health | G39: =SUM(G38) -> -704.12
A40: 7247 Emp-ee Contrib -Dental
B41: 43708 | C41: Journal Entry | D41: 155 | F41: Employee Dental Contrib | G41: -20.31
...

Sheet AUG-FR
A1: National Urban League Financial Report
A2: 1. Funding Agency- National Urban League | I2: 2. Federal Grant Name - Urban Seniors Jobs Program CFDA 17.235 | N2: PY 19
A3: 3. Recipient Organization (Name and complete address including Zip code)
M4: 4. Final Report (mark X) Yes No | N4: 5. Basis of Reporting □ Accrual
A5: 6. Project/Grant Period From: July 1-2019 | H5: To: June 31, 2020 | M5: 7. Reporting Period End Date 8/31/2019
A6: 8. Transactions | M6: Cumulative
A7: Federal Cash:
A8: a. Cash Receipts
A9: b. Cash Disbursements | M9: =M8 -> 0
A10: c. Cash on Hand (line a minus b) | M10: =M8-M9 -> 0
A11: Federal Expenditures and Unobligated Balance:
A12: d. Approved Budget
A13: e. Federal Share of Expenditures -Program Costs | M13: =M9 -> 0
A14: f. Federal Share of Expenditures -Administrative Costs | M14: 0
A15: g. Federal Share of Unliquidated Obligations ( ACCRUALS) | M15: 0
A16: h. Total Federal Obligations (sum of lines e and g) | M16: =M13+M14+M15 -> 0
A17: i. Unobligated Balance of Federal Funds (line d minus h) | M17: =M12-M16 -> 0
A18: Recipient Share: Cost Sharing/ Matching/ In-Kind Costs
A19: j. Total Match and Inkind Required if Applicable | M19: 0
A20: k. Total Receipient share reported if Applicable | M20: 0
A21: l. Remaining Recipient Share to Be Provided (line j minus k) | M21: =M19-M20 -> 0
A22: Program Income:
A23: m. Total Program Income Earned if applicable | M23: 0
A24: n. Program Income Expended in Accordance with the Addition Method | M24: 0
A25: o. Unexpended Program Income (line m minus line n) | M25: =M23-M24 -> 0
A26: 9. Remarks: (Attach any explanations deemed necessary or information required by Federal sponsoring agency in compliance with governing legislation.)
A28: 10. Indirect Expenditures
A29: a. Type of Rate | C29: b. Rate | D29: c. Rate Approval Date | G29: d. Period From (MM/DD/YYYY) | I29: Period To (MM/DD/YYYY) | J29: e. Base | M29: f. Amount Charged | N29: g. Federal Share
A32: 11. Certification: By signing this report, I certify to the best of my knowledge and belief that the report is true, complete, and accurate, and the expenditures, disbursements and cash receipts are for the purposes and objectives set forth in the terms and conditions of the Federal award. I am aware that any false, fictitious, or fraudulent information, or the omission of any material fact, may subject me to criminal, civil or administrative penalties for fraud, false statements, false claims or otherwise. (U.S. Code Title 18, Section 1001 and Title 31, Sections 3729–3730 and 3801–3812).
A33: a. Typed or Printed Name and Title of Authorized Certifying Official | M33: c. Telephone (Area code, number, and extension)
M34: d. Email Address
A35: b. Signature of Authorized Certifying Official | M35: e. Date Report Submitted (MM/DD/YYYY)

Sheet Sept-2019
A1: Urban Seniors Jobs Program PY 19 | G1: 43709 | I1: %
A2: Urban League of Essex County | E2: Invoice # 3 | I2: Spent
A3: 1. PERSONNEL | E3: TOTAL
C4: ENROLLEE | D4: OPC | E4: MONTHLY | F4: CUMULATIVE | G4: TOTAL | H4: BUDGET
A5: POSITION TITLE | B5: ADMIN | C5: WAGES & FB | D5: PROGRAM | E5: AMOUNT | F5: EXPENSES | G5: BUDGET | H5: REMAINING
A6: COO Patricia Sermon | B6: =+'Salaries & Fringe Allocations'!F113 -> 1261.54 | E6: =SUM(B6:D6) -> 1261.54 | F6: =E6+'Aug-2019'!F6 -> 3469.23 | G6: 16400 | H6: =G6-F6 -> 12930.77 | I6: =F6/G6 -> 0.21153841
A7: Director Gwendolyn Morris | B7: =+'Salaries & Fringe Allocations'!F114 -> 2071.43 | D7: =+'Salaries & Fringe Allocations'!F115 -> 2928.57 | E7: =SUM(B7:D7) -> 5000 | F7: =E7+'Aug-2019'!F7 -> 13750 | G7: 66000 | H7: =G7-F7 -> 52250 | I7: =F7/G7 -> 0.20833333
A8: Prog Site Coordinator (Essex) Rahmel Leake | D8: =+'Salaries & Fringe Allocations'!F116 -> 3076.94 | E8: =SUM(B8:D8) -> 3076.94 | F8: =E8+'Aug-2019'!F8 -> 6923.12 | G8: 40000 | H8: =G8-F8 -> 33076.88 | I8: =F8/G8 -> 0.173078
A9: Prog Site Coordinator (Passaic) Irene Cerna | D9: =+'Salaries & Fringe Allocations'!F117 -> 1730.78 | E9: =SUM(B9:D9) -> 1730.78 | F9: =E9+'Aug-2019'!F9 -> 5769.36 | G9: 30000 | H9: =G9-F9 -> 24230.64 | I9: =F9/G9 -> 0.192312
A10: Prog Site Coordinator (Morris) Alberto Almanzar | D10: =+'Salaries & Fringe Allocations'!F118 -> 1268.96 | E10: =SUM(B10:D10) -> 1268.96 | F10: =E10+'Aug-2019'!F10 -> 4210.64 | G10: 21500 | H10: =G10-F10 -> 17289.36 | I10: =F10/G10 -> 0.19584372
A11: Program Assistant Joanna Martinez | B11: =+'Salaries & Fringe Allocations'!F119 -> 703.3 | D11: =+'Salaries & Fringe Allocations'!F120 -> 1050.57 | E11: =SUM(B11:D11) -> 1753.87 | F11: =E11+'Aug-2019'!F11 -> 6984.67 | G11: 36000 | H11: =G11-F11 -> 29015.33 | I11: =F11/G11 -> 0.19401861
A12: Staff Accountant - Gregory Ward | B12: =+'Salaries & Fringe Allocations'!F121 -> 846.15 | E12: =SUM(B12:D12) -> 846.15 | F12: =E12+'Aug-2019'!F12 -> 1692.3 | G12: 4000 | H12: =G12-F12 -> 2307.7 | I12: =F12/G12 -> 0.423075
A16: Total Salaries | B16: =SUM(B6:B15) -> 4882.42 | C16: =SUM(C6:C15) -> 0 | D16: =SUM(D6:D15) -> 10055.82 | E16: =SUM(E6:E15) -> 14938.24 | F16: =SUM(F6:F15) -> 42799.32 | G16: =SUM(G6:G15) -> 213900 | H16: =SUM(H6:H15) -> 171100.68 | I16: =F16/G16 -> 0.20009032
A18: Fringe Benefits Rate | B18: =+'Salaries & Fringe Allocations'!Q113+'Salaries & Fringe Allocations'!Q114+'Salaries & Fringe Allocations'!Q119+'Salaries & Fringe Allocations'!Q121 -> 1816.6301 | D18: =+'Salaries & Fringe Allocations'!Q115+'Salaries & Fringe Allocations'!Q116+'Salaries & Fringe Allocations'!Q117+'Salaries & Fringe Allocations'!Q118+'Salaries & Fringe Allocations'!Q120 -> 3474.9889 | E18: =SUM(B18:D18) -> 5291.619 | F18: =E18+'Aug-2019'!F18 -> 15935.49 | G18: 68136 | H18: =G18-F18 -> 52200.51 | I18: =F18/G18 -> 0.23387769
H19: =G19-F19 -> 0
A20: TOTAL PERSONNEL (Salaries + Fringe Benefits) | B20: =B16+B18 -> 6699.0501 | C20: =C16+C18 -> 0 | D20: =D16+D18 -> 13530.809 | E20: =E16+E18 -> 20229.859 | F20: =F16+F18 -> 58734.81 | G20: =G16+G18 -> 282036 | H20: =H16+H18 -> 223301.19 | I20: =F20/G20 -> 0.20825288
A22: 2. Non-Personnel Operating Costs
A23: Travel | B23: =+'Sept-2019 GL'!G81 -> 312.43 | E23: =SUM(B23:D23) -> 312.43 | F23: =E23+'Aug-2019'!F23 -> 867.58 | G23: 4000 | H23: =G23-F23 -> 3132.42 | I23: =F23/G23 -> 0.216895
A24: Supplies | E24: =SUM(B24:D24) -> 0 | F24: =E24+'Aug-2019'!F24 -> 471.49 | G24: 7000 | H24: =G24-F24 -> 6528.51 | I24: =F24/G24 -> 0.067355714
A25: Staff Development | E25: =SUM(B25:D25) -> 0 | F25: =E25+'Aug-2019'!F25 -> 0 | G25: 2000 | H25: =G25-F25 -> 2000 | I25: =F25/G25 -> 0
A26: Contractual/Consultants | B26: =+'Sept-2019 GL'!G86 -> 606 | E26: =SUM(B26:D26) -> 606 | F26: =E26+'Aug-2019'!F26 -> 1463.69 | G26: 13200 | H26: =G26-F26 -> 11736.31 | I26: =F26/G26 -> 0.11088561
A27: Occupancy | B27: =+'Sept-2019 GL'!G100 -> 230 | D27: =+'Sept-2019 GL'!G91 -> 648 | E27: =SUM(B27:D27) -> 878 | F27: =E27+'Aug-2019'!F27 -> 2779.27 | G27: 12000 | H27: =G27-F27 -> 9220.73 | I27: =F27/G27 -> 0.23160583
A28: Audit (100% Admin) | E28: =SUM(B28:D28) -> 0 | F28: =E28+'Aug-2019'!F28 -> 1130.29 | G28: 6000 | H28: =G28-F28 -> 4869.71 | I28: =F28/G28 -> 0.18838167
A29: Marketing and Outreach | E29: =SUM(B29:D29) -> 0 | F29: =E29+'Aug-2019'!F29 -> 0 | G29: 570 | H29: =G29-F29 -> 570 | I29: =F29/G29 -> 0
A30: Rental Equipment | B30: =+'Sept-2019 GL'!G107 -> 287 | E30: =SUM(B30:D30) -> 287 | F30: =E30+'Aug-2019'!F30 -> 1009.95 | G30: 6475 | H30: =G30-F30 -> 5465.05 | I30: =F30/G30 -> 0.15597683
A31: Payroll fees | B31: =+'Sept-2019 GL'!G30 -> 877.52 | E31: =SUM(B31:D31) -> 877.52 | F31: =E31+'Aug-2019'!F31 -> 2751.47 | G31: 13000 | H31: =G31-F31 -> 10248.53 | I31: =F31/G31 -> 0.21165154
A32: Infrastructure Costs | E32: =SUM(B32:D32) -> 0 | F32: =E32+'Aug-2019'!F32 -> 0 | G32: 1500 | H32: =G32-F32 -> 1500 | I32: =F32/G32 -> 0
A33: Other Operating costs | B33: =+'Sept-2019 GL'!G117 -> 411 | E33: =SUM(B33:D33) -> 411 | F33: =E33+'Aug-2019'!F33 -> 1254.82 | G33: 3000.7 | H33: =G33-F33 -> 1745.88 | I33: =F33/G33 -> 0.41817576
A34: Communications | B34: =+'Sept-2019 GL'!G129 -> 226.16 | E34: =SUM(B34:D34) -> 226.16 | F34: =E34+'Aug-2019'!F34 -> 681.01 | G34: 3000 | H34: =G34-F34 -> 2318.99 | I34: =F34/G34 -> 0.22700333
A35: Insurance | B35: =+'Sept-2019 GL'!G135 -> 491 | E35: =SUM(B35:D35) -> 491 | F35: =E35+'Aug-2019'!F35 -> 1314.72 | G35: 4000 | H35: =G35-F35 -> 2685.28 | I35: =F35/G35 -> 0.32868
A36: Postage | E36: =SUM(B36:D36) -> 0 | F36: =E36+'Aug-2019'!F36 -> 38 | G36: 1000 | H36: =G36-F36 -> 962 | I36: =F36/G36 -> 0.038
A37: Total NPOC | B37: =SUM(B23:B36) -> 3441.11 | C37: =SUM(C23:C36) -> 0 | D37: =SUM(D23:D36) -> 648 | E37: =SUM(E23:E36) -> 4089.11 | F37: =SUM(F23:F36) -> 13762.29 | G37: =SUM(G23:G36) -> 76745.7 | H37: =SUM(H23:H36) -> 62983.41 | I37: =F37/G37 -> 0.17932327
A40: 3. Participant Costs
A41: Participant Wages | C41: =+'Sept-2019 GL'!G9 -> 90254 | E41: =SUM(B41:D41) -> 90254 | F41: =E41+'Aug-2019'!F41 -> 243751.48 | G41: 1452829.2 | H41: =G41-F41-F42 -> 1207081.2 | I41: =F41/G41 -> 0.1677771
A42: Reimbursable Participant Wage(Paid by Affiliate) | C42: =+'Sept-2019 GL'!G18 -> 1486.56 | E42: =SUM(B42:D42) -> 1486.56 | F42: =E42+'Aug-2019'!F42 -> 1996.52 | I42: 0
A43: Participant Specialized Training Wage | E43: =SUM(B43:D43) -> 0 | F43: =E43+'Aug-2019'!F43 -> 0 | G43: 12820 | H43: =G43-F43 -> 12820 | I43: =F43/G43 -> 0
A44: Participant FICA and other taxes | C44: =+'Sept-2019 GL'!G23 -> 6904.52 | E44: =SUM(B44:D44) -> 6904.52 | F44: =E44+'Aug-2019'!F44 -> 18716.27 | G44: 111141.44 | H44: =G44-F44 -> 92425.17 | I44: =F44/G44 -> 0.16840046
A45: Workers compensation | C45: =+'Sept-2019 GL'!G26 -> 2868 | E45: =SUM(B45:D45) -> 2868 | F45: =E45+'Aug-2019'!F45 -> 7658.2 | G45: 22373.57 | H45: =G45-F45 -> 14715.37 | I45: =F45/G45 -> 0.3422878
A46: Support Services | E46: =SUM(B46:D46) -> 0 | F46: =E46+'Aug-2019'!F46 -> 0 | G46: 8500 | H46: =G46-F46 -> 8500 | I46: =F46/G46 -> 0
A47: Specialized Training vendor | E47: =SUM(B47:D47) -> 0 | F47: =E47+'Aug-2019'!F47 -> 0 | G47: 29630 | H47: =G47-F47 -> 29630 | I47: =F47/G47 -> 0
...

Sheet Sept-2019 GL
A1: URBAN LEAGUE OF ESSEX COUNTY
A2: 451 USJP Program Transaction Detail by Account
A3: September 2019
B5: Date | C5: Transaction Type | D5: Num | E5: Name | F5: Memo/Description | G5: Amount | H5: Check #
A6: 7112 Participant Wages - USJP
B7: 09/09/2019 | C7: Journal Entry | D7: 243 | F7: USJP Participant Salaries 09/09 | G7: 47030
B8: 09/23/2019 | C8: Journal Entry | D8: 245 | F8: USJP Participant Salaries 09/09 | G8: 43224
A9: Total for 7112 Participant Wages - USJP | G9: =SUM(G7:G8) -> 90254
A10: 7112.1 USJP Manual Checks
B11: 09/11/2019 | C11: Bill | D11: 09.11.19CP | E11: Carolyn Parks | F11: Participant Wages 30 Training hours from 08/29 - 09/11/19 | G11: 273.13 | H11: 12506
B12: 09/11/2019 | C12: Bill | D12: 09.11.19CK | E12: Clarence Kersey | F12: 451-USJP - 25 Hrs Training from 08/29 - 09/11/19 | G12: 227.71 | H12: 12507
B13: 09/11/2019 | C13: Bill | D13: 09.11.19DD | E13: Deloris Davis | F13: 451-USJP - 25 Hrs Training from 08/29 - 09/11/19 | G13: 227.7 | H13: 12508
B14: 09/23/2019 | C14: Check | D14: 12494 | E14: David Garrett | F14: USJP 10 hours owed for Pay Period 8/29/19 - 9/11/19 Check Date 9/23/19 was paid for 30 hours instead of 40 hours in error | G14: 101.59 | H14: 12494
B15: 09/23/2019 | C15: Check | D15: 12496 | E15: Jeffrey Matthews | F15: USJP 29 Hours owed for Pay Period 8/29/19 - 9/11/19 Check Date 9/23/19. Employees hours were not included in Payroll file. | G15: 264.05 | H15: 12496
B16: 09/23/2019 | C16: Check | D16: 12497 | E16: Reginald Williams | F16: USJP Participant owed 16 hours for training from 8/29/19 - 9/11/19 Check Date 9/23/19. Not previously paid. | G16: 146.51 | H16: 12497
B17: 09/23/2019 | C17: Check | D17: 12495 | E17: Willie Chestnut | F17: USJP 27 Hours owed for Pay Period 8/29/19 - 9/11/19 Check Date 9/23/19. Employees hours were not included in Payroll file. | G17: 245.87 | H17: 12495
A18: Total for 7112.1 USJP Manual Checks | G18: =SUM(G11:G17) -> 1486.56
A19: Total for 7112 Participant Wages - USJP with subs | G19: =+G18+G9 -> 91740.56
A20: 7120 Payroll Taxes
B21: 09/09/2019 | C21: Journal Entry | D21: 243 | F21: Employer Liability | G21: 3597.9
B22: 09/23/2019 | C22: Journal Entry | D22: 245 | F22: Employer Liability | G22: 3306.62
A23: Total for 7120 Payroll Taxes | G23: 6904.52
A24: 7130 Worker's Compensation - USJP
B25: 43738 | C25: Journal Entry | D25: 192 | F25: Workers Comp Alloc | G25: 2868
A26: Total for 7130 Worker's Compensation - USJP | G26: =SUM(G25) -> 2868
A27: 7132 Payroll Expenses - Fees
B28: 09/09/2019 | C28: Journal Entry | D28: 243 | F28: USJP Payroll Fee | G28: 403.93
B29: 09/23/2019 | C29: Journal Entry | D29: 245 | F29: USJP Payroll Fee | G29: 473.59
A30: Total for 7132 Payroll Expenses - Fees | G30: 877.52
A31: Total for 7100 Participant Salaries & Wages | G31: =+G19+G23+G26+G30 -> 102390.6
A32: 7200 Salaries & Related Expenses
A33: 7220 Salaries & Wages
B34: 09/25/2019 | C34: Journal Entry | D34: 242 | F34: Salary Allocation - September | G34: 14938.24
A35: Total for 7220 Salaries & Wages | G35: =SUM(G34) -> 14938.24
A36: 7240 Employee Benefits
A37: 7241 Health Insurance
B38: 09/01/2019 | C38: Bill | D38: 292271815 | E38: Horizon Blue Cross Blue Shield of NJ | G38: 3813.99 | H38: 12472
A39: Total for 7241 Health Insurance | G39: =SUM(G38:G38) -> 3813.99
A40: 7242 Life and Dental Insurance
B41: 09/01/2019 | C41: Bill | D41: 09.01.19PL | E41: Principal Financial Group | F41: Life, Dental & AD&D - USJP | G41: 171.0615 | H41: 12433
...

Sheet Sept-FR
A1: National Urban League Financial Report
A2: 1. Funding Agency- National Urban League | I2: 2. Federal Grant Name - Urban Seniors Jobs Program CFDA 17.235 | N2: PY 19
A3: 3. Recipient Organization (Name and complete address including Zip code)
M4: 4. Final Report (mark X) Yes No | N4: 5. Basis of Reporting □ Accrual
A5: 6. Project/Grant Period From: July 1-2019 | H5: To: June 31, 2020 | M5: 7. Reporting Period End Date 9/30/2019
A6: 8. Transactions | M6: Cumulative
A7: Federal Cash:
A8: a. Cash Receipts
A9: b. Cash Disbursements | M9: =M8 -> 0
A10: c. Cash on Hand (line a minus b) | M10: =M8-M9 -> 0
A11: Federal Expenditures and Unobligated Balance:
A12: d. Approved Budget
A13: e. Federal Share of Expenditures -Program Costs | M13: =M9 -> 0
A14: f. Federal Share of Expenditures -Administrative Costs | M14: 0
A15: g. Federal Share of Unliquidated Obligations ( ACCRUALS) | M15: 0
A16: h. Total Federal Obligations (sum of lines e and g) | M16: =M13+M14+M15 -> 0
A17: i. Unobligated Balance of Federal Funds (line d minus h) | M17: =M12-M16 -> 0
A18: Recipient Share: Cost Sharing/ Matching/ In-Kind Costs
A19: j. Total Match and Inkind Required if Applicable | M19: 0
A20: k. Total Receipient share reported if Applicable | M20: 0
A21: l. Remaining Recipient Share to Be Provided (line j minus k) | M21: =M19-M20 -> 0
A22: Program Income:
A23: m. Total Program Income Earned if applicable | M23: 0
A24: n. Program Income Expended in Accordance with the Addition Method | M24: 0
A25: o. Unexpended Program Income (line m minus line n) | M25: =M23-M24 -> 0
A26: 9. Remarks: (Attach any explanations deemed necessary or information required by Federal sponsoring agency in compliance with governing legislation.)
A28: 10. Indirect Expenditures
A29: a. Type of Rate | C29: b. Rate | D29: c. Rate Approval Date | G29: d. Period From (MM/DD/YYYY) | I29: Period To (MM/DD/YYYY) | J29: e. Base | M29: f. Amount Charged | N29: g. Federal Share
A32: 11. Certification: By signing this report, I certify to the best of my knowledge and belief that the report is true, complete, and accurate, and the expenditures, disbursements and cash receipts are for the purposes and objectives set forth in the terms and conditions of the Federal award. I am aware that any false, fictitious, or fraudulent information, or the omission of any material fact, may subject me to criminal, civil or administrative penalties for fraud, false statements, false claims or otherwise. (U.S. Code Title 18, Section 1001 and Title 31, Sections 3729–3730 and 3801–3812).
A33: a. Typed or Printed Name and Title of Authorized Certifying Official | M33: c. Telephone (Area code, number, and extension)
M34: d. Email Address
A35: b. Signature of Authorized Certifying Official | M35: e. Date Report Submitted (MM/DD/YYYY)

Sheet Oct-2019
A1: Urban Seniors Jobs Program PY 19 | G1: 43739 | I1: %
A2: Urban League of Essex County | E2: Invoice # 4 | I2: Spent
A3: 1. PERSONNEL | E3: TOTAL
C4: ENROLLEE | D4: OPC | E4: MONTHLY | F4: CUMULATIVE | G4: TOTAL | H4: BUDGET
A5: POSITION TITLE | B5: ADMIN | C5: WAGES & FB | D5: PROGRAM | E5: AMOUNT | F5: EXPENSES | G5: BUDGET | H5: REMAINING
A6: COO Patricia Sermon | B6: =+'Salaries & Fringe Allocations'!F155 -> 1261.54 | E6: =SUM(B6:D6) -> 1261.54 | F6: =E6+'Sept-2019'!F6 -> 4730.77 | G6: 16400 | H6: =G6-F6 -> 11669.23 | I6: =F6/G6 -> 0.28846159
A7: Director Gwendolyn Morris | B7: =+'Salaries & Fringe Allocations'!F156 -> 2192.86 | D7: =+'Salaries & Fringe Allocations'!F157 -> 2807.14 | E7: =SUM(B7:D7) -> 5000 | F7: =E7+'Sept-2019'!F7 -> 18750 | G7: 66000 | H7: =G7-F7 -> 47250 | I7: =F7/G7 -> 0.28409091
A8: Prog Site Coordinator (Essex) Rahmel Leake | D8: =+'Salaries & Fringe Allocations'!F158 -> 3076.94 | E8: =SUM(B8:D8) -> 3076.94 | F8: =E8+'Sept-2019'!F8 -> 10000.06 | G8: 40000 | H8: =G8-F8 -> 29999.94 | I8: =F8/G8 -> 0.2500015
A9: Prog Site Coordinator (Passaic) Irene Cerna | D9: =+'Salaries & Fringe Allocations'!F159 -> 2192.32 | E9: =SUM(B9:D9) -> 2192.32 | F9: =E9+'Sept-2019'!F9 -> 7961.68 | G9: 30000 | H9: =G9-F9 -> 22038.32 | I9: =F9/G9 -> 0.26538933
A10: Site Coordinator (Morris) Armanda Johnson | D10: =+'Salaries & Fringe Allocations'!F160 -> 1586.2 | E10: =SUM(B10:D10) -> 1586.2 | F10: =E10+'Sept-2019'!F10 -> 5796.84 | G10: 21500 | H10: =G10-F10 -> 15703.16 | I10: =F10/G10 -> 0.26962047
A11: Program Assistant Joanna Martinez | E11: =SUM(B11:D11) -> 0 | F11: =E11+'Sept-2019'!F11 -> 6984.67 | G11: 36000 | H11: =G11-F11 -> 29015.33 | I11: =F11/G11 -> 0.19401861
A12: Staff Accountant - Gregory Ward | B12: =+'Salaries & Fringe Allocations'!F163 -> 846.15 | E12: =SUM(B12:D12) -> 846.15 | F12: =E12+'Sept-2019'!F12 -> 2538.45 | G12: 4000 | H12: =G12-F12 -> 1461.55 | I12: =F12/G12 -> 0.6346125
E13: =SUM(B13:D13) -> 0
E14: =SUM(B14:D14) -> 0
A16: Total Salaries | B16: =SUM(B6:B15) -> 4300.55 | C16: =SUM(C6:C15) -> 0 | D16: =SUM(D6:D15) -> 9662.6 | E16: =SUM(E6:E15) -> 13963.15 | F16: =SUM(F6:F15) -> 56762.47 | G16: =SUM(G6:G15) -> 213900 | H16: =SUM(H6:H15) -> 157137.53 | I16: =F16/G16 -> 0.26536919
A18: Fringe Benefits Rate | B18: =+'Salaries & Fringe Allocations'!Q155+'Salaries & Fringe Allocations'!Q156+'Salaries & Fringe Allocations'!Q161+'Salaries & Fringe Allocations'!Q163 -> 2590.7237 | D18: =+'Salaries & Fringe Allocations'!Q157+'Salaries & Fringe Allocations'!Q158+'Salaries & Fringe Allocations'!Q159+'Salaries & Fringe Allocations'!Q160+'Salaries & Fringe Allocations'!Q162 -> 2661.3133 | E18: =SUM(B18:D18) -> 5252.037 | F18: =E18+'Sept-2019'!F18 -> 21187.527 | G18: 68136 | H18: =G18-F18 -> 46948.473 | I18: =F18/G18 -> 0.31095937
H19: =G19-F19 -> 0
A20: TOTAL PERSONNEL (Salaries + Fringe Benefits) | B20: =B16+B18 -> 6891.2737 | C20: =C16+C18 -> 0 | D20: =D16+D18 -> 12323.913 | E20: =E16+E18 -> 19215.187 | F20: =F16+F18 -> 77949.997 | G20: =G16+G18 -> 282036 | H20: =H16+H18 -> 204086 | I20: =F20/G20 -> 0.27638315
A22: 2. Non-Personnel Operating Costs
A23: Travel | B23: =+'Oct-2019 GL'!G82 -> 271.3 | E23: =SUM(B23:D23) -> 271.3 | F23: =E23+'Sept-2019'!F23 -> 1138.88 | G23: 4000 | H23: =G23-F23 -> 2861.12 | I23: =F23/G23 -> 0.28472
A24: Supplies | B24: =+'Oct-2019 GL'!G88 -> 254 | D24: =+'Oct-2019 GL'!G85 -> 30.5 | E24: =SUM(B24:D24) -> 284.5 | F24: =E24+'Sept-2019'!F24 -> 755.99 | G24: 7000 | H24: =G24-F24 -> 6244.01 | I24: =F24/G24 -> 0.10799857
A25: Staff Development | E25: =SUM(B25:D25) -> 0 | F25: =E25+'Sept-2019'!F25 -> 0 | G25: 2000 | H25: =G25-F25 -> 2000 | I25: =F25/G25 -> 0
A26: Contractual/Consultants | B26: =+'Oct-2019 GL'!G95 -> 683 | E26: =SUM(B26:D26) -> 683 | F26: =E26+'Sept-2019'!F26 -> 2146.69 | G26: 13200 | H26: =G26-F26 -> 11053.31 | I26: =F26/G26 -> 0.16262803
A27: Occupancy | B27: =+'Oct-2019 GL'!G117 -> 766 | D27: =+'Oct-2019 GL'!G100 -> 648 | E27: =SUM(B27:D27) -> 1414 | F27: =E27+'Sept-2019'!F27 -> 4193.27 | G27: 12000 | H27: =G27-F27 -> 7806.73 | I27: =F27/G27 -> 0.34943917
A28: Audit (100% Admin) | E28: =SUM(B28:D28) -> 0 | F28: =E28+'Sept-2019'!F28 -> 1130.29 | G28: 6000 | H28: =G28-F28 -> 4869.71 | I28: =F28/G28 -> 0.18838167
A29: Marketing and Outreach | E29: =SUM(B29:D29) -> 0 | F29: =E29+'Sept-2019'!F29 -> 0 | G29: 570 | H29: =G29-F29 -> 570 | I29: =F29/G29 -> 0
A30: Rental Equipment | B30: =+'Oct-2019 GL'!G124 -> 274 | E30: =SUM(B30:D30) -> 274 | F30: =E30+'Sept-2019'!F30 -> 1283.95 | G30: 6475 | H30: =G30-F30 -> 5191.05 | I30: =F30/G30 -> 0.19829344
A31: Payroll fees | C31: =+'Oct-2019 GL'!G25 -> 900.49 | E31: =SUM(B31:D31) -> 900.49 | F31: =E31+'Sept-2019'!F31 -> 3651.96 | G31: 13000 | H31: =G31-F31 -> 9348.04 | I31: =F31/G31 -> 0.28092
A32: Infrastructure Costs | E32: =SUM(B32:D32) -> 0 | F32: =E32+'Sept-2019'!F32 -> 0 | G32: 1500 | H32: =G32-F32 -> 1500 | I32: =F32/G32 -> 0
A33: Other Operating costs | B33: =+'Oct-2019 GL'!G137 -> 107 | E33: =SUM(B33:D33) -> 107 | F33: =E33+'Sept-2019'!F33 -> 1361.82 | G33: 3000.7 | H33: =G33-F33 -> 1638.88 | I33: =F33/G33 -> 0.45383411
A34: Communications | B34: =+'Oct-2019 GL'!G152 -> 355.01 | E34: =SUM(B34:D34) -> 355.01 | F34: =E34+'Sept-2019'!F34 -> 1036.02 | G34: 3000 | H34: =G34-F34 -> 1963.98 | I34: =F34/G34 -> 0.34534
A35: Insurance | B35: =+'Oct-2019 GL'!G157 -> 443 | E35: =SUM(B35:D35) -> 443 | F35: =E35+'Sept-2019'!F35 -> 1757.72 | G35: 4000 | H35: =G35-F35 -> 2242.28 | I35: =F35/G35 -> 0.43943
